{"v":1,"kind":"tick","pair":"ADA/USD","channel":"book","ts_exchange":"2026-09-16T00:17:24.189589Z","ts_recv":"2026-09-16T00:17:24.364094Z","payload":{"channel":"book","type":"update","data":[{"symbol":"ADA/USD","bids":[],"asks":[{"price":0.194785,"qty":0.0},{"price":0.194841,"qty":20349.83229176}],"checksum":4194590890,"timestamp":"2026-09-16T00:17:24.189589Z"}]}}
{"v":1,"kind":"tick","pair":"ADA/USD","channel":"book","ts_exchange":"2026-09-16T00:17:24.189617Z","ts_recv":"2026-09-16T00:17:24.368240Z","payload":{"channel":"book","type":"update","data":[{"symbol":"ADA/USD","bids":[],"asks":[{"price":0.194785,"qty":1028.05784654}],"checksum":137958673,"timestamp":"2026-09-16T00:17:24.189617Z"}]}}
{"v":1,"kind":"tick","pair":"BTC/USD","channel":"book","ts_exchange":"2026-09-16T00:17:24.369656Z","ts_recv":"2026-09-16T00:17:24.496928Z","payload":{"channel":"book","type":"update","data":[{"symbol":"BTC/USD","bids":[],"asks":[{"price":75731.9,"qty":1.396914}],"checksum":47614666,"timestamp":"2026-09-16T00:17:24.369656Z"}]}}
{"v":1,"kind":"tick","pair":"ADA/USD","channel":"book","ts_exchange":"2026-09-16T00:17:24.498196Z","ts_recv":"2026-09-16T00:17:24.640026Z","payload":{"channel":"book","type":"update","data":[{"symbol":"ADA/USD","bids":[],"asks":[{"price":0.194785,"qty":0.0},{"price":0.194841,"qty":20349.83229176}],"checksum":4194590890,"timestamp":"2026-09-16T00:17:24.498196Z"}]}}
{"v":1,"kind":"tick","pair":"ADA/USD","channel":"book","ts_exchange":"2026-09-16T00:17:24.498799Z","ts_recv":"2026-09-16T00:17:24.641221Z","payload":{"channel":"book","type":"update","data":[{"symbol":"ADA/USD","bids":[],"asks":[{"price":0.194784,"qty":0.0},{"price":0.194845,"qty":3008.7},{"price":0.194786,"qty":3079.14650844}],"checksum":2307469320,"timestamp":"2026-09-16T00:17:24.498799Z"}]}}
{"v":1,"kind":"tick","pair":"ADA/USD","channel":"book","ts_exchange":"2026-09-16T00:17:24.665606Z","ts_recv":"2026-09-16T00:17:24.800489Z","payload":{"channel":"book","type":"update","data":[{"symbol":"ADA/USD","bids":[],"asks":[{"price":0.194785,"qty":1947.18307931}],"checksum":3181616455,"timestamp":"2026-09-16T00:17:24.665606Z"}]}}
{"v":1,"kind":"tick","pair":"ADA/USD","channel":"book","ts_exchange":"2026-09-16T00:17:24.666322Z","ts_recv":"2026-09-16T00:17:24.801435Z","payload":{"channel":"book","type":"update","data":[{"symbol":"ADA/USD","bids":[],"asks":[{"price":0.194786,"qty":0.0},{"price":0.194841,"qty":20349.83229176},{"price":0.194784,"qty":3079.14650844}],"checksum":2176901948,"timestamp":"2026-09-16T00:17:24.666322Z"}]}}
{"v":1,"kind":"tick","pair":"ADA/USD","channel":"book","ts_exchange":"2026-09-16T00:17:24.666998Z","ts_recv":"2026-09-16T00:17:24.802227Z","payload":{"channel":"book","type":"update","data":[{"symbol":"ADA/USD","bids":[],"asks":[{"price":0.194785,"qty":0.0},{"price":0.194841,"qty":20349.83229176}],"checksum":4194590890,"timestamp":"2026-09-16T00:17:24.666998Z"}]}}
{"v":1,"kind":"tick","pair":"ADA/USD","channel":"book","ts_exchange":"2026-09-16T00:17:24.667099Z","ts_recv":"2026-09-16T00:17:24.809933Z","payload":{"channel":"book","type":"update","data":[{"symbol":"ADA/USD","bids":[],"asks":[{"price":0.194785,"qty":1028.05784654}],"checksum":137958673,"timestamp":"2026-09-16T00:17:24.667099Z"}]}}
{"v":1,"kind":"tick","pair":"BTC/USD","channel":"book","ts_exchange":"2026-09-16T00:17:24.730553Z","ts_recv":"2026-09-16T00:17:24.859021Z","payload":{"channel":"book","type":"update","data":[{"symbol":"BTC/USD","bids":[],"asks":[{"price":75732.2,"qty":1.06490469}],"checksum":942963613,"timestamp":"2026-09-16T00:17:24.730553Z"}]}}
{"v":1,"kind":"tick","pair":"BTC/USD","channel":"book","ts_exchange":"2026-09-16T00:17:24.730708Z","ts_recv":"2026-09-16T00:17:24.859220Z","payload":{"channel":"book","type":"update","data":[{"symbol":"BTC/USD","bids":[{"price":75727.8,"qty":2.38542287}],"asks":[],"checksum":2938208914,"timestamp":"2026-09-16T00:17:24.730708Z"}]}}
{"v":1,"kind":"tick","pair":"BTC/USD","channel":"book","ts_exchange":"2026-09-16T00:17:24.731734Z","ts_recv":"2026-09-16T00:17:24.870735Z","payload":{"channel":"book","type":"update","data":[{"symbol":"BTC/USD","bids":[],"asks":[{"price":75734.2,"qty":0.0},{"price":75734.3,"qty":0.95245258},{"price":75733.1,"qty":0.11117396}],"checksum":3097431401,"timestamp":"2026-09-16T00:17:24.731734Z"}]}}
{"v":1,"kind":"tick","pair":"BTC/USD","channel":"book","ts_exchange":"2026-09-16T00:17:24.733445Z","ts_recv":"2026-09-16T00:17:24.870936Z","payload":{"channel":"book","type":"update","data":[{"symbol":"BTC/USD","bids":[],"asks":[{"price":75731.9,"qty":1.41839658}],"checksum":1330944337,"timestamp":"2026-09-16T00:17:24.733445Z"}]}}
{"v":1,"kind":"tick","pair":"BTC/USD","channel":"book","ts_exchange":"2026-09-16T00:17:25.477029Z","ts_recv":"2026-09-16T00:17:25.617159Z","payload":{"channel":"book","type":"update","data":[{"symbol":"BTC/USD","bids":[],"asks":[{"price":75732.8,"qty":0.0},{"price":75734.3,"qty":0.95245258}],"checksum":1818653382,"timestamp":"2026-09-16T00:17:25.477029Z"}]}}
{"v":1,"kind":"tick","pair":"BTC/USD","channel":"book","ts_exchange":"2026-09-16T00:17:25.477214Z","ts_recv":"2026-09-16T00:17:25.617983Z","payload":{"channel":"book","type":"update","data":[{"symbol":"BTC/USD","bids":[],"asks":[{"price":75733.5,"qty":0.0},{"price":75734.4,"qty":3.30101414}],"checksum":3267885146,"timestamp":"2026-09-16T00:17:25.477214Z"}]}}
{"v":1,"kind":"tick","pair":"BTC/USD","channel":"book","ts_exchange":"2026-09-16T00:17:25.478988Z","ts_recv":"2026-09-16T00:17:25.625996Z","payload":{"channel":"book","type":"update","data":[{"symbol":"BTC/USD","bids":[{"price":75727.9,"qty":0.71206395}],"asks":[],"checksum":2650168191,"timestamp":"2026-09-16T00:17:25.478988Z"}]}}
{"v":1,"kind":"tick","pair":"BTC/USD","channel":"book","ts_exchange":"2026-09-16T00:17:25.482793Z","ts_recv":"2026-09-16T00:17:25.628391Z","payload":{"channel":"book","type":"update","data":[{"symbol":"BTC/USD","bids":[{"price":75724.4,"qty":0.0},{"price":75719.6,"qty":0.000051}],"asks":[],"checksum":3932440873,"timestamp":"2026-09-16T00:17:25.482793Z"}]}}
{"v":1,"kind":"tick","pair":"BTC/USD","channel":"book","ts_exchange":"2026-09-16T00:17:25.483849Z","ts_recv":"2026-09-16T00:17:25.628632Z","payload":{"channel":"book","type":"update","data":[{"symbol":"BTC/USD","bids":[{"price":75725.6,"qty":3.30139066}],"asks":[],"checksum":3498572630,"timestamp":"2026-09-16T00:17:25.483849Z"}]}}
{"v":1,"kind":"tick","pair":"BTC/USD","channel":"book","ts_exchange":"2026-09-16T00:17:25.484405Z","ts_recv":"2026-09-16T00:17:25.628897Z","payload":{"channel":"book","type":"update","data":[{"symbol":"BTC/USD","bids":[{"price":75724.5,"qty":0.01320355}],"asks":[],"checksum":688877559,"timestamp":"2026-09-16T00:17:25.484405Z"}]}}
{"v":1,"kind":"tick","pair":"BTC/USD","channel":"book","ts_exchange":"2026-09-16T00:17:25.485086Z","ts_recv":"2026-09-16T00:17:25.629142Z","payload":{"channel":"book","type":"update","data":[{"symbol":"BTC/USD","bids":[{"price":75725.7,"qty":1.30109246}],"asks":[],"checksum":633725119,"timestamp":"2026-09-16T00:17:25.485086Z"}]}}
{"v":1,"kind":"tick","pair":"BTC/USD","channel":"book","ts_exchange":"2026-09-16T00:17:25.509700Z","ts_recv":"2026-09-16T00:17:25.647241Z","payload":{"channel":"book","type":"update","data":[{"symbol":"BTC/USD","bids":[{"price":75727.8,"qty":1.06490469}],"asks":[],"checksum":169147278,"timestamp":"2026-09-16T00:17:25.509700Z"}]}}
{"v":1,"kind":"tick","pair":"BTC/USD","channel":"book","ts_exchange":"2026-09-16T00:17:25.510403Z","ts_recv":"2026-09-16T00:17:25.647399Z","payload":{"channel":"book","type":"update","data":[{"symbol":"BTC/USD","bids":[{"price":75727.9,"qty":0.0},{"price":75722.6,"qty":0.9904235}],"asks":[],"checksum":1807035152,"timestamp":"2026-09-16T00:17:25.510403Z"}]}}
{"v":1,"kind":"tick","pair":"BTC/USD","channel":"book","ts_exchange":"2026-09-16T00:17:25.510454Z","ts_recv":"2026-09-16T00:17:25.647556Z","payload":{"channel":"book","type":"update","data":[{"symbol":"BTC/USD","bids":[{"price":75728.5,"qty":1.32050678}],"asks":[],"checksum":1363574650,"timestamp":"2026-09-16T00:17:25.510454Z"}]}}
{"v":1,"kind":"tick","pair":"BTC/USD","channel":"book","ts_exchange":"2026-09-16T00:17:25.511432Z","ts_recv":"2026-09-16T00:17:25.655433Z","payload":{"channel":"book","type":"update","data":[{"symbol":"BTC/USD","bids":[{"price":75727.9,"qty":0.31788927}],"asks":[],"checksum":3672955224,"timestamp":"2026-09-16T00:17:25.511432Z"}]}}
{"v":1,"kind":"tick","pair":"ADA/USD","channel":"book","ts_exchange":"2026-09-16T00:17:25.529101Z","ts_recv":"2026-09-16T00:17:25.666249Z","payload":{"channel":"book","type":"update","data":[{"symbol":"ADA/USD","bids":[],"asks":[{"price":0.19479,"qty":0.0},{"price":0.194841,"qty":20349.83229176}],"checksum":1903794173,"timestamp":"2026-09-16T00:17:25.529101Z"}]}}
{"v":1,"kind":"tick","pair":"BTC/USD","channel":"book","ts_exchange":"2026-09-16T00:17:25.530211Z","ts_recv":"2026-09-16T00:17:25.675587Z","payload":{"channel":"book","type":"update","data":[{"symbol":"BTC/USD","bids":[{"price":75727.9,"qty":0.0},{"price":75723.4,"qty":0.000051}],"asks":[],"checksum":1363574650,"timestamp":"2026-09-16T00:17:25.530211Z"}]}}
{"v":1,"kind":"tick","pair":"BTC/USD","channel":"book","ts_exchange":"2026-09-16T00:17:25.649699Z","ts_recv":"2026-09-16T00:17:25.780475Z","payload":{"channel":"book","type":"update","data":[{"symbol":"BTC/USD","bids":[{"price":75724.5,"qty":0.0},{"price":75722.6,"qty":0.9904235},{"price":75725.8,"qty":0.11117396}],"asks":[],"checksum":2305356204,"timestamp":"2026-09-16T00:17:25.649699Z"}]}}
{"v":1,"kind":"tick","pair":"BTC/USD","channel":"book","ts_exchange":"2026-09-16T00:17:25.829131Z","ts_recv":"2026-09-16T00:17:26.002690Z","payload":{"channel":"book","type":"update","data":[{"symbol":"BTC/USD","bids":[{"price":75728.5,"qty":0.0},{"price":75722.6,"qty":0.9904235}],"asks":[],"checksum":3506681310,"timestamp":"2026-09-16T00:17:25.829131Z"}]}}
{"v":1,"kind":"tick","pair":"ADA/USD","channel":"book","ts_exchange":"2026-09-16T00:17:25.829264Z","ts_recv":"2026-09-16T00:17:26.004729Z","payload":{"channel":"book","type":"update","data":[{"symbol":"ADA/USD","bids":[],"asks":[{"price":0.194785,"qty":0.0},{"price":0.194845,"qty":3008.7}],"checksum":2089901240,"timestamp":"2026-09-16T00:17:25.829264Z"}]}}
{"v":1,"kind":"tick","pair":"BTC/USD","channel":"book","ts_exchange":"2026-09-16T00:17:25.829370Z","ts_recv":"2026-09-16T00:17:26.006883Z","payload":{"channel":"book","type":"update","data":[{"symbol":"BTC/USD","bids":[],"asks":[{"price":75731.9,"qty":1.36469658}],"checksum":3000178602,"timestamp":"2026-09-16T00:17:25.829370Z"}]}}
{"v":1,"kind":"tick","pair":"BTC/USD","channel":"book","ts_exchange":"2026-09-16T00:17:25.829465Z","ts_recv":"2026-09-16T00:17:26.009796Z","payload":{"channel":"book","type":"update","data":[{"symbol":"BTC/USD","bids":[{"price":75725.6,"qty":0.0},{"price":75721.0,"qty":0.99183715}],"asks":[],"checksum":2408435253,"timestamp":"2026-09-16T00:17:25.829465Z"}]}}
{"v":1,"kind":"tick","pair":"BTC/USD","channel":"book","ts_exchange":"2026-09-16T00:17:25.829795Z","ts_recv":"2026-09-16T00:17:26.012324Z","payload":{"channel":"book","type":"update","data":[{"symbol":"BTC/USD","bids":[],"asks":[{"price":75734.4,"qty":0.0},{"price":75734.7,"qty":0.0005}],"checksum":3822357913,"timestamp":"2026-09-16T00:17:25.829795Z"}]}}
{"v":1,"kind":"tick","pair":"ADA/USD","channel":"book","ts_exchange":"2026-09-16T00:17:25.830961Z","ts_recv":"2026-09-16T00:17:26.013449Z","payload":{"channel":"book","type":"update","data":[{"symbol":"ADA/USD","bids":[],"asks":[{"price":0.194784,"qty":0.0},{"price":0.19487,"qty":2565.81310617},{"price":0.194786,"qty":3079.14650844}],"checksum":1144656684,"timestamp":"2026-09-16T00:17:25.830961Z"}]}}
{"v":1,"kind":"tick","pair":"BTC/USD","channel":"book","ts_exchange":"2026-09-16T00:17:25.831768Z","ts_recv":"2026-09-16T00:17:26.014692Z","payload":{"channel":"book","type":"update","data":[{"symbol":"BTC/USD","bids":[{"price":75730.6,"qty":1.32046987}],"asks":[],"checksum":893303374,"timestamp":"2026-09-16T00:17:25.831768Z"}]}}
{"v":1,"kind":"tick","pair":"BTC/USD","channel":"book","ts_exchange":"2026-09-16T00:17:25.831798Z","ts_recv":"2026-09-16T00:17:26.016423Z","payload":{"channel":"book","type":"update","data":[{"symbol":"BTC/USD","bids":[],"asks":[{"price":75734.3,"qty":0.37600792}],"checksum":3759297686,"timestamp":"2026-09-16T00:17:25.831798Z"}]}}
{"v":1,"kind":"tick","pair":"BTC/USD","channel":"book","ts_exchange":"2026-09-16T00:17:25.831814Z","ts_recv":"2026-09-16T00:17:26.018770Z","payload":{"channel":"book","type":"update","data":[{"symbol":"BTC/USD","bids":[{"price":75725.7,"qty":0.0},{"price":75721.0,"qty":0.99183715}],"asks":[],"checksum":2072204473,"timestamp":"2026-09-16T00:17:25.831814Z"}]}}
{"v":1,"kind":"tick","pair":"BTC/USD","channel":"book","ts_exchange":"2026-09-16T00:17:25.831864Z","ts_recv":"2026-09-16T00:17:26.020769Z","payload":{"channel":"book","type":"update","data":[{"symbol":"BTC/USD","bids":[{"price":75727.1,"qty":3.30132622}],"asks":[],"checksum":3836144204,"timestamp":"2026-09-16T00:17:25.831864Z"}]}}
{"v":1,"kind":"tick","pair":"BTC/USD","channel":"book","ts_exchange":"2026-09-16T00:17:25.831978Z","ts_recv":"2026-09-16T00:17:26.022911Z","payload":{"channel":"book","type":"update","data":[{"symbol":"BTC/USD","bids":[],"asks":[{"price":75732.4,"qty":0.80136892}],"checksum":3986491656,"timestamp":"2026-09-16T00:17:25.831978Z"}]}}
{"v":1,"kind":"tick","pair":"BTC/USD","channel":"book","ts_exchange":"2026-09-16T00:17:25.831996Z","ts_recv":"2026-09-16T00:17:26.024706Z","payload":{"channel":"book","type":"update","data":[{"symbol":"BTC/USD","bids":[],"asks":[{"price":75732.4,"qty":0.0},{"price":75735.6,"qty":0.02641206}],"checksum":2939880265,"timestamp":"2026-09-16T00:17:25.831996Z"}]}}
{"v":1,"kind":"tick","pair":"BTC/USD","channel":"book","ts_exchange":"2026-09-16T00:17:25.832304Z","ts_recv":"2026-09-16T00:17:26.027925Z","payload":{"channel":"book","type":"update","data":[{"symbol":"BTC/USD","bids":[{"price":75727.1,"qty":0.0},{"price":75721.0,"qty":0.99183715}],"asks":[],"checksum":3804108444,"timestamp":"2026-09-16T00:17:25.832304Z"}]}}
{"v":1,"kind":"tick","pair":"BTC/USD","channel":"book","ts_exchange":"2026-09-16T00:17:25.832722Z","ts_recv":"2026-09-16T00:17:26.040617Z","payload":{"channel":"book","type":"update","data":[{"symbol":"BTC/USD","bids":[{"price":75730.6,"qty":0.0},{"price":75719.6,"qty":0.000051}],"asks":[],"checksum":551955797,"timestamp":"2026-09-16T00:17:25.832722Z"}]}}
{"v":1,"kind":"tick","pair":"BTC/USD","channel":"book","ts_exchange":"2026-09-16T00:17:25.833010Z","ts_recv":"2026-09-16T00:17:26.042788Z","payload":{"channel":"book","type":"update","data":[{"symbol":"BTC/USD","bids":[],"asks":[{"price":75731.9,"qty":0.04424906}],"checksum":2515126496,"timestamp":"2026-09-16T00:17:25.833010Z"}]}}
{"v":1,"kind":"tick","pair":"BTC/USD","channel":"book","ts_exchange":"2026-09-16T00:17:25.833155Z","ts_recv":"2026-09-16T00:17:26.043849Z","payload":{"channel":"book","type":"update","data":[{"symbol":"BTC/USD","bids":[{"price":75722.7,"qty":0.29564141}],"asks":[],"checksum":1575357293,"timestamp":"2026-09-16T00:17:25.833155Z"}]}}
{"v":1,"kind":"tick","pair":"BTC/USD","channel":"book","ts_exchange":"2026-09-16T00:17:25.833233Z","ts_recv":"2026-09-16T00:17:26.045177Z","payload":{"channel":"book","type":"update","data":[{"symbol":"BTC/USD","bids":[{"price":75727.9,"qty":0.31788927}],"asks":[],"checksum":1672841458,"timestamp":"2026-09-16T00:17:25.833233Z"}]}}
{"v":1,"kind":"tick","pair":"BTC/USD","channel":"book","ts_exchange":"2026-09-16T00:17:25.833343Z","ts_recv":"2026-09-16T00:17:26.049049Z","payload":{"channel":"book","type":"update","data":[{"symbol":"BTC/USD","bids":[{"price":75727.9,"qty":1.26269363}],"asks":[],"checksum":1975628225,"timestamp":"2026-09-16T00:17:25.833343Z"}]}}
{"v":1,"kind":"tick","pair":"BTC/USD","channel":"book","ts_exchange":"2026-09-16T00:17:25.833756Z","ts_recv":"2026-09-16T00:17:26.051381Z","payload":{"channel":"book","type":"update","data":[{"symbol":"BTC/USD","bids":[],"asks":[{"price":75733.2,"qty":0.0},{"price":75736.4,"qty":0.06602878}],"checksum":2607626034,"timestamp":"2026-09-16T00:17:25.833756Z"}]}}
{"v":1,"kind":"tick","pair":"BTC/USD","channel":"book","ts_exchange":"2026-09-16T00:17:25.834728Z","ts_recv":"2026-09-16T00:17:26.058684Z","payload":{"channel":"book","type":"update","data":[{"symbol":"BTC/USD","bids":[{"price":75727.9,"qty":0.31788927}],"asks":[],"checksum":3243399152,"timestamp":"2026-09-16T00:17:25.834728Z"}]}}
{"v":1,"kind":"tick","pair":"BTC/USD","channel":"book","ts_exchange":"2026-09-16T00:17:25.834810Z","ts_recv":"2026-09-16T00:17:26.058947Z","payload":{"channel":"book","type":"update","data":[{"symbol":"BTC/USD","bids":[{"price":75722.6,"qty":0.0},{"price":75721.0,"qty":0.99183715}],"asks":[],"checksum":4234171887,"timestamp":"2026-09-16T00:17:25.834810Z"}]}}
{"v":1,"kind":"tick","pair":"BTC/USD","channel":"book","ts_exchange":"2026-09-16T00:17:25.834826Z","ts_recv":"2026-09-16T00:17:26.059125Z","payload":{"channel":"book","type":"update","data":[{"symbol":"BTC/USD","bids":[{"price":75721.0,"qty":0.0},{"price":75719.6,"qty":0.000051}],"asks":[],"checksum":3057096916,"timestamp":"2026-09-16T00:17:25.834826Z"}]}}
{"v":1,"kind":"tick","pair":"BTC/USD","channel":"book","ts_exchange":"2026-09-16T00:17:25.835354Z","ts_recv":"2026-09-16T00:17:26.059452Z","payload":{"channel":"book","type":"update","data":[{"symbol":"BTC/USD","bids":[{"price":75725.8,"qty":0.0},{"price":75719.4,"qty":0.02109115},{"price":75724.3,"qty":0.013425}],"asks":[],"checksum":4065766381,"timestamp":"2026-09-16T00:17:25.835354Z"}]}}
{"v":1,"kind":"tick","pair":"BTC/USD","channel":"book","ts_exchange":"2026-09-16T00:17:25.835420Z","ts_recv":"2026-09-16T00:17:26.059634Z","payload":{"channel":"book","type":"update","data":[{"symbol":"BTC/USD","bids":[],"asks":[{"price":75733.1,"qty":0.0},{"price":75736.9,"qty":0.11117396},{"price":75734.2,"qty":0.11117396}],"checksum":1161665254,"timestamp":"2026-09-16T00:17:25.835420Z"}]}}
{"v":1,"kind":"tick","pair":"BTC/USD","channel":"book","ts_exchange":"2026-09-16T00:17:25.835732Z","ts_recv":"2026-09-16T00:17:26.059949Z","payload":{"channel":"book","type":"update","data":[{"symbol":"BTC/USD","bids":[{"price":75731.8,"qty":0.01153295}],"asks":[],"checksum":3419870571,"timestamp":"2026-09-16T00:17:25.835732Z"}]}}
{"v":1,"kind":"tick","pair":"BTC/USD","channel":"book","ts_exchange":"2026-09-16T00:17:25.835983Z","ts_recv":"2026-09-16T00:17:26.060276Z","payload":{"channel":"book","type":"update","data":[{"symbol":"BTC/USD","bids":[],"asks":[{"price":75731.9,"qty":1.36469658}],"checksum":352162262,"timestamp":"2026-09-16T00:17:25.835983Z"}]}}
{"v":1,"kind":"tick","pair":"BTC/USD","channel":"book","ts_exchange":"2026-09-16T00:17:25.836252Z","ts_recv":"2026-09-16T00:17:26.060431Z","payload":{"channel":"book","type":"update","data":[{"symbol":"BTC/USD","bids":[],"asks":[{"price":75734.1,"qty":3.30102518}],"checksum":2027067358,"timestamp":"2026-09-16T00:17:25.836252Z"}]}}
{"v":1,"kind":"tick","pair":"BTC/USD","channel":"book","ts_exchange":"2026-09-16T00:17:25.836624Z","ts_recv":"2026-09-16T00:17:26.060676Z","payload":{"channel":"book","type":"update","data":[{"symbol":"BTC/USD","bids":[{"price":75723.7,"qty":3.30147294}],"asks":[],"checksum":2299104938,"timestamp":"2026-09-16T00:17:25.836624Z"}]}}
{"v":1,"kind":"tick","pair":"BTC/USD","channel":"book","ts_exchange":"2026-09-16T00:17:25.836771Z","ts_recv":"2026-09-16T00:17:26.060841Z","payload":{"channel":"book","type":"update","data":[{"symbol":"BTC/USD","bids":[],"asks":[{"price":75731.9,"qty":1.343214}],"checksum":3389362295,"timestamp":"2026-09-16T00:17:25.836771Z"}]}}
{"v":1,"kind":"tick","pair":"BTC/USD","channel":"book","ts_exchange":"2026-09-16T00:17:25.837348Z","ts_recv":"2026-09-16T00:17:26.061148Z","payload":{"channel":"book","type":"update","data":[{"symbol":"BTC/USD","bids":[],"asks":[{"price":75734.3,"qty":0.0},{"price":75736.4,"qty":0.06602878}],"checksum":2831688236,"timestamp":"2026-09-16T00:17:25.837348Z"}]}}
{"v":1,"kind":"tick","pair":"BTC/USD","channel":"book","ts_exchange":"2026-09-16T00:17:25.837359Z","ts_recv":"2026-09-16T00:17:26.061328Z","payload":{"channel":"book","type":"update","data":[{"symbol":"BTC/USD","bids":[{"price":75722.7,"qty":0.0},{"price":75719.6,"qty":0.000051}],"asks":[],"checksum":2340836406,"timestamp":"2026-09-16T00:17:25.837359Z"}]}}
{"v":1,"kind":"tick","pair":"BTC/USD","channel":"book","ts_exchange":"2026-09-16T00:17:25.837384Z","ts_recv":"2026-09-16T00:17:26.061485Z","payload":{"channel":"book","type":"update","data":[{"symbol":"BTC/USD","bids":[{"price":75725.9,"qty":0.0492301}],"asks":[],"checksum":2541305406,"timestamp":"2026-09-16T00:17:25.837384Z"}]}}
{"v":1,"kind":"tick","pair":"BTC/USD","channel":"book","ts_exchange":"2026-09-16T00:17:25.839029Z","ts_recv":"2026-09-16T00:17:26.061872Z","payload":{"channel":"book","type":"update","data":[{"symbol":"BTC/USD","bids":[{"price":75731.8,"qty":0.00061717}],"asks":[],"checksum":2351482877,"timestamp":"2026-09-16T00:17:25.839029Z"}]}}
{"v":1,"kind":"tick","pair":"BTC/USD","channel":"book","ts_exchange":"2026-09-16T00:17:25.839879Z","ts_recv":"2026-09-16T00:17:26.062031Z","payload":{"channel":"book","type":"update","data":[{"symbol":"BTC/USD","bids":[{"price":75725.9,"qty":0.0},{"price":75719.6,"qty":0.000051}],"asks":[],"checksum":4057084746,"timestamp":"2026-09-16T00:17:25.839879Z"}]}}
{"v":1,"kind":"tick","pair":"BTC/USD","channel":"book","ts_exchange":"2026-09-16T00:17:25.840061Z","ts_recv":"2026-09-16T00:17:26.062203Z","payload":{"channel":"book","type":"update","data":[{"symbol":"BTC/USD","bids":[{"price":75725.9,"qty":0.02005204}],"asks":[],"checksum":3267705092,"timestamp":"2026-09-16T00:17:25.840061Z"}]}}
{"v":1,"kind":"tick","pair":"BTC/USD","channel":"book","ts_exchange":"2026-09-16T00:17:25.840147Z","ts_recv":"2026-09-16T00:17:26.062358Z","payload":{"channel":"book","type":"update","data":[{"symbol":"BTC/USD","bids":[],"asks":[{"price":75731.9,"qty":1.36469658}],"checksum":1978603562,"timestamp":"2026-09-16T00:17:25.840147Z"}]}}
{"v":1,"kind":"tick","pair":"BTC/USD","channel":"book","ts_exchange":"2026-09-16T00:17:25.840222Z","ts_recv":"2026-09-16T00:17:26.064937Z","payload":{"channel":"book","type":"update","data":[{"symbol":"BTC/USD","bids":[],"asks":[{"price":75736.3,"qty":0.06035752}],"checksum":2051968537,"timestamp":"2026-09-16T00:17:25.840222Z"}]}}
{"v":1,"kind":"tick","pair":"BTC/USD","channel":"book","ts_exchange":"2026-09-16T00:17:25.840424Z","ts_recv":"2026-09-16T00:17:26.069091Z","payload":{"channel":"book","type":"update","data":[{"symbol":"BTC/USD","bids":[{"price":75731.8,"qty":0.37524258}],"asks":[],"checksum":2576303573,"timestamp":"2026-09-16T00:17:25.840424Z"}]}}
{"v":1,"kind":"tick","pair":"BTC/USD","channel":"book","ts_exchange":"2026-09-16T00:17:25.841529Z","ts_recv":"2026-09-16T00:17:26.069565Z","payload":{"channel":"book","type":"update","data":[{"symbol":"BTC/USD","bids":[{"price":75725.9,"qty":1.00297809}],"asks":[],"checksum":1795531541,"timestamp":"2026-09-16T00:17:25.841529Z"}]}}
{"v":1,"kind":"tick","pair":"BTC/USD","channel":"book","ts_exchange":"2026-09-16T00:17:25.863288Z","ts_recv":"2026-09-16T00:17:26.076638Z","payload":{"channel":"book","type":"update","data":[{"symbol":"BTC/USD","bids":[{"price":75723.8,"qty":0.9904235}],"asks":[],"checksum":2090556487,"timestamp":"2026-09-16T00:17:25.863288Z"}]}}
{"v":1,"kind":"tick","pair":"BTC/USD","channel":"book","ts_exchange":"2026-09-16T00:17:26.005547Z","ts_recv":"2026-09-16T00:17:26.134770Z","payload":{"channel":"book","type":"update","data":[{"symbol":"BTC/USD","bids":[{"price":75724.3,"qty":0.0},{"price":75723.4,"qty":0.000051},{"price":75726.0,"qty":0.11117396}],"asks":[],"checksum":1180330755,"timestamp":"2026-09-16T00:17:26.005547Z"}]}}
{"v":1,"kind":"tick","pair":"BTC/USD","channel":"book","ts_exchange":"2026-09-16T00:17:26.226441Z","ts_recv":"2026-09-16T00:17:26.358605Z","payload":{"channel":"book","type":"update","data":[{"symbol":"BTC/USD","bids":[{"price":75727.8,"qty":0.0},{"price":75723.4,"qty":0.000051}],"asks":[],"checksum":3344484170,"timestamp":"2026-09-16T00:17:26.226441Z"}]}}
{"v":1,"kind":"tick","pair":"BTC/USD","channel":"book","ts_exchange":"2026-09-16T00:17:26.226462Z","ts_recv":"2026-09-16T00:17:26.358804Z","payload":{"channel":"book","type":"update","data":[{"symbol":"BTC/USD","bids":[{"price":75723.8,"qty":0.0},{"price":75719.6,"qty":0.000051}],"asks":[],"checksum":101693029,"timestamp":"2026-09-16T00:17:26.226462Z"}]}}
{"v":1,"kind":"tick","pair":"BTC/USD","channel":"book","ts_exchange":"2026-09-16T00:17:26.226588Z","ts_recv":"2026-09-16T00:17:26.370910Z","payload":{"channel":"book","type":"update","data":[{"symbol":"BTC/USD","bids":[],"asks":[{"price":75732.2,"qty":0.0},{"price":75736.4,"qty":0.06602878}],"checksum":3301819152,"timestamp":"2026-09-16T00:17:26.226588Z"}]}}
{"v":1,"kind":"tick","pair":"BTC/USD","channel":"book","ts_exchange":"2026-09-16T00:17:26.227359Z","ts_recv":"2026-09-16T00:17:26.371480Z","payload":{"channel":"book","type":"update","data":[{"symbol":"BTC/USD","bids":[{"price":75727.9,"qty":0.0},{"price":75719.4,"qty":0.02109115}],"asks":[],"checksum":1293739130,"timestamp":"2026-09-16T00:17:26.227359Z"}]}}
{"v":1,"kind":"tick","pair":"BTC/USD","channel":"book","ts_exchange":"2026-09-16T00:17:26.229593Z","ts_recv":"2026-09-16T00:17:26.371977Z","payload":{"channel":"book","type":"update","data":[{"symbol":"BTC/USD","bids":[{"price":75731.8,"qty":1.69569184}],"asks":[],"checksum":975847381,"timestamp":"2026-09-16T00:17:26.229593Z"}]}}
{"v":1,"kind":"tick","pair":"BTC/USD","channel":"book","ts_exchange":"2026-09-16T00:17:26.229612Z","ts_recv":"2026-09-16T00:17:26.372512Z","payload":{"channel":"book","type":"update","data":[{"symbol":"BTC/USD","bids":[{"price":75729.9,"qty":3.30120566}],"asks":[],"checksum":1420098634,"timestamp":"2026-09-16T00:17:26.229612Z"}]}}
{"v":1,"kind":"tick","pair":"BTC/USD","channel":"book","ts_exchange":"2026-09-16T00:17:26.230826Z","ts_recv":"2026-09-16T00:17:26.373890Z","payload":{"channel":"book","type":"update","data":[{"symbol":"BTC/USD","bids":[{"price":75730.0,"qty":0.98542511}],"asks":[],"checksum":4093333701,"timestamp":"2026-09-16T00:17:26.230826Z"}]}}
{"v":1,"kind":"tick","pair":"BTC/USD","channel":"book","ts_exchange":"2026-09-16T00:17:26.231940Z","ts_recv":"2026-09-16T00:17:26.375125Z","payload":{"channel":"book","type":"update","data":[{"symbol":"BTC/USD","bids":[],"asks":[{"price":75731.9,"qty":1.343214}],"checksum":198898354,"timestamp":"2026-09-16T00:17:26.231940Z"}]}}
{"v":1,"kind":"tick","pair":"BTC/USD","channel":"book","ts_exchange":"2026-09-16T00:17:26.233155Z","ts_recv":"2026-09-16T00:17:26.381134Z","payload":{"channel":"book","type":"update","data":[{"symbol":"BTC/USD","bids":[{"price":75731.8,"qty":1.70660762}],"asks":[],"checksum":3333854935,"timestamp":"2026-09-16T00:17:26.233155Z"}]}}
{"v":1,"kind":"tick","pair":"BTC/USD","channel":"book","ts_exchange":"2026-09-16T00:17:26.233171Z","ts_recv":"2026-09-16T00:17:26.381801Z","payload":{"channel":"book","type":"update","data":[{"symbol":"BTC/USD","bids":[],"asks":[{"price":75731.9,"qty":1.33721555}],"checksum":1225711287,"timestamp":"2026-09-16T00:17:26.233171Z"}]}}
{"v":1,"kind":"tick","pair":"BTC/USD","channel":"book","ts_exchange":"2026-09-16T00:17:26.263735Z","ts_recv":"2026-09-16T00:17:26.401230Z","payload":{"channel":"book","type":"update","data":[{"symbol":"BTC/USD","bids":[{"price":75724.8,"qty":0.9904235}],"asks":[],"checksum":558454023,"timestamp":"2026-09-16T00:17:26.263735Z"}]}}
{"v":1,"kind":"tick","pair":"BTC/USD","channel":"book","ts_exchange":"2026-09-16T00:17:26.683762Z","ts_recv":"2026-09-16T00:17:26.832656Z","payload":{"channel":"book","type":"update","data":[{"symbol":"BTC/USD","bids":[],"asks":[{"price":75734.7,"qty":0.000551}],"checksum":1468829642,"timestamp":"2026-09-16T00:17:26.683762Z"}]}}
{"v":1,"kind":"tick","pair":"ADA/USD","channel":"book","ts_exchange":"2026-09-16T00:17:26.857183Z","ts_recv":"2026-09-16T00:17:26.984822Z","payload":{"channel":"book","type":"update","data":[{"symbol":"ADA/USD","bids":[],"asks":[{"price":0.194806,"qty":4251.71933202}],"checksum":3043831137,"timestamp":"2026-09-16T00:17:26.857183Z"}]}}
{"v":1,"kind":"tick","pair":"ADA/USD","channel":"book","ts_exchange":"2026-09-16T00:17:26.857960Z","ts_recv":"2026-09-16T00:17:26.985108Z","payload":{"channel":"book","type":"update","data":[{"symbol":"ADA/USD","bids":[],"asks":[{"price":0.194785,"qty":1708.38307931}],"checksum":1441853132,"timestamp":"2026-09-16T00:17:26.857960Z"}]}}
{"v":1,"kind":"tick","pair":"ADA/USD","channel":"book","ts_exchange":"2026-09-16T00:17:26.858908Z","ts_recv":"2026-09-16T00:17:26.993879Z","payload":{"channel":"book","type":"update","data":[{"symbol":"ADA/USD","bids":[],"asks":[{"price":0.194786,"qty":0.0},{"price":0.194845,"qty":3008.7},{"price":0.194784,"qty":3079.14650844}],"checksum":3572617397,"timestamp":"2026-09-16T00:17:26.858908Z"}]}}
{"v":1,"kind":"tick","pair":"ADA/USD","channel":"book","ts_exchange":"2026-09-16T00:17:26.859562Z","ts_recv":"2026-09-16T00:17:26.994093Z","payload":{"channel":"book","type":"update","data":[{"symbol":"ADA/USD","bids":[],"asks":[{"price":0.194785,"qty":0.0},{"price":0.194845,"qty":3008.7}],"checksum":2378588917,"timestamp":"2026-09-16T00:17:26.859562Z"}]}}
{"v":1,"kind":"tick","pair":"ADA/USD","channel":"book","ts_exchange":"2026-09-16T00:17:27.005599Z","ts_recv":"2026-09-16T00:17:27.132804Z","payload":{"channel":"book","type":"update","data":[{"symbol":"ADA/USD","bids":[],"asks":[{"price":0.194784,"qty":0.0},{"price":0.19487,"qty":2565.81310617},{"price":0.194786,"qty":3079.14650844}],"checksum":3043831137,"timestamp":"2026-09-16T00:17:27.005599Z"}]}}
{"v":1,"kind":"tick","pair":"ADA/USD","channel":"book","ts_exchange":"2026-09-16T00:17:27.006486Z","ts_recv":"2026-09-16T00:17:27.133438Z","payload":{"channel":"book","type":"update","data":[{"symbol":"ADA/USD","bids":[],"asks":[{"price":0.194785,"qty":1708.38307931}],"checksum":1441853132,"timestamp":"2026-09-16T00:17:27.006486Z"}]}}
{"v":1,"kind":"tick","pair":"ADA/USD","channel":"book","ts_exchange":"2026-09-16T00:17:27.166161Z","ts_recv":"2026-09-16T00:17:27.299432Z","payload":{"channel":"book","type":"update","data":[{"symbol":"ADA/USD","bids":[],"asks":[{"price":0.194786,"qty":0.0},{"price":0.194845,"qty":3008.7},{"price":0.194784,"qty":3079.14650844}],"checksum":3572617397,"timestamp":"2026-09-16T00:17:27.166161Z"}]}}
{"v":1,"kind":"tick","pair":"ADA/USD","channel":"book","ts_exchange":"2026-09-16T00:17:27.166824Z","ts_recv":"2026-09-16T00:17:27.301962Z","payload":{"channel":"book","type":"update","data":[{"symbol":"ADA/USD","bids":[],"asks":[{"price":0.194785,"qty":0.0},{"price":0.194845,"qty":3008.7}],"checksum":2378588917,"timestamp":"2026-09-16T00:17:27.166824Z"}]}}
{"v":1,"kind":"tick","pair":"ADA/USD","channel":"book","ts_exchange":"2026-09-16T00:17:27.327566Z","ts_recv":"2026-09-16T00:17:27.453077Z","payload":{"channel":"book","type":"update","data":[{"symbol":"ADA/USD","bids":[],"asks":[{"price":0.194784,"qty":0.0},{"price":0.19487,"qty":2565.81310617},{"price":0.194786,"qty":3079.14650844}],"checksum":3043831137,"timestamp":"2026-09-16T00:17:27.327566Z"}]}}
{"v":1,"kind":"tick","pair":"ADA/USD","channel":"book","ts_exchange":"2026-09-16T00:17:27.329213Z","ts_recv":"2026-09-16T00:17:27.455041Z","payload":{"channel":"book","type":"update","data":[{"symbol":"ADA/USD","bids":[{"price":0.194685,"qty":3008.7}],"asks":[],"checksum":1259017050,"timestamp":"2026-09-16T00:17:27.329213Z"}]}}
{"v":1,"kind":"tick","pair":"ADA/USD","channel":"book","ts_exchange":"2026-09-16T00:17:27.329309Z","ts_recv":"2026-09-16T00:17:27.455632Z","payload":{"channel":"book","type":"update","data":[{"symbol":"ADA/USD","bids":[],"asks":[{"price":0.194785,"qty":1708.38307931}],"checksum":2878787831,"timestamp":"2026-09-16T00:17:27.329309Z"}]}}
{"v":1,"kind":"tick","pair":"ADA/USD","channel":"book","ts_exchange":"2026-09-16T00:17:27.329825Z","ts_recv":"2026-09-16T00:17:27.468945Z","payload":{"channel":"book","type":"update","data":[{"symbol":"ADA/USD","bids":[{"price":0.194684,"qty":0.0},{"price":0.194622,"qty":2569.07582444},{"price":0.194686,"qty":3079.1465085}],"asks":[],"checksum":1915416221,"timestamp":"2026-09-16T00:17:27.329825Z"}]}}
{"v":1,"kind":"tick","pair":"ADA/USD","channel":"book","ts_exchange":"2026-09-16T00:17:27.361760Z","ts_recv":"2026-09-16T00:17:27.498164Z","payload":{"channel":"book","type":"update","data":[{"symbol":"ADA/USD","bids":[{"price":0.194638,"qty":0.0},{"price":0.194622,"qty":2569.07582444}],"asks":[],"checksum":2376019578,"timestamp":"2026-09-16T00:17:27.361760Z"}]}}
{"v":1,"kind":"tick","pair":"ADA/USD","channel":"book","ts_exchange":"2026-09-16T00:17:27.362487Z","ts_recv":"2026-09-16T00:17:27.499014Z","payload":{"channel":"book","type":"update","data":[{"symbol":"ADA/USD","bids":[{"price":0.19465,"qty":2568.71269105}],"asks":[],"checksum":3255327146,"timestamp":"2026-09-16T00:17:27.362487Z"}]}}
{"v":1,"kind":"tick","pair":"ADA/USD","channel":"book","ts_exchange":"2026-09-16T00:17:27.429802Z","ts_recv":"2026-09-16T00:17:27.555822Z","payload":{"channel":"book","type":"update","data":[{"symbol":"ADA/USD","bids":[{"price":0.194681,"qty":0.0},{"price":0.194622,"qty":2569.07582444}],"asks":[],"checksum":2832945109,"timestamp":"2026-09-16T00:17:27.429802Z"}]}}
{"v":1,"kind":"tick","pair":"BTC/USD","channel":"book","ts_exchange":"2026-09-16T00:17:27.574429Z","ts_recv":"2026-09-16T00:17:27.743730Z","payload":{"channel":"book","type":"update","data":[{"symbol":"BTC/USD","bids":[],"asks":[{"price":75731.9,"qty":1.39091555}],"checksum":3102091563,"timestamp":"2026-09-16T00:17:27.574429Z"}]}}
{"v":1,"kind":"tick","pair":"ADA/USD","channel":"book","ts_exchange":"2026-09-16T00:17:27.610580Z","ts_recv":"2026-09-16T00:17:27.778305Z","payload":{"channel":"book","type":"update","data":[{"symbol":"ADA/USD","bids":[],"asks":[{"price":0.194786,"qty":0.0},{"price":0.194845,"qty":3008.7},{"price":0.194784,"qty":3079.14650844}],"checksum":702181804,"timestamp":"2026-09-16T00:17:27.610580Z"}]}}
{"v":1,"kind":"tick","pair":"ADA/USD","channel":"book","ts_exchange":"2026-09-16T00:17:27.611552Z","ts_recv":"2026-09-16T00:17:27.778992Z","payload":{"channel":"book","type":"update","data":[{"symbol":"ADA/USD","bids":[],"asks":[{"price":0.194785,"qty":0.0},{"price":0.194845,"qty":3008.7}],"checksum":1894630380,"timestamp":"2026-09-16T00:17:27.611552Z"}]}}
{"v":1,"kind":"tick","pair":"ADA/USD","channel":"book","ts_exchange":"2026-09-16T00:17:27.850558Z","ts_recv":"2026-09-16T00:17:27.985078Z","payload":{"channel":"book","type":"update","data":[{"symbol":"ADA/USD","bids":[],"asks":[{"price":0.194784,"qty":0.0},{"price":0.19487,"qty":2565.81310617},{"price":0.194786,"qty":3079.14650844}],"checksum":1212583032,"timestamp":"2026-09-16T00:17:27.850558Z"}]}}
{"v":1,"kind":"tick","pair":"ADA/USD","channel":"book","ts_exchange":"2026-09-16T00:17:27.851028Z","ts_recv":"2026-09-16T00:17:27.986016Z","payload":{"channel":"book","type":"update","data":[{"symbol":"ADA/USD","bids":[],"asks":[{"price":0.194783,"qty":1708.38307931}],"checksum":3777404777,"timestamp":"2026-09-16T00:17:27.851028Z"}]}}
{"v":1,"kind":"tick","pair":"BTC/USD","channel":"book","ts_exchange":"2026-09-16T00:17:27.884770Z","ts_recv":"2026-09-16T00:17:28.011454Z","payload":{"channel":"book","type":"update","data":[{"symbol":"BTC/USD","bids":[{"price":75731.8,"qty":0.38615836}],"asks":[],"checksum":2050987775,"timestamp":"2026-09-16T00:17:27.884770Z"}]}}
{"v":1,"kind":"tick","pair":"BTC/USD","channel":"book","ts_exchange":"2026-09-16T00:17:27.884842Z","ts_recv":"2026-09-16T00:17:28.011750Z","payload":{"channel":"book","type":"update","data":[{"symbol":"BTC/USD","bids":[{"price":75729.9,"qty":0.0},{"price":75723.4,"qty":0.000051}],"asks":[],"checksum":927174390,"timestamp":"2026-09-16T00:17:27.884842Z"}]}}
{"v":1,"kind":"tick","pair":"BTC/USD","channel":"book","ts_exchange":"2026-09-16T00:17:27.885847Z","ts_recv":"2026-09-16T00:17:28.014826Z","payload":{"channel":"book","type":"update","data":[{"symbol":"BTC/USD","bids":[{"price":75730.0,"qty":0.0},{"price":75719.6,"qty":0.000051}],"asks":[],"checksum":561399838,"timestamp":"2026-09-16T00:17:27.885847Z"}]}}
{"v":1,"kind":"tick","pair":"BTC/USD","channel":"book","ts_exchange":"2026-09-16T00:17:27.885869Z","ts_recv":"2026-09-16T00:17:28.015217Z","payload":{"channel":"book","type":"update","data":[{"symbol":"BTC/USD","bids":[{"price":75730.9,"qty":1.32046324}],"asks":[],"checksum":1414935509,"timestamp":"2026-09-16T00:17:27.885869Z"}]}}
{"v":1,"kind":"tick","pair":"BTC/USD","channel":"book","ts_exchange":"2026-09-16T00:17:27.886044Z","ts_recv":"2026-09-16T00:17:28.015603Z","payload":{"channel":"book","type":"update","data":[{"symbol":"BTC/USD","bids":[{"price":75728.5,"qty":3.30126659}],"asks":[],"checksum":1729372413,"timestamp":"2026-09-16T00:17:27.886044Z"}]}}
{"v":1,"kind":"tick","pair":"BTC/USD","channel":"book","ts_exchange":"2026-09-16T00:17:27.889556Z","ts_recv":"2026-09-16T00:17:28.017523Z","payload":{"channel":"book","type":"update","data":[{"symbol":"BTC/USD","bids":[],"asks":[{"price":75731.9,"qty":1.41239813}],"checksum":452086236,"timestamp":"2026-09-16T00:17:27.889556Z"}]}}
{"v":1,"kind":"tick","pair":"BTC/USD","channel":"book","ts_exchange":"2026-09-16T00:17:27.889737Z","ts_recv":"2026-09-16T00:17:28.017847Z","payload":{"channel":"book","type":"update","data":[{"symbol":"BTC/USD","bids":[{"price":75731.8,"qty":0.37524258}],"asks":[],"checksum":708987086,"timestamp":"2026-09-16T00:17:27.889737Z"}]}}
{"v":1,"kind":"tick","pair":"BTC/USD","channel":"book","ts_exchange":"2026-09-16T00:17:27.892087Z","ts_recv":"2026-09-16T00:17:28.021175Z","payload":{"channel":"book","type":"update","data":[{"symbol":"BTC/USD","bids":[],"asks":[{"price":75731.9,"qty":1.39091555}],"checksum":1470374383,"timestamp":"2026-09-16T00:17:27.892087Z"}]}}
{"v":1,"kind":"tick","pair":"BTC/USD","channel":"book","ts_exchange":"2026-09-16T00:17:27.892532Z","ts_recv":"2026-09-16T00:17:28.021875Z","payload":{"channel":"book","type":"update","data":[{"symbol":"BTC/USD","bids":[{"price":75731.8,"qty":0.38615836}],"asks":[],"checksum":1729372413,"timestamp":"2026-09-16T00:17:27.892532Z"}]}}
{"v":1,"kind":"tick","pair":"BTC/USD","channel":"book","ts_exchange":"2026-09-16T00:17:27.964319Z","ts_recv":"2026-09-16T00:17:28.091920Z","payload":{"channel":"book","type":"update","data":[{"symbol":"BTC/USD","bids":[{"price":75730.9,"qty":0.0},{"price":75723.4,"qty":0.000051}],"asks":[],"checksum":1707192506,"timestamp":"2026-09-16T00:17:27.964319Z"}]}}
{"v":1,"kind":"tick","pair":"BTC/USD","channel":"book","ts_exchange":"2026-09-16T00:17:27.965059Z","ts_recv":"2026-09-16T00:17:28.092116Z","payload":{"channel":"book","type":"update","data":[{"symbol":"BTC/USD","bids":[{"price":75728.6,"qty":0.9854433}],"asks":[],"checksum":2448063347,"timestamp":"2026-09-16T00:17:27.965059Z"}]}}
{"v":1,"kind":"tick","pair":"BTC/USD","channel":"book","ts_exchange":"2026-09-16T00:17:27.967060Z","ts_recv":"2026-09-16T00:17:28.095009Z","payload":{"channel":"book","type":"update","data":[{"symbol":"BTC/USD","bids":[],"asks":[{"price":75731.9,"qty":1.41239813}],"checksum":1881009148,"timestamp":"2026-09-16T00:17:27.967060Z"}]}}
{"v":1,"kind":"tick","pair":"BTC/USD","channel":"book","ts_exchange":"2026-09-16T00:17:27.967340Z","ts_recv":"2026-09-16T00:17:28.095130Z","payload":{"channel":"book","type":"update","data":[{"symbol":"BTC/USD","bids":[{"price":75731.8,"qty":0.37524258}],"asks":[],"checksum":1977815059,"timestamp":"2026-09-16T00:17:27.967340Z"}]}}
{"v":1,"kind":"tick","pair":"ADA/USD","channel":"book","ts_exchange":"2026-09-16T00:17:28.016913Z","ts_recv":"2026-09-16T00:17:28.147077Z","payload":{"channel":"book","type":"update","data":[{"symbol":"ADA/USD","bids":[],"asks":[{"price":0.194786,"qty":0.0},{"price":0.194845,"qty":3008.7},{"price":0.194782,"qty":3079.14650844}],"checksum":2408035107,"timestamp":"2026-09-16T00:17:28.016913Z"}]}}
{"v":1,"kind":"tick","pair":"ADA/USD","channel":"book","ts_exchange":"2026-09-16T00:17:28.017713Z","ts_recv":"2026-09-16T00:17:28.147303Z","payload":{"channel":"book","type":"update","data":[{"symbol":"ADA/USD","bids":[],"asks":[{"price":0.194783,"qty":0.0},{"price":0.194845,"qty":3008.7}],"checksum":957354832,"timestamp":"2026-09-16T00:17:28.017713Z"}]}}
{"v":1,"kind":"tick","pair":"ADA/USD","channel":"book","ts_exchange":"2026-09-16T00:17:28.155483Z","ts_recv":"2026-09-16T00:17:28.284244Z","payload":{"channel":"book","type":"update","data":[{"symbol":"ADA/USD","bids":[],"asks":[{"price":0.194782,"qty":0.0},{"price":0.19487,"qty":2565.81310617},{"price":0.194786,"qty":3079.14650844}],"checksum":1212583032,"timestamp":"2026-09-16T00:17:28.155483Z"}]}}
{"v":1,"kind":"tick","pair":"ADA/USD","channel":"book","ts_exchange":"2026-09-16T00:17:28.156245Z","ts_recv":"2026-09-16T00:17:28.284471Z","payload":{"channel":"book","type":"update","data":[{"symbol":"ADA/USD","bids":[],"asks":[{"price":0.194785,"qty":1708.38307931}],"checksum":2832945109,"timestamp":"2026-09-16T00:17:28.156245Z"}]}}
{"v":1,"kind":"tick","pair":"BTC/USD","channel":"book","ts_exchange":"2026-09-16T00:17:28.162952Z","ts_recv":"2026-09-16T00:17:28.288863Z","payload":{"channel":"book","type":"update","data":[{"symbol":"BTC/USD","bids":[{"price":75730.8,"qty":1.3204663}],"asks":[],"checksum":3584959740,"timestamp":"2026-09-16T00:17:28.162952Z"}]}}
{"v":1,"kind":"tick","pair":"BTC/USD","channel":"book","ts_exchange":"2026-09-16T00:17:28.165614Z","ts_recv":"2026-09-16T00:17:28.293024Z","payload":{"channel":"book","type":"update","data":[{"symbol":"BTC/USD","bids":[{"price":75731.8,"qty":0.38615836}],"asks":[],"checksum":3494960915,"timestamp":"2026-09-16T00:17:28.165614Z"}]}}
{"v":1,"kind":"tick","pair":"BTC/USD","channel":"book","ts_exchange":"2026-09-16T00:17:28.165919Z","ts_recv":"2026-09-16T00:17:28.293143Z","payload":{"channel":"book","type":"update","data":[{"symbol":"BTC/USD","bids":[],"asks":[{"price":75731.9,"qty":1.39091555}],"checksum":833048476,"timestamp":"2026-09-16T00:17:28.165919Z"}]}}
{"v":1,"kind":"tick","pair":"ADA/USD","channel":"book","ts_exchange":"2026-09-16T00:17:28.317613Z","ts_recv":"2026-09-16T00:17:28.443367Z","payload":{"channel":"book","type":"update","data":[{"symbol":"ADA/USD","bids":[],"asks":[{"price":0.194786,"qty":0.0},{"price":0.194845,"qty":3008.7},{"price":0.194784,"qty":3079.14650844}],"checksum":702181804,"timestamp":"2026-09-16T00:17:28.317613Z"}]}}
{"v":1,"kind":"tick","pair":"ADA/USD","channel":"book","ts_exchange":"2026-09-16T00:17:28.318254Z","ts_recv":"2026-09-16T00:17:28.444316Z","payload":{"channel":"book","type":"update","data":[{"symbol":"ADA/USD","bids":[],"asks":[{"price":0.194785,"qty":0.0},{"price":0.194845,"qty":3008.7}],"checksum":1894630380,"timestamp":"2026-09-16T00:17:28.318254Z"}]}}
{"v":1,"kind":"tick","pair":"ADA/USD","channel":"book","ts_exchange":"2026-09-16T00:17:28.318324Z","ts_recv":"2026-09-16T00:17:28.444546Z","payload":{"channel":"book","type":"update","data":[{"symbol":"ADA/USD","bids":[],"asks":[{"price":0.194783,"qty":1708.38307931}],"checksum":225022791,"timestamp":"2026-09-16T00:17:28.318324Z"}]}}
{"v":1,"kind":"tick","pair":"ADA/USD","channel":"book","ts_exchange":"2026-09-16T00:17:28.521048Z","ts_recv":"2026-09-16T00:17:28.648763Z","payload":{"channel":"book","type":"update","data":[{"symbol":"ADA/USD","bids":[],"asks":[{"price":0.194784,"qty":0.0},{"price":0.194845,"qty":3008.7},{"price":0.194782,"qty":3079.14650844}],"checksum":2408035107,"timestamp":"2026-09-16T00:17:28.521048Z"}]}}
{"v":1,"kind":"tick","pair":"ADA/USD","channel":"book","ts_exchange":"2026-09-16T00:17:28.521798Z","ts_recv":"2026-09-16T00:17:28.650054Z","payload":{"channel":"book","type":"update","data":[{"symbol":"ADA/USD","bids":[],"asks":[{"price":0.194783,"qty":0.0},{"price":0.194845,"qty":3008.7}],"checksum":957354832,"timestamp":"2026-09-16T00:17:28.521798Z"}]}}
{"v":1,"kind":"tick","pair":"BTC/USD","channel":"book","ts_exchange":"2026-09-16T00:17:28.677085Z","ts_recv":"2026-09-16T00:17:28.804827Z","payload":{"channel":"book","type":"update","data":[{"symbol":"BTC/USD","bids":[{"price":75731.8,"qty":0.01153295}],"asks":[],"checksum":1910363165,"timestamp":"2026-09-16T00:17:28.677085Z"}]}}
{"v":1,"kind":"tick","pair":"ADA/USD","channel":"book","ts_exchange":"2026-09-16T00:17:28.691069Z","ts_recv":"2026-09-16T00:17:28.816462Z","payload":{"channel":"book","type":"update","data":[{"symbol":"ADA/USD","bids":[],"asks":[{"price":0.194782,"qty":0.0},{"price":0.19487,"qty":2565.81310617},{"price":0.194786,"qty":3079.14650844}],"checksum":1212583032,"timestamp":"2026-09-16T00:17:28.691069Z"}]}}
{"v":1,"kind":"tick","pair":"ADA/USD","channel":"book","ts_exchange":"2026-09-16T00:17:28.692061Z","ts_recv":"2026-09-16T00:17:28.817861Z","payload":{"channel":"book","type":"update","data":[{"symbol":"ADA/USD","bids":[],"asks":[{"price":0.194785,"qty":1708.38307931}],"checksum":2832945109,"timestamp":"2026-09-16T00:17:28.692061Z"}]}}
{"v":1,"kind":"tick","pair":"BTC/USD","channel":"book","ts_exchange":"2026-09-16T00:17:28.769636Z","ts_recv":"2026-09-16T00:17:28.896413Z","payload":{"channel":"book","type":"update","data":[{"symbol":"BTC/USD","bids":[{"price":75731.8,"qty":0.38688988}],"asks":[],"checksum":2891584520,"timestamp":"2026-09-16T00:17:28.769636Z"}]}}
{"v":1,"kind":"tick","pair":"BTC/USD","channel":"book","ts_exchange":"2026-09-16T00:17:28.843187Z","ts_recv":"2026-09-16T00:17:28.987223Z","payload":{"channel":"book","type":"update","data":[{"symbol":"BTC/USD","bids":[],"asks":[{"price":75734.2,"qty":1.17607865}],"checksum":2060083227,"timestamp":"2026-09-16T00:17:28.843187Z"}]}}
{"v":1,"kind":"tick","pair":"BTC/USD","channel":"book","ts_exchange":"2026-09-16T00:17:28.843481Z","ts_recv":"2026-09-16T00:17:28.989438Z","payload":{"channel":"book","type":"update","data":[{"symbol":"BTC/USD","bids":[{"price":75728.7,"qty":1.06490469}],"asks":[],"checksum":1329051874,"timestamp":"2026-09-16T00:17:28.843481Z"}]}}
{"v":1,"kind":"tick","pair":"BTC/USD","channel":"book","ts_exchange":"2026-09-16T00:17:28.844794Z","ts_recv":"2026-09-16T00:17:28.995413Z","payload":{"channel":"book","type":"update","data":[{"symbol":"BTC/USD","bids":[],"asks":[{"price":75736.3,"qty":0.0},{"price":75737.0,"qty":0.025}],"checksum":3087915682,"timestamp":"2026-09-16T00:17:28.844794Z"}]}}
{"v":1,"kind":"tick","pair":"BTC/USD","channel":"book","ts_exchange":"2026-09-16T00:17:28.845699Z","ts_recv":"2026-09-16T00:17:28.997346Z","payload":{"channel":"book","type":"update","data":[{"symbol":"BTC/USD","bids":[{"price":75731.8,"qty":0.3759741}],"asks":[],"checksum":29388269,"timestamp":"2026-09-16T00:17:28.845699Z"}]}}
{"v":1,"kind":"tick","pair":"ADA/USD","channel":"book","ts_exchange":"2026-09-16T00:17:28.852708Z","ts_recv":"2026-09-16T00:17:29.001328Z","payload":{"channel":"book","type":"update","data":[{"symbol":"ADA/USD","bids":[],"asks":[{"price":0.194786,"qty":0.0},{"price":0.194845,"qty":3008.7},{"price":0.194784,"qty":3079.14650844}],"checksum":702181804,"timestamp":"2026-09-16T00:17:28.852708Z"}]}}
{"v":1,"kind":"tick","pair":"ADA/USD","channel":"book","ts_exchange":"2026-09-16T00:17:28.853430Z","ts_recv":"2026-09-16T00:17:29.002780Z","payload":{"channel":"book","type":"update","data":[{"symbol":"ADA/USD","bids":[],"asks":[{"price":0.194785,"qty":0.0},{"price":0.194845,"qty":3008.7}],"checksum":1894630380,"timestamp":"2026-09-16T00:17:28.853430Z"}]}}
{"v":1,"kind":"tick","pair":"ADA/USD","channel":"book","ts_exchange":"2026-09-16T00:17:28.853490Z","ts_recv":"2026-09-16T00:17:29.005039Z","payload":{"channel":"book","type":"update","data":[{"symbol":"ADA/USD","bids":[],"asks":[{"price":0.194783,"qty":1708.38307931}],"checksum":225022791,"timestamp":"2026-09-16T00:17:28.853490Z"}]}}
{"v":1,"kind":"tick","pair":"BTC/USD","channel":"book","ts_exchange":"2026-09-16T00:17:29.137952Z","ts_recv":"2026-09-16T00:17:29.263473Z","payload":{"channel":"book","type":"update","data":[{"symbol":"BTC/USD","bids":[],"asks":[{"price":75731.9,"qty":1.33721555}],"checksum":2031109879,"timestamp":"2026-09-16T00:17:29.137952Z"}]}}
{"v":1,"kind":"tick","pair":"ADA/USD","channel":"book","ts_exchange":"2026-09-16T00:17:29.142435Z","ts_recv":"2026-09-16T00:17:29.268453Z","payload":{"channel":"book","type":"update","data":[{"symbol":"ADA/USD","bids":[],"asks":[{"price":0.194784,"qty":0.0},{"price":0.194845,"qty":3008.7},{"price":0.194782,"qty":3079.14650844}],"checksum":2408035107,"timestamp":"2026-09-16T00:17:29.142435Z"}]}}
{"v":1,"kind":"tick","pair":"ADA/USD","channel":"book","ts_exchange":"2026-09-16T00:17:29.143230Z","ts_recv":"2026-09-16T00:17:29.269293Z","payload":{"channel":"book","type":"update","data":[{"symbol":"ADA/USD","bids":[],"asks":[{"price":0.194783,"qty":0.0},{"price":0.194845,"qty":3008.7}],"checksum":957354832,"timestamp":"2026-09-16T00:17:29.143230Z"}]}}
{"v":1,"kind":"tick","pair":"BTC/USD","channel":"book","ts_exchange":"2026-09-16T00:17:29.183579Z","ts_recv":"2026-09-16T00:17:29.386713Z","payload":{"channel":"book","type":"update","data":[{"symbol":"BTC/USD","bids":[{"price":75728.7,"qty":0.0},{"price":75724.2,"qty":0.0537}],"asks":[],"checksum":2055892200,"timestamp":"2026-09-16T00:17:29.183579Z"}]}}
{"v":1,"kind":"tick","pair":"BTC/USD","channel":"book","ts_exchange":"2026-09-16T00:17:29.185482Z","ts_recv":"2026-09-16T00:17:29.394094Z","payload":{"channel":"book","type":"update","data":[{"symbol":"BTC/USD","bids":[{"price":75730.8,"qty":0.0},{"price":75723.7,"qty":3.30147294}],"asks":[],"checksum":3670497287,"timestamp":"2026-09-16T00:17:29.185482Z"}]}}
{"v":1,"kind":"tick","pair":"BTC/USD","channel":"book","ts_exchange":"2026-09-16T00:17:29.186305Z","ts_recv":"2026-09-16T00:17:29.396754Z","payload":{"channel":"book","type":"update","data":[{"symbol":"BTC/USD","bids":[{"price":75731.8,"qty":1.69642336}],"asks":[],"checksum":936612034,"timestamp":"2026-09-16T00:17:29.186305Z"}]}}
{"v":1,"kind":"tick","pair":"BTC/USD","channel":"book","ts_exchange":"2026-09-16T00:17:29.189798Z","ts_recv":"2026-09-16T00:17:29.402624Z","payload":{"channel":"book","type":"update","data":[{"symbol":"BTC/USD","bids":[{"price":75731.8,"qty":1.70733914}],"asks":[],"checksum":2667456223,"timestamp":"2026-09-16T00:17:29.189798Z"}]}}
{"v":1,"kind":"tick","pair":"ADA/USD","channel":"book","ts_exchange":"2026-09-16T00:17:29.290597Z","ts_recv":"2026-09-16T00:17:29.432779Z","payload":{"channel":"book","type":"update","data":[{"symbol":"ADA/USD","bids":[],"asks":[{"price":0.194782,"qty":0.0},{"price":0.19487,"qty":2565.81310617},{"price":0.194786,"qty":3078.99628794}],"checksum":575622664,"timestamp":"2026-09-16T00:17:29.290597Z"}]}}
{"v":1,"kind":"tick","pair":"ADA/USD","channel":"book","ts_exchange":"2026-09-16T00:17:29.291332Z","ts_recv":"2026-09-16T00:17:29.433798Z","payload":{"channel":"book","type":"update","data":[{"symbol":"ADA/USD","bids":[],"asks":[{"price":0.194785,"qty":1708.33823849}],"checksum":471947454,"timestamp":"2026-09-16T00:17:29.291332Z"}]}}
{"v":1,"kind":"tick","pair":"ADA/USD","channel":"book","ts_exchange":"2026-09-16T00:17:29.470114Z","ts_recv":"2026-09-16T00:17:29.598096Z","payload":{"channel":"book","type":"update","data":[{"symbol":"ADA/USD","bids":[],"asks":[{"price":0.194786,"qty":0.0},{"price":0.194845,"qty":3008.7},{"price":0.194784,"qty":3078.99628794}],"checksum":157302254,"timestamp":"2026-09-16T00:17:29.470114Z"}]}}
{"v":1,"kind":"tick","pair":"ADA/USD","channel":"book","ts_exchange":"2026-09-16T00:17:29.470797Z","ts_recv":"2026-09-16T00:17:29.600359Z","payload":{"channel":"book","type":"update","data":[{"symbol":"ADA/USD","bids":[],"asks":[{"price":0.194785,"qty":0.0},{"price":0.194845,"qty":3008.7}],"checksum":451150236,"timestamp":"2026-09-16T00:17:29.470797Z"}]}}
{"v":1,"kind":"tick","pair":"ADA/USD","channel":"book","ts_exchange":"2026-09-16T00:17:29.470907Z","ts_recv":"2026-09-16T00:17:29.602982Z","payload":{"channel":"book","type":"update","data":[{"symbol":"ADA/USD","bids":[],"asks":[{"price":0.194783,"qty":1708.33823849}],"checksum":3113452588,"timestamp":"2026-09-16T00:17:29.470907Z"}]}}
{"v":1,"kind":"tick","pair":"ADA/USD","channel":"book","ts_exchange":"2026-09-16T00:17:29.630488Z","ts_recv":"2026-09-16T00:17:29.755587Z","payload":{"channel":"book","type":"update","data":[{"symbol":"ADA/USD","bids":[],"asks":[{"price":0.194784,"qty":0.0},{"price":0.194845,"qty":3008.7},{"price":0.194782,"qty":3078.99628794}],"checksum":2940075873,"timestamp":"2026-09-16T00:17:29.630488Z"}]}}
{"v":1,"kind":"tick","pair":"ADA/USD","channel":"book","ts_exchange":"2026-09-16T00:17:29.631182Z","ts_recv":"2026-09-16T00:17:29.755889Z","payload":{"channel":"book","type":"update","data":[{"symbol":"ADA/USD","bids":[],"asks":[{"price":0.194783,"qty":0.0},{"price":0.194845,"qty":3008.7}],"checksum":1394200864,"timestamp":"2026-09-16T00:17:29.631182Z"}]}}
{"v":1,"kind":"tick","pair":"ADA/USD","channel":"book","ts_exchange":"2026-09-16T00:17:29.782834Z","ts_recv":"2026-09-16T00:17:29.914435Z","payload":{"channel":"book","type":"update","data":[{"symbol":"ADA/USD","bids":[],"asks":[{"price":0.194782,"qty":0.0},{"price":0.19487,"qty":2565.81310617},{"price":0.194786,"qty":3078.99628794}],"checksum":575622664,"timestamp":"2026-09-16T00:17:29.782834Z"}]}}
{"v":1,"kind":"tick","pair":"ADA/USD","channel":"book","ts_exchange":"2026-09-16T00:17:29.783560Z","ts_recv":"2026-09-16T00:17:29.914645Z","payload":{"channel":"book","type":"update","data":[{"symbol":"ADA/USD","bids":[],"asks":[{"price":0.194785,"qty":1708.33823849}],"checksum":471947454,"timestamp":"2026-09-16T00:17:29.783560Z"}]}}
{"v":1,"kind":"tick","pair":"BTC/USD","channel":"book","ts_exchange":"2026-09-16T00:17:29.918226Z","ts_recv":"2026-09-16T00:17:30.045008Z","payload":{"channel":"book","type":"update","data":[{"symbol":"BTC/USD","bids":[{"price":75725.9,"qty":0.02005204}],"asks":[],"checksum":3340040862,"timestamp":"2026-09-16T00:17:29.918226Z"}]}}
{"v":1,"kind":"tick","pair":"BTC/USD","channel":"book","ts_exchange":"2026-09-16T00:17:29.918273Z","ts_recv":"2026-09-16T00:17:30.045982Z","payload":{"channel":"book","type":"update","data":[{"symbol":"BTC/USD","bids":[{"price":75728.6,"qty":0.0},{"price":75723.4,"qty":0.000051}],"asks":[],"checksum":1804442503,"timestamp":"2026-09-16T00:17:29.918273Z"}]}}
{"v":1,"kind":"tick","pair":"BTC/USD","channel":"book","ts_exchange":"2026-09-16T00:17:29.918438Z","ts_recv":"2026-09-16T00:17:30.046620Z","payload":{"channel":"book","type":"update","data":[{"symbol":"BTC/USD","bids":[{"price":75725.9,"qty":0.0},{"price":75719.6,"qty":0.000051}],"asks":[],"checksum":1618853689,"timestamp":"2026-09-16T00:17:29.918438Z"}]}}
{"v":1,"kind":"tick","pair":"BTC/USD","channel":"book","ts_exchange":"2026-09-16T00:17:29.919958Z","ts_recv":"2026-09-16T00:17:30.047125Z","payload":{"channel":"book","type":"update","data":[{"symbol":"BTC/USD","bids":[{"price":75726.0,"qty":0.0},{"price":75719.4,"qty":0.02109115},{"price":75724.9,"qty":0.11117396}],"asks":[],"checksum":1515727037,"timestamp":"2026-09-16T00:17:29.919958Z"}]}}
{"v":1,"kind":"tick","pair":"ADA/USD","channel":"book","ts_exchange":"2026-09-16T00:17:30.006704Z","ts_recv":"2026-09-16T00:17:30.133413Z","payload":{"channel":"book","type":"update","data":[{"symbol":"ADA/USD","bids":[],"asks":[{"price":0.194786,"qty":0.0},{"price":0.194845,"qty":3008.7},{"price":0.194784,"qty":3078.99628794}],"checksum":157302254,"timestamp":"2026-09-16T00:17:30.006704Z"}]}}
{"v":1,"kind":"tick","pair":"ADA/USD","channel":"book","ts_exchange":"2026-09-16T00:17:30.007362Z","ts_recv":"2026-09-16T00:17:30.141557Z","payload":{"channel":"book","type":"update","data":[{"symbol":"ADA/USD","bids":[],"asks":[{"price":0.194785,"qty":0.0},{"price":0.194845,"qty":3008.7}],"checksum":451150236,"timestamp":"2026-09-16T00:17:30.007362Z"}]}}
{"v":1,"kind":"tick","pair":"ADA/USD","channel":"book","ts_exchange":"2026-09-16T00:17:30.007391Z","ts_recv":"2026-09-16T00:17:30.144557Z","payload":{"channel":"book","type":"update","data":[{"symbol":"ADA/USD","bids":[],"asks":[{"price":0.194783,"qty":1708.33823849}],"checksum":3113452588,"timestamp":"2026-09-16T00:17:30.007391Z"}]}}
{"v":1,"kind":"tick","pair":"ADA/USD","channel":"book","ts_exchange":"2026-09-16T00:17:30.183328Z","ts_recv":"2026-09-16T00:17:30.310989Z","payload":{"channel":"book","type":"update","data":[{"symbol":"ADA/USD","bids":[],"asks":[{"price":0.194784,"qty":0.0},{"price":0.194845,"qty":3008.7},{"price":0.194782,"qty":3078.99628794}],"checksum":2940075873,"timestamp":"2026-09-16T00:17:30.183328Z"}]}}
{"v":1,"kind":"tick","pair":"ADA/USD","channel":"book","ts_exchange":"2026-09-16T00:17:30.184265Z","ts_recv":"2026-09-16T00:17:30.311522Z","payload":{"channel":"book","type":"update","data":[{"symbol":"ADA/USD","bids":[],"asks":[{"price":0.194783,"qty":0.0},{"price":0.194845,"qty":3008.7}],"checksum":1394200864,"timestamp":"2026-09-16T00:17:30.184265Z"}]}}
{"v":1,"kind":"tick","pair":"ADA/USD","channel":"book","ts_exchange":"2026-09-16T00:17:30.194455Z","ts_recv":"2026-09-16T00:17:30.320300Z","payload":{"channel":"book","type":"update","data":[{"symbol":"ADA/USD","bids":[{"price":0.194686,"qty":0.0},{"price":0.194615,"qty":2569.17503789}],"asks":[],"checksum":1484726398,"timestamp":"2026-09-16T00:17:30.194455Z"}]}}
{"v":1,"kind":"tick","pair":"ADA/USD","channel":"book","ts_exchange":"2026-09-16T00:17:30.195125Z","ts_recv":"2026-09-16T00:17:30.321500Z","payload":{"channel":"book","type":"update","data":[{"symbol":"ADA/USD","bids":[{"price":0.194684,"qty":3078.996288}],"asks":[],"checksum":2351075718,"timestamp":"2026-09-16T00:17:30.195125Z"}]}}
{"v":1,"kind":"tick","pair":"ADA/USD","channel":"book","ts_exchange":"2026-09-16T00:17:30.195252Z","ts_recv":"2026-09-16T00:17:30.321783Z","payload":{"channel":"book","type":"update","data":[{"symbol":"ADA/USD","bids":[{"price":0.194685,"qty":0.0},{"price":0.194615,"qty":2569.17503789}],"asks":[],"checksum":2713886923,"timestamp":"2026-09-16T00:17:30.195252Z"}]}}
{"v":1,"kind":"tick","pair":"ADA/USD","channel":"book","ts_exchange":"2026-09-16T00:17:30.195467Z","ts_recv":"2026-09-16T00:17:30.322491Z","payload":{"channel":"book","type":"update","data":[{"symbol":"ADA/USD","bids":[{"price":0.194684,"qty":6087.696288}],"asks":[],"checksum":282481980,"timestamp":"2026-09-16T00:17:30.195467Z"}]}}
{"v":1,"kind":"tick","pair":"BTC/USD","channel":"book","ts_exchange":"2026-09-16T00:17:30.283883Z","ts_recv":"2026-09-16T00:17:30.414145Z","payload":{"channel":"book","type":"update","data":[{"symbol":"BTC/USD","bids":[],"asks":[{"price":75731.9,"qty":1.34382488}],"checksum":4121340185,"timestamp":"2026-09-16T00:17:30.283883Z"}]}}
{"v":1,"kind":"tick","pair":"ADA/USD","channel":"book","ts_exchange":"2026-09-16T00:17:30.342636Z","ts_recv":"2026-09-16T00:17:30.471814Z","payload":{"channel":"book","type":"update","data":[{"symbol":"ADA/USD","bids":[],"asks":[{"price":0.194782,"qty":0.0},{"price":0.19487,"qty":2565.81310617},{"price":0.194786,"qty":3078.99628794}],"checksum":1635830292,"timestamp":"2026-09-16T00:17:30.342636Z"}]}}
{"v":1,"kind":"tick","pair":"ADA/USD","channel":"book","ts_exchange":"2026-09-16T00:17:30.343752Z","ts_recv":"2026-09-16T00:17:30.472732Z","payload":{"channel":"book","type":"update","data":[{"symbol":"ADA/USD","bids":[],"asks":[{"price":0.194785,"qty":1708.33823849}],"checksum":1609489570,"timestamp":"2026-09-16T00:17:30.343752Z"}]}}
{"v":1,"kind":"tick","pair":"ADA/USD","channel":"book","ts_exchange":"2026-09-16T00:17:30.621530Z","ts_recv":"2026-09-16T00:17:30.747928Z","payload":{"channel":"book","type":"update","data":[{"symbol":"ADA/USD","bids":[],"asks":[{"price":0.194786,"qty":0.0},{"price":0.194845,"qty":3008.7},{"price":0.194784,"qty":3078.99628794}],"checksum":1253030386,"timestamp":"2026-09-16T00:17:30.621530Z"}]}}
{"v":1,"kind":"tick","pair":"ADA/USD","channel":"book","ts_exchange":"2026-09-16T00:17:30.622483Z","ts_recv":"2026-09-16T00:17:30.750236Z","payload":{"channel":"book","type":"update","data":[{"symbol":"ADA/USD","bids":[],"asks":[{"price":0.194785,"qty":0.0},{"price":0.194845,"qty":3008.7}],"checksum":1496024448,"timestamp":"2026-09-16T00:17:30.622483Z"}]}}
{"v":1,"kind":"tick","pair":"ADA/USD","channel":"book","ts_exchange":"2026-09-16T00:17:30.622599Z","ts_recv":"2026-09-16T00:17:30.750424Z","payload":{"channel":"book","type":"update","data":[{"symbol":"ADA/USD","bids":[],"asks":[{"price":0.194783,"qty":1708.33823849}],"checksum":4200333360,"timestamp":"2026-09-16T00:17:30.622599Z"}]}}
{"v":1,"kind":"tick","pair":"ADA/USD","channel":"book","ts_exchange":"2026-09-16T00:17:30.867851Z","ts_recv":"2026-09-16T00:17:30.993798Z","payload":{"channel":"book","type":"update","data":[{"symbol":"ADA/USD","bids":[],"asks":[{"price":0.194784,"qty":0.0},{"price":0.194845,"qty":3008.7},{"price":0.194782,"qty":3078.99628794}],"checksum":3975314301,"timestamp":"2026-09-16T00:17:30.867851Z"}]}}
{"v":1,"kind":"tick","pair":"ADA/USD","channel":"book","ts_exchange":"2026-09-16T00:17:30.868578Z","ts_recv":"2026-09-16T00:17:30.995751Z","payload":{"channel":"book","type":"update","data":[{"symbol":"ADA/USD","bids":[],"asks":[{"price":0.194783,"qty":0.0},{"price":0.194845,"qty":3008.7}],"checksum":282481980,"timestamp":"2026-09-16T00:17:30.868578Z"}]}}
{"v":1,"kind":"tick","pair":"BTC/USD","channel":"book","ts_exchange":"2026-09-16T00:17:30.890435Z","ts_recv":"2026-09-16T00:17:31.017928Z","payload":{"channel":"book","type":"update","data":[{"symbol":"BTC/USD","bids":[],"asks":[{"price":75731.9,"qty":1.32755202}],"checksum":3778817673,"timestamp":"2026-09-16T00:17:30.890435Z"}]}}
{"v":1,"kind":"tick","pair":"BTC/USD","channel":"book","ts_exchange":"2026-09-16T00:17:30.890515Z","ts_recv":"2026-09-16T00:17:31.018033Z","payload":{"channel":"book","type":"update","data":[{"symbol":"BTC/USD","bids":[{"price":75731.8,"qty":1.72463914}],"asks":[],"checksum":2854796246,"timestamp":"2026-09-16T00:17:30.890515Z"}]}}
{"v":1,"kind":"tick","pair":"ADA/USD","channel":"book","ts_exchange":"2026-09-16T00:17:31.004955Z","ts_recv":"2026-09-16T00:17:31.142112Z","payload":{"channel":"book","type":"update","data":[{"symbol":"ADA/USD","bids":[],"asks":[{"price":0.194782,"qty":0.0},{"price":0.19487,"qty":2565.81310617},{"price":0.194786,"qty":3078.99628794}],"checksum":1635830292,"timestamp":"2026-09-16T00:17:31.004955Z"}]}}
{"v":1,"kind":"tick","pair":"ADA/USD","channel":"book","ts_exchange":"2026-09-16T00:17:31.005682Z","ts_recv":"2026-09-16T00:17:31.151585Z","payload":{"channel":"book","type":"update","data":[{"symbol":"ADA/USD","bids":[],"asks":[{"price":0.194785,"qty":1708.33823849}],"checksum":1609489570,"timestamp":"2026-09-16T00:17:31.005682Z"}]}}
{"v":1,"kind":"tick","pair":"ADA/USD","channel":"book","ts_exchange":"2026-09-16T00:17:31.263983Z","ts_recv":"2026-09-16T00:17:31.389284Z","payload":{"channel":"book","type":"update","data":[{"symbol":"ADA/USD","bids":[],"asks":[{"price":0.194786,"qty":0.0},{"price":0.194845,"qty":3008.7},{"price":0.194784,"qty":3078.99628794}],"checksum":1253030386,"timestamp":"2026-09-16T00:17:31.263983Z"}]}}
{"v":1,"kind":"tick","pair":"ADA/USD","channel":"book","ts_exchange":"2026-09-16T00:17:31.264700Z","ts_recv":"2026-09-16T00:17:31.390451Z","payload":{"channel":"book","type":"update","data":[{"symbol":"ADA/USD","bids":[],"asks":[{"price":0.194785,"qty":0.0},{"price":0.194845,"qty":3008.7}],"checksum":1496024448,"timestamp":"2026-09-16T00:17:31.264700Z"}]}}
{"v":1,"kind":"tick","pair":"ADA/USD","channel":"book","ts_exchange":"2026-09-16T00:17:31.264743Z","ts_recv":"2026-09-16T00:17:31.390953Z","payload":{"channel":"book","type":"update","data":[{"symbol":"ADA/USD","bids":[],"asks":[{"price":0.194783,"qty":1708.33823849}],"checksum":4200333360,"timestamp":"2026-09-16T00:17:31.264743Z"}]}}
{"v":1,"kind":"tick","pair":"BTC/USD","channel":"book","ts_exchange":"2026-09-16T00:17:31.340692Z","ts_recv":"2026-09-16T00:17:31.474533Z","payload":{"channel":"book","type":"update","data":[{"symbol":"BTC/USD","bids":[{"price":75731.8,"qty":0.40418988}],"asks":[],"checksum":760333483,"timestamp":"2026-09-16T00:17:31.340692Z"}]}}
{"v":1,"kind":"tick","pair":"BTC/USD","channel":"book","ts_exchange":"2026-09-16T00:17:31.341844Z","ts_recv":"2026-09-16T00:17:31.475232Z","payload":{"channel":"book","type":"update","data":[{"symbol":"BTC/USD","bids":[{"price":75731.1,"qty":1.32046113}],"asks":[],"checksum":4269870418,"timestamp":"2026-09-16T00:17:31.341844Z"}]}}
{"v":1,"kind":"tick","pair":"BTC/USD","channel":"book","ts_exchange":"2026-09-16T00:17:31.342730Z","ts_recv":"2026-09-16T00:17:31.482784Z","payload":{"channel":"book","type":"update","data":[{"symbol":"BTC/USD","bids":[],"asks":[{"price":75731.9,"qty":1.34375202}],"checksum":2724641556,"timestamp":"2026-09-16T00:17:31.342730Z"}]}}
{"v":1,"kind":"tick","pair":"BTC/USD","channel":"book","ts_exchange":"2026-09-16T00:17:31.343421Z","ts_recv":"2026-09-16T00:17:31.483337Z","payload":{"channel":"book","type":"update","data":[{"symbol":"BTC/USD","bids":[{"price":75731.8,"qty":0.3932741}],"asks":[],"checksum":1861588722,"timestamp":"2026-09-16T00:17:31.343421Z"}]}}
{"v":1,"kind":"tick","pair":"BTC/USD","channel":"book","ts_exchange":"2026-09-16T00:17:31.345864Z","ts_recv":"2026-09-16T00:17:31.483823Z","payload":{"channel":"book","type":"update","data":[{"symbol":"BTC/USD","bids":[{"price":75731.8,"qty":0.40418988}],"asks":[],"checksum":2724641556,"timestamp":"2026-09-16T00:17:31.345864Z"}]}}
{"v":1,"kind":"tick","pair":"BTC/USD","channel":"book","ts_exchange":"2026-09-16T00:17:31.363428Z","ts_recv":"2026-09-16T00:17:31.489819Z","payload":{"channel":"book","type":"update","data":[{"symbol":"BTC/USD","bids":[{"price":75731.8,"qty":0.38688988}],"asks":[],"checksum":2607235664,"timestamp":"2026-09-16T00:17:31.363428Z"}]}}
{"v":1,"kind":"tick","pair":"ADA/USD","channel":"book","ts_exchange":"2026-09-16T00:17:31.612187Z","ts_recv":"2026-09-16T00:17:31.744359Z","payload":{"channel":"book","type":"update","data":[{"symbol":"ADA/USD","bids":[],"asks":[{"price":0.194784,"qty":0.0},{"price":0.194845,"qty":3008.7},{"price":0.194782,"qty":3078.99628794}],"checksum":3975314301,"timestamp":"2026-09-16T00:17:31.612187Z"}]}}
{"v":1,"kind":"tick","pair":"ADA/USD","channel":"book","ts_exchange":"2026-09-16T00:17:31.612897Z","ts_recv":"2026-09-16T00:17:31.744794Z","payload":{"channel":"book","type":"update","data":[{"symbol":"ADA/USD","bids":[],"asks":[{"price":0.194783,"qty":0.0},{"price":0.194845,"qty":3008.7}],"checksum":282481980,"timestamp":"2026-09-16T00:17:31.612897Z"}]}}
{"v":1,"kind":"tick","pair":"BTC/USD","channel":"book","ts_exchange":"2026-09-16T00:17:31.848812Z","ts_recv":"2026-09-16T00:17:31.985561Z","payload":{"channel":"book","type":"update","data":[{"symbol":"BTC/USD","bids":[{"price":75728.9,"qty":1.06490469}],"asks":[],"checksum":3073736694,"timestamp":"2026-09-16T00:17:31.848812Z"}]}}
{"v":1,"kind":"tick","pair":"ADA/USD","channel":"book","ts_exchange":"2026-09-16T00:17:31.898316Z","ts_recv":"2026-09-16T00:17:32.024126Z","payload":{"channel":"book","type":"update","data":[{"symbol":"ADA/USD","bids":[],"asks":[{"price":0.194782,"qty":0.0},{"price":0.19487,"qty":2565.81310617},{"price":0.194786,"qty":3078.99628794}],"checksum":1635830292,"timestamp":"2026-09-16T00:17:31.898316Z"}]}}
{"v":1,"kind":"tick","pair":"ADA/USD","channel":"book","ts_exchange":"2026-09-16T00:17:31.899244Z","ts_recv":"2026-09-16T00:17:32.036880Z","payload":{"channel":"book","type":"update","data":[{"symbol":"ADA/USD","bids":[],"asks":[{"price":0.194785,"qty":1708.33823849}],"checksum":1609489570,"timestamp":"2026-09-16T00:17:31.899244Z"}]}}
{"v":1,"kind":"tick","pair":"ADA/USD","channel":"book","ts_exchange":"2026-09-16T00:17:32.155050Z","ts_recv":"2026-09-16T00:17:32.283567Z","payload":{"channel":"book","type":"update","data":[{"symbol":"ADA/USD","bids":[],"asks":[{"price":0.194786,"qty":0.0},{"price":0.194845,"qty":3008.7},{"price":0.194784,"qty":3078.99628794}],"checksum":1253030386,"timestamp":"2026-09-16T00:17:32.155050Z"}]}}
{"v":1,"kind":"tick","pair":"ADA/USD","channel":"book","ts_exchange":"2026-09-16T00:17:32.155766Z","ts_recv":"2026-09-16T00:17:32.285585Z","payload":{"channel":"book","type":"update","data":[{"symbol":"ADA/USD","bids":[],"asks":[{"price":0.194785,"qty":0.0},{"price":0.194845,"qty":3008.7}],"checksum":1496024448,"timestamp":"2026-09-16T00:17:32.155766Z"}]}}
{"v":1,"kind":"tick","pair":"ADA/USD","channel":"book","ts_exchange":"2026-09-16T00:17:32.281831Z","ts_recv":"2026-09-16T00:17:32.413590Z","payload":{"channel":"book","type":"update","data":[{"symbol":"ADA/USD","bids":[{"price":0.194683,"qty":0.0},{"price":0.194597,"qty":3034.02570007}],"asks":[],"checksum":3710887761,"timestamp":"2026-09-16T00:17:32.281831Z"}]}}
{"v":1,"kind":"tick","pair":"ADA/USD","channel":"book","ts_exchange":"2026-09-16T00:17:32.281961Z","ts_recv":"2026-09-16T00:17:32.416196Z","payload":{"channel":"book","type":"update","data":[{"symbol":"ADA/USD","bids":[{"price":0.194685,"qty":1040.0}],"asks":[],"checksum":4192647739,"timestamp":"2026-09-16T00:17:32.281961Z"}]}}
{"v":1,"kind":"tick","pair":"ADA/USD","channel":"book","ts_exchange":"2026-09-16T00:17:32.282583Z","ts_recv":"2026-09-16T00:17:32.418421Z","payload":{"channel":"book","type":"update","data":[{"symbol":"ADA/USD","bids":[{"price":0.194684,"qty":3008.7},{"price":0.194651,"qty":3078.996288}],"asks":[],"checksum":3611486303,"timestamp":"2026-09-16T00:17:32.282583Z"}]}}
{"v":1,"kind":"tick","pair":"ADA/USD","channel":"book","ts_exchange":"2026-09-16T00:17:32.283345Z","ts_recv":"2026-09-16T00:17:32.420733Z","payload":{"channel":"book","type":"update","data":[{"symbol":"ADA/USD","bids":[{"price":0.194652,"qty":1299.22257417}],"asks":[],"checksum":3998456011,"timestamp":"2026-09-16T00:17:32.283345Z"}]}}
{"v":1,"kind":"tick","pair":"ADA/USD","channel":"book","ts_exchange":"2026-09-16T00:17:32.283484Z","ts_recv":"2026-09-16T00:17:32.423117Z","payload":{"channel":"book","type":"update","data":[{"symbol":"ADA/USD","bids":[{"price":0.194684,"qty":0.0},{"price":0.194615,"qty":2569.17503789}],"asks":[],"checksum":3677259293,"timestamp":"2026-09-16T00:17:32.283484Z"}]}}
{"v":1,"kind":"tick","pair":"ADA/USD","channel":"book","ts_exchange":"2026-09-16T00:17:32.283652Z","ts_recv":"2026-09-16T00:17:32.424800Z","payload":{"channel":"book","type":"update","data":[{"symbol":"ADA/USD","bids":[{"price":0.194653,"qty":3008.7}],"asks":[],"checksum":2428195376,"timestamp":"2026-09-16T00:17:32.283652Z"}]}}
{"v":1,"kind":"tick","pair":"ADA/USD","channel":"book","ts_exchange":"2026-09-16T00:17:32.410335Z","ts_recv":"2026-09-16T00:17:32.544650Z","payload":{"channel":"book","type":"update","data":[{"symbol":"ADA/USD","bids":[],"asks":[{"price":0.194784,"qty":0.0},{"price":0.19487,"qty":2565.81310617},{"price":0.194786,"qty":3078.99628794}],"checksum":1742843426,"timestamp":"2026-09-16T00:17:32.410335Z"}]}}
{"v":1,"kind":"tick","pair":"ADA/USD","channel":"book","ts_exchange":"2026-09-16T00:17:32.411120Z","ts_recv":"2026-09-16T00:17:32.546621Z","payload":{"channel":"book","type":"update","data":[{"symbol":"ADA/USD","bids":[],"asks":[{"price":0.194785,"qty":1708.33823849}],"checksum":1172166285,"timestamp":"2026-09-16T00:17:32.411120Z"}]}}
{"v":1,"kind":"tick","pair":"ADA/USD","channel":"book","ts_exchange":"2026-09-16T00:17:32.466721Z","ts_recv":"2026-09-16T00:17:32.622204Z","payload":{"channel":"book","type":"update","data":[{"symbol":"ADA/USD","bids":[{"price":0.194651,"qty":0.0},{"price":0.194615,"qty":2569.17503789},{"price":0.194654,"qty":3078.996288}],"asks":[],"checksum":2898402168,"timestamp":"2026-09-16T00:17:32.466721Z"}]}}
{"v":1,"kind":"tick","pair":"ADA/USD","channel":"book","ts_exchange":"2026-09-16T00:17:32.468807Z","ts_recv":"2026-09-16T00:17:32.631635Z","payload":{"channel":"book","type":"update","data":[{"symbol":"ADA/USD","bids":[{"price":0.194655,"qty":1199.22257417}],"asks":[],"checksum":3934641597,"timestamp":"2026-09-16T00:17:32.468807Z"}]}}
{"v":1,"kind":"tick","pair":"ADA/USD","channel":"book","ts_exchange":"2026-09-16T00:17:32.468993Z","ts_recv":"2026-09-16T00:17:32.632128Z","payload":{"channel":"book","type":"update","data":[{"symbol":"ADA/USD","bids":[{"price":0.194655,"qty":4207.92257417}],"asks":[],"checksum":3909444968,"timestamp":"2026-09-16T00:17:32.468993Z"}]}}
{"v":1,"kind":"tick","pair":"ADA/USD","channel":"book","ts_exchange":"2026-09-16T00:17:32.469036Z","ts_recv":"2026-09-16T00:17:32.632567Z","payload":{"channel":"book","type":"update","data":[{"symbol":"ADA/USD","bids":[{"price":0.194652,"qty":100.0}],"asks":[],"checksum":1676079414,"timestamp":"2026-09-16T00:17:32.469036Z"}]}}
{"v":1,"kind":"tick","pair":"ADA/USD","channel":"book","ts_exchange":"2026-09-16T00:17:32.569500Z","ts_recv":"2026-09-16T00:17:32.728671Z","payload":{"channel":"book","type":"update","data":[{"symbol":"ADA/USD","bids":[{"price":0.194653,"qty":0.0},{"price":0.194622,"qty":2569.07582444}],"asks":[],"checksum":3616841131,"timestamp":"2026-09-16T00:17:32.569500Z"}]}}
{"v":1,"kind":"tick","pair":"ADA/USD","channel":"book","ts_exchange":"2026-09-16T00:17:32.570543Z","ts_recv":"2026-09-16T00:17:32.734140Z","payload":{"channel":"book","type":"update","data":[{"symbol":"ADA/USD","bids":[],"asks":[{"price":0.194786,"qty":0.0},{"price":0.194845,"qty":3008.7},{"price":0.194784,"qty":3078.99628794}],"checksum":3268802811,"timestamp":"2026-09-16T00:17:32.570543Z"}]}}
{"v":1,"kind":"tick","pair":"ADA/USD","channel":"book","ts_exchange":"2026-09-16T00:17:32.571326Z","ts_recv":"2026-09-16T00:17:32.735936Z","payload":{"channel":"book","type":"update","data":[{"symbol":"ADA/USD","bids":[],"asks":[{"price":0.194785,"qty":0.0},{"price":0.194845,"qty":3008.7}],"checksum":3511796873,"timestamp":"2026-09-16T00:17:32.571326Z"}]}}
{"v":1,"kind":"tick","pair":"ADA/USD","channel":"book","ts_exchange":"2026-09-16T00:17:32.941346Z","ts_recv":"2026-09-16T00:17:33.073634Z","payload":{"channel":"book","type":"update","data":[{"symbol":"ADA/USD","bids":[{"price":0.194654,"qty":0.0},{"price":0.194615,"qty":2569.17503789},{"price":0.194656,"qty":3078.996288}],"asks":[],"checksum":1248688893,"timestamp":"2026-09-16T00:17:32.941346Z"}]}}
{"v":1,"kind":"tick","pair":"ADA/USD","channel":"book","ts_exchange":"2026-09-16T00:17:32.941835Z","ts_recv":"2026-09-16T00:17:33.073944Z","payload":{"channel":"book","type":"update","data":[{"symbol":"ADA/USD","bids":[],"asks":[{"price":0.194784,"qty":0.0},{"price":0.19487,"qty":2565.81310617},{"price":0.194786,"qty":3078.99628794}],"checksum":1925592425,"timestamp":"2026-09-16T00:17:32.941835Z"}]}}
{"v":1,"kind":"tick","pair":"ADA/USD","channel":"book","ts_exchange":"2026-09-16T00:17:32.944673Z","ts_recv":"2026-09-16T00:17:33.074219Z","payload":{"channel":"book","type":"update","data":[{"symbol":"ADA/USD","bids":[{"price":0.194655,"qty":3008.7}],"asks":[],"checksum":3221387754,"timestamp":"2026-09-16T00:17:32.944673Z"}]}}
{"v":1,"kind":"tick","pair":"ADA/USD","channel":"book","ts_exchange":"2026-09-16T00:17:32.944780Z","ts_recv":"2026-09-16T00:17:33.087215Z","payload":{"channel":"book","type":"update","data":[{"symbol":"ADA/USD","bids":[{"price":0.194657,"qty":1081.55548236}],"asks":[],"checksum":773741547,"timestamp":"2026-09-16T00:17:32.944780Z"}]}}
{"v":1,"kind":"tick","pair":"ADA/USD","channel":"book","ts_exchange":"2026-09-16T00:17:32.944799Z","ts_recv":"2026-09-16T00:17:33.089628Z","payload":{"channel":"book","type":"update","data":[{"symbol":"ADA/USD","bids":[],"asks":[{"price":0.194785,"qty":1708.33823849}],"checksum":275795293,"timestamp":"2026-09-16T00:17:32.944799Z"}]}}
{"v":1,"kind":"tick","pair":"ADA/USD","channel":"book","ts_exchange":"2026-09-16T00:17:33.154446Z","ts_recv":"2026-09-16T00:17:33.281490Z","payload":{"channel":"book","type":"update","data":[{"symbol":"ADA/USD","bids":[{"price":0.194656,"qty":0.0},{"price":0.194622,"qty":2569.07582444},{"price":0.194658,"qty":3078.996288}],"asks":[],"checksum":1177661828,"timestamp":"2026-09-16T00:17:33.154446Z"}]}}
{"v":1,"kind":"tick","pair":"ADA/USD","channel":"book","ts_exchange":"2026-09-16T00:17:33.154603Z","ts_recv":"2026-09-16T00:17:33.281794Z","payload":{"channel":"book","type":"update","data":[{"symbol":"ADA/USD","bids":[],"asks":[{"price":0.194786,"qty":0.0},{"price":0.194845,"qty":3008.7},{"price":0.194784,"qty":3078.99628794}],"checksum":1399903444,"timestamp":"2026-09-16T00:17:33.154603Z"}]}}
{"v":1,"kind":"tick","pair":"ADA/USD","channel":"book","ts_exchange":"2026-09-16T00:17:33.155361Z","ts_recv":"2026-09-16T00:17:33.282294Z","payload":{"channel":"book","type":"update","data":[{"symbol":"ADA/USD","bids":[],"asks":[{"price":0.194785,"qty":0.0},{"price":0.194845,"qty":3008.7}],"checksum":1089792166,"timestamp":"2026-09-16T00:17:33.155361Z"}]}}
{"v":1,"kind":"tick","pair":"ADA/USD","channel":"book","ts_exchange":"2026-09-16T00:17:33.572528Z","ts_recv":"2026-09-16T00:17:33.701177Z","payload":{"channel":"book","type":"update","data":[{"symbol":"ADA/USD","bids":[],"asks":[{"price":0.194784,"qty":0.0},{"price":0.19487,"qty":2565.81310617},{"price":0.194786,"qty":3078.99628794}],"checksum":2019534642,"timestamp":"2026-09-16T00:17:33.572528Z"}]}}
{"v":1,"kind":"tick","pair":"ADA/USD","channel":"book","ts_exchange":"2026-09-16T00:17:33.573479Z","ts_recv":"2026-09-16T00:17:33.701933Z","payload":{"channel":"book","type":"update","data":[{"symbol":"ADA/USD","bids":[],"asks":[{"price":0.194785,"qty":1708.33823849}],"checksum":1177661828,"timestamp":"2026-09-16T00:17:33.573479Z"}]}}
{"v":1,"kind":"tick","pair":"BTC/USD","channel":"book","ts_exchange":"2026-09-16T00:17:33.585061Z","ts_recv":"2026-09-16T00:17:33.720297Z","payload":{"channel":"book","type":"update","data":[{"symbol":"BTC/USD","bids":[],"asks":[{"price":75734.2,"qty":0.11117396}],"checksum":2129734269,"timestamp":"2026-09-16T00:17:33.585061Z"}]}}
{"v":1,"kind":"tick","pair":"BTC/USD","channel":"book","ts_exchange":"2026-09-16T00:17:33.585829Z","ts_recv":"2026-09-16T00:17:33.722430Z","payload":{"channel":"book","type":"update","data":[{"symbol":"BTC/USD","bids":[{"price":75731.8,"qty":0.01153295}],"asks":[],"checksum":141600927,"timestamp":"2026-09-16T00:17:33.585829Z"}]}}
{"v":1,"kind":"tick","pair":"BTC/USD","channel":"book","ts_exchange":"2026-09-16T00:17:33.589283Z","ts_recv":"2026-09-16T00:17:33.735036Z","payload":{"channel":"book","type":"update","data":[{"symbol":"BTC/USD","bids":[{"price":75728.9,"qty":0.0},{"price":75723.4,"qty":0.000051}],"asks":[],"checksum":1235342381,"timestamp":"2026-09-16T00:17:33.589283Z"}]}}
{"v":1,"kind":"tick","pair":"BTC/USD","channel":"book","ts_exchange":"2026-09-16T00:17:33.589808Z","ts_recv":"2026-09-16T00:17:33.739422Z","payload":{"channel":"book","type":"update","data":[{"symbol":"BTC/USD","bids":[{"price":75724.8,"qty":0.0},{"price":75719.6,"qty":0.000051}],"asks":[],"checksum":569054643,"timestamp":"2026-09-16T00:17:33.589808Z"}]}}
{"v":1,"kind":"tick","pair":"ADA/USD","channel":"book","ts_exchange":"2026-09-16T00:17:33.589926Z","ts_recv":"2026-09-16T00:17:33.740687Z","payload":{"channel":"book","type":"update","data":[{"symbol":"ADA/USD","bids":[],"asks":[{"price":0.194785,"qty":0.0},{"price":0.194845,"qty":3008.7}],"checksum":2019534642,"timestamp":"2026-09-16T00:17:33.589926Z"}]}}
{"v":1,"kind":"tick","pair":"BTC/USD","channel":"book","ts_exchange":"2026-09-16T00:17:33.590314Z","ts_recv":"2026-09-16T00:17:33.742582Z","payload":{"channel":"book","type":"update","data":[{"symbol":"BTC/USD","bids":[{"price":75731.1,"qty":0.0},{"price":75719.4,"qty":0.02109115}],"asks":[],"checksum":1194532470,"timestamp":"2026-09-16T00:17:33.590314Z"}]}}
{"v":1,"kind":"tick","pair":"BTC/USD","channel":"book","ts_exchange":"2026-09-16T00:17:33.590918Z","ts_recv":"2026-09-16T00:17:33.745880Z","payload":{"channel":"book","type":"update","data":[{"symbol":"BTC/USD","bids":[{"price":75731.8,"qty":0.06523295}],"asks":[],"checksum":2912213526,"timestamp":"2026-09-16T00:17:33.590918Z"}]}}
{"v":1,"kind":"tick","pair":"BTC/USD","channel":"book","ts_exchange":"2026-09-16T00:17:33.591445Z","ts_recv":"2026-09-16T00:17:33.747897Z","payload":{"channel":"book","type":"update","data":[{"symbol":"BTC/USD","bids":[{"price":75728.5,"qty":0.0},{"price":75717.0,"qty":0.00006024}],"asks":[],"checksum":3428673539,"timestamp":"2026-09-16T00:17:33.591445Z"}]}}
{"v":1,"kind":"tick","pair":"BTC/USD","channel":"book","ts_exchange":"2026-09-16T00:17:33.595440Z","ts_recv":"2026-09-16T00:17:33.755399Z","payload":{"channel":"book","type":"update","data":[{"symbol":"BTC/USD","bids":[{"price":75731.8,"qty":0.44242335}],"asks":[],"checksum":1794469287,"timestamp":"2026-09-16T00:17:33.595440Z"}]}}
{"v":1,"kind":"tick","pair":"BTC/USD","channel":"book","ts_exchange":"2026-09-16T00:17:33.596522Z","ts_recv":"2026-09-16T00:17:33.781929Z","payload":{"channel":"book","type":"update","data":[{"symbol":"BTC/USD","bids":[],"asks":[{"price":75731.9,"qty":1.3652346}],"checksum":370932371,"timestamp":"2026-09-16T00:17:33.596522Z"}]}}
{"v":1,"kind":"tick","pair":"BTC/USD","channel":"book","ts_exchange":"2026-09-16T00:17:33.597098Z","ts_recv":"2026-09-16T00:17:33.782748Z","payload":{"channel":"book","type":"update","data":[{"symbol":"BTC/USD","bids":[{"price":75727.7,"qty":0.9904235}],"asks":[],"checksum":527478092,"timestamp":"2026-09-16T00:17:33.597098Z"}]}}
{"v":1,"kind":"tick","pair":"BTC/USD","channel":"book","ts_exchange":"2026-09-16T00:17:33.597669Z","ts_recv":"2026-09-16T00:17:33.785530Z","payload":{"channel":"book","type":"update","data":[{"symbol":"BTC/USD","bids":[{"price":75731.8,"qty":0.43150757}],"asks":[],"checksum":2757575019,"timestamp":"2026-09-16T00:17:33.597669Z"}]}}
{"v":1,"kind":"tick","pair":"ADA/USD","channel":"book","ts_exchange":"2026-09-16T00:17:33.597848Z","ts_recv":"2026-09-16T00:17:33.785897Z","payload":{"channel":"book","type":"update","data":[{"symbol":"ADA/USD","bids":[],"asks":[{"price":0.194829,"qty":0.0},{"price":0.19487,"qty":2565.81310617},{"price":0.194839,"qty":2567.79344707}],"checksum":930990378,"timestamp":"2026-09-16T00:17:33.597848Z"}]}}
{"v":1,"kind":"tick","pair":"ADA/USD","channel":"book","ts_exchange":"2026-09-16T00:17:33.599654Z","ts_recv":"2026-09-16T00:17:33.788776Z","payload":{"channel":"book","type":"update","data":[{"symbol":"ADA/USD","bids":[],"asks":[{"price":0.194787,"qty":0.0},{"price":0.19487,"qty":2565.81310617}],"checksum":3674433851,"timestamp":"2026-09-16T00:17:33.599654Z"}]}}
{"v":1,"kind":"tick","pair":"BTC/USD","channel":"book","ts_exchange":"2026-09-16T00:17:33.600402Z","ts_recv":"2026-09-16T00:17:33.789694Z","payload":{"channel":"book","type":"update","data":[{"symbol":"BTC/USD","bids":[],"asks":[{"price":75731.9,"qty":0.04478708}],"checksum":3191398177,"timestamp":"2026-09-16T00:17:33.600402Z"}]}}
{"v":1,"kind":"tick","pair":"BTC/USD","channel":"book","ts_exchange":"2026-09-16T00:17:33.600690Z","ts_recv":"2026-09-16T00:17:33.790530Z","payload":{"channel":"book","type":"update","data":[{"symbol":"BTC/USD","bids":[],"asks":[{"price":75734.1,"qty":0.0},{"price":75737.6,"qty":0.04105332}],"checksum":3491987452,"timestamp":"2026-09-16T00:17:33.600690Z"}]}}
{"v":1,"kind":"tick","pair":"BTC/USD","channel":"book","ts_exchange":"2026-09-16T00:17:33.602893Z","ts_recv":"2026-09-16T00:17:33.792581Z","payload":{"channel":"book","type":"update","data":[{"symbol":"BTC/USD","bids":[{"price":75724.9,"qty":0.0},{"price":75717.0,"qty":0.00006024},{"price":75724.3,"qty":0.013425}],"asks":[],"checksum":1735161678,"timestamp":"2026-09-16T00:17:33.602893Z"}]}}
{"v":1,"kind":"tick","pair":"BTC/USD","channel":"book","ts_exchange":"2026-09-16T00:17:33.603434Z","ts_recv":"2026-09-16T00:17:33.793599Z","payload":{"channel":"book","type":"update","data":[{"symbol":"BTC/USD","bids":[{"price":75723.7,"qty":0.0},{"price":75717.0,"qty":0.00006024}],"asks":[],"checksum":1191176579,"timestamp":"2026-09-16T00:17:33.603434Z"}]}}
{"v":1,"kind":"tick","pair":"ADA/USD","channel":"book","ts_exchange":"2026-09-16T00:17:33.604080Z","ts_recv":"2026-09-16T00:17:33.795010Z","payload":{"channel":"book","type":"update","data":[{"symbol":"ADA/USD","bids":[],"asks":[{"price":0.194805,"qty":1525.80514394}],"checksum":2392678570,"timestamp":"2026-09-16T00:17:33.604080Z"}]}}
{"v":1,"kind":"tick","pair":"ADA/USD","channel":"book","ts_exchange":"2026-09-16T00:17:33.605104Z","ts_recv":"2026-09-16T00:17:33.795818Z","payload":{"channel":"book","type":"update","data":[{"symbol":"ADA/USD","bids":[],"asks":[{"price":0.194841,"qty":0.0},{"price":0.194871,"qty":1030.33822061}],"checksum":302533869,"timestamp":"2026-09-16T00:17:33.605104Z"}]}}
{"v":1,"kind":"tick","pair":"BTC/USD","channel":"book","ts_exchange":"2026-09-16T00:17:33.608673Z","ts_recv":"2026-09-16T00:17:33.797813Z","payload":{"channel":"book","type":"update","data":[{"symbol":"BTC/USD","bids":[],"asks":[{"price":75731.9,"qty":0.0233045}],"checksum":1268884077,"timestamp":"2026-09-16T00:17:33.608673Z"}]}}
{"v":1,"kind":"tick","pair":"ADA/USD","channel":"book","ts_exchange":"2026-09-16T00:17:33.609274Z","ts_recv":"2026-09-16T00:17:33.800371Z","payload":{"channel":"book","type":"update","data":[{"symbol":"ADA/USD","bids":[],"asks":[{"price":0.19484,"qty":0.0},{"price":0.194873,"qty":3451.71933202}],"checksum":2694818398,"timestamp":"2026-09-16T00:17:33.609274Z"}]}}
{"v":1,"kind":"tick","pair":"ADA/USD","channel":"book","ts_exchange":"2026-09-16T00:17:33.610033Z","ts_recv":"2026-09-16T00:17:33.801118Z","payload":{"channel":"book","type":"update","data":[{"symbol":"ADA/USD","bids":[],"asks":[{"price":0.194805,"qty":256.66692333}],"checksum":1001395433,"timestamp":"2026-09-16T00:17:33.610033Z"}]}}
{"v":1,"kind":"tick","pair":"ADA/USD","channel":"book","ts_exchange":"2026-09-16T00:17:33.610324Z","ts_recv":"2026-09-16T00:17:33.801940Z","payload":{"channel":"book","type":"update","data":[{"symbol":"ADA/USD","bids":[{"price":0.194658,"qty":0.0},{"price":0.194622,"qty":2569.07582444},{"price":0.194686,"qty":3078.996288}],"asks":[],"checksum":1611585495,"timestamp":"2026-09-16T00:17:33.610324Z"}]}}
{"v":1,"kind":"tick","pair":"BTC/USD","channel":"book","ts_exchange":"2026-09-16T00:17:33.612223Z","ts_recv":"2026-09-16T00:17:33.810951Z","payload":{"channel":"book","type":"update","data":[{"symbol":"BTC/USD","bids":[{"price":75731.8,"qty":0.44242335}],"asks":[],"checksum":2371505644,"timestamp":"2026-09-16T00:17:33.612223Z"}]}}
{"v":1,"kind":"tick","pair":"ADA/USD","channel":"book","ts_exchange":"2026-09-16T00:17:33.612416Z","ts_recv":"2026-09-16T00:17:33.829736Z","payload":{"channel":"book","type":"update","data":[{"symbol":"ADA/USD","bids":[],"asks":[{"price":0.194805,"qty":0.0},{"price":0.194885,"qty":25688.148332}],"checksum":236698346,"timestamp":"2026-09-16T00:17:33.612416Z"}]}}
{"v":1,"kind":"tick","pair":"ADA/USD","channel":"book","ts_exchange":"2026-09-16T00:17:33.612800Z","ts_recv":"2026-09-16T00:17:33.831422Z","payload":{"channel":"book","type":"update","data":[{"symbol":"ADA/USD","bids":[],"asks":[{"price":0.194786,"qty":0.0},{"price":0.194886,"qty":36057.4483484}],"checksum":529541272,"timestamp":"2026-09-16T00:17:33.612800Z"}]}}
{"v":1,"kind":"tick","pair":"BTC/USD","channel":"book","ts_exchange":"2026-09-16T00:17:33.612924Z","ts_recv":"2026-09-16T00:17:33.831972Z","payload":{"channel":"book","type":"update","data":[{"symbol":"BTC/USD","bids":[{"price":75731.8,"qty":0.45972335}],"asks":[],"checksum":2721000281,"timestamp":"2026-09-16T00:17:33.612924Z"}]}}
{"v":1,"kind":"tick","pair":"ADA/USD","channel":"book","ts_exchange":"2026-09-16T00:17:33.612943Z","ts_recv":"2026-09-16T00:17:33.832430Z","payload":{"channel":"book","type":"update","data":[{"symbol":"ADA/USD","bids":[{"price":0.19465,"qty":0.0},{"price":0.194622,"qty":2569.07582444}],"asks":[],"checksum":1342660424,"timestamp":"2026-09-16T00:17:33.612943Z"}]}}
{"v":1,"kind":"tick","pair":"ADA/USD","channel":"book","ts_exchange":"2026-09-16T00:17:33.614639Z","ts_recv":"2026-09-16T00:17:33.834231Z","payload":{"channel":"book","type":"update","data":[{"symbol":"ADA/USD","bids":[{"price":0.194687,"qty":1081.55548236}],"asks":[],"checksum":4080227243,"timestamp":"2026-09-16T00:17:33.614639Z"}]}}
{"v":1,"kind":"tick","pair":"BTC/USD","channel":"book","ts_exchange":"2026-09-16T00:17:33.614709Z","ts_recv":"2026-09-16T00:17:33.834654Z","payload":{"channel":"book","type":"update","data":[{"symbol":"BTC/USD","bids":[],"asks":[{"price":75737.6,"qty":0.0},{"price":75738.4,"qty":0.000051}],"checksum":1174694989,"timestamp":"2026-09-16T00:17:33.614709Z"}]}}
{"v":1,"kind":"tick","pair":"BTC/USD","channel":"book","ts_exchange":"2026-09-16T00:17:33.620723Z","ts_recv":"2026-09-16T00:17:33.836931Z","payload":{"channel":"book","type":"update","data":[{"symbol":"BTC/USD","bids":[],"asks":[{"price":75734.2,"qty":0.0},{"price":75738.8,"qty":0.00006024}],"checksum":2598715698,"timestamp":"2026-09-16T00:17:33.620723Z"}]}}
{"v":1,"kind":"tick","pair":"ADA/USD","channel":"book","ts_exchange":"2026-09-16T00:17:33.621078Z","ts_recv":"2026-09-16T00:17:33.837708Z","payload":{"channel":"book","type":"update","data":[{"symbol":"ADA/USD","bids":[],"asks":[{"price":0.19487,"qty":0.0},{"price":0.194887,"qty":50000.0}],"checksum":1025811879,"timestamp":"2026-09-16T00:17:33.621078Z"}]}}
{"v":1,"kind":"tick","pair":"ADA/USD","channel":"book","ts_exchange":"2026-09-16T00:17:33.621194Z","ts_recv":"2026-09-16T00:17:33.837912Z","payload":{"channel":"book","type":"update","data":[{"symbol":"ADA/USD","bids":[],"asks":[{"price":0.194887,"qty":0.0},{"price":0.19489,"qty":10227.90268009}],"checksum":613173694,"timestamp":"2026-09-16T00:17:33.621194Z"}]}}
{"v":1,"kind":"tick","pair":"BTC/USD","channel":"book","ts_exchange":"2026-09-16T00:17:33.623554Z","ts_recv":"2026-09-16T00:17:33.839047Z","payload":{"channel":"book","type":"update","data":[{"symbol":"BTC/USD","bids":[],"asks":[{"price":75735.6,"qty":0.0},{"price":75739.5,"qty":0.14497434}],"checksum":4236410903,"timestamp":"2026-09-16T00:17:33.623554Z"}]}}
{"v":1,"kind":"tick","pair":"ADA/USD","channel":"book","ts_exchange":"2026-09-16T00:17:33.623797Z","ts_recv":"2026-09-16T00:17:33.839191Z","payload":{"channel":"book","type":"update","data":[{"symbol":"ADA/USD","bids":[],"asks":[{"price":0.194839,"qty":0.0},{"price":0.194898,"qty":256.54567046},{"price":0.194844,"qty":2567.79344707}],"checksum":1587416863,"timestamp":"2026-09-16T00:17:33.623797Z"}]}}
{"v":1,"kind":"tick","pair":"ADA/USD","channel":"book","ts_exchange":"2026-09-16T00:17:33.623922Z","ts_recv":"2026-09-16T00:17:33.839332Z","payload":{"channel":"book","type":"update","data":[{"symbol":"ADA/USD","bids":[{"price":0.19466,"qty":12245.46516048}],"asks":[],"checksum":4002756841,"timestamp":"2026-09-16T00:17:33.623922Z"}]}}
{"v":1,"kind":"tick","pair":"ADA/USD","channel":"book","ts_exchange":"2026-09-16T00:17:33.624201Z","ts_recv":"2026-09-16T00:17:33.840168Z","payload":{"channel":"book","type":"update","data":[{"symbol":"ADA/USD","bids":[],"asks":[{"price":0.194885,"qty":0.0},{"price":0.194898,"qty":256.54567046}],"checksum":2774833628,"timestamp":"2026-09-16T00:17:33.624201Z"}]}}
{"v":1,"kind":"tick","pair":"BTC/USD","channel":"book","ts_exchange":"2026-09-16T00:17:33.625545Z","ts_recv":"2026-09-16T00:17:33.842218Z","payload":{"channel":"book","type":"update","data":[{"symbol":"BTC/USD","bids":[],"asks":[{"price":75732.5,"qty":0.0},{"price":75740.4,"qty":0.06}],"checksum":2260164704,"timestamp":"2026-09-16T00:17:33.625545Z"}]}}
{"v":1,"kind":"tick","pair":"ADA/USD","channel":"book","ts_exchange":"2026-09-16T00:17:33.625591Z","ts_recv":"2026-09-16T00:17:33.842498Z","payload":{"channel":"book","type":"update","data":[{"symbol":"ADA/USD","bids":[{"price":0.194687,"qty":13327.02064284}],"asks":[],"checksum":3160672099,"timestamp":"2026-09-16T00:17:33.625591Z"}]}}
{"v":1,"kind":"tick","pair":"ADA/USD","channel":"book","ts_exchange":"2026-09-16T00:17:33.625694Z","ts_recv":"2026-09-16T00:17:33.843216Z","payload":{"channel":"book","type":"update","data":[{"symbol":"ADA/USD","bids":[],"asks":[{"price":0.194844,"qty":0.0},{"price":0.1949,"qty":28223.22835849},{"price":0.194869,"qty":2567.79344707}],"checksum":210694381,"timestamp":"2026-09-16T00:17:33.625694Z"}]}}
{"v":1,"kind":"tick","pair":"BTC/USD","channel":"book","ts_exchange":"2026-09-16T00:17:33.626593Z","ts_recv":"2026-09-16T00:17:33.843629Z","payload":{"channel":"book","type":"update","data":[{"symbol":"BTC/USD","bids":[],"asks":[{"price":75733.6,"qty":0.0},{"price":75740.5,"qty":0.0537}],"checksum":2812234741,"timestamp":"2026-09-16T00:17:33.626593Z"}]}}
{"v":1,"kind":"tick","pair":"ADA/USD","channel":"book","ts_exchange":"2026-09-16T00:17:33.626771Z","ts_recv":"2026-09-16T00:17:33.844099Z","payload":{"channel":"book","type":"update","data":[{"symbol":"ADA/USD","bids":[],"asks":[{"price":0.194843,"qty":1664.58329395}],"checksum":2772452600,"timestamp":"2026-09-16T00:17:33.626771Z"}]}}
{"v":1,"kind":"tick","pair":"ADA/USD","channel":"book","ts_exchange":"2026-09-16T00:17:33.627652Z","ts_recv":"2026-09-16T00:17:33.844363Z","payload":{"channel":"book","type":"update","data":[{"symbol":"ADA/USD","bids":[{"price":0.194661,"qty":5608.14859176}],"asks":[],"checksum":3676655471,"timestamp":"2026-09-16T00:17:33.627652Z"}]}}
{"v":1,"kind":"tick","pair":"ADA/USD","channel":"book","ts_exchange":"2026-09-16T00:17:33.628926Z","ts_recv":"2026-09-16T00:17:33.845792Z","payload":{"channel":"book","type":"update","data":[{"symbol":"ADA/USD","bids":[],"asks":[{"price":0.194843,"qty":0.0},{"price":0.194898,"qty":256.54567046}],"checksum":1928067962,"timestamp":"2026-09-16T00:17:33.628926Z"}]}}
{"v":1,"kind":"tick","pair":"ADA/USD","channel":"book","ts_exchange":"2026-09-16T00:17:33.629025Z","ts_recv":"2026-09-16T00:17:33.846284Z","payload":{"channel":"book","type":"update","data":[{"symbol":"ADA/USD","bids":[],"asks":[{"price":0.1948,"qty":0.0},{"price":0.1949,"qty":28223.22835849}],"checksum":848393766,"timestamp":"2026-09-16T00:17:33.629025Z"}]}}
{"v":1,"kind":"tick","pair":"BTC/USD","channel":"book","ts_exchange":"2026-09-16T00:17:33.631444Z","ts_recv":"2026-09-16T00:17:33.847586Z","payload":{"channel":"book","type":"update","data":[{"symbol":"BTC/USD","bids":[{"price":75731.8,"qty":1.52462804}],"asks":[],"checksum":3682173855,"timestamp":"2026-09-16T00:17:33.631444Z"}]}}
{"v":1,"kind":"tick","pair":"BTC/USD","channel":"book","ts_exchange":"2026-09-16T00:17:33.632895Z","ts_recv":"2026-09-16T00:17:33.848010Z","payload":{"channel":"book","type":"update","data":[{"symbol":"BTC/USD","bids":[],"asks":[{"price":75731.9,"qty":0.0071045}],"checksum":518546205,"timestamp":"2026-09-16T00:17:33.632895Z"}]}}
{"v":1,"kind":"tick","pair":"BTC/USD","channel":"book","ts_exchange":"2026-09-16T00:17:33.633466Z","ts_recv":"2026-09-16T00:17:33.848128Z","payload":{"channel":"book","type":"update","data":[{"symbol":"BTC/USD","bids":[{"price":75727.7,"qty":0.0},{"price":75716.7,"qty":0.1}],"asks":[],"checksum":2627439887,"timestamp":"2026-09-16T00:17:33.633466Z"}]}}
{"v":1,"kind":"tick","pair":"ADA/USD","channel":"book","ts_exchange":"2026-09-16T00:17:33.635354Z","ts_recv":"2026-09-16T00:17:33.861960Z","payload":{"channel":"book","type":"update","data":[{"symbol":"ADA/USD","bids":[{"price":0.194688,"qty":2568.21170282}],"asks":[],"checksum":2641098975,"timestamp":"2026-09-16T00:17:33.635354Z"}]}}
{"v":1,"kind":"tick","pair":"BTC/USD","channel":"book","ts_exchange":"2026-09-16T00:17:33.635969Z","ts_recv":"2026-09-16T00:17:33.862425Z","payload":{"channel":"book","type":"update","data":[{"symbol":"BTC/USD","bids":[],"asks":[{"price":75735.3,"qty":1.32038838}],"checksum":3196830336,"timestamp":"2026-09-16T00:17:33.635969Z"}]}}
{"v":1,"kind":"tick","pair":"BTC/USD","channel":"book","ts_exchange":"2026-09-16T00:17:33.636720Z","ts_recv":"2026-09-16T00:17:33.863622Z","payload":{"channel":"book","type":"update","data":[{"symbol":"BTC/USD","bids":[],"asks":[{"price":75738.1,"qty":3.30085287}],"checksum":2012337733,"timestamp":"2026-09-16T00:17:33.636720Z"}]}}
{"v":1,"kind":"tick","pair":"BTC/USD","channel":"book","ts_exchange":"2026-09-16T00:17:33.638119Z","ts_recv":"2026-09-16T00:17:33.865614Z","payload":{"channel":"book","type":"update","data":[{"symbol":"BTC/USD","bids":[],"asks":[{"price":75737.7,"qty":0.04105332}],"checksum":2893193470,"timestamp":"2026-09-16T00:17:33.638119Z"}]}}
{"v":1,"kind":"tick","pair":"BTC/USD","channel":"book","ts_exchange":"2026-09-16T00:17:33.638702Z","ts_recv":"2026-09-16T00:17:33.866348Z","payload":{"channel":"book","type":"update","data":[{"symbol":"BTC/USD","bids":[{"price":75731.8,"qty":2.8450773}],"asks":[],"checksum":3183235344,"timestamp":"2026-09-16T00:17:33.638702Z"}]}}
{"v":1,"kind":"tick","pair":"BTC/USD","channel":"book","ts_exchange":"2026-09-16T00:17:33.639299Z","ts_recv":"2026-09-16T00:17:33.867280Z","payload":{"channel":"book","type":"update","data":[{"symbol":"BTC/USD","bids":[{"price":75730.2,"qty":3.30119275}],"asks":[],"checksum":4090271731,"timestamp":"2026-09-16T00:17:33.639299Z"}]}}
{"v":1,"kind":"tick","pair":"BTC/USD","channel":"book","ts_exchange":"2026-09-16T00:17:33.639813Z","ts_recv":"2026-09-16T00:17:33.868029Z","payload":{"channel":"book","type":"update","data":[{"symbol":"BTC/USD","bids":[{"price":75727.0,"qty":3.30133158}],"asks":[],"checksum":1346659958,"timestamp":"2026-09-16T00:17:33.639813Z"}]}}
{"v":1,"kind":"tick","pair":"ADA/USD","channel":"book","ts_exchange":"2026-09-16T00:17:33.641518Z","ts_recv":"2026-09-16T00:17:33.872440Z","payload":{"channel":"book","type":"update","data":[{"symbol":"ADA/USD","bids":[],"asks":[{"price":0.1949,"qty":1376.81858639},{"price":0.194884,"qty":26846.4097721}],"checksum":1316258463,"timestamp":"2026-09-16T00:17:33.641518Z"}]}}
{"v":1,"kind":"tick","pair":"BTC/USD","channel":"book","ts_exchange":"2026-09-16T00:17:33.642079Z","ts_recv":"2026-09-16T00:17:33.875025Z","payload":{"channel":"book","type":"update","data":[{"symbol":"BTC/USD","bids":[],"asks":[{"price":75736.4,"qty":0.0},{"price":75739.5,"qty":0.14497434},{"price":75738.1,"qty":3.32726351}],"checksum":3171546064,"timestamp":"2026-09-16T00:17:33.642079Z"}]}}
{"v":1,"kind":"tick","pair":"BTC/USD","channel":"book","ts_exchange":"2026-09-16T00:17:33.642772Z","ts_recv":"2026-09-16T00:17:33.875354Z","payload":{"channel":"book","type":"update","data":[{"symbol":"BTC/USD","bids":[],"asks":[{"price":75735.3,"qty":0.0},{"price":75740.4,"qty":0.06}],"checksum":1033434473,"timestamp":"2026-09-16T00:17:33.642772Z"}]}}
{"v":1,"kind":"tick","pair":"ADA/USD","channel":"book","ts_exchange":"2026-09-16T00:17:33.643884Z","ts_recv":"2026-09-16T00:17:33.876882Z","payload":{"channel":"book","type":"update","data":[{"symbol":"ADA/USD","bids":[],"asks":[{"price":0.19483,"qty":0.0},{"price":0.1949,"qty":1376.81858639}],"checksum":150367416,"timestamp":"2026-09-16T00:17:33.643884Z"}]}}
{"v":1,"kind":"tick","pair":"ADA/USD","channel":"book","ts_exchange":"2026-09-16T00:17:33.644589Z","ts_recv":"2026-09-16T00:17:33.877653Z","payload":{"channel":"book","type":"update","data":[{"symbol":"ADA/USD","bids":[],"asks":[{"price":0.19489,"qty":0.0},{"price":0.194901,"qty":70914.01474649}],"checksum":2063704245,"timestamp":"2026-09-16T00:17:33.644589Z"}]}}
{"v":1,"kind":"tick","pair":"BTC/USD","channel":"book","ts_exchange":"2026-09-16T00:17:33.648666Z","ts_recv":"2026-09-16T00:17:33.884846Z","payload":{"channel":"book","type":"update","data":[{"symbol":"BTC/USD","bids":[],"asks":[{"price":75738.1,"qty":0.02641064}],"checksum":885267963,"timestamp":"2026-09-16T00:17:33.648666Z"}]}}
{"v":1,"kind":"tick","pair":"BTC/USD","channel":"book","ts_exchange":"2026-09-16T00:17:33.650077Z","ts_recv":"2026-09-16T00:17:33.887497Z","payload":{"channel":"book","type":"update","data":[{"symbol":"BTC/USD","bids":[{"price":75723.0,"qty":0.11}],"asks":[],"checksum":3205721699,"timestamp":"2026-09-16T00:17:33.650077Z"}]}}
{"v":1,"kind":"tick","pair":"BTC/USD","channel":"book","ts_exchange":"2026-09-16T00:17:33.651192Z","ts_recv":"2026-09-16T00:17:33.888916Z","payload":{"channel":"book","type":"update","data":[{"symbol":"BTC/USD","bids":[],"asks":[{"price":75738.1,"qty":0.0},{"price":75740.5,"qty":0.0537}],"checksum":3853904277,"timestamp":"2026-09-16T00:17:33.651192Z"}]}}
{"v":1,"kind":"tick","pair":"ADA/USD","channel":"book","ts_exchange":"2026-09-16T00:17:33.653382Z","ts_recv":"2026-09-16T00:17:33.889733Z","payload":{"channel":"book","type":"update","data":[{"symbol":"ADA/USD","bids":[{"price":0.194648,"qty":1201.63699232}],"asks":[],"checksum":3234544284,"timestamp":"2026-09-16T00:17:33.653382Z"}]}}
{"v":1,"kind":"tick","pair":"ADA/USD","channel":"book","ts_exchange":"2026-09-16T00:17:33.656970Z","ts_recv":"2026-09-16T00:17:33.891138Z","payload":{"channel":"book","type":"update","data":[{"symbol":"ADA/USD","bids":[{"price":0.194701,"qty":2568.03717142}],"asks":[],"checksum":450497765,"timestamp":"2026-09-16T00:17:33.656970Z"}]}}
{"v":1,"kind":"tick","pair":"BTC/USD","channel":"book","ts_exchange":"2026-09-16T00:17:33.660668Z","ts_recv":"2026-09-16T00:17:33.903963Z","payload":{"channel":"book","type":"update","data":[{"symbol":"BTC/USD","bids":[],"asks":[{"price":75737.7,"qty":0.0},{"price":75742.2,"qty":0.000051}],"checksum":3946432923,"timestamp":"2026-09-16T00:17:33.660668Z"}]}}
{"v":1,"kind":"tick","pair":"ADA/USD","channel":"book","ts_exchange":"2026-09-16T00:17:33.669582Z","ts_recv":"2026-09-16T00:17:33.921301Z","payload":{"channel":"book","type":"update","data":[{"symbol":"ADA/USD","bids":[],"asks":[{"price":0.194869,"qty":0.0},{"price":0.194902,"qty":5608.14859176},{"price":0.194872,"qty":2567.79344707}],"checksum":2019973993,"timestamp":"2026-09-16T00:17:33.669582Z"}]}}
{"v":1,"kind":"tick","pair":"ADA/USD","channel":"book","ts_exchange":"2026-09-16T00:17:33.674145Z","ts_recv":"2026-09-16T00:17:33.922515Z","payload":{"channel":"book","type":"update","data":[{"symbol":"ADA/USD","bids":[],"asks":[{"price":0.194885,"qty":10763.148332}],"checksum":3097867568,"timestamp":"2026-09-16T00:17:33.674145Z"}]}}
{"v":1,"kind":"tick","pair":"ADA/USD","channel":"book","ts_exchange":"2026-09-16T00:17:33.676968Z","ts_recv":"2026-09-16T00:17:33.923441Z","payload":{"channel":"book","type":"update","data":[{"symbol":"ADA/USD","bids":[],"asks":[{"price":0.194872,"qty":0.0},{"price":0.194901,"qty":70914.01474649},{"price":0.19487,"qty":2567.79344707}],"checksum":475780884,"timestamp":"2026-09-16T00:17:33.676968Z"}]}}
{"v":1,"kind":"tick","pair":"ADA/USD","channel":"book","ts_exchange":"2026-09-16T00:17:33.686638Z","ts_recv":"2026-09-16T00:17:33.973902Z","payload":{"channel":"book","type":"update","data":[{"symbol":"ADA/USD","bids":[{"price":0.194688,"qty":0.0},{"price":0.194648,"qty":1201.63699232},{"price":0.194661,"qty":8176.7165124}],"asks":[],"checksum":3675568226,"timestamp":"2026-09-16T00:17:33.686638Z"}]}}
{"v":1,"kind":"tick","pair":"ADA/USD","channel":"book","ts_exchange":"2026-09-16T00:17:33.689153Z","ts_recv":"2026-09-16T00:17:33.974246Z","payload":{"channel":"book","type":"update","data":[{"symbol":"ADA/USD","bids":[],"asks":[{"price":0.194806,"qty":3451.71933202}],"checksum":4256699043,"timestamp":"2026-09-16T00:17:33.689153Z"}]}}
{"v":1,"kind":"tick","pair":"BTC/USD","channel":"book","ts_exchange":"2026-09-16T00:17:33.695771Z","ts_recv":"2026-09-16T00:17:33.975063Z","payload":{"channel":"book","type":"update","data":[{"symbol":"BTC/USD","bids":[],"asks":[{"price":75738.8,"qty":0.06608686}],"checksum":1044771258,"timestamp":"2026-09-16T00:17:33.695771Z"}]}}
{"v":1,"kind":"tick","pair":"BTC/USD","channel":"book","ts_exchange":"2026-09-16T00:17:33.698820Z","ts_recv":"2026-09-16T00:17:33.975833Z","payload":{"channel":"book","type":"update","data":[{"symbol":"BTC/USD","bids":[],"asks":[{"price":75738.1,"qty":0.02641064}],"checksum":2055284415,"timestamp":"2026-09-16T00:17:33.698820Z"}]}}
{"v":1,"kind":"tick","pair":"ADA/USD","channel":"book","ts_exchange":"2026-09-16T00:17:33.701895Z","ts_recv":"2026-09-16T00:17:33.977180Z","payload":{"channel":"book","type":"update","data":[{"symbol":"ADA/USD","bids":[],"asks":[{"price":0.194867,"qty":2470.72075858}],"checksum":1179056273,"timestamp":"2026-09-16T00:17:33.701895Z"}]}}
{"v":1,"kind":"tick","pair":"BTC/USD","channel":"book","ts_exchange":"2026-09-16T00:17:33.702462Z","ts_recv":"2026-09-16T00:17:33.977343Z","payload":{"channel":"book","type":"update","data":[{"symbol":"BTC/USD","bids":[{"price":75731.5,"qty":0.9904235}],"asks":[],"checksum":1198417740,"timestamp":"2026-09-16T00:17:33.702462Z"}]}}
{"v":1,"kind":"tick","pair":"ADA/USD","channel":"book","ts_exchange":"2026-09-16T00:17:33.728602Z","ts_recv":"2026-09-16T00:17:34.029053Z","payload":{"channel":"book","type":"update","data":[{"symbol":"ADA/USD","bids":[{"price":0.19466,"qty":0.0},{"price":0.194647,"qty":5608.14859176}],"asks":[],"checksum":1242708333,"timestamp":"2026-09-16T00:17:33.728602Z"}]}}
{"v":1,"kind":"tick","pair":"ADA/USD","channel":"book","ts_exchange":"2026-09-16T00:17:33.730572Z","ts_recv":"2026-09-16T00:17:34.032555Z","payload":{"channel":"book","type":"update","data":[{"symbol":"ADA/USD","bids":[{"price":0.194647,"qty":0.0},{"price":0.194645,"qty":20349.83229176}],"asks":[],"checksum":2189955914,"timestamp":"2026-09-16T00:17:33.730572Z"}]}}
{"v":1,"kind":"tick","pair":"ADA/USD","channel":"book","ts_exchange":"2026-09-16T00:17:33.732664Z","ts_recv":"2026-09-16T00:17:34.039192Z","payload":{"channel":"book","type":"update","data":[{"symbol":"ADA/USD","bids":[],"asks":[{"price":0.194886,"qty":0.0},{"price":0.1949,"qty":1376.81858639},{"price":0.194844,"qty":3078.996288}],"checksum":3205677026,"timestamp":"2026-09-16T00:17:33.732664Z"}]}}
{"v":1,"kind":"tick","pair":"ADA/USD","channel":"book","ts_exchange":"2026-09-16T00:17:33.736030Z","ts_recv":"2026-09-16T00:17:34.042724Z","payload":{"channel":"book","type":"update","data":[{"symbol":"ADA/USD","bids":[],"asks":[{"price":0.194843,"qty":1817.17734197}],"checksum":1694510032,"timestamp":"2026-09-16T00:17:33.736030Z"}]}}
{"v":1,"kind":"tick","pair":"ADA/USD","channel":"book","ts_exchange":"2026-09-16T00:17:33.739586Z","ts_recv":"2026-09-16T00:17:34.044323Z","payload":{"channel":"book","type":"update","data":[{"symbol":"ADA/USD","bids":[{"price":0.194688,"qty":12245.46516048}],"asks":[],"checksum":3110168701,"timestamp":"2026-09-16T00:17:33.739586Z"}]}}
{"v":1,"kind":"tick","pair":"ADA/USD","channel":"book","ts_exchange":"2026-09-16T00:17:33.744122Z","ts_recv":"2026-09-16T00:17:34.047628Z","payload":{"channel":"book","type":"update","data":[{"symbol":"ADA/USD","bids":[],"asks":[{"price":0.194885,"qty":0.0},{"price":0.194898,"qty":256.54567046}],"checksum":1263000550,"timestamp":"2026-09-16T00:17:33.744122Z"}]}}
{"v":1,"kind":"tick","pair":"BTC/USD","channel":"book","ts_exchange":"2026-09-16T00:17:33.744739Z","ts_recv":"2026-09-16T00:17:34.048602Z","payload":{"channel":"book","type":"update","data":[{"symbol":"BTC/USD","bids":[{"price":75731.5,"qty":0.0},{"price":75719.6,"qty":0.000051}],"asks":[],"checksum":2055284415,"timestamp":"2026-09-16T00:17:33.744739Z"}]}}
{"v":1,"kind":"tick","pair":"ADA/USD","channel":"book","ts_exchange":"2026-09-16T00:17:33.746203Z","ts_recv":"2026-09-16T00:17:34.049502Z","payload":{"channel":"book","type":"update","data":[{"symbol":"ADA/USD","bids":[],"asks":[{"price":0.194866,"qty":1503.99649039}],"checksum":2067892925,"timestamp":"2026-09-16T00:17:33.746203Z"}]}}
{"v":1,"kind":"tick","pair":"BTC/USD","channel":"book","ts_exchange":"2026-09-16T00:17:33.763624Z","ts_recv":"2026-09-16T00:17:34.061139Z","payload":{"channel":"book","type":"update","data":[{"symbol":"BTC/USD","bids":[{"price":75731.3,"qty":0.9904235}],"asks":[],"checksum":3052685963,"timestamp":"2026-09-16T00:17:33.763624Z"}]}}
{"v":1,"kind":"tick","pair":"ADA/USD","channel":"book","ts_exchange":"2026-09-16T00:17:33.763774Z","ts_recv":"2026-09-16T00:17:34.061326Z","payload":{"channel":"book","type":"update","data":[{"symbol":"ADA/USD","bids":[],"asks":[{"price":0.194884,"qty":0.0},{"price":0.194898,"qty":256.54567046}],"checksum":1714627708,"timestamp":"2026-09-16T00:17:33.763774Z"}]}}
{"v":1,"kind":"tick","pair":"BTC/USD","channel":"book","ts_exchange":"2026-09-16T00:17:33.766208Z","ts_recv":"2026-09-16T00:17:34.061824Z","payload":{"channel":"book","type":"update","data":[{"symbol":"BTC/USD","bids":[{"price":75731.8,"qty":2.9550773}],"asks":[],"checksum":3428126269,"timestamp":"2026-09-16T00:17:33.766208Z"}]}}
{"v":1,"kind":"tick","pair":"BTC/USD","channel":"book","ts_exchange":"2026-09-16T00:17:33.771065Z","ts_recv":"2026-09-16T00:17:34.081339Z","payload":{"channel":"book","type":"update","data":[{"symbol":"BTC/USD","bids":[],"asks":[{"price":75733.8,"qty":0.03673187}],"checksum":1552798658,"timestamp":"2026-09-16T00:17:33.771065Z"}]}}
{"v":1,"kind":"tick","pair":"ADA/USD","channel":"book","ts_exchange":"2026-09-16T00:17:33.774549Z","ts_recv":"2026-09-16T00:17:34.081741Z","payload":{"channel":"book","type":"update","data":[{"symbol":"ADA/USD","bids":[{"price":0.194686,"qty":0.0},{"price":0.194645,"qty":20349.83229176},{"price":0.194702,"qty":3078.996288}],"asks":[],"checksum":2423278788,"timestamp":"2026-09-16T00:17:33.774549Z"}]}}
{"v":1,"kind":"tick","pair":"ADA/USD","channel":"book","ts_exchange":"2026-09-16T00:17:33.775306Z","ts_recv":"2026-09-16T00:17:34.081818Z","payload":{"channel":"book","type":"update","data":[{"symbol":"ADA/USD","bids":[{"price":0.194701,"qty":0.0},{"price":0.194645,"qty":20349.83229176}],"asks":[],"checksum":4120981258,"timestamp":"2026-09-16T00:17:33.775306Z"}]}}
{"v":1,"kind":"tick","pair":"ADA/USD","channel":"book","ts_exchange":"2026-09-16T00:17:33.776092Z","ts_recv":"2026-09-16T00:17:34.081894Z","payload":{"channel":"book","type":"update","data":[{"symbol":"ADA/USD","bids":[{"price":0.194703,"qty":2568.01384673}],"asks":[],"checksum":575856550,"timestamp":"2026-09-16T00:17:33.776092Z"}]}}
{"v":1,"kind":"tick","pair":"ADA/USD","channel":"book","ts_exchange":"2026-09-16T00:17:33.800936Z","ts_recv":"2026-09-16T00:17:34.110370Z","payload":{"channel":"book","type":"update","data":[{"symbol":"ADA/USD","bids":[],"asks":[{"price":0.194842,"qty":2363.94312211}],"checksum":150493020,"timestamp":"2026-09-16T00:17:33.800936Z"}]}}
{"v":1,"kind":"tick","pair":"ADA/USD","channel":"book","ts_exchange":"2026-09-16T00:17:33.802581Z","ts_recv":"2026-09-16T00:17:34.110532Z","payload":{"channel":"book","type":"update","data":[{"symbol":"ADA/USD","bids":[],"asks":[{"price":0.194867,"qty":0.0},{"price":0.194898,"qty":256.54567046}],"checksum":3398242370,"timestamp":"2026-09-16T00:17:33.802581Z"}]}}
{"v":1,"kind":"tick","pair":"ADA/USD","channel":"book","ts_exchange":"2026-09-16T00:17:33.804886Z","ts_recv":"2026-09-16T00:17:34.110789Z","payload":{"channel":"book","type":"update","data":[{"symbol":"ADA/USD","bids":[],"asks":[{"price":0.194866,"qty":0.0},{"price":0.1949,"qty":28223.22835849}],"checksum":1997878182,"timestamp":"2026-09-16T00:17:33.804886Z"}]}}
{"v":1,"kind":"tick","pair":"BTC/USD","channel":"book","ts_exchange":"2026-09-16T00:17:33.833106Z","ts_recv":"2026-09-16T00:17:34.133181Z","payload":{"channel":"book","type":"update","data":[{"symbol":"BTC/USD","bids":[],"asks":[{"price":75740.4,"qty":0.0},{"price":75740.5,"qty":0.0537}],"checksum":3779875660,"timestamp":"2026-09-16T00:17:33.833106Z"}]}}
{"v":1,"kind":"tick","pair":"ADA/USD","channel":"book","ts_exchange":"2026-09-16T00:17:33.840114Z","ts_recv":"2026-09-16T00:17:34.143508Z","payload":{"channel":"book","type":"update","data":[{"symbol":"ADA/USD","bids":[{"price":0.194687,"qty":1081.55548236}],"asks":[],"checksum":1032486937,"timestamp":"2026-09-16T00:17:33.840114Z"}]}}
{"v":1,"kind":"tick","pair":"ADA/USD","channel":"book","ts_exchange":"2026-09-16T00:17:33.840937Z","ts_recv":"2026-09-16T00:17:34.143622Z","payload":{"channel":"book","type":"update","data":[{"symbol":"ADA/USD","bids":[{"price":0.194687,"qty":0.0},{"price":0.194645,"qty":20349.83229176}],"asks":[],"checksum":547347683,"timestamp":"2026-09-16T00:17:33.840937Z"}]}}
{"v":1,"kind":"tick","pair":"ADA/USD","channel":"book","ts_exchange":"2026-09-16T00:17:33.840950Z","ts_recv":"2026-09-16T00:17:34.144159Z","payload":{"channel":"book","type":"update","data":[{"symbol":"ADA/USD","bids":[{"price":0.194689,"qty":1081.55548236}],"asks":[],"checksum":3191266206,"timestamp":"2026-09-16T00:17:33.840950Z"}]}}
{"v":1,"kind":"tick","pair":"ADA/USD","channel":"book","ts_exchange":"2026-09-16T00:17:33.841070Z","ts_recv":"2026-09-16T00:17:34.145624Z","payload":{"channel":"book","type":"update","data":[{"symbol":"ADA/USD","bids":[{"price":0.194704,"qty":12245.46516048}],"asks":[],"checksum":3402771091,"timestamp":"2026-09-16T00:17:33.841070Z"}]}}
{"v":1,"kind":"tick","pair":"ADA/USD","channel":"book","ts_exchange":"2026-09-16T00:17:33.842000Z","ts_recv":"2026-09-16T00:17:34.146662Z","payload":{"channel":"book","type":"update","data":[{"symbol":"ADA/USD","bids":[{"price":0.194703,"qty":0.0},{"price":0.194648,"qty":1201.63699232}],"asks":[],"checksum":3279888107,"timestamp":"2026-09-16T00:17:33.842000Z"}]}}
{"v":1,"kind":"tick","pair":"BTC/USD","channel":"book","ts_exchange":"2026-09-16T00:17:33.853589Z","ts_recv":"2026-09-16T00:17:34.153947Z","payload":{"channel":"book","type":"update","data":[{"symbol":"BTC/USD","bids":[{"price":75731.3,"qty":0.0},{"price":75719.6,"qty":0.000051}],"asks":[],"checksum":2908376356,"timestamp":"2026-09-16T00:17:33.853589Z"}]}}
{"v":1,"kind":"tick","pair":"BTC/USD","channel":"book","ts_exchange":"2026-09-16T00:17:33.853731Z","ts_recv":"2026-09-16T00:17:34.157498Z","payload":{"channel":"book","type":"update","data":[{"symbol":"BTC/USD","bids":[],"asks":[{"price":75740.4,"qty":1.06490469}],"checksum":644338843,"timestamp":"2026-09-16T00:17:33.853731Z"}]}}
{"v":1,"kind":"tick","pair":"BTC/USD","channel":"book","ts_exchange":"2026-09-16T00:17:33.863718Z","ts_recv":"2026-09-16T00:17:34.162567Z","payload":{"channel":"book","type":"update","data":[{"symbol":"BTC/USD","bids":[{"price":75729.8,"qty":0.9904235}],"asks":[],"checksum":87218392,"timestamp":"2026-09-16T00:17:33.863718Z"}]}}
{"v":1,"kind":"tick","pair":"BTC/USD","channel":"book","ts_exchange":"2026-09-16T00:17:33.866886Z","ts_recv":"2026-09-16T00:17:34.163681Z","payload":{"channel":"book","type":"update","data":[{"symbol":"BTC/USD","bids":[{"price":75723.0,"qty":0.0},{"price":75719.6,"qty":0.000051}],"asks":[],"checksum":3861154967,"timestamp":"2026-09-16T00:17:33.866886Z"}]}}
{"v":1,"kind":"tick","pair":"BTC/USD","channel":"book","ts_exchange":"2026-09-16T00:17:33.892174Z","ts_recv":"2026-09-16T00:17:34.164668Z","payload":{"channel":"book","type":"update","data":[{"symbol":"BTC/USD","bids":[],"asks":[{"price":75735.5,"qty":1.32038606}],"checksum":856722769,"timestamp":"2026-09-16T00:17:33.892174Z"}]}}
{"v":1,"kind":"tick","pair":"BTC/USD","channel":"book","ts_exchange":"2026-09-16T00:17:33.914533Z","ts_recv":"2026-09-16T00:17:34.176589Z","payload":{"channel":"book","type":"update","data":[{"symbol":"BTC/USD","bids":[{"price":75724.3,"qty":0.0},{"price":75719.4,"qty":0.02109115},{"price":75729.9,"qty":0.11117396}],"asks":[],"checksum":2656410041,"timestamp":"2026-09-16T00:17:33.914533Z"}]}}
{"v":1,"kind":"tick","pair":"ADA/USD","channel":"book","ts_exchange":"2026-09-16T00:17:33.939821Z","ts_recv":"2026-09-16T00:17:34.193178Z","payload":{"channel":"book","type":"update","data":[{"symbol":"ADA/USD","bids":[{"price":0.194702,"qty":0.0},{"price":0.194645,"qty":20349.83229176},{"price":0.194705,"qty":3078.996288}],"asks":[],"checksum":640302758,"timestamp":"2026-09-16T00:17:33.939821Z"}]}}
{"v":1,"kind":"tick","pair":"ADA/USD","channel":"book","ts_exchange":"2026-09-16T00:17:33.939974Z","ts_recv":"2026-09-16T00:17:34.193758Z","payload":{"channel":"book","type":"update","data":[{"symbol":"ADA/USD","bids":[],"asks":[{"price":0.194844,"qty":0.0},{"price":0.194901,"qty":70914.01474649},{"price":0.194841,"qty":3078.996288}],"checksum":905356281,"timestamp":"2026-09-16T00:17:33.939974Z"}]}}
{"v":1,"kind":"tick","pair":"ADA/USD","channel":"book","ts_exchange":"2026-09-16T00:17:33.940987Z","ts_recv":"2026-09-16T00:17:34.194349Z","payload":{"channel":"book","type":"update","data":[{"symbol":"ADA/USD","bids":[],"asks":[{"price":0.19484,"qty":2522.81436392}],"checksum":1828693107,"timestamp":"2026-09-16T00:17:33.940987Z"}]}}
{"v":1,"kind":"tick","pair":"ADA/USD","channel":"book","ts_exchange":"2026-09-16T00:17:33.941092Z","ts_recv":"2026-09-16T00:17:34.201072Z","payload":{"channel":"book","type":"update","data":[{"symbol":"ADA/USD","bids":[],"asks":[{"price":0.194843,"qty":0.0},{"price":0.1949,"qty":28223.22835849}],"checksum":2088109025,"timestamp":"2026-09-16T00:17:33.941092Z"}]}}
{"v":1,"kind":"tick","pair":"ADA/USD","channel":"book","ts_exchange":"2026-09-16T00:17:33.941671Z","ts_recv":"2026-09-16T00:17:34.201295Z","payload":{"channel":"book","type":"update","data":[{"symbol":"ADA/USD","bids":[{"price":0.194688,"qty":0.0},{"price":0.194645,"qty":20349.83229176}],"asks":[],"checksum":4109782973,"timestamp":"2026-09-16T00:17:33.941671Z"}]}}
{"v":1,"kind":"tick","pair":"ADA/USD","channel":"book","ts_exchange":"2026-09-16T00:17:33.942670Z","ts_recv":"2026-09-16T00:17:34.201447Z","payload":{"channel":"book","type":"update","data":[{"symbol":"ADA/USD","bids":[{"price":0.194689,"qty":0.0},{"price":0.19463,"qty":1272.4897279}],"asks":[],"checksum":599085425,"timestamp":"2026-09-16T00:17:33.942670Z"}]}}
{"v":1,"kind":"tick","pair":"ADA/USD","channel":"book","ts_exchange":"2026-09-16T00:17:33.943896Z","ts_recv":"2026-09-16T00:17:34.210756Z","payload":{"channel":"book","type":"update","data":[{"symbol":"ADA/USD","bids":[{"price":0.194661,"qty":2568.56792064}],"asks":[],"checksum":935616012,"timestamp":"2026-09-16T00:17:33.943896Z"}]}}
{"v":1,"kind":"tick","pair":"ADA/USD","channel":"book","ts_exchange":"2026-09-16T00:17:33.943961Z","ts_recv":"2026-09-16T00:17:34.210805Z","payload":{"channel":"book","type":"update","data":[{"symbol":"ADA/USD","bids":[{"price":0.194658,"qty":5608.14859176}],"asks":[],"checksum":842387045,"timestamp":"2026-09-16T00:17:33.943961Z"}]}}
{"v":1,"kind":"tick","pair":"ADA/USD","channel":"book","ts_exchange":"2026-09-16T00:17:33.944993Z","ts_recv":"2026-09-16T00:17:34.210975Z","payload":{"channel":"book","type":"update","data":[{"symbol":"ADA/USD","bids":[],"asks":[{"price":0.19487,"qty":0.0},{"price":0.194901,"qty":70914.01474649}],"checksum":4243959573,"timestamp":"2026-09-16T00:17:33.944993Z"}]}}
{"v":1,"kind":"tick","pair":"ADA/USD","channel":"book","ts_exchange":"2026-09-16T00:17:33.950041Z","ts_recv":"2026-09-16T00:17:34.223868Z","payload":{"channel":"book","type":"update","data":[{"symbol":"ADA/USD","bids":[],"asks":[{"price":0.194841,"qty":0.0},{"price":0.194902,"qty":5608.14859176}],"checksum":1422816927,"timestamp":"2026-09-16T00:17:33.950041Z"}]}}
{"v":1,"kind":"tick","pair":"ADA/USD","channel":"book","ts_exchange":"2026-09-16T00:17:33.951511Z","ts_recv":"2026-09-16T00:17:34.224352Z","payload":{"channel":"book","type":"update","data":[{"symbol":"ADA/USD","bids":[],"asks":[{"price":0.19484,"qty":0.0},{"price":0.194907,"qty":76973.1}],"checksum":2577668090,"timestamp":"2026-09-16T00:17:33.951511Z"}]}}
{"v":1,"kind":"tick","pair":"ADA/USD","channel":"book","ts_exchange":"2026-09-16T00:17:33.951735Z","ts_recv":"2026-09-16T00:17:34.224839Z","payload":{"channel":"book","type":"update","data":[{"symbol":"ADA/USD","bids":[],"asks":[{"price":0.1949,"qty":1376.81858639}],"checksum":1182933681,"timestamp":"2026-09-16T00:17:33.951735Z"}]}}
{"v":1,"kind":"tick","pair":"ADA/USD","channel":"book","ts_exchange":"2026-09-16T00:17:33.951789Z","ts_recv":"2026-09-16T00:17:34.225400Z","payload":{"channel":"book","type":"update","data":[{"symbol":"ADA/USD","bids":[],"asks":[{"price":0.19484,"qty":1603.73397195}],"checksum":3015753798,"timestamp":"2026-09-16T00:17:33.951789Z"}]}}
{"v":1,"kind":"tick","pair":"ADA/USD","channel":"book","ts_exchange":"2026-09-16T00:17:33.962327Z","ts_recv":"2026-09-16T00:17:34.238370Z","payload":{"channel":"book","type":"update","data":[{"symbol":"ADA/USD","bids":[],"asks":[{"price":0.19487,"qty":2567.39173987}],"checksum":4220578219,"timestamp":"2026-09-16T00:17:33.962327Z"}]}}
{"v":1,"kind":"tick","pair":"ADA/USD","channel":"book","ts_exchange":"2026-09-16T00:17:34.026641Z","ts_recv":"2026-09-16T00:17:34.264390Z","payload":{"channel":"book","type":"update","data":[{"symbol":"ADA/USD","bids":[],"asks":[{"price":0.194865,"qty":256.58801786}],"checksum":3692637818,"timestamp":"2026-09-16T00:17:34.026641Z"}]}}
{"v":1,"kind":"tick","pair":"ADA/USD","channel":"book","ts_exchange":"2026-09-16T00:17:34.027108Z","ts_recv":"2026-09-16T00:17:34.271625Z","payload":{"channel":"book","type":"update","data":[{"symbol":"ADA/USD","bids":[{"price":0.194705,"qty":5646.98375622}],"asks":[],"checksum":3591492728,"timestamp":"2026-09-16T00:17:34.027108Z"}]}}
{"v":1,"kind":"tick","pair":"ADA/USD","channel":"book","ts_exchange":"2026-09-16T00:17:34.029662Z","ts_recv":"2026-09-16T00:17:34.271754Z","payload":{"channel":"book","type":"update","data":[{"symbol":"ADA/USD","bids":[{"price":0.194707,"qty":12245.46516048}],"asks":[],"checksum":3168757108,"timestamp":"2026-09-16T00:17:34.029662Z"}]}}
{"v":1,"kind":"tick","pair":"ADA/USD","channel":"book","ts_exchange":"2026-09-16T00:17:34.029850Z","ts_recv":"2026-09-16T00:17:34.271832Z","payload":{"channel":"book","type":"update","data":[{"symbol":"ADA/USD","bids":[],"asks":[{"price":0.1949,"qty":28223.22835849}],"checksum":2538675345,"timestamp":"2026-09-16T00:17:34.029850Z"}]}}
{"v":1,"kind":"tick","pair":"BTC/USD","channel":"book","ts_exchange":"2026-09-16T00:17:34.074493Z","ts_recv":"2026-09-16T00:17:34.303780Z","payload":{"channel":"book","type":"update","data":[{"symbol":"BTC/USD","bids":[{"price":75729.8,"qty":0.0},{"price":75718.2,"qty":3.30171321}],"asks":[],"checksum":2940440060,"timestamp":"2026-09-16T00:17:34.074493Z"}]}}
{"v":1,"kind":"tick","pair":"BTC/USD","channel":"book","ts_exchange":"2026-09-16T00:17:34.074684Z","ts_recv":"2026-09-16T00:17:34.303842Z","payload":{"channel":"book","type":"update","data":[{"symbol":"BTC/USD","bids":[{"price":75729.9,"qty":0.0},{"price":75717.0,"qty":0.00006024},{"price":75731.1,"qty":0.11117396}],"asks":[],"checksum":1970851190,"timestamp":"2026-09-16T00:17:34.074684Z"}]}}
{"v":1,"kind":"tick","pair":"ADA/USD","channel":"book","ts_exchange":"2026-09-16T00:17:34.094557Z","ts_recv":"2026-09-16T00:17:34.312525Z","payload":{"channel":"book","type":"update","data":[{"symbol":"ADA/USD","bids":[],"asks":[{"price":0.19487,"qty":0.0},{"price":0.194901,"qty":70914.01474649},{"price":0.194869,"qty":2567.39173987}],"checksum":1860038621,"timestamp":"2026-09-16T00:17:34.094557Z"}]}}
{"v":1,"kind":"tick","pair":"ADA/USD","channel":"book","ts_exchange":"2026-09-16T00:17:34.097634Z","ts_recv":"2026-09-16T00:17:34.312935Z","payload":{"channel":"book","type":"update","data":[{"symbol":"ADA/USD","bids":[],"asks":[{"price":0.194869,"qty":0.0},{"price":0.194901,"qty":70914.01474649},{"price":0.19487,"qty":2567.39173987}],"checksum":2538675345,"timestamp":"2026-09-16T00:17:34.097634Z"}]}}
{"v":1,"kind":"tick","pair":"ADA/USD","channel":"book","ts_exchange":"2026-09-16T00:17:34.112367Z","ts_recv":"2026-09-16T00:17:34.333615Z","payload":{"channel":"book","type":"update","data":[{"symbol":"ADA/USD","bids":[{"price":0.194705,"qty":2567.98746822},{"price":0.194708,"qty":3078.996288}],"asks":[],"checksum":1396443633,"timestamp":"2026-09-16T00:17:34.112367Z"}]}}
{"v":1,"kind":"tick","pair":"ADA/USD","channel":"book","ts_exchange":"2026-09-16T00:17:34.112521Z","ts_recv":"2026-09-16T00:17:34.334054Z","payload":{"channel":"book","type":"update","data":[{"symbol":"ADA/USD","bids":[],"asks":[{"price":0.194839,"qty":3078.996288}],"checksum":1003909906,"timestamp":"2026-09-16T00:17:34.112521Z"}]}}
{"v":1,"kind":"tick","pair":"BTC/USD","channel":"book","ts_exchange":"2026-09-16T00:17:34.113275Z","ts_recv":"2026-09-16T00:17:34.345949Z","payload":{"channel":"book","type":"update","data":[{"symbol":"BTC/USD","bids":[{"price":75729.0,"qty":0.9904235}],"asks":[],"checksum":1954870420,"timestamp":"2026-09-16T00:17:34.113275Z"}]}}
{"v":1,"kind":"tick","pair":"ADA/USD","channel":"book","ts_exchange":"2026-09-16T00:17:34.130401Z","ts_recv":"2026-09-16T00:17:34.365432Z","payload":{"channel":"book","type":"update","data":[{"symbol":"ADA/USD","bids":[{"price":0.194704,"qty":0.0},{"price":0.194648,"qty":1201.63699232}],"asks":[],"checksum":2336324072,"timestamp":"2026-09-16T00:17:34.130401Z"}]}}
{"v":1,"kind":"tick","pair":"ADA/USD","channel":"book","ts_exchange":"2026-09-16T00:17:34.155573Z","ts_recv":"2026-09-16T00:17:34.427077Z","payload":{"channel":"book","type":"update","data":[{"symbol":"ADA/USD","bids":[{"price":0.194722,"qty":3804.421975}],"asks":[],"checksum":3145397574,"timestamp":"2026-09-16T00:17:34.155573Z"}]}}
{"v":1,"kind":"tick","pair":"BTC/USD","channel":"book","ts_exchange":"2026-09-16T00:17:34.227932Z","ts_recv":"2026-09-16T00:17:34.478609Z","payload":{"channel":"book","type":"update","data":[{"symbol":"BTC/USD","bids":[],"asks":[{"price":75738.0,"qty":3.3008553}],"checksum":1926577431,"timestamp":"2026-09-16T00:17:34.227932Z"}]}}
{"v":1,"kind":"tick","pair":"BTC/USD","channel":"book","ts_exchange":"2026-09-16T00:17:34.230724Z","ts_recv":"2026-09-16T00:17:34.483674Z","payload":{"channel":"book","type":"update","data":[{"symbol":"BTC/USD","bids":[{"price":75731.1,"qty":0.0},{"price":75718.2,"qty":3.30171321},{"price":75730.3,"qty":0.11117396}],"asks":[],"checksum":3961469812,"timestamp":"2026-09-16T00:17:34.230724Z"}]}}
{"v":1,"kind":"tick","pair":"BTC/USD","channel":"book","ts_exchange":"2026-09-16T00:17:34.231860Z","ts_recv":"2026-09-16T00:17:34.484962Z","payload":{"channel":"book","type":"update","data":[{"symbol":"BTC/USD","bids":[],"asks":[{"price":75735.5,"qty":0.0},{"price":75739.5,"qty":0.14497434}],"checksum":176446544,"timestamp":"2026-09-16T00:17:34.231860Z"}]}}
{"v":1,"kind":"tick","pair":"BTC/USD","channel":"book","ts_exchange":"2026-09-16T00:17:34.231886Z","ts_recv":"2026-09-16T00:17:34.486296Z","payload":{"channel":"book","type":"update","data":[{"symbol":"BTC/USD","bids":[],"asks":[{"price":75738.0,"qty":0.0},{"price":75740.4,"qty":1.06490469}],"checksum":2560401779,"timestamp":"2026-09-16T00:17:34.231886Z"}]}}
{"v":1,"kind":"tick","pair":"BTC/USD","channel":"book","ts_exchange":"2026-09-16T00:17:34.232838Z","ts_recv":"2026-09-16T00:17:34.487678Z","payload":{"channel":"book","type":"update","data":[{"symbol":"BTC/USD","bids":[],"asks":[{"price":75734.3,"qty":1.3204065}],"checksum":2841574439,"timestamp":"2026-09-16T00:17:34.232838Z"}]}}
{"v":1,"kind":"tick","pair":"BTC/USD","channel":"book","ts_exchange":"2026-09-16T00:17:34.259378Z","ts_recv":"2026-09-16T00:17:34.517082Z","payload":{"channel":"book","type":"update","data":[{"symbol":"BTC/USD","bids":[{"price":75731.8,"qty":1.89017261}],"asks":[],"checksum":1026679837,"timestamp":"2026-09-16T00:17:34.259378Z"}]}}
{"v":1,"kind":"tick","pair":"BTC/USD","channel":"book","ts_exchange":"2026-09-16T00:17:34.352243Z","ts_recv":"2026-09-16T00:17:34.686005Z","payload":{"channel":"book","type":"update","data":[{"symbol":"BTC/USD","bids":[{"price":75731.8,"qty":1.83647261}],"asks":[],"checksum":1189193684,"timestamp":"2026-09-16T00:17:34.352243Z"}]}}
{"v":1,"kind":"tick","pair":"ADA/USD","channel":"book","ts_exchange":"2026-09-16T00:17:34.357464Z","ts_recv":"2026-09-16T00:17:34.687102Z","payload":{"channel":"book","type":"update","data":[{"symbol":"ADA/USD","bids":[],"asks":[{"price":0.194817,"qty":2773.17989399}],"checksum":2523884265,"timestamp":"2026-09-16T00:17:34.357464Z"}]}}
{"v":1,"kind":"tick","pair":"ADA/USD","channel":"book","ts_exchange":"2026-09-16T00:17:34.358762Z","ts_recv":"2026-09-16T00:17:34.695440Z","payload":{"channel":"book","type":"update","data":[{"symbol":"ADA/USD","bids":[],"asks":[{"price":0.194842,"qty":0.0},{"price":0.194898,"qty":256.54567046}],"checksum":635836534,"timestamp":"2026-09-16T00:17:34.358762Z"}]}}
{"v":1,"kind":"tick","pair":"ADA/USD","channel":"book","ts_exchange":"2026-09-16T00:17:34.359433Z","ts_recv":"2026-09-16T00:17:34.696185Z","payload":{"channel":"book","type":"update","data":[{"symbol":"ADA/USD","bids":[],"asks":[{"price":0.19484,"qty":0.0},{"price":0.1949,"qty":1376.81858639}],"checksum":2219907555,"timestamp":"2026-09-16T00:17:34.359433Z"}]}}
{"v":1,"kind":"tick","pair":"BTC/USD","channel":"book","ts_exchange":"2026-09-16T00:17:34.430496Z","ts_recv":"2026-09-16T00:17:34.752666Z","payload":{"channel":"book","type":"update","data":[{"symbol":"BTC/USD","bids":[{"price":75730.3,"qty":0.0},{"price":75718.2,"qty":3.30171321},{"price":75731.1,"qty":0.11117396}],"asks":[],"checksum":3626738103,"timestamp":"2026-09-16T00:17:34.430496Z"}]}}
{"v":1,"kind":"tick","pair":"ADA/USD","channel":"book","ts_exchange":"2026-09-16T00:17:34.438286Z","ts_recv":"2026-09-16T00:17:34.758720Z","payload":{"channel":"book","type":"update","data":[{"symbol":"ADA/USD","bids":[{"price":0.194722,"qty":0.0},{"price":0.194648,"qty":1201.63699232}],"asks":[],"checksum":3026883917,"timestamp":"2026-09-16T00:17:34.438286Z"}]}}
{"v":1,"kind":"tick","pair":"BTC/USD","channel":"book","ts_exchange":"2026-09-16T00:17:34.507528Z","ts_recv":"2026-09-16T00:17:34.800022Z","payload":{"channel":"book","type":"update","data":[{"symbol":"BTC/USD","bids":[{"price":75721.1,"qty":0.02401151}],"asks":[],"checksum":2236272838,"timestamp":"2026-09-16T00:17:34.507528Z"}]}}
{"v":1,"kind":"tick","pair":"BTC/USD","channel":"book","ts_exchange":"2026-09-16T00:17:34.579104Z","ts_recv":"2026-09-16T00:17:34.805550Z","payload":{"channel":"book","type":"update","data":[{"symbol":"BTC/USD","bids":[{"price":75731.1,"qty":0.0},{"price":75719.6,"qty":0.000051},{"price":75730.3,"qty":0.11117396}],"asks":[],"checksum":3794807049,"timestamp":"2026-09-16T00:17:34.579104Z"}]}}
{"v":1,"kind":"tick","pair":"ADA/USD","channel":"book","ts_exchange":"2026-09-16T00:17:34.631524Z","ts_recv":"2026-09-16T00:17:34.827851Z","payload":{"channel":"book","type":"update","data":[{"symbol":"ADA/USD","bids":[],"asks":[{"price":0.194839,"qty":0.0},{"price":0.194901,"qty":44518.72373616},{"price":0.194844,"qty":3078.996288}],"checksum":2991020129,"timestamp":"2026-09-16T00:17:34.631524Z"}]}}
{"v":1,"kind":"tick","pair":"ADA/USD","channel":"book","ts_exchange":"2026-09-16T00:17:34.632187Z","ts_recv":"2026-09-16T00:17:34.828709Z","payload":{"channel":"book","type":"update","data":[{"symbol":"ADA/USD","bids":[],"asks":[{"price":0.194843,"qty":1817.17734197}],"checksum":185177519,"timestamp":"2026-09-16T00:17:34.632187Z"}]}}
{"v":1,"kind":"tick","pair":"ADA/USD","channel":"book","ts_exchange":"2026-09-16T00:17:34.656600Z","ts_recv":"2026-09-16T00:17:34.837577Z","payload":{"channel":"book","type":"update","data":[{"symbol":"ADA/USD","bids":[{"price":0.194652,"qty":0.0},{"price":0.194645,"qty":20349.83229176}],"asks":[],"checksum":3198620295,"timestamp":"2026-09-16T00:17:34.656600Z"}]}}
{"v":1,"kind":"tick","pair":"ADA/USD","channel":"book","ts_exchange":"2026-09-16T00:17:34.658134Z","ts_recv":"2026-09-16T00:17:34.838433Z","payload":{"channel":"book","type":"update","data":[{"symbol":"ADA/USD","bids":[{"price":0.194709,"qty":100.0}],"asks":[],"checksum":3836912870,"timestamp":"2026-09-16T00:17:34.658134Z"}]}}
{"v":1,"kind":"tick","pair":"ADA/USD","channel":"book","ts_exchange":"2026-09-16T00:17:34.662550Z","ts_recv":"2026-09-16T00:17:34.847669Z","payload":{"channel":"book","type":"update","data":[{"symbol":"ADA/USD","bids":[{"price":0.194664,"qty":2568.52556644}],"asks":[],"checksum":4090008877,"timestamp":"2026-09-16T00:17:34.662550Z"}]}}
{"v":1,"kind":"tick","pair":"ADA/USD","channel":"book","ts_exchange":"2026-09-16T00:17:34.663644Z","ts_recv":"2026-09-16T00:17:34.847832Z","payload":{"channel":"book","type":"update","data":[{"symbol":"ADA/USD","bids":[{"price":0.194665,"qty":1081.15317831}],"asks":[],"checksum":2828069964,"timestamp":"2026-09-16T00:17:34.663644Z"}]}}
{"v":1,"kind":"tick","pair":"ADA/USD","channel":"book","ts_exchange":"2026-09-16T00:17:34.665787Z","ts_recv":"2026-09-16T00:17:34.847995Z","payload":{"channel":"book","type":"update","data":[{"symbol":"ADA/USD","bids":[{"price":0.194721,"qty":3718.828609}],"asks":[],"checksum":106753330,"timestamp":"2026-09-16T00:17:34.665787Z"}]}}
{"v":1,"kind":"tick","pair":"BTC/USD","channel":"book","ts_exchange":"2026-09-16T00:17:34.731070Z","ts_recv":"2026-09-16T00:17:34.895007Z","payload":{"channel":"book","type":"update","data":[{"symbol":"BTC/USD","bids":[],"asks":[{"price":75731.9,"qty":0.00844981}],"checksum":65784618,"timestamp":"2026-09-16T00:17:34.731070Z"}]}}
{"v":1,"kind":"tick","pair":"BTC/USD","channel":"book","ts_exchange":"2026-09-16T00:17:34.754959Z","ts_recv":"2026-09-16T00:17:34.898058Z","payload":{"channel":"book","type":"update","data":[{"symbol":"BTC/USD","bids":[{"price":75730.3,"qty":0.0},{"price":75719.6,"qty":0.000051},{"price":75731.1,"qty":0.11117396}],"asks":[],"checksum":1687237349,"timestamp":"2026-09-16T00:17:34.754959Z"}]}}
{"v":1,"kind":"tick","pair":"ADA/USD","channel":"book","ts_exchange":"2026-09-16T00:17:34.810406Z","ts_recv":"2026-09-16T00:17:34.938100Z","payload":{"channel":"book","type":"update","data":[{"symbol":"ADA/USD","bids":[],"asks":[{"price":0.194844,"qty":0.0},{"price":0.1949,"qty":1376.81858639},{"price":0.194842,"qty":3078.996288}],"checksum":124455267,"timestamp":"2026-09-16T00:17:34.810406Z"}]}}
{"v":1,"kind":"tick","pair":"ADA/USD","channel":"book","ts_exchange":"2026-09-16T00:17:34.811141Z","ts_recv":"2026-09-16T00:17:34.948980Z","payload":{"channel":"book","type":"update","data":[{"symbol":"ADA/USD","bids":[],"asks":[{"price":0.194843,"qty":0.0},{"price":0.1949,"qty":1376.81858639}],"checksum":3755856331,"timestamp":"2026-09-16T00:17:34.811141Z"}]}}
{"v":1,"kind":"tick","pair":"ADA/USD","channel":"book","ts_exchange":"2026-09-16T00:17:34.811220Z","ts_recv":"2026-09-16T00:17:34.950489Z","payload":{"channel":"book","type":"update","data":[{"symbol":"ADA/USD","bids":[],"asks":[{"price":0.194841,"qty":1817.17734197}],"checksum":871673504,"timestamp":"2026-09-16T00:17:34.811220Z"}]}}
{"v":1,"kind":"tick","pair":"ADA/USD","channel":"book","ts_exchange":"2026-09-16T00:17:34.889646Z","ts_recv":"2026-09-16T00:17:35.028173Z","payload":{"channel":"book","type":"update","data":[{"symbol":"ADA/USD","bids":[{"price":0.19467,"qty":3451.71933202}],"asks":[],"checksum":2114340633,"timestamp":"2026-09-16T00:17:34.889646Z"}]}}
{"v":1,"kind":"tick","pair":"BTC/USD","channel":"book","ts_exchange":"2026-09-16T00:17:34.889798Z","ts_recv":"2026-09-16T00:17:35.028776Z","payload":{"channel":"book","type":"update","data":[{"symbol":"BTC/USD","bids":[{"price":75731.8,"qty":2.9013773}],"asks":[],"checksum":2927074686,"timestamp":"2026-09-16T00:17:34.889798Z"}]}}
{"v":1,"kind":"tick","pair":"ADA/USD","channel":"book","ts_exchange":"2026-09-16T00:17:34.890897Z","ts_recv":"2026-09-16T00:17:35.037107Z","payload":{"channel":"book","type":"update","data":[{"symbol":"ADA/USD","bids":[{"price":0.194671,"qty":1030.33822061}],"asks":[],"checksum":2499499779,"timestamp":"2026-09-16T00:17:34.890897Z"}]}}
{"v":1,"kind":"tick","pair":"BTC/USD","channel":"book","ts_exchange":"2026-09-16T00:17:34.891689Z","ts_recv":"2026-09-16T00:17:35.037595Z","payload":{"channel":"book","type":"update","data":[{"symbol":"BTC/USD","bids":[{"price":75731.1,"qty":0.0},{"price":75719.6,"qty":0.000051},{"price":75730.3,"qty":0.11117396}],"asks":[],"checksum":3373098161,"timestamp":"2026-09-16T00:17:34.891689Z"}]}}
{"v":1,"kind":"tick","pair":"ADA/USD","channel":"book","ts_exchange":"2026-09-16T00:17:35.004233Z","ts_recv":"2026-09-16T00:17:35.137877Z","payload":{"channel":"book","type":"update","data":[{"symbol":"ADA/USD","bids":[{"price":0.194709,"qty":0.0},{"price":0.194661,"qty":2568.56792064}],"asks":[],"checksum":708909138,"timestamp":"2026-09-16T00:17:35.004233Z"}]}}
{"v":1,"kind":"tick","pair":"ADA/USD","channel":"book","ts_exchange":"2026-09-16T00:17:35.005553Z","ts_recv":"2026-09-16T00:17:35.138055Z","payload":{"channel":"book","type":"update","data":[{"symbol":"ADA/USD","bids":[{"price":0.194721,"qty":0.0},{"price":0.194658,"qty":5608.14859176}],"asks":[],"checksum":1309396314,"timestamp":"2026-09-16T00:17:35.005553Z"}]}}
{"v":1,"kind":"tick","pair":"ADA/USD","channel":"book","ts_exchange":"2026-09-16T00:17:35.006680Z","ts_recv":"2026-09-16T00:17:35.147725Z","payload":{"channel":"book","type":"update","data":[{"symbol":"ADA/USD","bids":[],"asks":[{"price":0.19487,"qty":0.0},{"price":0.1949,"qty":1376.81858639},{"price":0.194864,"qty":2567.44361145}],"checksum":4185126106,"timestamp":"2026-09-16T00:17:35.006680Z"}]}}
{"v":1,"kind":"tick","pair":"ADA/USD","channel":"book","ts_exchange":"2026-09-16T00:17:35.007614Z","ts_recv":"2026-09-16T00:17:35.148239Z","payload":{"channel":"book","type":"update","data":[{"symbol":"ADA/USD","bids":[],"asks":[{"price":0.194842,"qty":0.0},{"price":0.1949,"qty":1376.81858639},{"price":0.19484,"qty":3078.996288}],"checksum":1708416136,"timestamp":"2026-09-16T00:17:35.007614Z"}]}}
{"v":1,"kind":"tick","pair":"ADA/USD","channel":"book","ts_exchange":"2026-09-16T00:17:35.010937Z","ts_recv":"2026-09-16T00:17:35.148378Z","payload":{"channel":"book","type":"update","data":[{"symbol":"ADA/USD","bids":[],"asks":[{"price":0.194841,"qty":0.0},{"price":0.1949,"qty":1376.81858639}],"checksum":157760669,"timestamp":"2026-09-16T00:17:35.010937Z"}]}}
{"v":1,"kind":"tick","pair":"BTC/USD","channel":"book","ts_exchange":"2026-09-16T00:17:35.110369Z","ts_recv":"2026-09-16T00:17:35.237345Z","payload":{"channel":"book","type":"update","data":[{"symbol":"BTC/USD","bids":[{"price":75730.3,"qty":0.0},{"price":75719.6,"qty":0.000051},{"price":75731.1,"qty":0.11117396}],"asks":[],"checksum":2927074686,"timestamp":"2026-09-16T00:17:35.110369Z"}]}}
{"v":1,"kind":"tick","pair":"ADA/USD","channel":"book","ts_exchange":"2026-09-16T00:17:35.137957Z","ts_recv":"2026-09-16T00:17:35.268993Z","payload":{"channel":"book","type":"update","data":[{"symbol":"ADA/USD","bids":[],"asks":[{"price":0.19484,"qty":0.0},{"price":0.194901,"qty":44518.72373616},{"price":0.194844,"qty":3078.996288}],"checksum":1864470006,"timestamp":"2026-09-16T00:17:35.137957Z"}]}}
{"v":1,"kind":"tick","pair":"ADA/USD","channel":"book","ts_exchange":"2026-09-16T00:17:35.138722Z","ts_recv":"2026-09-16T00:17:35.278752Z","payload":{"channel":"book","type":"update","data":[{"symbol":"ADA/USD","bids":[],"asks":[{"price":0.194843,"qty":1817.17734197}],"checksum":3880234737,"timestamp":"2026-09-16T00:17:35.138722Z"}]}}
{"v":1,"kind":"tick","pair":"BTC/USD","channel":"book","ts_exchange":"2026-09-16T00:17:35.143005Z","ts_recv":"2026-09-16T00:17:35.291039Z","payload":{"channel":"book","type":"update","data":[{"symbol":"BTC/USD","bids":[],"asks":[{"price":75731.9,"qty":0.00843204}],"checksum":3017139271,"timestamp":"2026-09-16T00:17:35.143005Z"}]}}
{"v":1,"kind":"tick","pair":"BTC/USD","channel":"book","ts_exchange":"2026-09-16T00:17:35.227913Z","ts_recv":"2026-09-16T00:17:35.415564Z","payload":{"channel":"book","type":"update","data":[{"symbol":"BTC/USD","bids":[],"asks":[{"price":75736.8,"qty":3.30090639}],"checksum":1550040856,"timestamp":"2026-09-16T00:17:35.227913Z"}]}}
{"v":1,"kind":"tick","pair":"BTC/USD","channel":"book","ts_exchange":"2026-09-16T00:17:35.240667Z","ts_recv":"2026-09-16T00:17:35.424158Z","payload":{"channel":"book","type":"update","data":[{"symbol":"BTC/USD","bids":[{"price":75731.1,"qty":0.0},{"price":75719.6,"qty":0.000051},{"price":75730.3,"qty":0.11117396}],"asks":[],"checksum":991512279,"timestamp":"2026-09-16T00:17:35.240667Z"}]}}
{"v":1,"kind":"tick","pair":"ADA/USD","channel":"book","ts_exchange":"2026-09-16T00:17:35.306823Z","ts_recv":"2026-09-16T00:17:35.459592Z","payload":{"channel":"book","type":"update","data":[{"symbol":"ADA/USD","bids":[],"asks":[{"price":0.194844,"qty":0.0},{"price":0.1949,"qty":1376.81858639},{"price":0.194842,"qty":3078.996288}],"checksum":4213897335,"timestamp":"2026-09-16T00:17:35.306823Z"}]}}
{"v":1,"kind":"tick","pair":"ADA/USD","channel":"book","ts_exchange":"2026-09-16T00:17:35.307544Z","ts_recv":"2026-09-16T00:17:35.459844Z","payload":{"channel":"book","type":"update","data":[{"symbol":"ADA/USD","bids":[],"asks":[{"price":0.194843,"qty":0.0},{"price":0.1949,"qty":1376.81858639}],"checksum":3623675656,"timestamp":"2026-09-16T00:17:35.307544Z"}]}}
{"v":1,"kind":"tick","pair":"ADA/USD","channel":"book","ts_exchange":"2026-09-16T00:17:35.307626Z","ts_recv":"2026-09-16T00:17:35.459993Z","payload":{"channel":"book","type":"update","data":[{"symbol":"ADA/USD","bids":[],"asks":[{"price":0.194841,"qty":1817.17734197}],"checksum":4185126106,"timestamp":"2026-09-16T00:17:35.307626Z"}]}}
{"v":1,"kind":"tick","pair":"BTC/USD","channel":"book","ts_exchange":"2026-09-16T00:17:35.394974Z","ts_recv":"2026-09-16T00:17:35.551216Z","payload":{"channel":"book","type":"update","data":[{"symbol":"BTC/USD","bids":[{"price":75729.0,"qty":0.0},{"price":75719.6,"qty":0.000051}],"asks":[],"checksum":168693852,"timestamp":"2026-09-16T00:17:35.394974Z"}]}}
{"v":1,"kind":"tick","pair":"BTC/USD","channel":"book","ts_exchange":"2026-09-16T00:17:35.401917Z","ts_recv":"2026-09-16T00:17:35.552322Z","payload":{"channel":"book","type":"update","data":[{"symbol":"BTC/USD","bids":[{"price":75730.3,"qty":0.0},{"price":75718.2,"qty":3.30171321},{"price":75731.1,"qty":0.11117396}],"asks":[],"checksum":2761805915,"timestamp":"2026-09-16T00:17:35.401917Z"}]}}
{"v":1,"kind":"tick","pair":"BTC/USD","channel":"book","ts_exchange":"2026-09-16T00:17:35.413328Z","ts_recv":"2026-09-16T00:17:35.575298Z","payload":{"channel":"book","type":"update","data":[{"symbol":"BTC/USD","bids":[{"price":75730.0,"qty":0.9904235}],"asks":[],"checksum":1328208481,"timestamp":"2026-09-16T00:17:35.413328Z"}]}}
{"v":1,"kind":"tick","pair":"ADA/USD","channel":"book","ts_exchange":"2026-09-16T00:17:35.489416Z","ts_recv":"2026-09-16T00:17:35.621780Z","payload":{"channel":"book","type":"update","data":[{"symbol":"ADA/USD","bids":[],"asks":[{"price":0.194842,"qty":0.0},{"price":0.194901,"qty":44518.72373616},{"price":0.19484,"qty":3078.996288}],"checksum":1708416136,"timestamp":"2026-09-16T00:17:35.489416Z"}]}}
{"v":1,"kind":"tick","pair":"ADA/USD","channel":"book","ts_exchange":"2026-09-16T00:17:35.490559Z","ts_recv":"2026-09-16T00:17:35.633160Z","payload":{"channel":"book","type":"update","data":[{"symbol":"ADA/USD","bids":[],"asks":[{"price":0.194841,"qty":0.0},{"price":0.194901,"qty":44518.72373616}],"checksum":1047477824,"timestamp":"2026-09-16T00:17:35.490559Z"}]}}
{"v":1,"kind":"tick","pair":"ADA/USD","channel":"book","ts_exchange":"2026-09-16T00:17:35.492068Z","ts_recv":"2026-09-16T00:17:35.633930Z","payload":{"channel":"book","type":"update","data":[{"symbol":"ADA/USD","bids":[],"asks":[{"price":0.1949,"qty":26846.4097721}],"checksum":928555915,"timestamp":"2026-09-16T00:17:35.492068Z"}]}}
{"v":1,"kind":"tick","pair":"BTC/USD","channel":"book","ts_exchange":"2026-09-16T00:17:35.559044Z","ts_recv":"2026-09-16T00:17:35.693316Z","payload":{"channel":"book","type":"update","data":[{"symbol":"BTC/USD","bids":[{"price":75731.1,"qty":0.0},{"price":75719.6,"qty":0.000051},{"price":75730.3,"qty":0.11117396}],"asks":[],"checksum":676340654,"timestamp":"2026-09-16T00:17:35.559044Z"}]}}
{"v":1,"kind":"tick","pair":"BTC/USD","channel":"book","ts_exchange":"2026-09-16T00:17:35.619795Z","ts_recv":"2026-09-16T00:17:35.761435Z","payload":{"channel":"book","type":"update","data":[{"symbol":"BTC/USD","bids":[{"price":75731.8,"qty":2.90096013},{"price":75731.8,"qty":2.90086013},{"price":75731.8,"qty":2.90076013},{"price":75731.8,"qty":2.88986365}],"asks":[],"checksum":3457257748,"timestamp":"2026-09-16T00:17:35.619795Z"}]}}
{"v":1,"kind":"tick","pair":"BTC/USD","channel":"book","ts_exchange":"2026-09-16T00:17:35.654375Z","ts_recv":"2026-09-16T00:17:35.802200Z","payload":{"channel":"book","type":"update","data":[{"symbol":"BTC/USD","bids":[{"price":75731.8,"qty":2.89035882}],"asks":[],"checksum":2919571108,"timestamp":"2026-09-16T00:17:35.654375Z"}]}}
{"v":1,"kind":"tick","pair":"ADA/USD","channel":"book","ts_exchange":"2026-09-16T00:17:35.663803Z","ts_recv":"2026-09-16T00:17:35.822643Z","payload":{"channel":"book","type":"update","data":[{"symbol":"ADA/USD","bids":[],"asks":[{"price":0.19484,"qty":0.0},{"price":0.194901,"qty":44518.72373616},{"price":0.194844,"qty":3078.996288}],"checksum":3982384618,"timestamp":"2026-09-16T00:17:35.663803Z"}]}}
{"v":1,"kind":"tick","pair":"ADA/USD","channel":"book","ts_exchange":"2026-09-16T00:17:35.664678Z","ts_recv":"2026-09-16T00:17:35.823162Z","payload":{"channel":"book","type":"update","data":[{"symbol":"ADA/USD","bids":[],"asks":[{"price":0.194843,"qty":1817.17734197}],"checksum":3880234737,"timestamp":"2026-09-16T00:17:35.664678Z"}]}}
{"v":1,"kind":"tick","pair":"BTC/USD","channel":"book","ts_exchange":"2026-09-16T00:17:35.690561Z","ts_recv":"2026-09-16T00:17:35.833003Z","payload":{"channel":"book","type":"update","data":[{"symbol":"BTC/USD","bids":[],"asks":[{"price":75734.3,"qty":0.0},{"price":75739.5,"qty":0.14497434}],"checksum":2257242988,"timestamp":"2026-09-16T00:17:35.690561Z"}]}}
{"v":1,"kind":"tick","pair":"BTC/USD","channel":"book","ts_exchange":"2026-09-16T00:17:35.691442Z","ts_recv":"2026-09-16T00:17:35.842417Z","payload":{"channel":"book","type":"update","data":[{"symbol":"BTC/USD","bids":[],"asks":[{"price":75733.7,"qty":1.32041786}],"checksum":2261440974,"timestamp":"2026-09-16T00:17:35.691442Z"}]}}
{"v":1,"kind":"tick","pair":"BTC/USD","channel":"book","ts_exchange":"2026-09-16T00:17:35.719199Z","ts_recv":"2026-09-16T00:17:35.854199Z","payload":{"channel":"book","type":"update","data":[{"symbol":"BTC/USD","bids":[{"price":75730.3,"qty":0.0},{"price":75719.6,"qty":0.000051},{"price":75731.1,"qty":0.11117396}],"asks":[],"checksum":3786416129,"timestamp":"2026-09-16T00:17:35.719199Z"}]}}
{"v":1,"kind":"tick","pair":"BTC/USD","channel":"book","ts_exchange":"2026-09-16T00:17:35.753766Z","ts_recv":"2026-09-16T00:17:35.896658Z","payload":{"channel":"book","type":"update","data":[{"symbol":"BTC/USD","bids":[{"price":75722.1,"qty":0.0616067}],"asks":[],"checksum":188579632,"timestamp":"2026-09-16T00:17:35.753766Z"}]}}
{"v":1,"kind":"tick","pair":"BTC/USD","channel":"book","ts_exchange":"2026-09-16T00:17:35.857753Z","ts_recv":"2026-09-16T00:17:35.997695Z","payload":{"channel":"book","type":"update","data":[{"symbol":"BTC/USD","bids":[{"price":75731.1,"qty":0.0},{"price":75721.1,"qty":0.02401151},{"price":75730.3,"qty":0.11117396}],"asks":[],"checksum":1816626943,"timestamp":"2026-09-16T00:17:35.857753Z"}]}}
{"v":1,"kind":"tick","pair":"ADA/USD","channel":"book","ts_exchange":"2026-09-16T00:17:35.872642Z","ts_recv":"2026-09-16T00:17:36.001584Z","payload":{"channel":"book","type":"update","data":[{"symbol":"ADA/USD","bids":[],"asks":[{"price":0.194844,"qty":0.0},{"price":0.1949,"qty":26846.4097721},{"price":0.194842,"qty":3078.996288}],"checksum":4213897335,"timestamp":"2026-09-16T00:17:35.872642Z"}]}}
{"v":1,"kind":"tick","pair":"ADA/USD","channel":"book","ts_exchange":"2026-09-16T00:17:35.873614Z","ts_recv":"2026-09-16T00:17:36.003863Z","payload":{"channel":"book","type":"update","data":[{"symbol":"ADA/USD","bids":[],"asks":[{"price":0.194843,"qty":0.0},{"price":0.1949,"qty":26846.4097721}],"checksum":3085131675,"timestamp":"2026-09-16T00:17:35.873614Z"}]}}
{"v":1,"kind":"tick","pair":"ADA/USD","channel":"book","ts_exchange":"2026-09-16T00:17:35.873685Z","ts_recv":"2026-09-16T00:17:36.005361Z","payload":{"channel":"book","type":"update","data":[{"symbol":"ADA/USD","bids":[],"asks":[{"price":0.194841,"qty":1817.17734197}],"checksum":4185126106,"timestamp":"2026-09-16T00:17:35.873685Z"}]}}
{"v":1,"kind":"tick","pair":"BTC/USD","channel":"book","ts_exchange":"2026-09-16T00:17:35.911533Z","ts_recv":"2026-09-16T00:17:36.044580Z","payload":{"channel":"book","type":"update","data":[{"symbol":"BTC/USD","bids":[{"price":75730.0,"qty":0.0},{"price":75721.1,"qty":0.02401151}],"asks":[],"checksum":3573717748,"timestamp":"2026-09-16T00:17:35.911533Z"}]}}
{"v":1,"kind":"tick","pair":"BTC/USD","channel":"book","ts_exchange":"2026-09-16T00:17:35.914207Z","ts_recv":"2026-09-16T00:17:36.054851Z","payload":{"channel":"book","type":"update","data":[{"symbol":"BTC/USD","bids":[{"price":75729.1,"qty":0.9904235}],"asks":[],"checksum":644406253,"timestamp":"2026-09-16T00:17:35.914207Z"}]}}
