{"_fixture":"book_frames","schema":1,"cut_by":"scripts/cut_book_fixture.py","window":{"from":"2026-09-16T00:17:06.100000Z","to":"2026-09-16T00:17:36.100000Z","bounds":"[from, to)"},"pairs":["ADA/USD","BTC/USD"],"source_files":["kraken_v2__msi__2026-09-16.jsonl"],"lines":{"total":977,"scanned":6000046,"per_pair":{"ADA/USD":{"snapshot":1,"update":451},"BTC/USD":{"snapshot":1,"update":524}}},"sha256_of_body":"87d4143b562186c9a33a1a506dc4a955ff6defd42e2feb906f0f86a6f07977ad","note":"Line 1 is this header and is not a recorded line. Every line after it is a Kraken v2 book frame copied byte-for-byte out of data/raw/, in recorded order. No gap marker intersects the window."}
{"v":1,"kind":"tick","pair":"BTC/USD","channel":"book","ts_exchange":"2026-09-16T00:17:06.134128Z","ts_recv":"2026-09-16T00:17:06.310036Z","payload":{"channel":"book","type":"snapshot","data":[{"symbol":"BTC/USD","bids":[{"price":75731.8,"qty":0.00069517},{"price":75731.0,"qty":0.000051},{"price":75727.2,"qty":0.000051},{"price":75726.8,"qty":1.06491467},{"price":75724.3,"qty":0.11117396},{"price":75724.2,"qty":0.0537},{"price":75724.1,"qty":0.29571343},{"price":75723.4,"qty":0.000051},{"price":75722.7,"qty":0.99061375},{"price":75719.6,"qty":0.000051}],"asks":[{"price":75731.9,"qty":1.211833},{"price":75732.4,"qty":0.91087196},{"price":75732.5,"qty":0.739448},{"price":75732.6,"qty":1.32043562},{"price":75733.6,"qty":0.52596},{"price":75733.9,"qty":0.14692751},{"price":75734.0,"qty":0.001},{"price":75734.3,"qty":1.06362654},{"price":75734.4,"qty":3.30101414},{"price":75734.7,"qty":0.0005}],"checksum":964943809,"timestamp":"2026-09-16T00:17:06.134128Z"}]}}
{"v":1,"kind":"tick","pair":"ADA/USD","channel":"book","ts_exchange":"2026-09-16T00:17:06.179487Z","ts_recv":"2026-09-16T00:17:06.341180Z","payload":{"channel":"book","type":"snapshot","data":[{"symbol":"ADA/USD","bids":[{"price":0.194674,"qty":3008.7},{"price":0.194673,"qty":100.0},{"price":0.194652,"qty":3079.1243748},{"price":0.194651,"qty":1030.33822061},{"price":0.19465,"qty":3451.71933202},{"price":0.194648,"qty":1226.99287505},{"price":0.194647,"qty":5608.14859176},{"price":0.194645,"qty":2568.77854701},{"price":0.19463,"qty":1272.4897279},{"price":0.194629,"qty":16485.2089321}],"asks":[{"price":0.194795,"qty":3079.1243748},{"price":0.194796,"qty":4574.38997628},{"price":0.194798,"qty":12245.46516048},{"price":0.1948,"qty":1106.95329722},{"price":0.194805,"qty":256.66692333},{"price":0.194806,"qty":4251.71933202},{"price":0.194814,"qty":2608.88579485},{"price":0.194829,"qty":2567.87546463},{"price":0.19483,"qty":256.63529344},{"price":0.19484,"qty":7891.99819803}],"checksum":3816327271,"timestamp":"2026-09-16T00:17:06.179487Z"}]}}
{"v":1,"kind":"tick","pair":"BTC/USD","channel":"book","ts_exchange":"2026-09-16T00:17:06.229190Z","ts_recv":"2026-09-16T00:17:06.357083Z","payload":{"channel":"book","type":"update","data":[{"symbol":"BTC/USD","bids":[{"price":75724.8,"qty":1.32056974}],"asks":[],"checksum":53529033,"timestamp":"2026-09-16T00:17:06.229190Z"}]}}
{"v":1,"kind":"tick","pair":"BTC/USD","channel":"book","ts_exchange":"2026-09-16T00:17:06.230077Z","ts_recv":"2026-09-16T00:17:06.357249Z","payload":{"channel":"book","type":"update","data":[{"symbol":"BTC/USD","bids":[{"price":75724.3,"qty":0.0},{"price":75721.2,"qty":3.30158218},{"price":75724.9,"qty":0.11117396}],"asks":[],"checksum":97565816,"timestamp":"2026-09-16T00:17:06.230077Z"}]}}
{"v":1,"kind":"tick","pair":"BTC/USD","channel":"book","ts_exchange":"2026-09-16T00:17:06.230197Z","ts_recv":"2026-09-16T00:17:06.357336Z","payload":{"channel":"book","type":"update","data":[{"symbol":"BTC/USD","bids":[{"price":75724.1,"qty":0.0},{"price":75721.2,"qty":3.30158218}],"asks":[],"checksum":4181378407,"timestamp":"2026-09-16T00:17:06.230197Z"}]}}
{"v":1,"kind":"tick","pair":"BTC/USD","channel":"book","ts_exchange":"2026-09-16T00:17:06.230898Z","ts_recv":"2026-09-16T00:17:06.362640Z","payload":{"channel":"book","type":"update","data":[{"symbol":"BTC/USD","bids":[{"price":75724.9,"qty":0.81710691}],"asks":[],"checksum":3139233411,"timestamp":"2026-09-16T00:17:06.230898Z"}]}}
{"v":1,"kind":"tick","pair":"ADA/USD","channel":"book","ts_exchange":"2026-09-16T00:17:06.258204Z","ts_recv":"2026-09-16T00:17:06.385233Z","payload":{"channel":"book","type":"update","data":[{"symbol":"ADA/USD","bids":[{"price":0.194669,"qty":3079.1243748}],"asks":[],"checksum":2437204927,"timestamp":"2026-09-16T00:17:06.258204Z"}]}}
{"v":1,"kind":"tick","pair":"ADA/USD","channel":"book","ts_exchange":"2026-09-16T00:17:06.258984Z","ts_recv":"2026-09-16T00:17:06.387401Z","payload":{"channel":"book","type":"update","data":[{"symbol":"ADA/USD","bids":[{"price":0.194652,"qty":0.0},{"price":0.194629,"qty":16485.2089321},{"price":0.19467,"qty":3079.1243748}],"asks":[],"checksum":1456299845,"timestamp":"2026-09-16T00:17:06.258984Z"}]}}
{"v":1,"kind":"tick","pair":"BTC/USD","channel":"book","ts_exchange":"2026-09-16T00:17:06.400336Z","ts_recv":"2026-09-16T00:17:06.541190Z","payload":{"channel":"book","type":"update","data":[{"symbol":"BTC/USD","bids":[{"price":75721.3,"qty":0.9855375}],"asks":[],"checksum":793453849,"timestamp":"2026-09-16T00:17:06.400336Z"}]}}
{"v":1,"kind":"tick","pair":"ADA/USD","channel":"book","ts_exchange":"2026-09-16T00:17:06.470280Z","ts_recv":"2026-09-16T00:17:06.603530Z","payload":{"channel":"book","type":"update","data":[{"symbol":"ADA/USD","bids":[{"price":0.194669,"qty":0.0},{"price":0.194629,"qty":16485.2089321}],"asks":[],"checksum":494723964,"timestamp":"2026-09-16T00:17:06.470280Z"}]}}
{"v":1,"kind":"tick","pair":"ADA/USD","channel":"book","ts_exchange":"2026-09-16T00:17:06.471738Z","ts_recv":"2026-09-16T00:17:06.604825Z","payload":{"channel":"book","type":"update","data":[{"symbol":"ADA/USD","bids":[{"price":0.19467,"qty":0.0},{"price":0.194622,"qty":2569.07582444},{"price":0.194652,"qty":3079.1243748}],"asks":[],"checksum":3816327271,"timestamp":"2026-09-16T00:17:06.471738Z"}]}}
{"v":1,"kind":"tick","pair":"BTC/USD","channel":"book","ts_exchange":"2026-09-16T00:17:06.479613Z","ts_recv":"2026-09-16T00:17:06.622011Z","payload":{"channel":"book","type":"update","data":[{"symbol":"BTC/USD","bids":[{"price":75721.3,"qty":0.0},{"price":75719.6,"qty":0.000051}],"asks":[],"checksum":2085549697,"timestamp":"2026-09-16T00:17:06.479613Z"}]}}
{"v":1,"kind":"tick","pair":"BTC/USD","channel":"book","ts_exchange":"2026-09-16T00:17:06.480279Z","ts_recv":"2026-09-16T00:17:06.622224Z","payload":{"channel":"book","type":"update","data":[{"symbol":"BTC/USD","bids":[{"price":75724.2,"qty":0.0},{"price":75718.1,"qty":0.02051113}],"asks":[],"checksum":2584279886,"timestamp":"2026-09-16T00:17:06.480279Z"}]}}
{"v":1,"kind":"tick","pair":"BTC/USD","channel":"book","ts_exchange":"2026-09-16T00:17:06.525373Z","ts_recv":"2026-09-16T00:17:06.668588Z","payload":{"channel":"book","type":"update","data":[{"symbol":"BTC/USD","bids":[{"price":75731.8,"qty":0.3582342}],"asks":[],"checksum":4030998507,"timestamp":"2026-09-16T00:17:06.525373Z"}]}}
{"v":1,"kind":"tick","pair":"BTC/USD","channel":"book","ts_exchange":"2026-09-16T00:17:06.529124Z","ts_recv":"2026-09-16T00:17:06.670663Z","payload":{"channel":"book","type":"update","data":[{"symbol":"BTC/USD","bids":[],"asks":[{"price":75731.9,"qty":1.19035042}],"checksum":166977830,"timestamp":"2026-09-16T00:17:06.529124Z"}]}}
{"v":1,"kind":"tick","pair":"BTC/USD","channel":"book","ts_exchange":"2026-09-16T00:17:06.629303Z","ts_recv":"2026-09-16T00:17:06.777621Z","payload":{"channel":"book","type":"update","data":[{"symbol":"BTC/USD","bids":[{"price":75731.8,"qty":0.00069517}],"asks":[],"checksum":1733907698,"timestamp":"2026-09-16T00:17:06.629303Z"}]}}
{"v":1,"kind":"tick","pair":"BTC/USD","channel":"book","ts_exchange":"2026-09-16T00:17:06.630929Z","ts_recv":"2026-09-16T00:17:06.783799Z","payload":{"channel":"book","type":"update","data":[{"symbol":"BTC/USD","bids":[{"price":75724.9,"qty":0.11117396}],"asks":[],"checksum":3174414203,"timestamp":"2026-09-16T00:17:06.630929Z"}]}}
{"v":1,"kind":"tick","pair":"BTC/USD","channel":"book","ts_exchange":"2026-09-16T00:17:06.632140Z","ts_recv":"2026-09-16T00:17:06.785036Z","payload":{"channel":"book","type":"update","data":[{"symbol":"BTC/USD","bids":[],"asks":[{"price":75731.9,"qty":1.211833}],"checksum":1080301767,"timestamp":"2026-09-16T00:17:06.632140Z"}]}}
{"v":1,"kind":"tick","pair":"BTC/USD","channel":"book","ts_exchange":"2026-09-16T00:17:06.659767Z","ts_recv":"2026-09-16T00:17:06.807720Z","payload":{"channel":"book","type":"update","data":[{"symbol":"BTC/USD","bids":[{"price":75724.8,"qty":0.0},{"price":75717.5,"qty":0.00105736}],"asks":[],"checksum":2983610794,"timestamp":"2026-09-16T00:17:06.659767Z"}]}}
{"v":1,"kind":"tick","pair":"BTC/USD","channel":"book","ts_exchange":"2026-09-16T00:17:06.660661Z","ts_recv":"2026-09-16T00:17:06.816556Z","payload":{"channel":"book","type":"update","data":[{"symbol":"BTC/USD","bids":[{"price":75724.9,"qty":0.0},{"price":75717.4,"qty":1.04514049},{"price":75722.8,"qty":0.11117396}],"asks":[],"checksum":143196861,"timestamp":"2026-09-16T00:17:06.660661Z"}]}}
{"v":1,"kind":"tick","pair":"BTC/USD","channel":"book","ts_exchange":"2026-09-16T00:17:06.660772Z","ts_recv":"2026-09-16T00:17:06.818740Z","payload":{"channel":"book","type":"update","data":[{"symbol":"BTC/USD","bids":[{"price":75722.8,"qty":0.40687216}],"asks":[],"checksum":51447864,"timestamp":"2026-09-16T00:17:06.660772Z"}]}}
{"v":1,"kind":"tick","pair":"BTC/USD","channel":"book","ts_exchange":"2026-09-16T00:17:06.660792Z","ts_recv":"2026-09-16T00:17:06.820772Z","payload":{"channel":"book","type":"update","data":[{"symbol":"BTC/USD","bids":[{"price":75723.9,"qty":1.32058662}],"asks":[],"checksum":3772515075,"timestamp":"2026-09-16T00:17:06.660792Z"}]}}
{"v":1,"kind":"tick","pair":"BTC/USD","channel":"book","ts_exchange":"2026-09-16T00:17:06.661100Z","ts_recv":"2026-09-16T00:17:06.822610Z","payload":{"channel":"book","type":"update","data":[{"symbol":"BTC/USD","bids":[{"price":75720.9,"qty":3.30159428}],"asks":[],"checksum":3465208783,"timestamp":"2026-09-16T00:17:06.661100Z"}]}}
{"v":1,"kind":"tick","pair":"BTC/USD","channel":"book","ts_exchange":"2026-09-16T00:17:06.675312Z","ts_recv":"2026-09-16T00:17:06.838183Z","payload":{"channel":"book","type":"update","data":[{"symbol":"BTC/USD","bids":[{"price":75722.7,"qty":0.0},{"price":75718.1,"qty":0.02051113}],"asks":[],"checksum":3782625948,"timestamp":"2026-09-16T00:17:06.675312Z"}]}}
{"v":1,"kind":"tick","pair":"BTC/USD","channel":"book","ts_exchange":"2026-09-16T00:17:06.676060Z","ts_recv":"2026-09-16T00:17:06.842864Z","payload":{"channel":"book","type":"update","data":[{"symbol":"BTC/USD","bids":[{"price":75722.8,"qty":0.11117396}],"asks":[],"checksum":1339908830,"timestamp":"2026-09-16T00:17:06.676060Z"}]}}
{"v":1,"kind":"tick","pair":"BTC/USD","channel":"book","ts_exchange":"2026-09-16T00:17:06.676526Z","ts_recv":"2026-09-16T00:17:06.843041Z","payload":{"channel":"book","type":"update","data":[{"symbol":"BTC/USD","bids":[{"price":75723.9,"qty":0.0},{"price":75717.5,"qty":0.00105736}],"asks":[],"checksum":2061677877,"timestamp":"2026-09-16T00:17:06.676526Z"}]}}
{"v":1,"kind":"tick","pair":"BTC/USD","channel":"book","ts_exchange":"2026-09-16T00:17:06.677509Z","ts_recv":"2026-09-16T00:17:06.843201Z","payload":{"channel":"book","type":"update","data":[{"symbol":"BTC/USD","bids":[],"asks":[{"price":75731.9,"qty":1.19035042}],"checksum":792283736,"timestamp":"2026-09-16T00:17:06.677509Z"}]}}
{"v":1,"kind":"tick","pair":"BTC/USD","channel":"book","ts_exchange":"2026-09-16T00:17:06.677651Z","ts_recv":"2026-09-16T00:17:06.843358Z","payload":{"channel":"book","type":"update","data":[{"symbol":"BTC/USD","bids":[{"price":75722.9,"qty":0.03318543}],"asks":[],"checksum":2372264909,"timestamp":"2026-09-16T00:17:06.677651Z"}]}}
{"v":1,"kind":"tick","pair":"BTC/USD","channel":"book","ts_exchange":"2026-09-16T00:17:06.678102Z","ts_recv":"2026-09-16T00:17:06.843517Z","payload":{"channel":"book","type":"update","data":[{"symbol":"BTC/USD","bids":[{"price":75722.9,"qty":0.0},{"price":75717.5,"qty":0.00105736}],"asks":[],"checksum":792283736,"timestamp":"2026-09-16T00:17:06.678102Z"}]}}
{"v":1,"kind":"tick","pair":"BTC/USD","channel":"book","ts_exchange":"2026-09-16T00:17:06.713090Z","ts_recv":"2026-09-16T00:17:06.877468Z","payload":{"channel":"book","type":"update","data":[{"symbol":"BTC/USD","bids":[{"price":75721.7,"qty":0.99061375}],"asks":[],"checksum":2480977235,"timestamp":"2026-09-16T00:17:06.713090Z"}]}}
{"v":1,"kind":"tick","pair":"BTC/USD","channel":"book","ts_exchange":"2026-09-16T00:17:06.713925Z","ts_recv":"2026-09-16T00:17:06.879523Z","payload":{"channel":"book","type":"update","data":[{"symbol":"BTC/USD","bids":[{"price":75721.8,"qty":1.28123932}],"asks":[],"checksum":314666112,"timestamp":"2026-09-16T00:17:06.713925Z"}]}}
{"v":1,"kind":"tick","pair":"BTC/USD","channel":"book","ts_exchange":"2026-09-16T00:17:06.715544Z","ts_recv":"2026-09-16T00:17:06.881601Z","payload":{"channel":"book","type":"update","data":[{"symbol":"BTC/USD","bids":[],"asks":[{"price":75731.9,"qty":1.211833}],"checksum":483970588,"timestamp":"2026-09-16T00:17:06.715544Z"}]}}
{"v":1,"kind":"tick","pair":"BTC/USD","channel":"book","ts_exchange":"2026-09-16T00:17:06.726704Z","ts_recv":"2026-09-16T00:17:06.896890Z","payload":{"channel":"book","type":"update","data":[{"symbol":"BTC/USD","bids":[{"price":75720.9,"qty":0.0},{"price":75718.1,"qty":0.02051113}],"asks":[],"checksum":1299852602,"timestamp":"2026-09-16T00:17:06.726704Z"}]}}
{"v":1,"kind":"tick","pair":"BTC/USD","channel":"book","ts_exchange":"2026-09-16T00:17:06.727936Z","ts_recv":"2026-09-16T00:17:06.897762Z","payload":{"channel":"book","type":"update","data":[{"symbol":"BTC/USD","bids":[{"price":75721.8,"qty":0.0},{"price":75717.4,"qty":1.04514049}],"asks":[],"checksum":3333889086,"timestamp":"2026-09-16T00:17:06.727936Z"}]}}
{"v":1,"kind":"tick","pair":"BTC/USD","channel":"book","ts_exchange":"2026-09-16T00:17:06.728116Z","ts_recv":"2026-09-16T00:17:06.898608Z","payload":{"channel":"book","type":"update","data":[{"symbol":"BTC/USD","bids":[{"price":75721.7,"qty":0.0},{"price":75717.1,"qty":0.11117396}],"asks":[],"checksum":3257903360,"timestamp":"2026-09-16T00:17:06.728116Z"}]}}
{"v":1,"kind":"tick","pair":"BTC/USD","channel":"book","ts_exchange":"2026-09-16T00:17:06.730245Z","ts_recv":"2026-09-16T00:17:06.914941Z","payload":{"channel":"book","type":"update","data":[{"symbol":"BTC/USD","bids":[{"price":75721.8,"qty":0.29571343}],"asks":[],"checksum":2769789295,"timestamp":"2026-09-16T00:17:06.730245Z"}]}}
{"v":1,"kind":"tick","pair":"BTC/USD","channel":"book","ts_exchange":"2026-09-16T00:17:06.730292Z","ts_recv":"2026-09-16T00:17:06.915992Z","payload":{"channel":"book","type":"update","data":[{"symbol":"BTC/USD","bids":[{"price":75721.8,"qty":0.0},{"price":75717.1,"qty":0.11117396}],"asks":[],"checksum":3257903360,"timestamp":"2026-09-16T00:17:06.730292Z"}]}}
{"v":1,"kind":"tick","pair":"BTC/USD","channel":"book","ts_exchange":"2026-09-16T00:17:06.732736Z","ts_recv":"2026-09-16T00:17:06.917465Z","payload":{"channel":"book","type":"update","data":[{"symbol":"BTC/USD","bids":[{"price":75717.5,"qty":0.00105736}],"asks":[],"checksum":1500428986,"timestamp":"2026-09-16T00:17:06.732736Z"}]}}
{"v":1,"kind":"tick","pair":"BTC/USD","channel":"book","ts_exchange":"2026-09-16T00:17:06.763171Z","ts_recv":"2026-09-16T00:17:06.986009Z","payload":{"channel":"book","type":"update","data":[{"symbol":"BTC/USD","bids":[{"price":75720.4,"qty":0.99061375}],"asks":[],"checksum":3937148098,"timestamp":"2026-09-16T00:17:06.763171Z"}]}}
{"v":1,"kind":"tick","pair":"BTC/USD","channel":"book","ts_exchange":"2026-09-16T00:17:06.764316Z","ts_recv":"2026-09-16T00:17:06.998455Z","payload":{"channel":"book","type":"update","data":[{"symbol":"BTC/USD","bids":[{"price":75720.5,"qty":0.29571343}],"asks":[],"checksum":980420218,"timestamp":"2026-09-16T00:17:06.764316Z"}]}}
{"v":1,"kind":"tick","pair":"BTC/USD","channel":"book","ts_exchange":"2026-09-16T00:17:06.797238Z","ts_recv":"2026-09-16T00:17:06.998801Z","payload":{"channel":"book","type":"update","data":[{"symbol":"BTC/USD","bids":[{"price":75722.8,"qty":0.0},{"price":75717.5,"qty":0.00105736},{"price":75720.6,"qty":0.0739411}],"asks":[],"checksum":1879193589,"timestamp":"2026-09-16T00:17:06.797238Z"}]}}
{"v":1,"kind":"tick","pair":"BTC/USD","channel":"book","ts_exchange":"2026-09-16T00:17:06.944790Z","ts_recv":"2026-09-16T00:17:07.083737Z","payload":{"channel":"book","type":"update","data":[{"symbol":"BTC/USD","bids":[{"price":75722.9,"qty":1.32060315}],"asks":[],"checksum":2173812490,"timestamp":"2026-09-16T00:17:06.944790Z"}]}}
{"v":1,"kind":"tick","pair":"BTC/USD","channel":"book","ts_exchange":"2026-09-16T00:17:06.994888Z","ts_recv":"2026-09-16T00:17:07.121441Z","payload":{"channel":"book","type":"update","data":[{"symbol":"BTC/USD","bids":[{"price":75722.9,"qty":0.0},{"price":75718.1,"qty":0.02051113}],"asks":[],"checksum":1879193589,"timestamp":"2026-09-16T00:17:06.994888Z"}]}}
{"v":1,"kind":"tick","pair":"BTC/USD","channel":"book","ts_exchange":"2026-09-16T00:17:06.995739Z","ts_recv":"2026-09-16T00:17:07.122122Z","payload":{"channel":"book","type":"update","data":[{"symbol":"BTC/USD","bids":[{"price":75721.3,"qty":3.30158009}],"asks":[],"checksum":4111354494,"timestamp":"2026-09-16T00:17:06.995739Z"}]}}
{"v":1,"kind":"tick","pair":"BTC/USD","channel":"book","ts_exchange":"2026-09-16T00:17:06.996345Z","ts_recv":"2026-09-16T00:17:07.138790Z","payload":{"channel":"book","type":"update","data":[{"symbol":"BTC/USD","bids":[{"price":75720.5,"qty":0.0},{"price":75718.1,"qty":0.02051113}],"asks":[],"checksum":55659895,"timestamp":"2026-09-16T00:17:06.996345Z"}]}}
{"v":1,"kind":"tick","pair":"BTC/USD","channel":"book","ts_exchange":"2026-09-16T00:17:06.997018Z","ts_recv":"2026-09-16T00:17:07.140463Z","payload":{"channel":"book","type":"update","data":[{"symbol":"BTC/USD","bids":[{"price":75721.4,"qty":1.3033065}],"asks":[],"checksum":847657068,"timestamp":"2026-09-16T00:17:06.997018Z"}]}}
{"v":1,"kind":"tick","pair":"BTC/USD","channel":"book","ts_exchange":"2026-09-16T00:17:07.000002Z","ts_recv":"2026-09-16T00:17:07.141937Z","payload":{"channel":"book","type":"update","data":[{"symbol":"BTC/USD","bids":[],"asks":[{"price":75734.0,"qty":0.0005}],"checksum":4011393063,"timestamp":"2026-09-16T00:17:07.000002Z"}]}}
{"v":1,"kind":"tick","pair":"BTC/USD","channel":"book","ts_exchange":"2026-09-16T00:17:07.073853Z","ts_recv":"2026-09-16T00:17:07.202498Z","payload":{"channel":"book","type":"update","data":[{"symbol":"BTC/USD","bids":[{"price":75720.4,"qty":0.0},{"price":75718.1,"qty":0.02051113}],"asks":[],"checksum":3943608793,"timestamp":"2026-09-16T00:17:07.073853Z"}]}}
{"v":1,"kind":"tick","pair":"BTC/USD","channel":"book","ts_exchange":"2026-09-16T00:17:07.075721Z","ts_recv":"2026-09-16T00:17:07.204602Z","payload":{"channel":"book","type":"update","data":[{"symbol":"BTC/USD","bids":[],"asks":[{"price":75731.9,"qty":1.19035042}],"checksum":3629676483,"timestamp":"2026-09-16T00:17:07.075721Z"}]}}
{"v":1,"kind":"tick","pair":"BTC/USD","channel":"book","ts_exchange":"2026-09-16T00:17:07.108618Z","ts_recv":"2026-09-16T00:17:07.248966Z","payload":{"channel":"book","type":"update","data":[{"symbol":"BTC/USD","bids":[{"price":75724.7,"qty":1.3205728}],"asks":[],"checksum":372785695,"timestamp":"2026-09-16T00:17:07.108618Z"}]}}
{"v":1,"kind":"tick","pair":"BTC/USD","channel":"book","ts_exchange":"2026-09-16T00:17:07.109495Z","ts_recv":"2026-09-16T00:17:07.261599Z","payload":{"channel":"book","type":"update","data":[{"symbol":"BTC/USD","bids":[{"price":75720.6,"qty":0.0},{"price":75718.1,"qty":0.02051113},{"price":75724.8,"qty":0.11117396}],"asks":[],"checksum":2960686307,"timestamp":"2026-09-16T00:17:07.109495Z"}]}}
{"v":1,"kind":"tick","pair":"BTC/USD","channel":"book","ts_exchange":"2026-09-16T00:17:07.113193Z","ts_recv":"2026-09-16T00:17:07.266262Z","payload":{"channel":"book","type":"update","data":[{"symbol":"BTC/USD","bids":[{"price":75721.2,"qty":0.99061375}],"asks":[],"checksum":3512807,"timestamp":"2026-09-16T00:17:07.113193Z"}]}}
{"v":1,"kind":"tick","pair":"BTC/USD","channel":"book","ts_exchange":"2026-09-16T00:17:07.115757Z","ts_recv":"2026-09-16T00:17:07.266776Z","payload":{"channel":"book","type":"update","data":[{"symbol":"BTC/USD","bids":[],"asks":[{"price":75731.9,"qty":1.211833}],"checksum":1374145258,"timestamp":"2026-09-16T00:17:07.115757Z"}]}}
{"v":1,"kind":"tick","pair":"BTC/USD","channel":"book","ts_exchange":"2026-09-16T00:17:07.470582Z","ts_recv":"2026-09-16T00:17:07.597794Z","payload":{"channel":"book","type":"update","data":[{"symbol":"BTC/USD","bids":[{"price":75726.8,"qty":0.0},{"price":75719.6,"qty":0.000051}],"asks":[],"checksum":37123021,"timestamp":"2026-09-16T00:17:07.470582Z"}]}}
{"v":1,"kind":"tick","pair":"BTC/USD","channel":"book","ts_exchange":"2026-09-16T00:17:07.470694Z","ts_recv":"2026-09-16T00:17:07.598061Z","payload":{"channel":"book","type":"update","data":[{"symbol":"BTC/USD","bids":[{"price":75721.2,"qty":0.0},{"price":75718.1,"qty":0.02051113}],"asks":[],"checksum":2774550404,"timestamp":"2026-09-16T00:17:07.470694Z"}]}}
{"v":1,"kind":"tick","pair":"BTC/USD","channel":"book","ts_exchange":"2026-09-16T00:17:07.473050Z","ts_recv":"2026-09-16T00:17:07.601114Z","payload":{"channel":"book","type":"update","data":[{"symbol":"BTC/USD","bids":[],"asks":[{"price":75731.9,"qty":1.19035042}],"checksum":1479665720,"timestamp":"2026-09-16T00:17:07.473050Z"}]}}
{"v":1,"kind":"tick","pair":"BTC/USD","channel":"book","ts_exchange":"2026-09-16T00:17:07.512958Z","ts_recv":"2026-09-16T00:17:07.639481Z","payload":{"channel":"book","type":"update","data":[{"symbol":"BTC/USD","bids":[{"price":75719.8,"qty":0.99061375}],"asks":[],"checksum":1540133600,"timestamp":"2026-09-16T00:17:07.512958Z"}]}}
{"v":1,"kind":"tick","pair":"BTC/USD","channel":"book","ts_exchange":"2026-09-16T00:17:07.513020Z","ts_recv":"2026-09-16T00:17:07.639554Z","payload":{"channel":"book","type":"update","data":[{"symbol":"BTC/USD","bids":[],"asks":[{"price":75734.5,"qty":0.99061375}],"checksum":4189462717,"timestamp":"2026-09-16T00:17:07.513020Z"}]}}
{"v":1,"kind":"tick","pair":"BTC/USD","channel":"book","ts_exchange":"2026-09-16T00:17:07.515541Z","ts_recv":"2026-09-16T00:17:07.645493Z","payload":{"channel":"book","type":"update","data":[{"symbol":"BTC/USD","bids":[],"asks":[{"price":75731.9,"qty":1.211833}],"checksum":479865206,"timestamp":"2026-09-16T00:17:07.515541Z"}]}}
{"v":1,"kind":"tick","pair":"ADA/USD","channel":"book","ts_exchange":"2026-09-16T00:17:07.549830Z","ts_recv":"2026-09-16T00:17:07.688981Z","payload":{"channel":"book","type":"update","data":[{"symbol":"ADA/USD","bids":[{"price":0.194675,"qty":1040.0}],"asks":[],"checksum":2456155026,"timestamp":"2026-09-16T00:17:07.549830Z"}]}}
{"v":1,"kind":"tick","pair":"ADA/USD","channel":"book","ts_exchange":"2026-09-16T00:17:07.550755Z","ts_recv":"2026-09-16T00:17:07.689332Z","payload":{"channel":"book","type":"update","data":[{"symbol":"ADA/USD","bids":[{"price":0.194676,"qty":3008.7}],"asks":[],"checksum":4079110703,"timestamp":"2026-09-16T00:17:07.550755Z"}]}}
{"v":1,"kind":"tick","pair":"ADA/USD","channel":"book","ts_exchange":"2026-09-16T00:17:07.569578Z","ts_recv":"2026-09-16T00:17:07.695374Z","payload":{"channel":"book","type":"update","data":[{"symbol":"ADA/USD","bids":[{"price":0.194675,"qty":0.0},{"price":0.19463,"qty":1272.4897279}],"asks":[],"checksum":3279260784,"timestamp":"2026-09-16T00:17:07.569578Z"}]}}
{"v":1,"kind":"tick","pair":"ADA/USD","channel":"book","ts_exchange":"2026-09-16T00:17:07.651270Z","ts_recv":"2026-09-16T00:17:07.792390Z","payload":{"channel":"book","type":"update","data":[{"symbol":"ADA/USD","bids":[{"price":0.194674,"qty":0.0},{"price":0.194629,"qty":16485.2089321}],"asks":[],"checksum":3752199579,"timestamp":"2026-09-16T00:17:07.651270Z"}]}}
{"v":1,"kind":"tick","pair":"BTC/USD","channel":"book","ts_exchange":"2026-09-16T00:17:07.728686Z","ts_recv":"2026-09-16T00:17:07.857015Z","payload":{"channel":"book","type":"update","data":[{"symbol":"BTC/USD","bids":[{"price":75724.5,"qty":1.06491467}],"asks":[],"checksum":3386320396,"timestamp":"2026-09-16T00:17:07.728686Z"}]}}
{"v":1,"kind":"tick","pair":"BTC/USD","channel":"book","ts_exchange":"2026-09-16T00:17:07.951120Z","ts_recv":"2026-09-16T00:17:08.083848Z","payload":{"channel":"book","type":"update","data":[{"symbol":"BTC/USD","bids":[{"price":75719.9,"qty":0.11117396}],"asks":[],"checksum":1698384832,"timestamp":"2026-09-16T00:17:07.951120Z"}]}}
{"v":1,"kind":"tick","pair":"BTC/USD","channel":"book","ts_exchange":"2026-09-16T00:17:08.042307Z","ts_recv":"2026-09-16T00:17:08.191882Z","payload":{"channel":"book","type":"update","data":[{"symbol":"BTC/USD","bids":[{"price":75721.3,"qty":0.0},{"price":75719.8,"qty":0.99061375}],"asks":[],"checksum":3854482149,"timestamp":"2026-09-16T00:17:08.042307Z"}]}}
{"v":1,"kind":"tick","pair":"BTC/USD","channel":"book","ts_exchange":"2026-09-16T00:17:08.043249Z","ts_recv":"2026-09-16T00:17:08.192112Z","payload":{"channel":"book","type":"update","data":[{"symbol":"BTC/USD","bids":[{"price":75722.6,"qty":3.30152045}],"asks":[],"checksum":1573463462,"timestamp":"2026-09-16T00:17:08.043249Z"}]}}
{"v":1,"kind":"tick","pair":"BTC/USD","channel":"book","ts_exchange":"2026-09-16T00:17:08.043468Z","ts_recv":"2026-09-16T00:17:08.192859Z","payload":{"channel":"book","type":"update","data":[{"symbol":"BTC/USD","bids":[{"price":75721.4,"qty":0.0},{"price":75719.8,"qty":0.99061375}],"asks":[],"checksum":3311637676,"timestamp":"2026-09-16T00:17:08.043468Z"}]}}
{"v":1,"kind":"tick","pair":"BTC/USD","channel":"book","ts_exchange":"2026-09-16T00:17:08.044540Z","ts_recv":"2026-09-16T00:17:08.193098Z","payload":{"channel":"book","type":"update","data":[{"symbol":"BTC/USD","bids":[{"price":75724.8,"qty":1.80876105}],"asks":[],"checksum":3917786972,"timestamp":"2026-09-16T00:17:08.044540Z"}]}}
{"v":1,"kind":"tick","pair":"BTC/USD","channel":"book","ts_exchange":"2026-09-16T00:17:08.074078Z","ts_recv":"2026-09-16T00:17:08.221705Z","payload":{"channel":"book","type":"update","data":[{"symbol":"BTC/USD","bids":[],"asks":[{"price":75734.5,"qty":0.0},{"price":75734.7,"qty":0.0005}],"checksum":4218055866,"timestamp":"2026-09-16T00:17:08.074078Z"}]}}
{"v":1,"kind":"tick","pair":"BTC/USD","channel":"book","ts_exchange":"2026-09-16T00:17:08.074183Z","ts_recv":"2026-09-16T00:17:08.221937Z","payload":{"channel":"book","type":"update","data":[{"symbol":"BTC/USD","bids":[{"price":75719.8,"qty":0.0},{"price":75719.6,"qty":0.000051}],"asks":[],"checksum":4004763698,"timestamp":"2026-09-16T00:17:08.074183Z"}]}}
{"v":1,"kind":"tick","pair":"BTC/USD","channel":"book","ts_exchange":"2026-09-16T00:17:08.076882Z","ts_recv":"2026-09-16T00:17:08.222178Z","payload":{"channel":"book","type":"update","data":[{"symbol":"BTC/USD","bids":[{"price":75731.8,"qty":0.01161095}],"asks":[],"checksum":1369233643,"timestamp":"2026-09-16T00:17:08.076882Z"}]}}
{"v":1,"kind":"tick","pair":"BTC/USD","channel":"book","ts_exchange":"2026-09-16T00:17:08.077315Z","ts_recv":"2026-09-16T00:17:08.222284Z","payload":{"channel":"book","type":"update","data":[{"symbol":"BTC/USD","bids":[],"asks":[{"price":75731.9,"qty":1.19035042}],"checksum":3031486752,"timestamp":"2026-09-16T00:17:08.077315Z"}]}}
{"v":1,"kind":"tick","pair":"BTC/USD","channel":"book","ts_exchange":"2026-09-16T00:17:08.109968Z","ts_recv":"2026-09-16T00:17:08.245599Z","payload":{"channel":"book","type":"update","data":[{"symbol":"BTC/USD","bids":[{"price":75724.7,"qty":0.0},{"price":75718.1,"qty":0.02051113}],"asks":[],"checksum":2920680627,"timestamp":"2026-09-16T00:17:08.109968Z"}]}}
{"v":1,"kind":"tick","pair":"BTC/USD","channel":"book","ts_exchange":"2026-09-16T00:17:08.110944Z","ts_recv":"2026-09-16T00:17:08.247598Z","payload":{"channel":"book","type":"update","data":[{"symbol":"BTC/USD","bids":[{"price":75725.6,"qty":1.32055577}],"asks":[],"checksum":4143292233,"timestamp":"2026-09-16T00:17:08.110944Z"}]}}
{"v":1,"kind":"tick","pair":"BTC/USD","channel":"book","ts_exchange":"2026-09-16T00:17:08.112080Z","ts_recv":"2026-09-16T00:17:08.265317Z","payload":{"channel":"book","type":"update","data":[{"symbol":"BTC/USD","bids":[{"price":75724.8,"qty":1.69758709},{"price":75725.7,"qty":0.11117396}],"asks":[],"checksum":2341805842,"timestamp":"2026-09-16T00:17:08.112080Z"}]}}
{"v":1,"kind":"tick","pair":"BTC/USD","channel":"book","ts_exchange":"2026-09-16T00:17:08.112432Z","ts_recv":"2026-09-16T00:17:08.267148Z","payload":{"channel":"book","type":"update","data":[{"symbol":"BTC/USD","bids":[{"price":75725.6,"qty":0.0},{"price":75719.6,"qty":0.000051}],"asks":[],"checksum":471974020,"timestamp":"2026-09-16T00:17:08.112432Z"}]}}
{"v":1,"kind":"tick","pair":"BTC/USD","channel":"book","ts_exchange":"2026-09-16T00:17:08.112511Z","ts_recv":"2026-09-16T00:17:08.269796Z","payload":{"channel":"book","type":"update","data":[{"symbol":"BTC/USD","bids":[{"price":75722.6,"qty":0.0},{"price":75718.1,"qty":0.02051113}],"asks":[],"checksum":1895026731,"timestamp":"2026-09-16T00:17:08.112511Z"}]}}
{"v":1,"kind":"tick","pair":"BTC/USD","channel":"book","ts_exchange":"2026-09-16T00:17:08.113512Z","ts_recv":"2026-09-16T00:17:08.276361Z","payload":{"channel":"book","type":"update","data":[{"symbol":"BTC/USD","bids":[{"price":75724.8,"qty":0.0},{"price":75717.4,"qty":1.04514049}],"asks":[],"checksum":1807121317,"timestamp":"2026-09-16T00:17:08.113512Z"}]}}
{"v":1,"kind":"tick","pair":"BTC/USD","channel":"book","ts_exchange":"2026-09-16T00:17:08.113560Z","ts_recv":"2026-09-16T00:17:08.276818Z","payload":{"channel":"book","type":"update","data":[{"symbol":"BTC/USD","bids":[{"price":75721.3,"qty":0.99061375}],"asks":[],"checksum":1725612001,"timestamp":"2026-09-16T00:17:08.113560Z"}]}}
{"v":1,"kind":"tick","pair":"BTC/USD","channel":"book","ts_exchange":"2026-09-16T00:17:08.114813Z","ts_recv":"2026-09-16T00:17:08.277051Z","payload":{"channel":"book","type":"update","data":[{"symbol":"BTC/USD","bids":[{"price":75724.6,"qty":0.31789225}],"asks":[],"checksum":2303086176,"timestamp":"2026-09-16T00:17:08.114813Z"}]}}
{"v":1,"kind":"tick","pair":"BTC/USD","channel":"book","ts_exchange":"2026-09-16T00:17:08.114889Z","ts_recv":"2026-09-16T00:17:08.277462Z","payload":{"channel":"book","type":"update","data":[{"symbol":"BTC/USD","bids":[{"price":75724.2,"qty":0.0537}],"asks":[],"checksum":2853569938,"timestamp":"2026-09-16T00:17:08.114889Z"}]}}
{"v":1,"kind":"tick","pair":"BTC/USD","channel":"book","ts_exchange":"2026-09-16T00:17:08.115444Z","ts_recv":"2026-09-16T00:17:08.277637Z","payload":{"channel":"book","type":"update","data":[{"symbol":"BTC/USD","bids":[],"asks":[{"price":75731.9,"qty":1.211833}],"checksum":1329204313,"timestamp":"2026-09-16T00:17:08.115444Z"}]}}
{"v":1,"kind":"tick","pair":"BTC/USD","channel":"book","ts_exchange":"2026-09-16T00:17:08.115665Z","ts_recv":"2026-09-16T00:17:08.277811Z","payload":{"channel":"book","type":"update","data":[{"symbol":"BTC/USD","bids":[{"price":75731.8,"qty":0.00069517}],"asks":[],"checksum":4027911296,"timestamp":"2026-09-16T00:17:08.115665Z"}]}}
{"v":1,"kind":"tick","pair":"BTC/USD","channel":"book","ts_exchange":"2026-09-16T00:17:08.131816Z","ts_recv":"2026-09-16T00:17:08.281439Z","payload":{"channel":"book","type":"update","data":[{"symbol":"BTC/USD","bids":[{"price":75724.5,"qty":0.0},{"price":75719.6,"qty":0.000051}],"asks":[],"checksum":3728254337,"timestamp":"2026-09-16T00:17:08.131816Z"}]}}
{"v":1,"kind":"tick","pair":"BTC/USD","channel":"book","ts_exchange":"2026-09-16T00:17:08.132264Z","ts_recv":"2026-09-16T00:17:08.281614Z","payload":{"channel":"book","type":"update","data":[{"symbol":"BTC/USD","bids":[{"price":75721.3,"qty":0.0},{"price":75718.1,"qty":0.02051113}],"asks":[],"checksum":664222568,"timestamp":"2026-09-16T00:17:08.132264Z"}]}}
{"v":1,"kind":"tick","pair":"BTC/USD","channel":"book","ts_exchange":"2026-09-16T00:17:08.132606Z","ts_recv":"2026-09-16T00:17:08.293771Z","payload":{"channel":"book","type":"update","data":[{"symbol":"BTC/USD","bids":[{"price":75724.6,"qty":0.0},{"price":75717.5,"qty":0.00105736}],"asks":[],"checksum":1193345324,"timestamp":"2026-09-16T00:17:08.132606Z"}]}}
{"v":1,"kind":"tick","pair":"BTC/USD","channel":"book","ts_exchange":"2026-09-16T00:17:08.134144Z","ts_recv":"2026-09-16T00:17:08.295188Z","payload":{"channel":"book","type":"update","data":[{"symbol":"BTC/USD","bids":[],"asks":[{"price":75731.9,"qty":1.19035042}],"checksum":4083309421,"timestamp":"2026-09-16T00:17:08.134144Z"}]}}
{"v":1,"kind":"tick","pair":"BTC/USD","channel":"book","ts_exchange":"2026-09-16T00:17:08.136587Z","ts_recv":"2026-09-16T00:17:08.303643Z","payload":{"channel":"book","type":"update","data":[{"symbol":"BTC/USD","bids":[],"asks":[{"price":75731.9,"qty":1.211833}],"checksum":1193345324,"timestamp":"2026-09-16T00:17:08.136587Z"}]}}
{"v":1,"kind":"tick","pair":"BTC/USD","channel":"book","ts_exchange":"2026-09-16T00:17:08.147071Z","ts_recv":"2026-09-16T00:17:08.328345Z","payload":{"channel":"book","type":"update","data":[{"symbol":"BTC/USD","bids":[{"price":75723.0,"qty":0.99061375}],"asks":[],"checksum":407199762,"timestamp":"2026-09-16T00:17:08.147071Z"}]}}
{"v":1,"kind":"tick","pair":"BTC/USD","channel":"book","ts_exchange":"2026-09-16T00:17:08.149394Z","ts_recv":"2026-09-16T00:17:08.328660Z","payload":{"channel":"book","type":"update","data":[{"symbol":"BTC/USD","bids":[{"price":75723.1,"qty":0.2956982}],"asks":[],"checksum":1215479660,"timestamp":"2026-09-16T00:17:08.149394Z"}]}}
{"v":1,"kind":"tick","pair":"BTC/USD","channel":"book","ts_exchange":"2026-09-16T00:17:08.162512Z","ts_recv":"2026-09-16T00:17:08.345064Z","payload":{"channel":"book","type":"update","data":[{"symbol":"BTC/USD","bids":[{"price":75723.0,"qty":0.0},{"price":75718.1,"qty":0.02051113}],"asks":[],"checksum":3235869051,"timestamp":"2026-09-16T00:17:08.162512Z"}]}}
{"v":1,"kind":"tick","pair":"BTC/USD","channel":"book","ts_exchange":"2026-09-16T00:17:08.163859Z","ts_recv":"2026-09-16T00:17:08.353278Z","payload":{"channel":"book","type":"update","data":[{"symbol":"BTC/USD","bids":[{"price":75723.1,"qty":0.0},{"price":75717.5,"qty":0.00105736}],"asks":[],"checksum":1193345324,"timestamp":"2026-09-16T00:17:08.163859Z"}]}}
{"v":1,"kind":"tick","pair":"BTC/USD","channel":"book","ts_exchange":"2026-09-16T00:17:08.164612Z","ts_recv":"2026-09-16T00:17:08.354533Z","payload":{"channel":"book","type":"update","data":[{"symbol":"BTC/USD","bids":[],"asks":[{"price":75731.9,"qty":1.19035042}],"checksum":4083309421,"timestamp":"2026-09-16T00:17:08.164612Z"}]}}
{"v":1,"kind":"tick","pair":"BTC/USD","channel":"book","ts_exchange":"2026-09-16T00:17:08.164688Z","ts_recv":"2026-09-16T00:17:08.355755Z","payload":{"channel":"book","type":"update","data":[{"symbol":"BTC/USD","bids":[{"price":75725.8,"qty":0.0492301}],"asks":[],"checksum":445957557,"timestamp":"2026-09-16T00:17:08.164688Z"}]}}
{"v":1,"kind":"tick","pair":"BTC/USD","channel":"book","ts_exchange":"2026-09-16T00:17:08.167147Z","ts_recv":"2026-09-16T00:17:08.357044Z","payload":{"channel":"book","type":"update","data":[{"symbol":"BTC/USD","bids":[],"asks":[{"price":75731.9,"qty":1.211833}],"checksum":469497833,"timestamp":"2026-09-16T00:17:08.167147Z"}]}}
{"v":1,"kind":"tick","pair":"BTC/USD","channel":"book","ts_exchange":"2026-09-16T00:17:08.177204Z","ts_recv":"2026-09-16T00:17:08.376008Z","payload":{"channel":"book","type":"update","data":[{"symbol":"BTC/USD","bids":[{"price":75724.1,"qty":0.99061375}],"asks":[],"checksum":4080945466,"timestamp":"2026-09-16T00:17:08.177204Z"}]}}
{"v":1,"kind":"tick","pair":"BTC/USD","channel":"book","ts_exchange":"2026-09-16T00:17:08.179506Z","ts_recv":"2026-09-16T00:17:08.382589Z","payload":{"channel":"book","type":"update","data":[{"symbol":"BTC/USD","bids":[],"asks":[{"price":75731.9,"qty":1.19035042}],"checksum":2447522775,"timestamp":"2026-09-16T00:17:08.179506Z"}]}}
{"v":1,"kind":"tick","pair":"BTC/USD","channel":"book","ts_exchange":"2026-09-16T00:17:08.229327Z","ts_recv":"2026-09-16T00:17:08.416652Z","payload":{"channel":"book","type":"update","data":[{"symbol":"BTC/USD","bids":[{"price":75726.7,"qty":1.32053801}],"asks":[],"checksum":758265010,"timestamp":"2026-09-16T00:17:08.229327Z"}]}}
{"v":1,"kind":"tick","pair":"BTC/USD","channel":"book","ts_exchange":"2026-09-16T00:17:08.273537Z","ts_recv":"2026-09-16T00:17:08.416946Z","payload":{"channel":"book","type":"update","data":[{"symbol":"BTC/USD","bids":[{"price":75725.7,"qty":0.0},{"price":75719.6,"qty":0.000051},{"price":75725.9,"qty":0.01320355}],"asks":[],"checksum":808645980,"timestamp":"2026-09-16T00:17:08.273537Z"}]}}
{"v":1,"kind":"tick","pair":"BTC/USD","channel":"book","ts_exchange":"2026-09-16T00:17:08.459529Z","ts_recv":"2026-09-16T00:17:08.593261Z","payload":{"channel":"book","type":"update","data":[{"symbol":"BTC/USD","bids":[{"price":75719.9,"qty":0.0},{"price":75719.6,"qty":0.000051}],"asks":[],"checksum":662590769,"timestamp":"2026-09-16T00:17:08.459529Z"}]}}
{"v":1,"kind":"tick","pair":"BTC/USD","channel":"book","ts_exchange":"2026-09-16T00:17:08.470764Z","ts_recv":"2026-09-16T00:17:08.603485Z","payload":{"channel":"book","type":"update","data":[{"symbol":"BTC/USD","bids":[{"price":75724.1,"qty":0.0},{"price":75718.1,"qty":0.02051113}],"asks":[],"checksum":1001783790,"timestamp":"2026-09-16T00:17:08.470764Z"}]}}
{"v":1,"kind":"tick","pair":"BTC/USD","channel":"book","ts_exchange":"2026-09-16T00:17:08.471525Z","ts_recv":"2026-09-16T00:17:08.603573Z","payload":{"channel":"book","type":"update","data":[{"symbol":"BTC/USD","bids":[{"price":75725.8,"qty":0.0},{"price":75717.5,"qty":0.00105736}],"asks":[],"checksum":564803010,"timestamp":"2026-09-16T00:17:08.471525Z"}]}}
{"v":1,"kind":"tick","pair":"BTC/USD","channel":"book","ts_exchange":"2026-09-16T00:17:08.472363Z","ts_recv":"2026-09-16T00:17:08.613895Z","payload":{"channel":"book","type":"update","data":[{"symbol":"BTC/USD","bids":[{"price":75726.8,"qty":0.3941806}],"asks":[],"checksum":3949783169,"timestamp":"2026-09-16T00:17:08.472363Z"}]}}
{"v":1,"kind":"tick","pair":"BTC/USD","channel":"book","ts_exchange":"2026-09-16T00:17:08.473745Z","ts_recv":"2026-09-16T00:17:08.614132Z","payload":{"channel":"book","type":"update","data":[{"symbol":"BTC/USD","bids":[{"price":75731.8,"qty":0.01161095}],"asks":[],"checksum":482111894,"timestamp":"2026-09-16T00:17:08.473745Z"}]}}
{"v":1,"kind":"tick","pair":"BTC/USD","channel":"book","ts_exchange":"2026-09-16T00:17:08.478837Z","ts_recv":"2026-09-16T00:17:08.698014Z","payload":{"channel":"book","type":"update","data":[{"symbol":"BTC/USD","bids":[],"asks":[{"price":75731.9,"qty":1.14240829}],"checksum":121838127,"timestamp":"2026-09-16T00:17:08.478837Z"}]}}
{"v":1,"kind":"tick","pair":"BTC/USD","channel":"book","ts_exchange":"2026-09-16T00:17:08.478934Z","ts_recv":"2026-09-16T00:17:08.698670Z","payload":{"channel":"book","type":"update","data":[{"symbol":"BTC/USD","bids":[{"price":75731.8,"qty":0.36985133}],"asks":[],"checksum":1583603249,"timestamp":"2026-09-16T00:17:08.478934Z"}]}}
{"v":1,"kind":"tick","pair":"BTC/USD","channel":"book","ts_exchange":"2026-09-16T00:17:08.494286Z","ts_recv":"2026-09-16T00:17:08.733986Z","payload":{"channel":"book","type":"update","data":[{"symbol":"BTC/USD","bids":[{"price":75723.1,"qty":0.99061375}],"asks":[],"checksum":3495872370,"timestamp":"2026-09-16T00:17:08.494286Z"}]}}
{"v":1,"kind":"tick","pair":"BTC/USD","channel":"book","ts_exchange":"2026-09-16T00:17:08.541297Z","ts_recv":"2026-09-16T00:17:08.813562Z","payload":{"channel":"book","type":"update","data":[{"symbol":"BTC/USD","bids":[{"price":75726.7,"qty":0.0},{"price":75718.1,"qty":0.02051113}],"asks":[],"checksum":2235307607,"timestamp":"2026-09-16T00:17:08.541297Z"}]}}
{"v":1,"kind":"tick","pair":"BTC/USD","channel":"book","ts_exchange":"2026-09-16T00:17:08.542123Z","ts_recv":"2026-09-16T00:17:08.818150Z","payload":{"channel":"book","type":"update","data":[{"symbol":"BTC/USD","bids":[{"price":75727.8,"qty":1.32051879}],"asks":[],"checksum":3427182231,"timestamp":"2026-09-16T00:17:08.542123Z"}]}}
{"v":1,"kind":"tick","pair":"BTC/USD","channel":"book","ts_exchange":"2026-09-16T00:17:08.542164Z","ts_recv":"2026-09-16T00:17:08.819099Z","payload":{"channel":"book","type":"update","data":[{"symbol":"BTC/USD","bids":[{"price":75726.8,"qty":0.0},{"price":75718.1,"qty":0.02051113}],"asks":[],"checksum":3419735302,"timestamp":"2026-09-16T00:17:08.542164Z"}]}}
{"v":1,"kind":"tick","pair":"BTC/USD","channel":"book","ts_exchange":"2026-09-16T00:17:08.542234Z","ts_recv":"2026-09-16T00:17:08.819953Z","payload":{"channel":"book","type":"update","data":[{"symbol":"BTC/USD","bids":[{"price":75723.9,"qty":3.30146443}],"asks":[],"checksum":3520181766,"timestamp":"2026-09-16T00:17:08.542234Z"}]}}
{"v":1,"kind":"tick","pair":"BTC/USD","channel":"book","ts_exchange":"2026-09-16T00:17:08.542328Z","ts_recv":"2026-09-16T00:17:08.820799Z","payload":{"channel":"book","type":"update","data":[{"symbol":"BTC/USD","bids":[{"price":75720.2,"qty":3.30162786}],"asks":[],"checksum":386596484,"timestamp":"2026-09-16T00:17:08.542328Z"}]}}
{"v":1,"kind":"tick","pair":"BTC/USD","channel":"book","ts_exchange":"2026-09-16T00:17:08.543797Z","ts_recv":"2026-09-16T00:17:08.821584Z","payload":{"channel":"book","type":"update","data":[{"symbol":"BTC/USD","bids":[{"price":75724.0,"qty":1.28120056}],"asks":[],"checksum":3566926101,"timestamp":"2026-09-16T00:17:08.543797Z"}]}}
{"v":1,"kind":"tick","pair":"BTC/USD","channel":"book","ts_exchange":"2026-09-16T00:17:08.543816Z","ts_recv":"2026-09-16T00:17:08.822339Z","payload":{"channel":"book","type":"update","data":[{"symbol":"BTC/USD","bids":[{"price":75723.2,"qty":0.2956982}],"asks":[],"checksum":608997361,"timestamp":"2026-09-16T00:17:08.543816Z"}]}}
{"v":1,"kind":"tick","pair":"BTC/USD","channel":"book","ts_exchange":"2026-09-16T00:17:08.544019Z","ts_recv":"2026-09-16T00:17:08.823047Z","payload":{"channel":"book","type":"update","data":[{"symbol":"BTC/USD","bids":[{"price":75723.2,"qty":0.0},{"price":75723.1,"qty":0.99061375}],"asks":[],"checksum":3566926101,"timestamp":"2026-09-16T00:17:08.544019Z"}]}}
{"v":1,"kind":"tick","pair":"BTC/USD","channel":"book","ts_exchange":"2026-09-16T00:17:08.550040Z","ts_recv":"2026-09-16T00:17:08.828266Z","payload":{"channel":"book","type":"update","data":[{"symbol":"BTC/USD","bids":[{"price":75727.8,"qty":0.0},{"price":75720.2,"qty":3.30162786}],"asks":[],"checksum":845691135,"timestamp":"2026-09-16T00:17:08.550040Z"}]}}
{"v":1,"kind":"tick","pair":"BTC/USD","channel":"book","ts_exchange":"2026-09-16T00:17:08.552121Z","ts_recv":"2026-09-16T00:17:08.828769Z","payload":{"channel":"book","type":"update","data":[{"symbol":"BTC/USD","bids":[{"price":75731.8,"qty":0.35893555}],"asks":[],"checksum":333877646,"timestamp":"2026-09-16T00:17:08.552121Z"}]}}
{"v":1,"kind":"tick","pair":"BTC/USD","channel":"book","ts_exchange":"2026-09-16T00:17:08.569885Z","ts_recv":"2026-09-16T00:17:08.836960Z","payload":{"channel":"book","type":"update","data":[{"symbol":"BTC/USD","bids":[{"price":75725.9,"qty":0.0},{"price":75719.6,"qty":0.000051}],"asks":[],"checksum":1518330476,"timestamp":"2026-09-16T00:17:08.569885Z"}]}}
{"v":1,"kind":"tick","pair":"BTC/USD","channel":"book","ts_exchange":"2026-09-16T00:17:08.570667Z","ts_recv":"2026-09-16T00:17:08.838757Z","payload":{"channel":"book","type":"update","data":[{"symbol":"BTC/USD","bids":[{"price":75723.9,"qty":0.0},{"price":75718.1,"qty":0.02051113}],"asks":[],"checksum":935977609,"timestamp":"2026-09-16T00:17:08.570667Z"}]}}
{"v":1,"kind":"tick","pair":"BTC/USD","channel":"book","ts_exchange":"2026-09-16T00:17:08.570701Z","ts_recv":"2026-09-16T00:17:08.839592Z","payload":{"channel":"book","type":"update","data":[{"symbol":"BTC/USD","bids":[{"price":75720.2,"qty":0.0},{"price":75717.5,"qty":0.00105736}],"asks":[],"checksum":3580257183,"timestamp":"2026-09-16T00:17:08.570701Z"}]}}
{"v":1,"kind":"tick","pair":"BTC/USD","channel":"book","ts_exchange":"2026-09-16T00:17:08.571047Z","ts_recv":"2026-09-16T00:17:08.840401Z","payload":{"channel":"book","type":"update","data":[{"symbol":"BTC/USD","bids":[{"price":75724.0,"qty":0.0},{"price":75717.4,"qty":0.02988321}],"asks":[],"checksum":3571393813,"timestamp":"2026-09-16T00:17:08.571047Z"}]}}
{"v":1,"kind":"tick","pair":"BTC/USD","channel":"book","ts_exchange":"2026-09-16T00:17:08.572455Z","ts_recv":"2026-09-16T00:17:08.841368Z","payload":{"channel":"book","type":"update","data":[{"symbol":"BTC/USD","bids":[{"price":75723.2,"qty":0.2956982}],"asks":[],"checksum":238824479,"timestamp":"2026-09-16T00:17:08.572455Z"}]}}
{"v":1,"kind":"tick","pair":"BTC/USD","channel":"book","ts_exchange":"2026-09-16T00:17:08.578091Z","ts_recv":"2026-09-16T00:17:08.842381Z","payload":{"channel":"book","type":"update","data":[{"symbol":"BTC/USD","bids":[{"price":75724.2,"qty":0.0},{"price":75717.4,"qty":0.02988321}],"asks":[],"checksum":46848720,"timestamp":"2026-09-16T00:17:08.578091Z"}]}}
{"v":1,"kind":"tick","pair":"BTC/USD","channel":"book","ts_exchange":"2026-09-16T00:17:08.582841Z","ts_recv":"2026-09-16T00:17:08.843343Z","payload":{"channel":"book","type":"update","data":[{"symbol":"BTC/USD","bids":[{"price":75723.2,"qty":0.0},{"price":75717.0,"qty":0.00006024}],"asks":[],"checksum":3885554715,"timestamp":"2026-09-16T00:17:08.582841Z"}]}}
{"v":1,"kind":"tick","pair":"BTC/USD","channel":"book","ts_exchange":"2026-09-16T00:17:08.603720Z","ts_recv":"2026-09-16T00:17:08.880035Z","payload":{"channel":"book","type":"update","data":[{"symbol":"BTC/USD","bids":[{"price":75717.5,"qty":0.0},{"price":75716.7,"qty":0.1}],"asks":[],"checksum":1797341762,"timestamp":"2026-09-16T00:17:08.603720Z"}]}}
{"v":1,"kind":"tick","pair":"BTC/USD","channel":"book","ts_exchange":"2026-09-16T00:17:08.620829Z","ts_recv":"2026-09-16T00:17:08.889799Z","payload":{"channel":"book","type":"update","data":[{"symbol":"BTC/USD","bids":[],"asks":[{"price":75731.9,"qty":1.18651719}],"checksum":872262962,"timestamp":"2026-09-16T00:17:08.620829Z"}]}}
{"v":1,"kind":"tick","pair":"BTC/USD","channel":"book","ts_exchange":"2026-09-16T00:17:08.621714Z","ts_recv":"2026-09-16T00:17:08.890115Z","payload":{"channel":"book","type":"update","data":[{"symbol":"BTC/USD","bids":[{"price":75723.2,"qty":0.11117396}],"asks":[],"checksum":3984747350,"timestamp":"2026-09-16T00:17:08.621714Z"}]}}
{"v":1,"kind":"tick","pair":"BTC/USD","channel":"book","ts_exchange":"2026-09-16T00:17:08.622528Z","ts_recv":"2026-09-16T00:17:08.895982Z","payload":{"channel":"book","type":"update","data":[{"symbol":"BTC/USD","bids":[{"price":75723.2,"qty":0.40687216}],"asks":[],"checksum":3492912690,"timestamp":"2026-09-16T00:17:08.622528Z"}]}}
{"v":1,"kind":"tick","pair":"BTC/USD","channel":"book","ts_exchange":"2026-09-16T00:17:08.659955Z","ts_recv":"2026-09-16T00:17:08.963434Z","payload":{"channel":"book","type":"update","data":[{"symbol":"BTC/USD","bids":[{"price":75725.2,"qty":1.32056404}],"asks":[],"checksum":1641166151,"timestamp":"2026-09-16T00:17:08.659955Z"}]}}
{"v":1,"kind":"tick","pair":"BTC/USD","channel":"book","ts_exchange":"2026-09-16T00:17:08.660913Z","ts_recv":"2026-09-16T00:17:08.969574Z","payload":{"channel":"book","type":"update","data":[{"symbol":"BTC/USD","bids":[{"price":75723.2,"qty":0.11117396}],"asks":[],"checksum":4228635362,"timestamp":"2026-09-16T00:17:08.660913Z"}]}}
{"v":1,"kind":"tick","pair":"BTC/USD","channel":"book","ts_exchange":"2026-09-16T00:17:08.660987Z","ts_recv":"2026-09-16T00:17:08.970572Z","payload":{"channel":"book","type":"update","data":[{"symbol":"BTC/USD","bids":[{"price":75725.3,"qty":0.72308722}],"asks":[],"checksum":2569576575,"timestamp":"2026-09-16T00:17:08.660987Z"}]}}
{"v":1,"kind":"tick","pair":"BTC/USD","channel":"book","ts_exchange":"2026-09-16T00:17:08.685524Z","ts_recv":"2026-09-16T00:17:08.989151Z","payload":{"channel":"book","type":"update","data":[{"symbol":"BTC/USD","bids":[{"price":75725.3,"qty":0.0},{"price":75717.4,"qty":0.02988321}],"asks":[],"checksum":4228635362,"timestamp":"2026-09-16T00:17:08.685524Z"}]}}
{"v":1,"kind":"tick","pair":"BTC/USD","channel":"book","ts_exchange":"2026-09-16T00:17:08.906716Z","ts_recv":"2026-09-16T00:17:09.125719Z","payload":{"channel":"book","type":"update","data":[{"symbol":"BTC/USD","bids":[],"asks":[{"price":75733.5,"qty":0.06603139}],"checksum":2332330268,"timestamp":"2026-09-16T00:17:08.906716Z"}]}}
{"v":1,"kind":"tick","pair":"BTC/USD","channel":"book","ts_exchange":"2026-09-16T00:17:08.906736Z","ts_recv":"2026-09-16T00:17:09.130680Z","payload":{"channel":"book","type":"update","data":[{"symbol":"BTC/USD","bids":[],"asks":[{"price":75732.8,"qty":0.02641255}],"checksum":1063338724,"timestamp":"2026-09-16T00:17:08.906736Z"}]}}
{"v":1,"kind":"tick","pair":"BTC/USD","channel":"book","ts_exchange":"2026-09-16T00:17:08.911409Z","ts_recv":"2026-09-16T00:17:09.131591Z","payload":{"channel":"book","type":"update","data":[{"symbol":"BTC/USD","bids":[{"price":75723.1,"qty":0.0},{"price":75717.0,"qty":0.00006024}],"asks":[],"checksum":712723804,"timestamp":"2026-09-16T00:17:08.911409Z"}]}}
{"v":1,"kind":"tick","pair":"BTC/USD","channel":"book","ts_exchange":"2026-09-16T00:17:08.913160Z","ts_recv":"2026-09-16T00:17:09.139460Z","payload":{"channel":"book","type":"update","data":[{"symbol":"BTC/USD","bids":[{"price":75722.2,"qty":0.99061375}],"asks":[],"checksum":2137237474,"timestamp":"2026-09-16T00:17:08.913160Z"}]}}
{"v":1,"kind":"tick","pair":"BTC/USD","channel":"book","ts_exchange":"2026-09-16T00:17:08.913939Z","ts_recv":"2026-09-16T00:17:09.141065Z","payload":{"channel":"book","type":"update","data":[{"symbol":"BTC/USD","bids":[{"price":75731.8,"qty":0.36985133}],"asks":[],"checksum":1086315003,"timestamp":"2026-09-16T00:17:08.913939Z"}]}}
{"v":1,"kind":"tick","pair":"BTC/USD","channel":"book","ts_exchange":"2026-09-16T00:17:08.914096Z","ts_recv":"2026-09-16T00:17:09.141863Z","payload":{"channel":"book","type":"update","data":[{"symbol":"BTC/USD","bids":[{"price":75723.2,"qty":0.0},{"price":75717.0,"qty":0.00006024},{"price":75722.3,"qty":0.11117396}],"asks":[],"checksum":3810546309,"timestamp":"2026-09-16T00:17:08.914096Z"}]}}
{"v":1,"kind":"tick","pair":"BTC/USD","channel":"book","ts_exchange":"2026-09-16T00:17:08.916680Z","ts_recv":"2026-09-16T00:17:09.149163Z","payload":{"channel":"book","type":"update","data":[{"symbol":"BTC/USD","bids":[{"price":75731.8,"qty":0.35893555}],"asks":[],"checksum":3707514012,"timestamp":"2026-09-16T00:17:08.916680Z"}]}}
{"v":1,"kind":"tick","pair":"BTC/USD","channel":"book","ts_exchange":"2026-09-16T00:17:08.994943Z","ts_recv":"2026-09-16T00:17:09.168702Z","payload":{"channel":"book","type":"update","data":[{"symbol":"BTC/USD","bids":[{"price":75731.8,"qty":0.00069517}],"asks":[],"checksum":3450355868,"timestamp":"2026-09-16T00:17:08.994943Z"}]}}
{"v":1,"kind":"tick","pair":"BTC/USD","channel":"book","ts_exchange":"2026-09-16T00:17:08.997400Z","ts_recv":"2026-09-16T00:17:09.179735Z","payload":{"channel":"book","type":"update","data":[{"symbol":"BTC/USD","bids":[],"asks":[{"price":75731.9,"qty":1.20799977}],"checksum":2054344451,"timestamp":"2026-09-16T00:17:08.997400Z"}]}}
{"v":1,"kind":"tick","pair":"BTC/USD","channel":"book","ts_exchange":"2026-09-16T00:17:09.191199Z","ts_recv":"2026-09-16T00:17:09.327278Z","payload":{"channel":"book","type":"update","data":[{"symbol":"BTC/USD","bids":[{"price":75726.8,"qty":1.06491467}],"asks":[],"checksum":3136537795,"timestamp":"2026-09-16T00:17:09.191199Z"}]}}
{"v":1,"kind":"tick","pair":"BTC/USD","channel":"book","ts_exchange":"2026-09-16T00:17:09.193706Z","ts_recv":"2026-09-16T00:17:09.337945Z","payload":{"channel":"book","type":"update","data":[{"symbol":"BTC/USD","bids":[],"asks":[{"price":75731.9,"qty":1.18651719}],"checksum":825064317,"timestamp":"2026-09-16T00:17:09.193706Z"}]}}
{"v":1,"kind":"tick","pair":"BTC/USD","channel":"book","ts_exchange":"2026-09-16T00:17:09.228139Z","ts_recv":"2026-09-16T00:17:09.363396Z","payload":{"channel":"book","type":"update","data":[{"symbol":"BTC/USD","bids":[{"price":75722.0,"qty":3.30154895}],"asks":[],"checksum":2866172776,"timestamp":"2026-09-16T00:17:09.228139Z"}]}}
{"v":1,"kind":"tick","pair":"BTC/USD","channel":"book","ts_exchange":"2026-09-16T00:17:09.269356Z","ts_recv":"2026-09-16T00:17:09.407965Z","payload":{"channel":"book","type":"update","data":[{"symbol":"BTC/USD","bids":[],"asks":[{"price":75731.9,"qty":1.14240829}],"checksum":90011534,"timestamp":"2026-09-16T00:17:09.269356Z"}]}}
{"v":1,"kind":"tick","pair":"BTC/USD","channel":"book","ts_exchange":"2026-09-16T00:17:09.470729Z","ts_recv":"2026-09-16T00:17:09.597741Z","payload":{"channel":"book","type":"update","data":[{"symbol":"BTC/USD","bids":[{"price":75722.2,"qty":0.0},{"price":75718.1,"qty":0.02051113}],"asks":[],"checksum":3090469569,"timestamp":"2026-09-16T00:17:09.470729Z"}]}}
{"v":1,"kind":"tick","pair":"BTC/USD","channel":"book","ts_exchange":"2026-09-16T00:17:09.471594Z","ts_recv":"2026-09-16T00:17:09.610526Z","payload":{"channel":"book","type":"update","data":[{"symbol":"BTC/USD","bids":[{"price":75722.3,"qty":0.0},{"price":75717.4,"qty":0.02988321},{"price":75722.1,"qty":0.11117396}],"asks":[],"checksum":1791411211,"timestamp":"2026-09-16T00:17:09.471594Z"}]}}
{"v":1,"kind":"tick","pair":"BTC/USD","channel":"book","ts_exchange":"2026-09-16T00:17:09.473568Z","ts_recv":"2026-09-16T00:17:09.610649Z","payload":{"channel":"book","type":"update","data":[{"symbol":"BTC/USD","bids":[{"price":75731.8,"qty":0.01161095}],"asks":[],"checksum":1309788927,"timestamp":"2026-09-16T00:17:09.473568Z"}]}}
{"v":1,"kind":"tick","pair":"BTC/USD","channel":"book","ts_exchange":"2026-09-16T00:17:09.513342Z","ts_recv":"2026-09-16T00:17:09.668898Z","payload":{"channel":"book","type":"update","data":[{"symbol":"BTC/USD","bids":[{"price":75721.4,"qty":0.99061375}],"asks":[],"checksum":1490461159,"timestamp":"2026-09-16T00:17:09.513342Z"}]}}
{"v":1,"kind":"tick","pair":"BTC/USD","channel":"book","ts_exchange":"2026-09-16T00:17:09.515818Z","ts_recv":"2026-09-16T00:17:09.669108Z","payload":{"channel":"book","type":"update","data":[{"symbol":"BTC/USD","bids":[{"price":75731.8,"qty":0.00069517}],"asks":[],"checksum":3793895660,"timestamp":"2026-09-16T00:17:09.515818Z"}]}}
{"v":1,"kind":"tick","pair":"BTC/USD","channel":"book","ts_exchange":"2026-09-16T00:17:10.061570Z","ts_recv":"2026-09-16T00:17:10.191583Z","payload":{"channel":"book","type":"update","data":[{"symbol":"BTC/USD","bids":[{"price":75721.4,"qty":0.0},{"price":75718.1,"qty":0.02051113}],"asks":[],"checksum":1791411211,"timestamp":"2026-09-16T00:17:10.061570Z"}]}}
{"v":1,"kind":"tick","pair":"BTC/USD","channel":"book","ts_exchange":"2026-09-16T00:17:10.061772Z","ts_recv":"2026-09-16T00:17:10.193917Z","payload":{"channel":"book","type":"update","data":[{"symbol":"BTC/USD","bids":[{"price":75725.2,"qty":0.0},{"price":75717.4,"qty":0.02988321}],"asks":[],"checksum":4188554524,"timestamp":"2026-09-16T00:17:10.061772Z"}]}}
{"v":1,"kind":"tick","pair":"BTC/USD","channel":"book","ts_exchange":"2026-09-16T00:17:10.061804Z","ts_recv":"2026-09-16T00:17:10.195237Z","payload":{"channel":"book","type":"update","data":[{"symbol":"BTC/USD","bids":[{"price":75722.0,"qty":0.0},{"price":75717.2,"qty":3.30175775}],"asks":[],"checksum":2034790287,"timestamp":"2026-09-16T00:17:10.061804Z"}]}}
{"v":1,"kind":"tick","pair":"BTC/USD","channel":"book","ts_exchange":"2026-09-16T00:17:10.062009Z","ts_recv":"2026-09-16T00:17:10.205785Z","payload":{"channel":"book","type":"update","data":[{"symbol":"BTC/USD","bids":[],"asks":[{"price":75731.9,"qty":0.07749362}],"checksum":1766329612,"timestamp":"2026-09-16T00:17:10.062009Z"}]}}
{"v":1,"kind":"tick","pair":"BTC/USD","channel":"book","ts_exchange":"2026-09-16T00:17:10.062764Z","ts_recv":"2026-09-16T00:17:10.206404Z","payload":{"channel":"book","type":"update","data":[{"symbol":"BTC/USD","bids":[{"price":75726.0,"qty":1.32054956}],"asks":[],"checksum":3954129538,"timestamp":"2026-09-16T00:17:10.062764Z"}]}}
{"v":1,"kind":"tick","pair":"BTC/USD","channel":"book","ts_exchange":"2026-09-16T00:17:10.062918Z","ts_recv":"2026-09-16T00:17:10.207003Z","payload":{"channel":"book","type":"update","data":[{"symbol":"BTC/USD","bids":[{"price":75723.4,"qty":3.3015401}],"asks":[],"checksum":60761095,"timestamp":"2026-09-16T00:17:10.062918Z"}]}}
{"v":1,"kind":"tick","pair":"BTC/USD","channel":"book","ts_exchange":"2026-09-16T00:17:10.064314Z","ts_recv":"2026-09-16T00:17:10.208147Z","payload":{"channel":"book","type":"update","data":[{"symbol":"BTC/USD","bids":[{"price":75722.1,"qty":0.0},{"price":75717.2,"qty":3.30175775},{"price":75718.2,"qty":0.01320355}],"asks":[],"checksum":1223608674,"timestamp":"2026-09-16T00:17:10.064314Z"}]}}
{"v":1,"kind":"tick","pair":"BTC/USD","channel":"book","ts_exchange":"2026-09-16T00:17:10.064680Z","ts_recv":"2026-09-16T00:17:10.223167Z","payload":{"channel":"book","type":"update","data":[{"symbol":"BTC/USD","bids":[{"price":75726.0,"qty":0.0},{"price":75717.2,"qty":3.30175775}],"asks":[],"checksum":2466808787,"timestamp":"2026-09-16T00:17:10.064680Z"}]}}
{"v":1,"kind":"tick","pair":"BTC/USD","channel":"book","ts_exchange":"2026-09-16T00:17:10.065039Z","ts_recv":"2026-09-16T00:17:10.223354Z","payload":{"channel":"book","type":"update","data":[{"symbol":"BTC/USD","bids":[{"price":75731.8,"qty":0.01161095}],"asks":[],"checksum":3398981998,"timestamp":"2026-09-16T00:17:10.065039Z"}]}}
{"v":1,"kind":"tick","pair":"BTC/USD","channel":"book","ts_exchange":"2026-09-16T00:17:10.069425Z","ts_recv":"2026-09-16T00:17:10.223719Z","payload":{"channel":"book","type":"update","data":[{"symbol":"BTC/USD","bids":[{"price":75731.8,"qty":0.39022605}],"asks":[],"checksum":3625829414,"timestamp":"2026-09-16T00:17:10.069425Z"}]}}
{"v":1,"kind":"tick","pair":"BTC/USD","channel":"book","ts_exchange":"2026-09-16T00:17:10.069655Z","ts_recv":"2026-09-16T00:17:10.223832Z","payload":{"channel":"book","type":"update","data":[{"symbol":"BTC/USD","bids":[{"price":75717.2,"qty":0.0},{"price":75717.0,"qty":0.00006024}],"asks":[],"checksum":1257191510,"timestamp":"2026-09-16T00:17:10.069655Z"}]}}
{"v":1,"kind":"tick","pair":"BTC/USD","channel":"book","ts_exchange":"2026-09-16T00:17:10.069801Z","ts_recv":"2026-09-16T00:17:10.223951Z","payload":{"channel":"book","type":"update","data":[{"symbol":"BTC/USD","bids":[{"price":75723.4,"qty":0.000051}],"asks":[],"checksum":3021863923,"timestamp":"2026-09-16T00:17:10.069801Z"}]}}
{"v":1,"kind":"tick","pair":"BTC/USD","channel":"book","ts_exchange":"2026-09-16T00:17:10.071394Z","ts_recv":"2026-09-16T00:17:10.224299Z","payload":{"channel":"book","type":"update","data":[{"symbol":"BTC/USD","bids":[{"price":75720.4,"qty":3.30162009}],"asks":[],"checksum":3940855394,"timestamp":"2026-09-16T00:17:10.071394Z"}]}}
{"v":1,"kind":"tick","pair":"BTC/USD","channel":"book","ts_exchange":"2026-09-16T00:17:10.087144Z","ts_recv":"2026-09-16T00:17:10.233146Z","payload":{"channel":"book","type":"update","data":[{"symbol":"BTC/USD","bids":[{"price":75724.2,"qty":0.0537}],"asks":[],"checksum":2135780492,"timestamp":"2026-09-16T00:17:10.087144Z"}]}}
{"v":1,"kind":"tick","pair":"BTC/USD","channel":"book","ts_exchange":"2026-09-16T00:17:10.113500Z","ts_recv":"2026-09-16T00:17:10.253848Z","payload":{"channel":"book","type":"update","data":[{"symbol":"BTC/USD","bids":[{"price":75722.6,"qty":0.99061375}],"asks":[],"checksum":455791967,"timestamp":"2026-09-16T00:17:10.113500Z"}]}}
{"v":1,"kind":"tick","pair":"BTC/USD","channel":"book","ts_exchange":"2026-09-16T00:17:10.179908Z","ts_recv":"2026-09-16T00:17:10.313967Z","payload":{"channel":"book","type":"update","data":[{"symbol":"BTC/USD","bids":[{"price":75727.2,"qty":1.32057926}],"asks":[],"checksum":2648360882,"timestamp":"2026-09-16T00:17:10.179908Z"}]}}
{"v":1,"kind":"tick","pair":"BTC/USD","channel":"book","ts_exchange":"2026-09-16T00:17:10.226275Z","ts_recv":"2026-09-16T00:17:10.365466Z","payload":{"channel":"book","type":"update","data":[{"symbol":"BTC/USD","bids":[{"price":75718.2,"qty":0.0},{"price":75718.1,"qty":0.02051113},{"price":75724.3,"qty":0.013425}],"asks":[],"checksum":3280791231,"timestamp":"2026-09-16T00:17:10.226275Z"}]}}
{"v":1,"kind":"tick","pair":"ADA/USD","channel":"book","ts_exchange":"2026-09-16T00:17:10.257419Z","ts_recv":"2026-09-16T00:17:10.384273Z","payload":{"channel":"book","type":"update","data":[{"symbol":"ADA/USD","bids":[{"price":0.194648,"qty":0.0},{"price":0.194622,"qty":2569.07582444}],"asks":[],"checksum":3953654823,"timestamp":"2026-09-16T00:17:10.257419Z"}]}}
{"v":1,"kind":"tick","pair":"ADA/USD","channel":"book","ts_exchange":"2026-09-16T00:17:10.257453Z","ts_recv":"2026-09-16T00:17:10.385186Z","payload":{"channel":"book","type":"update","data":[{"symbol":"ADA/USD","bids":[{"price":0.194651,"qty":0.0},{"price":0.194615,"qty":2569.17503789}],"asks":[],"checksum":3384937085,"timestamp":"2026-09-16T00:17:10.257453Z"}]}}
{"v":1,"kind":"tick","pair":"ADA/USD","channel":"book","ts_exchange":"2026-09-16T00:17:10.258241Z","ts_recv":"2026-09-16T00:17:10.395473Z","payload":{"channel":"book","type":"update","data":[{"symbol":"ADA/USD","bids":[{"price":0.194652,"qty":0.0},{"price":0.194597,"qty":3034.02570007},{"price":0.194651,"qty":3079.1243748}],"asks":[],"checksum":2141849366,"timestamp":"2026-09-16T00:17:10.258241Z"}]}}
{"v":1,"kind":"tick","pair":"ADA/USD","channel":"book","ts_exchange":"2026-09-16T00:17:10.258369Z","ts_recv":"2026-09-16T00:17:10.396078Z","payload":{"channel":"book","type":"update","data":[{"symbol":"ADA/USD","bids":[{"price":0.194676,"qty":0.0},{"price":0.194597,"qty":3034.02570007}],"asks":[],"checksum":1857695466,"timestamp":"2026-09-16T00:17:10.258369Z"}]}}
{"v":1,"kind":"tick","pair":"ADA/USD","channel":"book","ts_exchange":"2026-09-16T00:17:10.258386Z","ts_recv":"2026-09-16T00:17:10.396586Z","payload":{"channel":"book","type":"update","data":[{"symbol":"ADA/USD","bids":[],"asks":[{"price":0.194798,"qty":0.0},{"price":0.194841,"qty":20349.83229176}],"checksum":4015015042,"timestamp":"2026-09-16T00:17:10.258386Z"}]}}
{"v":1,"kind":"tick","pair":"ADA/USD","channel":"book","ts_exchange":"2026-09-16T00:17:10.258613Z","ts_recv":"2026-09-16T00:17:10.399164Z","payload":{"channel":"book","type":"update","data":[{"symbol":"ADA/USD","bids":[{"price":0.194674,"qty":3008.7}],"asks":[],"checksum":3265192066,"timestamp":"2026-09-16T00:17:10.258613Z"}]}}
{"v":1,"kind":"tick","pair":"ADA/USD","channel":"book","ts_exchange":"2026-09-16T00:17:10.259550Z","ts_recv":"2026-09-16T00:17:10.404131Z","payload":{"channel":"book","type":"update","data":[{"symbol":"ADA/USD","bids":[],"asks":[{"price":0.194794,"qty":12245.46516048}],"checksum":1037091301,"timestamp":"2026-09-16T00:17:10.259550Z"}]}}
{"v":1,"kind":"tick","pair":"ADA/USD","channel":"book","ts_exchange":"2026-09-16T00:17:10.259671Z","ts_recv":"2026-09-16T00:17:10.404534Z","payload":{"channel":"book","type":"update","data":[{"symbol":"ADA/USD","bids":[],"asks":[{"price":0.194796,"qty":0.0},{"price":0.194841,"qty":20349.83229176}],"checksum":3665822717,"timestamp":"2026-09-16T00:17:10.259671Z"}]}}
{"v":1,"kind":"tick","pair":"ADA/USD","channel":"book","ts_exchange":"2026-09-16T00:17:10.260461Z","ts_recv":"2026-09-16T00:17:10.404916Z","payload":{"channel":"book","type":"update","data":[{"symbol":"ADA/USD","bids":[],"asks":[{"price":0.194793,"qty":4574.38997628}],"checksum":75533549,"timestamp":"2026-09-16T00:17:10.260461Z"}]}}
{"v":1,"kind":"tick","pair":"ADA/USD","channel":"book","ts_exchange":"2026-09-16T00:17:10.260685Z","ts_recv":"2026-09-16T00:17:10.405321Z","payload":{"channel":"book","type":"update","data":[{"symbol":"ADA/USD","bids":[],"asks":[{"price":0.194795,"qty":0.0},{"price":0.194841,"qty":20349.83229176},{"price":0.194793,"qty":7653.51435108}],"checksum":1004669594,"timestamp":"2026-09-16T00:17:10.260685Z"}]}}
{"v":1,"kind":"tick","pair":"ADA/USD","channel":"book","ts_exchange":"2026-09-16T00:17:10.261143Z","ts_recv":"2026-09-16T00:17:10.405720Z","payload":{"channel":"book","type":"update","data":[{"symbol":"ADA/USD","bids":[],"asks":[{"price":0.194794,"qty":0.0},{"price":0.194845,"qty":3008.7}],"checksum":1446323492,"timestamp":"2026-09-16T00:17:10.261143Z"}]}}
{"v":1,"kind":"tick","pair":"ADA/USD","channel":"book","ts_exchange":"2026-09-16T00:17:10.261184Z","ts_recv":"2026-09-16T00:17:10.406153Z","payload":{"channel":"book","type":"update","data":[{"symbol":"ADA/USD","bids":[{"price":0.194645,"qty":0.0},{"price":0.194597,"qty":3034.02570007}],"asks":[],"checksum":754162179,"timestamp":"2026-09-16T00:17:10.261184Z"}]}}
{"v":1,"kind":"tick","pair":"ADA/USD","channel":"book","ts_exchange":"2026-09-16T00:17:10.261674Z","ts_recv":"2026-09-16T00:17:10.406586Z","payload":{"channel":"book","type":"update","data":[{"symbol":"ADA/USD","bids":[],"asks":[{"price":0.194791,"qty":12245.46516048}],"checksum":2924736432,"timestamp":"2026-09-16T00:17:10.261674Z"}]}}
{"v":1,"kind":"tick","pair":"ADA/USD","channel":"book","ts_exchange":"2026-09-16T00:17:10.262012Z","ts_recv":"2026-09-16T00:17:10.407026Z","payload":{"channel":"book","type":"update","data":[{"symbol":"ADA/USD","bids":[],"asks":[{"price":0.194793,"qty":3079.1243748}],"checksum":26160773,"timestamp":"2026-09-16T00:17:10.262012Z"}]}}
{"v":1,"kind":"tick","pair":"ADA/USD","channel":"book","ts_exchange":"2026-09-16T00:17:10.262717Z","ts_recv":"2026-09-16T00:17:10.415649Z","payload":{"channel":"book","type":"update","data":[{"symbol":"ADA/USD","bids":[],"asks":[{"price":0.19479,"qty":4574.38997628}],"checksum":1337963177,"timestamp":"2026-09-16T00:17:10.262717Z"}]}}
{"v":1,"kind":"tick","pair":"ADA/USD","channel":"book","ts_exchange":"2026-09-16T00:17:10.263043Z","ts_recv":"2026-09-16T00:17:10.416311Z","payload":{"channel":"book","type":"update","data":[{"symbol":"ADA/USD","bids":[],"asks":[{"price":0.194791,"qty":0.0},{"price":0.194841,"qty":20349.83229176}],"checksum":1944972467,"timestamp":"2026-09-16T00:17:10.263043Z"}]}}
{"v":1,"kind":"tick","pair":"ADA/USD","channel":"book","ts_exchange":"2026-09-16T00:17:10.263664Z","ts_recv":"2026-09-16T00:17:10.417262Z","payload":{"channel":"book","type":"update","data":[{"symbol":"ADA/USD","bids":[],"asks":[{"price":0.194788,"qty":12245.46516048}],"checksum":3372463197,"timestamp":"2026-09-16T00:17:10.263664Z"}]}}
{"v":1,"kind":"tick","pair":"ADA/USD","channel":"book","ts_exchange":"2026-09-16T00:17:10.264303Z","ts_recv":"2026-09-16T00:17:10.417939Z","payload":{"channel":"book","type":"update","data":[{"symbol":"ADA/USD","bids":[],"asks":[{"price":0.19479,"qty":0.0},{"price":0.194841,"qty":20349.83229176}],"checksum":1745664412,"timestamp":"2026-09-16T00:17:10.264303Z"}]}}
{"v":1,"kind":"tick","pair":"ADA/USD","channel":"book","ts_exchange":"2026-09-16T00:17:10.264849Z","ts_recv":"2026-09-16T00:17:10.418122Z","payload":{"channel":"book","type":"update","data":[{"symbol":"ADA/USD","bids":[],"asks":[{"price":0.194787,"qty":3655.2713504}],"checksum":2446414629,"timestamp":"2026-09-16T00:17:10.264849Z"}]}}
{"v":1,"kind":"tick","pair":"ADA/USD","channel":"book","ts_exchange":"2026-09-16T00:17:10.265631Z","ts_recv":"2026-09-16T00:17:10.426958Z","payload":{"channel":"book","type":"update","data":[{"symbol":"ADA/USD","bids":[],"asks":[{"price":0.194788,"qty":0.0},{"price":0.194841,"qty":20349.83229176}],"checksum":1608455507,"timestamp":"2026-09-16T00:17:10.265631Z"}]}}
{"v":1,"kind":"tick","pair":"ADA/USD","channel":"book","ts_exchange":"2026-09-16T00:17:10.266133Z","ts_recv":"2026-09-16T00:17:10.427397Z","payload":{"channel":"book","type":"update","data":[{"symbol":"ADA/USD","bids":[{"price":0.194673,"qty":0.0},{"price":0.194586,"qty":2569.55130738}],"asks":[],"checksum":180798884,"timestamp":"2026-09-16T00:17:10.266133Z"}]}}
{"v":1,"kind":"tick","pair":"ADA/USD","channel":"book","ts_exchange":"2026-09-16T00:17:10.266399Z","ts_recv":"2026-09-16T00:17:10.427712Z","payload":{"channel":"book","type":"update","data":[{"symbol":"ADA/USD","bids":[],"asks":[{"price":0.194787,"qty":6299.3512383}],"checksum":2409461591,"timestamp":"2026-09-16T00:17:10.266399Z"}]}}
{"v":1,"kind":"tick","pair":"ADA/USD","channel":"book","ts_exchange":"2026-09-16T00:17:10.266416Z","ts_recv":"2026-09-16T00:17:10.428020Z","payload":{"channel":"book","type":"update","data":[{"symbol":"ADA/USD","bids":[],"asks":[{"price":0.194787,"qty":2644.0798879}],"checksum":2662913470,"timestamp":"2026-09-16T00:17:10.266416Z"}]}}
{"v":1,"kind":"tick","pair":"ADA/USD","channel":"book","ts_exchange":"2026-09-16T00:17:10.267325Z","ts_recv":"2026-09-16T00:17:10.428335Z","payload":{"channel":"book","type":"update","data":[{"symbol":"ADA/USD","bids":[{"price":0.194652,"qty":100.0}],"asks":[],"checksum":1052484618,"timestamp":"2026-09-16T00:17:10.267325Z"}]}}
{"v":1,"kind":"tick","pair":"ADA/USD","channel":"book","ts_exchange":"2026-09-16T00:17:10.269188Z","ts_recv":"2026-09-16T00:17:10.428639Z","payload":{"channel":"book","type":"update","data":[{"symbol":"ADA/USD","bids":[],"asks":[{"price":0.194814,"qty":0.0},{"price":0.194845,"qty":3008.7}],"checksum":4286508871,"timestamp":"2026-09-16T00:17:10.269188Z"}]}}
{"v":1,"kind":"tick","pair":"ADA/USD","channel":"book","ts_exchange":"2026-09-16T00:17:10.274455Z","ts_recv":"2026-09-16T00:17:10.434211Z","payload":{"channel":"book","type":"update","data":[{"symbol":"ADA/USD","bids":[],"asks":[{"price":0.194806,"qty":3451.71933202}],"checksum":237621514,"timestamp":"2026-09-16T00:17:10.274455Z"}]}}
{"v":1,"kind":"tick","pair":"ADA/USD","channel":"book","ts_exchange":"2026-09-16T00:17:10.362010Z","ts_recv":"2026-09-16T00:17:10.496039Z","payload":{"channel":"book","type":"update","data":[{"symbol":"ADA/USD","bids":[{"price":0.194652,"qty":1299.62497203}],"asks":[],"checksum":197734480,"timestamp":"2026-09-16T00:17:10.362010Z"}]}}
{"v":1,"kind":"tick","pair":"ADA/USD","channel":"book","ts_exchange":"2026-09-16T00:17:10.362258Z","ts_recv":"2026-09-16T00:17:10.496314Z","payload":{"channel":"book","type":"update","data":[{"symbol":"ADA/USD","bids":[{"price":0.194638,"qty":2568.86111244}],"asks":[],"checksum":322845123,"timestamp":"2026-09-16T00:17:10.362258Z"}]}}
{"v":1,"kind":"tick","pair":"ADA/USD","channel":"book","ts_exchange":"2026-09-16T00:17:10.366654Z","ts_recv":"2026-09-16T00:17:10.506332Z","payload":{"channel":"book","type":"update","data":[{"symbol":"ADA/USD","bids":[],"asks":[{"price":0.194829,"qty":0.0},{"price":0.194871,"qty":1030.33822061},{"price":0.194813,"qty":2567.87495462}],"checksum":2329362493,"timestamp":"2026-09-16T00:17:10.366654Z"}]}}
{"v":1,"kind":"tick","pair":"ADA/USD","channel":"book","ts_exchange":"2026-09-16T00:17:10.415909Z","ts_recv":"2026-09-16T00:17:10.541620Z","payload":{"channel":"book","type":"update","data":[{"symbol":"ADA/USD","bids":[],"asks":[{"price":0.194813,"qty":0.0},{"price":0.194871,"qty":1030.33822061},{"price":0.194829,"qty":2567.87488172}],"checksum":3867703746,"timestamp":"2026-09-16T00:17:10.415909Z"}]}}
{"v":1,"kind":"tick","pair":"ADA/USD","channel":"book","ts_exchange":"2026-09-16T00:17:10.430803Z","ts_recv":"2026-09-16T00:17:10.569659Z","payload":{"channel":"book","type":"update","data":[{"symbol":"ADA/USD","bids":[],"asks":[{"price":0.194793,"qty":0.0},{"price":0.194871,"qty":1030.33822061},{"price":0.194786,"qty":3079.1243748}],"checksum":3552847091,"timestamp":"2026-09-16T00:17:10.430803Z"}]}}
{"v":1,"kind":"tick","pair":"ADA/USD","channel":"book","ts_exchange":"2026-09-16T00:17:10.431565Z","ts_recv":"2026-09-16T00:17:10.576578Z","payload":{"channel":"book","type":"update","data":[{"symbol":"ADA/USD","bids":[],"asks":[{"price":0.194785,"qty":1708.37647242}],"checksum":634186422,"timestamp":"2026-09-16T00:17:10.431565Z"}]}}
{"v":1,"kind":"tick","pair":"BTC/USD","channel":"book","ts_exchange":"2026-09-16T00:17:10.470441Z","ts_recv":"2026-09-16T00:17:10.607615Z","payload":{"channel":"book","type":"update","data":[{"symbol":"BTC/USD","bids":[{"price":75722.6,"qty":0.0},{"price":75718.1,"qty":0.02051113}],"asks":[],"checksum":1828850702,"timestamp":"2026-09-16T00:17:10.470441Z"}]}}
{"v":1,"kind":"tick","pair":"BTC/USD","channel":"book","ts_exchange":"2026-09-16T00:17:10.470882Z","ts_recv":"2026-09-16T00:17:10.616185Z","payload":{"channel":"book","type":"update","data":[{"symbol":"BTC/USD","bids":[{"price":75726.8,"qty":0.0},{"price":75717.4,"qty":0.02988321}],"asks":[],"checksum":4153410796,"timestamp":"2026-09-16T00:17:10.470882Z"}]}}
{"v":1,"kind":"tick","pair":"BTC/USD","channel":"book","ts_exchange":"2026-09-16T00:17:10.513212Z","ts_recv":"2026-09-16T00:17:10.643767Z","payload":{"channel":"book","type":"update","data":[{"symbol":"BTC/USD","bids":[{"price":75724.4,"qty":0.99061375}],"asks":[],"checksum":3408941218,"timestamp":"2026-09-16T00:17:10.513212Z"}]}}
{"v":1,"kind":"tick","pair":"ADA/USD","channel":"book","ts_exchange":"2026-09-16T00:17:10.558742Z","ts_recv":"2026-09-16T00:17:10.716487Z","payload":{"channel":"book","type":"update","data":[{"symbol":"ADA/USD","bids":[{"price":0.194651,"qty":0.0},{"price":0.194597,"qty":3034.02570007},{"price":0.194653,"qty":3079.1243748}],"asks":[],"checksum":469513457,"timestamp":"2026-09-16T00:17:10.558742Z"}]}}
{"v":1,"kind":"tick","pair":"ADA/USD","channel":"book","ts_exchange":"2026-09-16T00:17:10.559746Z","ts_recv":"2026-09-16T00:17:10.717939Z","payload":{"channel":"book","type":"update","data":[{"symbol":"ADA/USD","bids":[{"price":0.194674,"qty":0.0},{"price":0.194597,"qty":3034.02570007}],"asks":[],"checksum":3254537954,"timestamp":"2026-09-16T00:17:10.559746Z"}]}}
{"v":1,"kind":"tick","pair":"ADA/USD","channel":"book","ts_exchange":"2026-09-16T00:17:10.559930Z","ts_recv":"2026-09-16T00:17:10.718248Z","payload":{"channel":"book","type":"update","data":[{"symbol":"ADA/USD","bids":[{"price":0.194654,"qty":3008.7}],"asks":[],"checksum":821844227,"timestamp":"2026-09-16T00:17:10.559930Z"}]}}
{"v":1,"kind":"tick","pair":"BTC/USD","channel":"book","ts_exchange":"2026-09-16T00:17:10.563952Z","ts_recv":"2026-09-16T00:17:10.725927Z","payload":{"channel":"book","type":"update","data":[{"symbol":"BTC/USD","bids":[{"price":75727.2,"qty":0.000051}],"asks":[],"checksum":3530440533,"timestamp":"2026-09-16T00:17:10.563952Z"}]}}
{"v":1,"kind":"tick","pair":"BTC/USD","channel":"book","ts_exchange":"2026-09-16T00:17:10.564779Z","ts_recv":"2026-09-16T00:17:10.726091Z","payload":{"channel":"book","type":"update","data":[{"symbol":"BTC/USD","bids":[{"price":75726.1,"qty":1.32054751}],"asks":[],"checksum":226955510,"timestamp":"2026-09-16T00:17:10.564779Z"}]}}
{"v":1,"kind":"tick","pair":"BTC/USD","channel":"book","ts_exchange":"2026-09-16T00:17:10.564940Z","ts_recv":"2026-09-16T00:17:10.726242Z","payload":{"channel":"book","type":"update","data":[{"symbol":"BTC/USD","bids":[{"price":75724.0,"qty":3.30145933}],"asks":[],"checksum":1664639888,"timestamp":"2026-09-16T00:17:10.564940Z"}]}}
{"v":1,"kind":"tick","pair":"BTC/USD","channel":"book","ts_exchange":"2026-09-16T00:17:10.566274Z","ts_recv":"2026-09-16T00:17:10.726389Z","payload":{"channel":"book","type":"update","data":[{"symbol":"BTC/USD","bids":[{"price":75731.8,"qty":0.37931027}],"asks":[],"checksum":997627984,"timestamp":"2026-09-16T00:17:10.566274Z"}]}}
{"v":1,"kind":"tick","pair":"BTC/USD","channel":"book","ts_exchange":"2026-09-16T00:17:10.569539Z","ts_recv":"2026-09-16T00:17:10.736181Z","payload":{"channel":"book","type":"update","data":[{"symbol":"BTC/USD","bids":[{"price":75731.8,"qty":0.39022605}],"asks":[],"checksum":1664639888,"timestamp":"2026-09-16T00:17:10.569539Z"}]}}
{"v":1,"kind":"tick","pair":"BTC/USD","channel":"book","ts_exchange":"2026-09-16T00:17:10.580024Z","ts_recv":"2026-09-16T00:17:10.749972Z","payload":{"channel":"book","type":"update","data":[{"symbol":"BTC/USD","bids":[{"price":75726.1,"qty":0.0},{"price":75719.6,"qty":0.000051}],"asks":[],"checksum":2688512244,"timestamp":"2026-09-16T00:17:10.580024Z"}]}}
{"v":1,"kind":"tick","pair":"BTC/USD","channel":"book","ts_exchange":"2026-09-16T00:17:10.580149Z","ts_recv":"2026-09-16T00:17:10.750081Z","payload":{"channel":"book","type":"update","data":[{"symbol":"BTC/USD","bids":[{"price":75724.0,"qty":0.0},{"price":75718.1,"qty":0.02051113}],"asks":[],"checksum":3530440533,"timestamp":"2026-09-16T00:17:10.580149Z"}]}}
{"v":1,"kind":"tick","pair":"BTC/USD","channel":"book","ts_exchange":"2026-09-16T00:17:10.582506Z","ts_recv":"2026-09-16T00:17:10.759939Z","payload":{"channel":"book","type":"update","data":[{"symbol":"BTC/USD","bids":[{"price":75731.8,"qty":0.37931027}],"asks":[],"checksum":262967473,"timestamp":"2026-09-16T00:17:10.582506Z"}]}}
{"v":1,"kind":"tick","pair":"BTC/USD","channel":"book","ts_exchange":"2026-09-16T00:17:10.587201Z","ts_recv":"2026-09-16T00:17:10.768569Z","payload":{"channel":"book","type":"update","data":[{"symbol":"BTC/USD","bids":[{"price":75720.4,"qty":0.0},{"price":75717.4,"qty":0.02988321}],"asks":[],"checksum":990838062,"timestamp":"2026-09-16T00:17:10.587201Z"}]}}
{"v":1,"kind":"tick","pair":"ADA/USD","channel":"book","ts_exchange":"2026-09-16T00:17:10.596323Z","ts_recv":"2026-09-16T00:17:10.781155Z","payload":{"channel":"book","type":"update","data":[{"symbol":"ADA/USD","bids":[],"asks":[{"price":0.194786,"qty":0.0},{"price":0.194845,"qty":3008.7},{"price":0.194784,"qty":3079.1243748}],"checksum":3790636191,"timestamp":"2026-09-16T00:17:10.596323Z"}]}}
{"v":1,"kind":"tick","pair":"ADA/USD","channel":"book","ts_exchange":"2026-09-16T00:17:10.597067Z","ts_recv":"2026-09-16T00:17:10.782450Z","payload":{"channel":"book","type":"update","data":[{"symbol":"ADA/USD","bids":[],"asks":[{"price":0.194785,"qty":0.0},{"price":0.194845,"qty":3008.7}],"checksum":833514324,"timestamp":"2026-09-16T00:17:10.597067Z"}]}}
{"v":1,"kind":"tick","pair":"ADA/USD","channel":"book","ts_exchange":"2026-09-16T00:17:10.597266Z","ts_recv":"2026-09-16T00:17:10.790134Z","payload":{"channel":"book","type":"update","data":[{"symbol":"ADA/USD","bids":[],"asks":[{"price":0.194783,"qty":1708.37647242}],"checksum":777525687,"timestamp":"2026-09-16T00:17:10.597266Z"}]}}
{"v":1,"kind":"tick","pair":"BTC/USD","channel":"book","ts_exchange":"2026-09-16T00:17:10.606802Z","ts_recv":"2026-09-16T00:17:10.797012Z","payload":{"channel":"book","type":"update","data":[{"symbol":"BTC/USD","bids":[{"price":75717.5,"qty":0.00105736}],"asks":[],"checksum":3156203173,"timestamp":"2026-09-16T00:17:10.606802Z"}]}}
{"v":1,"kind":"tick","pair":"BTC/USD","channel":"book","ts_exchange":"2026-09-16T00:17:10.620538Z","ts_recv":"2026-09-16T00:17:10.806442Z","payload":{"channel":"book","type":"update","data":[{"symbol":"BTC/USD","bids":[{"price":75724.4,"qty":0.0},{"price":75717.4,"qty":0.02988321}],"asks":[],"checksum":753678697,"timestamp":"2026-09-16T00:17:10.620538Z"}]}}
{"v":1,"kind":"tick","pair":"BTC/USD","channel":"book","ts_exchange":"2026-09-16T00:17:10.663340Z","ts_recv":"2026-09-16T00:17:10.817597Z","payload":{"channel":"book","type":"update","data":[{"symbol":"BTC/USD","bids":[{"price":75723.6,"qty":0.99061375}],"asks":[],"checksum":1346484475,"timestamp":"2026-09-16T00:17:10.663340Z"}]}}
{"v":1,"kind":"tick","pair":"BTC/USD","channel":"book","ts_exchange":"2026-09-16T00:17:10.665563Z","ts_recv":"2026-09-16T00:17:10.826844Z","payload":{"channel":"book","type":"update","data":[{"symbol":"BTC/USD","bids":[],"asks":[{"price":75731.9,"qty":0.0989762}],"checksum":978957029,"timestamp":"2026-09-16T00:17:10.665563Z"}]}}
{"v":1,"kind":"tick","pair":"BTC/USD","channel":"book","ts_exchange":"2026-09-16T00:17:10.668932Z","ts_recv":"2026-09-16T00:17:10.828162Z","payload":{"channel":"book","type":"update","data":[{"symbol":"BTC/USD","bids":[],"asks":[{"price":75731.9,"qty":0.07749362}],"checksum":1346484475,"timestamp":"2026-09-16T00:17:10.668932Z"}]}}
{"v":1,"kind":"tick","pair":"BTC/USD","channel":"book","ts_exchange":"2026-09-16T00:17:10.742492Z","ts_recv":"2026-09-16T00:17:10.891178Z","payload":{"channel":"book","type":"update","data":[{"symbol":"BTC/USD","bids":[{"price":75728.4,"qty":1.06491467}],"asks":[],"checksum":1336683282,"timestamp":"2026-09-16T00:17:10.742492Z"}]}}
{"v":1,"kind":"tick","pair":"BTC/USD","channel":"book","ts_exchange":"2026-09-16T00:17:10.745243Z","ts_recv":"2026-09-16T00:17:10.892026Z","payload":{"channel":"book","type":"update","data":[{"symbol":"BTC/USD","bids":[{"price":75731.8,"qty":0.39022605}],"asks":[],"checksum":2456716534,"timestamp":"2026-09-16T00:17:10.745243Z"}]}}
{"v":1,"kind":"tick","pair":"ADA/USD","channel":"book","ts_exchange":"2026-09-16T00:17:10.838211Z","ts_recv":"2026-09-16T00:17:10.976699Z","payload":{"channel":"book","type":"update","data":[{"symbol":"ADA/USD","bids":[],"asks":[{"price":0.194784,"qty":0.0},{"price":0.194845,"qty":3008.7},{"price":0.194782,"qty":3079.1243748}],"checksum":2622572524,"timestamp":"2026-09-16T00:17:10.838211Z"}]}}
{"v":1,"kind":"tick","pair":"ADA/USD","channel":"book","ts_exchange":"2026-09-16T00:17:10.838948Z","ts_recv":"2026-09-16T00:17:10.976874Z","payload":{"channel":"book","type":"update","data":[{"symbol":"ADA/USD","bids":[],"asks":[{"price":0.194783,"qty":0.0},{"price":0.194845,"qty":3008.7}],"checksum":4080036131,"timestamp":"2026-09-16T00:17:10.838948Z"}]}}
{"v":1,"kind":"tick","pair":"ADA/USD","channel":"book","ts_exchange":"2026-09-16T00:17:10.839046Z","ts_recv":"2026-09-16T00:17:10.977056Z","payload":{"channel":"book","type":"update","data":[{"symbol":"ADA/USD","bids":[],"asks":[{"price":0.194781,"qty":1708.37647242}],"checksum":1715283105,"timestamp":"2026-09-16T00:17:10.839046Z"}]}}
{"v":1,"kind":"tick","pair":"BTC/USD","channel":"book","ts_exchange":"2026-09-16T00:17:10.915419Z","ts_recv":"2026-09-16T00:17:11.042954Z","payload":{"channel":"book","type":"update","data":[{"symbol":"BTC/USD","bids":[{"price":75731.8,"qty":0.01161095}],"asks":[],"checksum":2984581770,"timestamp":"2026-09-16T00:17:10.915419Z"}]}}
{"v":1,"kind":"tick","pair":"BTC/USD","channel":"book","ts_exchange":"2026-09-16T00:17:10.917049Z","ts_recv":"2026-09-16T00:17:11.045773Z","payload":{"channel":"book","type":"update","data":[{"symbol":"BTC/USD","bids":[{"price":75723.7,"qty":0.29571343}],"asks":[],"checksum":3316093293,"timestamp":"2026-09-16T00:17:10.917049Z"}]}}
{"v":1,"kind":"tick","pair":"ADA/USD","channel":"book","ts_exchange":"2026-09-16T00:17:10.954692Z","ts_recv":"2026-09-16T00:17:11.084649Z","payload":{"channel":"book","type":"update","data":[{"symbol":"ADA/USD","bids":[{"price":0.194653,"qty":0.0},{"price":0.194597,"qty":3034.02570007},{"price":0.194655,"qty":3079.1243748}],"asks":[],"checksum":702611021,"timestamp":"2026-09-16T00:17:10.954692Z"}]}}
{"v":1,"kind":"tick","pair":"ADA/USD","channel":"book","ts_exchange":"2026-09-16T00:17:10.955702Z","ts_recv":"2026-09-16T00:17:11.084834Z","payload":{"channel":"book","type":"update","data":[{"symbol":"ADA/USD","bids":[{"price":0.194656,"qty":3008.7}],"asks":[],"checksum":2103757689,"timestamp":"2026-09-16T00:17:10.955702Z"}]}}
{"v":1,"kind":"tick","pair":"ADA/USD","channel":"book","ts_exchange":"2026-09-16T00:17:11.005324Z","ts_recv":"2026-09-16T00:17:11.131474Z","payload":{"channel":"book","type":"update","data":[{"symbol":"ADA/USD","bids":[],"asks":[{"price":0.194782,"qty":0.0},{"price":0.194845,"qty":3008.7},{"price":0.19478,"qty":3079.1243748}],"checksum":2892502757,"timestamp":"2026-09-16T00:17:11.005324Z"}]}}
{"v":1,"kind":"tick","pair":"ADA/USD","channel":"book","ts_exchange":"2026-09-16T00:17:11.006043Z","ts_recv":"2026-09-16T00:17:11.131720Z","payload":{"channel":"book","type":"update","data":[{"symbol":"ADA/USD","bids":[],"asks":[{"price":0.194781,"qty":0.0},{"price":0.194845,"qty":3008.7}],"checksum":523467497,"timestamp":"2026-09-16T00:17:11.006043Z"}]}}
{"v":1,"kind":"tick","pair":"ADA/USD","channel":"book","ts_exchange":"2026-09-16T00:17:11.056230Z","ts_recv":"2026-09-16T00:17:11.181602Z","payload":{"channel":"book","type":"update","data":[{"symbol":"ADA/USD","bids":[{"price":0.194654,"qty":0.0},{"price":0.194615,"qty":2569.17503789}],"asks":[],"checksum":2944003378,"timestamp":"2026-09-16T00:17:11.056230Z"}]}}
{"v":1,"kind":"tick","pair":"ADA/USD","channel":"book","ts_exchange":"2026-09-16T00:17:11.136442Z","ts_recv":"2026-09-16T00:17:11.264957Z","payload":{"channel":"book","type":"update","data":[{"symbol":"ADA/USD","bids":[{"price":0.194655,"qty":0.0},{"price":0.194597,"qty":3034.02570007},{"price":0.194657,"qty":3079.1243748}],"asks":[],"checksum":4116961520,"timestamp":"2026-09-16T00:17:11.136442Z"}]}}
{"v":1,"kind":"tick","pair":"ADA/USD","channel":"book","ts_exchange":"2026-09-16T00:17:11.136727Z","ts_recv":"2026-09-16T00:17:11.265662Z","payload":{"channel":"book","type":"update","data":[{"symbol":"ADA/USD","bids":[],"asks":[{"price":0.19478,"qty":0.0},{"price":0.194871,"qty":1030.33822061},{"price":0.194786,"qty":3079.1243748}],"checksum":939383431,"timestamp":"2026-09-16T00:17:11.136727Z"}]}}
{"v":1,"kind":"tick","pair":"ADA/USD","channel":"book","ts_exchange":"2026-09-16T00:17:11.137283Z","ts_recv":"2026-09-16T00:17:11.266043Z","payload":{"channel":"book","type":"update","data":[{"symbol":"ADA/USD","bids":[{"price":0.194658,"qty":3008.7}],"asks":[],"checksum":3063458079,"timestamp":"2026-09-16T00:17:11.137283Z"}]}}
{"v":1,"kind":"tick","pair":"ADA/USD","channel":"book","ts_exchange":"2026-09-16T00:17:11.137548Z","ts_recv":"2026-09-16T00:17:11.266735Z","payload":{"channel":"book","type":"update","data":[{"symbol":"ADA/USD","bids":[],"asks":[{"price":0.194785,"qty":1708.37647242}],"checksum":1083205466,"timestamp":"2026-09-16T00:17:11.137548Z"}]}}
{"v":1,"kind":"tick","pair":"ADA/USD","channel":"book","ts_exchange":"2026-09-16T00:17:11.138924Z","ts_recv":"2026-09-16T00:17:11.267185Z","payload":{"channel":"book","type":"update","data":[{"symbol":"ADA/USD","bids":[{"price":0.194677,"qty":3388.611118}],"asks":[],"checksum":1144156493,"timestamp":"2026-09-16T00:17:11.138924Z"}]}}
{"v":1,"kind":"tick","pair":"ADA/USD","channel":"book","ts_exchange":"2026-09-16T00:17:11.147039Z","ts_recv":"2026-09-16T00:17:11.273266Z","payload":{"channel":"book","type":"update","data":[{"symbol":"ADA/USD","bids":[{"price":0.194677,"qty":0.0},{"price":0.194622,"qty":2569.07582444}],"asks":[],"checksum":1083205466,"timestamp":"2026-09-16T00:17:11.147039Z"}]}}
{"v":1,"kind":"tick","pair":"BTC/USD","channel":"book","ts_exchange":"2026-09-16T00:17:11.170601Z","ts_recv":"2026-09-16T00:17:11.299868Z","payload":{"channel":"book","type":"update","data":[{"symbol":"BTC/USD","bids":[{"price":75726.2,"qty":1.3205466}],"asks":[],"checksum":3666284075,"timestamp":"2026-09-16T00:17:11.170601Z"}]}}
{"v":1,"kind":"tick","pair":"ADA/USD","channel":"book","ts_exchange":"2026-09-16T00:17:11.237763Z","ts_recv":"2026-09-16T00:17:11.370913Z","payload":{"channel":"book","type":"update","data":[{"symbol":"ADA/USD","bids":[{"price":0.194656,"qty":0.0},{"price":0.194615,"qty":2569.17503789}],"asks":[],"checksum":728430899,"timestamp":"2026-09-16T00:17:11.237763Z"}]}}
{"v":1,"kind":"tick","pair":"ADA/USD","channel":"book","ts_exchange":"2026-09-16T00:17:11.393615Z","ts_recv":"2026-09-16T00:17:11.581457Z","payload":{"channel":"book","type":"update","data":[{"symbol":"ADA/USD","bids":[{"price":0.194657,"qty":0.0},{"price":0.194597,"qty":3034.02570007},{"price":0.194659,"qty":3079.1243748}],"asks":[],"checksum":1329134979,"timestamp":"2026-09-16T00:17:11.393615Z"}]}}
{"v":1,"kind":"tick","pair":"ADA/USD","channel":"book","ts_exchange":"2026-09-16T00:17:11.393820Z","ts_recv":"2026-09-16T00:17:11.581545Z","payload":{"channel":"book","type":"update","data":[{"symbol":"ADA/USD","bids":[],"asks":[{"price":0.194786,"qty":0.0},{"price":0.194845,"qty":3008.7},{"price":0.194784,"qty":3079.1243748}],"checksum":2654216223,"timestamp":"2026-09-16T00:17:11.393820Z"}]}}
{"v":1,"kind":"tick","pair":"ADA/USD","channel":"book","ts_exchange":"2026-09-16T00:17:11.394469Z","ts_recv":"2026-09-16T00:17:11.591793Z","payload":{"channel":"book","type":"update","data":[{"symbol":"ADA/USD","bids":[{"price":0.19466,"qty":3008.7}],"asks":[],"checksum":1232771550,"timestamp":"2026-09-16T00:17:11.394469Z"}]}}
{"v":1,"kind":"tick","pair":"ADA/USD","channel":"book","ts_exchange":"2026-09-16T00:17:11.394524Z","ts_recv":"2026-09-16T00:17:11.592007Z","payload":{"channel":"book","type":"update","data":[{"symbol":"ADA/USD","bids":[],"asks":[{"price":0.194785,"qty":0.0},{"price":0.194845,"qty":3008.7}],"checksum":2569303573,"timestamp":"2026-09-16T00:17:11.394524Z"}]}}
{"v":1,"kind":"tick","pair":"ADA/USD","channel":"book","ts_exchange":"2026-09-16T00:17:11.394656Z","ts_recv":"2026-09-16T00:17:11.592124Z","payload":{"channel":"book","type":"update","data":[{"symbol":"ADA/USD","bids":[],"asks":[{"price":0.194783,"qty":1708.37647242}],"checksum":2261910774,"timestamp":"2026-09-16T00:17:11.394656Z"}]}}
{"v":1,"kind":"tick","pair":"BTC/USD","channel":"book","ts_exchange":"2026-09-16T00:17:11.470296Z","ts_recv":"2026-09-16T00:17:11.632303Z","payload":{"channel":"book","type":"update","data":[{"symbol":"BTC/USD","bids":[{"price":75723.6,"qty":0.0},{"price":75719.6,"qty":0.000051}],"asks":[],"checksum":2543117254,"timestamp":"2026-09-16T00:17:11.470296Z"}]}}
{"v":1,"kind":"tick","pair":"BTC/USD","channel":"book","ts_exchange":"2026-09-16T00:17:11.471053Z","ts_recv":"2026-09-16T00:17:11.644525Z","payload":{"channel":"book","type":"update","data":[{"symbol":"BTC/USD","bids":[{"price":75723.7,"qty":0.0},{"price":75718.1,"qty":0.02051113}],"asks":[],"checksum":2809825482,"timestamp":"2026-09-16T00:17:11.471053Z"}]}}
{"v":1,"kind":"tick","pair":"ADA/USD","channel":"book","ts_exchange":"2026-09-16T00:17:11.494988Z","ts_recv":"2026-09-16T00:17:11.655319Z","payload":{"channel":"book","type":"update","data":[{"symbol":"ADA/USD","bids":[{"price":0.194658,"qty":0.0},{"price":0.194615,"qty":2569.17503789}],"asks":[],"checksum":2192288834,"timestamp":"2026-09-16T00:17:11.494988Z"}]}}
{"v":1,"kind":"tick","pair":"BTC/USD","channel":"book","ts_exchange":"2026-09-16T00:17:11.513143Z","ts_recv":"2026-09-16T00:17:11.665483Z","payload":{"channel":"book","type":"update","data":[{"symbol":"BTC/USD","bids":[{"price":75722.7,"qty":0.99061375}],"asks":[],"checksum":41141733,"timestamp":"2026-09-16T00:17:11.513143Z"}]}}
{"v":1,"kind":"tick","pair":"BTC/USD","channel":"book","ts_exchange":"2026-09-16T00:17:11.515760Z","ts_recv":"2026-09-16T00:17:11.666478Z","payload":{"channel":"book","type":"update","data":[{"symbol":"BTC/USD","bids":[{"price":75731.8,"qty":0.00069517}],"asks":[],"checksum":174020231,"timestamp":"2026-09-16T00:17:11.515760Z"}]}}
{"v":1,"kind":"tick","pair":"ADA/USD","channel":"book","ts_exchange":"2026-09-16T00:17:11.561290Z","ts_recv":"2026-09-16T00:17:11.693172Z","payload":{"channel":"book","type":"update","data":[{"symbol":"ADA/USD","bids":[{"price":0.194659,"qty":0.0},{"price":0.194597,"qty":3034.02570007},{"price":0.194661,"qty":3079.1243748}],"asks":[],"checksum":2693572563,"timestamp":"2026-09-16T00:17:11.561290Z"}]}}
{"v":1,"kind":"tick","pair":"ADA/USD","channel":"book","ts_exchange":"2026-09-16T00:17:11.561550Z","ts_recv":"2026-09-16T00:17:11.703436Z","payload":{"channel":"book","type":"update","data":[{"symbol":"ADA/USD","bids":[],"asks":[{"price":0.194784,"qty":0.0},{"price":0.194845,"qty":3008.7},{"price":0.194782,"qty":3079.1243748}],"checksum":310770056,"timestamp":"2026-09-16T00:17:11.561550Z"}]}}
{"v":1,"kind":"tick","pair":"ADA/USD","channel":"book","ts_exchange":"2026-09-16T00:17:11.562343Z","ts_recv":"2026-09-16T00:17:11.704758Z","payload":{"channel":"book","type":"update","data":[{"symbol":"ADA/USD","bids":[],"asks":[{"price":0.194783,"qty":0.0},{"price":0.194845,"qty":3008.7}],"checksum":2112149319,"timestamp":"2026-09-16T00:17:11.562343Z"}]}}
{"v":1,"kind":"tick","pair":"ADA/USD","channel":"book","ts_exchange":"2026-09-16T00:17:11.562411Z","ts_recv":"2026-09-16T00:17:11.705360Z","payload":{"channel":"book","type":"update","data":[{"symbol":"ADA/USD","bids":[],"asks":[{"price":0.194781,"qty":1708.37647242}],"checksum":3907623621,"timestamp":"2026-09-16T00:17:11.562411Z"}]}}
{"v":1,"kind":"tick","pair":"ADA/USD","channel":"book","ts_exchange":"2026-09-16T00:17:11.757788Z","ts_recv":"2026-09-16T00:17:11.893979Z","payload":{"channel":"book","type":"update","data":[{"symbol":"ADA/USD","bids":[],"asks":[{"price":0.194782,"qty":0.0},{"price":0.194845,"qty":3008.7},{"price":0.19478,"qty":3079.1243748}],"checksum":971327321,"timestamp":"2026-09-16T00:17:11.757788Z"}]}}
{"v":1,"kind":"tick","pair":"ADA/USD","channel":"book","ts_exchange":"2026-09-16T00:17:11.758468Z","ts_recv":"2026-09-16T00:17:11.894366Z","payload":{"channel":"book","type":"update","data":[{"symbol":"ADA/USD","bids":[],"asks":[{"price":0.194781,"qty":0.0},{"price":0.194845,"qty":3008.7}],"checksum":2327718741,"timestamp":"2026-09-16T00:17:11.758468Z"}]}}
{"v":1,"kind":"tick","pair":"ADA/USD","channel":"book","ts_exchange":"2026-09-16T00:17:11.890461Z","ts_recv":"2026-09-16T00:17:12.034354Z","payload":{"channel":"book","type":"update","data":[{"symbol":"ADA/USD","bids":[],"asks":[{"price":0.19478,"qty":0.0},{"price":0.194871,"qty":1030.33822061},{"price":0.194786,"qty":3079.1243748}],"checksum":1210067234,"timestamp":"2026-09-16T00:17:11.890461Z"}]}}
{"v":1,"kind":"tick","pair":"ADA/USD","channel":"book","ts_exchange":"2026-09-16T00:17:11.891158Z","ts_recv":"2026-09-16T00:17:12.044803Z","payload":{"channel":"book","type":"update","data":[{"symbol":"ADA/USD","bids":[],"asks":[{"price":0.194785,"qty":1708.37647242}],"checksum":3190351719,"timestamp":"2026-09-16T00:17:11.891158Z"}]}}
{"v":1,"kind":"tick","pair":"BTC/USD","channel":"book","ts_exchange":"2026-09-16T00:17:11.891218Z","ts_recv":"2026-09-16T00:17:12.045101Z","payload":{"channel":"book","type":"update","data":[{"symbol":"BTC/USD","bids":[],"asks":[{"price":75731.9,"qty":0.07699845},{"price":75731.9,"qty":0.07675057}],"checksum":1195233289,"timestamp":"2026-09-16T00:17:11.891218Z"}]}}
{"v":1,"kind":"tick","pair":"BTC/USD","channel":"book","ts_exchange":"2026-09-16T00:17:11.910053Z","ts_recv":"2026-09-16T00:17:12.049250Z","payload":{"channel":"book","type":"update","data":[{"symbol":"BTC/USD","bids":[{"price":75726.2,"qty":0.0},{"price":75718.1,"qty":0.02051113}],"asks":[],"checksum":1369875757,"timestamp":"2026-09-16T00:17:11.910053Z"}]}}
{"v":1,"kind":"tick","pair":"BTC/USD","channel":"book","ts_exchange":"2026-09-16T00:17:11.910906Z","ts_recv":"2026-09-16T00:17:12.049367Z","payload":{"channel":"book","type":"update","data":[{"symbol":"BTC/USD","bids":[{"price":75726.9,"qty":1.32053336}],"asks":[],"checksum":208312603,"timestamp":"2026-09-16T00:17:11.910906Z"}]}}
{"v":1,"kind":"tick","pair":"BTC/USD","channel":"book","ts_exchange":"2026-09-16T00:17:11.911135Z","ts_recv":"2026-09-16T00:17:12.049471Z","payload":{"channel":"book","type":"update","data":[{"symbol":"BTC/USD","bids":[{"price":75724.1,"qty":3.30145804}],"asks":[],"checksum":3968574745,"timestamp":"2026-09-16T00:17:11.911135Z"}]}}
{"v":1,"kind":"tick","pair":"BTC/USD","channel":"book","ts_exchange":"2026-09-16T00:17:11.932752Z","ts_recv":"2026-09-16T00:17:12.065361Z","payload":{"channel":"book","type":"update","data":[{"symbol":"BTC/USD","bids":[],"asks":[{"price":75731.9,"qty":0.07724574}],"checksum":3503735494,"timestamp":"2026-09-16T00:17:11.932752Z"}]}}
{"v":1,"kind":"tick","pair":"ADA/USD","channel":"book","ts_exchange":"2026-09-16T00:17:12.110250Z","ts_recv":"2026-09-16T00:17:12.248572Z","payload":{"channel":"book","type":"update","data":[{"symbol":"ADA/USD","bids":[],"asks":[{"price":0.194786,"qty":0.0},{"price":0.194845,"qty":3008.7},{"price":0.194784,"qty":3079.1243748}],"checksum":1864645371,"timestamp":"2026-09-16T00:17:12.110250Z"}]}}
{"v":1,"kind":"tick","pair":"ADA/USD","channel":"book","ts_exchange":"2026-09-16T00:17:12.111079Z","ts_recv":"2026-09-16T00:17:12.248852Z","payload":{"channel":"book","type":"update","data":[{"symbol":"ADA/USD","bids":[],"asks":[{"price":0.194785,"qty":0.0},{"price":0.194845,"qty":3008.7}],"checksum":3212498224,"timestamp":"2026-09-16T00:17:12.111079Z"}]}}
{"v":1,"kind":"tick","pair":"ADA/USD","channel":"book","ts_exchange":"2026-09-16T00:17:12.111165Z","ts_recv":"2026-09-16T00:17:12.249098Z","payload":{"channel":"book","type":"update","data":[{"symbol":"ADA/USD","bids":[],"asks":[{"price":0.194783,"qty":1708.37647242}],"checksum":2693572563,"timestamp":"2026-09-16T00:17:12.111165Z"}]}}
{"v":1,"kind":"tick","pair":"BTC/USD","channel":"book","ts_exchange":"2026-09-16T00:17:12.200427Z","ts_recv":"2026-09-16T00:17:12.340243Z","payload":{"channel":"book","type":"update","data":[{"symbol":"BTC/USD","bids":[{"price":75731.8,"qty":0.38005232}],"asks":[],"checksum":1597944241,"timestamp":"2026-09-16T00:17:12.200427Z"}]}}
{"v":1,"kind":"tick","pair":"BTC/USD","channel":"book","ts_exchange":"2026-09-16T00:17:12.203064Z","ts_recv":"2026-09-16T00:17:12.346117Z","payload":{"channel":"book","type":"update","data":[{"symbol":"BTC/USD","bids":[{"price":75731.8,"qty":0.3909681}],"asks":[],"checksum":511561584,"timestamp":"2026-09-16T00:17:12.203064Z"}]}}
{"v":1,"kind":"tick","pair":"ADA/USD","channel":"book","ts_exchange":"2026-09-16T00:17:12.314842Z","ts_recv":"2026-09-16T00:17:12.441604Z","payload":{"channel":"book","type":"update","data":[{"symbol":"ADA/USD","bids":[],"asks":[{"price":0.194784,"qty":0.0},{"price":0.194845,"qty":3008.7},{"price":0.194782,"qty":3079.1243748}],"checksum":310770056,"timestamp":"2026-09-16T00:17:12.314842Z"}]}}
{"v":1,"kind":"tick","pair":"ADA/USD","channel":"book","ts_exchange":"2026-09-16T00:17:12.315630Z","ts_recv":"2026-09-16T00:17:12.442570Z","payload":{"channel":"book","type":"update","data":[{"symbol":"ADA/USD","bids":[],"asks":[{"price":0.194783,"qty":0.0},{"price":0.194845,"qty":3008.7}],"checksum":2112149319,"timestamp":"2026-09-16T00:17:12.315630Z"}]}}
{"v":1,"kind":"tick","pair":"ADA/USD","channel":"book","ts_exchange":"2026-09-16T00:17:12.315748Z","ts_recv":"2026-09-16T00:17:12.443134Z","payload":{"channel":"book","type":"update","data":[{"symbol":"ADA/USD","bids":[],"asks":[{"price":0.194781,"qty":1708.37647242}],"checksum":3907623621,"timestamp":"2026-09-16T00:17:12.315748Z"}]}}
{"v":1,"kind":"tick","pair":"ADA/USD","channel":"book","ts_exchange":"2026-09-16T00:17:12.484267Z","ts_recv":"2026-09-16T00:17:12.611518Z","payload":{"channel":"book","type":"update","data":[{"symbol":"ADA/USD","bids":[],"asks":[{"price":0.194782,"qty":0.0},{"price":0.194845,"qty":3008.7},{"price":0.19478,"qty":3079.1243748}],"checksum":971327321,"timestamp":"2026-09-16T00:17:12.484267Z"}]}}
{"v":1,"kind":"tick","pair":"ADA/USD","channel":"book","ts_exchange":"2026-09-16T00:17:12.485001Z","ts_recv":"2026-09-16T00:17:12.613512Z","payload":{"channel":"book","type":"update","data":[{"symbol":"ADA/USD","bids":[],"asks":[{"price":0.194781,"qty":0.0},{"price":0.194845,"qty":3008.7}],"checksum":2327718741,"timestamp":"2026-09-16T00:17:12.485001Z"}]}}
{"v":1,"kind":"tick","pair":"BTC/USD","channel":"book","ts_exchange":"2026-09-16T00:17:12.611933Z","ts_recv":"2026-09-16T00:17:12.744202Z","payload":{"channel":"book","type":"update","data":[{"symbol":"BTC/USD","bids":[{"price":75726.9,"qty":0.0},{"price":75719.6,"qty":0.000051}],"asks":[],"checksum":344846520,"timestamp":"2026-09-16T00:17:12.611933Z"}]}}
{"v":1,"kind":"tick","pair":"BTC/USD","channel":"book","ts_exchange":"2026-09-16T00:17:12.612880Z","ts_recv":"2026-09-16T00:17:12.744514Z","payload":{"channel":"book","type":"update","data":[{"symbol":"BTC/USD","bids":[{"price":75726.0,"qty":1.32055025}],"asks":[],"checksum":111187413,"timestamp":"2026-09-16T00:17:12.612880Z"}]}}
{"v":1,"kind":"tick","pair":"BTC/USD","channel":"book","ts_exchange":"2026-09-16T00:17:12.639407Z","ts_recv":"2026-09-16T00:17:12.779598Z","payload":{"channel":"book","type":"update","data":[{"symbol":"BTC/USD","bids":[{"price":75726.0,"qty":0.0},{"price":75719.6,"qty":0.000051}],"asks":[],"checksum":344846520,"timestamp":"2026-09-16T00:17:12.639407Z"}]}}
{"v":1,"kind":"tick","pair":"BTC/USD","channel":"book","ts_exchange":"2026-09-16T00:17:12.639469Z","ts_recv":"2026-09-16T00:17:12.779727Z","payload":{"channel":"book","type":"update","data":[{"symbol":"BTC/USD","bids":[{"price":75724.1,"qty":0.0},{"price":75718.1,"qty":0.02051113}],"asks":[],"checksum":3509122851,"timestamp":"2026-09-16T00:17:12.639469Z"}]}}
{"v":1,"kind":"tick","pair":"BTC/USD","channel":"book","ts_exchange":"2026-09-16T00:17:12.640281Z","ts_recv":"2026-09-16T00:17:12.779815Z","payload":{"channel":"book","type":"update","data":[{"symbol":"BTC/USD","bids":[{"price":75722.6,"qty":3.3015225}],"asks":[],"checksum":1476615482,"timestamp":"2026-09-16T00:17:12.640281Z"}]}}
{"v":1,"kind":"tick","pair":"ADA/USD","channel":"book","ts_exchange":"2026-09-16T00:17:12.786620Z","ts_recv":"2026-09-16T00:17:12.930096Z","payload":{"channel":"book","type":"update","data":[{"symbol":"ADA/USD","bids":[],"asks":[{"price":0.19478,"qty":0.0},{"price":0.194871,"qty":1030.33822061},{"price":0.194786,"qty":3079.1243748}],"checksum":1210067234,"timestamp":"2026-09-16T00:17:12.786620Z"}]}}
{"v":1,"kind":"tick","pair":"ADA/USD","channel":"book","ts_exchange":"2026-09-16T00:17:12.787281Z","ts_recv":"2026-09-16T00:17:12.930362Z","payload":{"channel":"book","type":"update","data":[{"symbol":"ADA/USD","bids":[],"asks":[{"price":0.194785,"qty":1708.37647242}],"checksum":3190351719,"timestamp":"2026-09-16T00:17:12.787281Z"}]}}
{"v":1,"kind":"tick","pair":"BTC/USD","channel":"book","ts_exchange":"2026-09-16T00:17:12.976670Z","ts_recv":"2026-09-16T00:17:13.113140Z","payload":{"channel":"book","type":"update","data":[{"symbol":"BTC/USD","bids":[{"price":75731.8,"qty":0.38005232}],"asks":[],"checksum":3526005939,"timestamp":"2026-09-16T00:17:12.976670Z"}]}}
{"v":1,"kind":"tick","pair":"ADA/USD","channel":"book","ts_exchange":"2026-09-16T00:17:13.052945Z","ts_recv":"2026-09-16T00:17:13.191663Z","payload":{"channel":"book","type":"update","data":[{"symbol":"ADA/USD","bids":[],"asks":[{"price":0.194786,"qty":0.0},{"price":0.194845,"qty":3008.7},{"price":0.194784,"qty":3079.1243748}],"checksum":1864645371,"timestamp":"2026-09-16T00:17:13.052945Z"}]}}
{"v":1,"kind":"tick","pair":"ADA/USD","channel":"book","ts_exchange":"2026-09-16T00:17:13.053642Z","ts_recv":"2026-09-16T00:17:13.202498Z","payload":{"channel":"book","type":"update","data":[{"symbol":"ADA/USD","bids":[],"asks":[{"price":0.194785,"qty":0.0},{"price":0.194845,"qty":3008.7}],"checksum":3212498224,"timestamp":"2026-09-16T00:17:13.053642Z"}]}}
{"v":1,"kind":"tick","pair":"ADA/USD","channel":"book","ts_exchange":"2026-09-16T00:17:13.053746Z","ts_recv":"2026-09-16T00:17:13.203373Z","payload":{"channel":"book","type":"update","data":[{"symbol":"ADA/USD","bids":[],"asks":[{"price":0.194783,"qty":1708.37647242}],"checksum":2693572563,"timestamp":"2026-09-16T00:17:13.053746Z"}]}}
{"v":1,"kind":"tick","pair":"BTC/USD","channel":"book","ts_exchange":"2026-09-16T00:17:13.227994Z","ts_recv":"2026-09-16T00:17:13.427342Z","payload":{"channel":"book","type":"update","data":[{"symbol":"BTC/USD","bids":[{"price":75725.2,"qty":1.32056349}],"asks":[],"checksum":1272086278,"timestamp":"2026-09-16T00:17:13.227994Z"}]}}
{"v":1,"kind":"tick","pair":"BTC/USD","channel":"book","ts_exchange":"2026-09-16T00:17:13.230929Z","ts_recv":"2026-09-16T00:17:13.429665Z","payload":{"channel":"book","type":"update","data":[{"symbol":"BTC/USD","bids":[{"price":75731.8,"qty":0.3909681}],"asks":[],"checksum":177275335,"timestamp":"2026-09-16T00:17:13.230929Z"}]}}
{"v":1,"kind":"tick","pair":"BTC/USD","channel":"book","ts_exchange":"2026-09-16T00:17:13.233955Z","ts_recv":"2026-09-16T00:17:13.435543Z","payload":{"channel":"book","type":"update","data":[{"symbol":"BTC/USD","bids":[{"price":75725.2,"qty":0.0},{"price":75719.6,"qty":0.000051}],"asks":[],"checksum":1476615482,"timestamp":"2026-09-16T00:17:13.233955Z"}]}}
{"v":1,"kind":"tick","pair":"BTC/USD","channel":"book","ts_exchange":"2026-09-16T00:17:13.234033Z","ts_recv":"2026-09-16T00:17:13.437888Z","payload":{"channel":"book","type":"update","data":[{"symbol":"BTC/USD","bids":[{"price":75722.6,"qty":0.0},{"price":75718.1,"qty":0.02051113}],"asks":[],"checksum":3509122851,"timestamp":"2026-09-16T00:17:13.234033Z"}]}}
{"v":1,"kind":"tick","pair":"BTC/USD","channel":"book","ts_exchange":"2026-09-16T00:17:13.235695Z","ts_recv":"2026-09-16T00:17:13.438596Z","payload":{"channel":"book","type":"update","data":[{"symbol":"BTC/USD","bids":[{"price":75723.9,"qty":3.30146427}],"asks":[],"checksum":3353578075,"timestamp":"2026-09-16T00:17:13.235695Z"}]}}
{"v":1,"kind":"tick","pair":"BTC/USD","channel":"book","ts_exchange":"2026-09-16T00:17:13.236532Z","ts_recv":"2026-09-16T00:17:13.439153Z","payload":{"channel":"book","type":"update","data":[{"symbol":"BTC/USD","bids":[{"price":75731.8,"qty":0.38005232}],"asks":[],"checksum":1305101266,"timestamp":"2026-09-16T00:17:13.236532Z"}]}}
{"v":1,"kind":"tick","pair":"BTC/USD","channel":"book","ts_exchange":"2026-09-16T00:17:13.239368Z","ts_recv":"2026-09-16T00:17:13.444072Z","payload":{"channel":"book","type":"update","data":[{"symbol":"BTC/USD","bids":[{"price":75731.8,"qty":0.3909681}],"asks":[],"checksum":3353578075,"timestamp":"2026-09-16T00:17:13.239368Z"}]}}
{"v":1,"kind":"tick","pair":"BTC/USD","channel":"book","ts_exchange":"2026-09-16T00:17:13.517976Z","ts_recv":"2026-09-16T00:17:13.660154Z","payload":{"channel":"book","type":"update","data":[{"symbol":"BTC/USD","bids":[{"price":75731.8,"qty":0.01161095}],"asks":[],"checksum":2812388903,"timestamp":"2026-09-16T00:17:13.517976Z"}]}}
{"v":1,"kind":"tick","pair":"BTC/USD","channel":"book","ts_exchange":"2026-09-16T00:17:13.520606Z","ts_recv":"2026-09-16T00:17:13.668658Z","payload":{"channel":"book","type":"update","data":[{"symbol":"BTC/USD","bids":[{"price":75731.8,"qty":0.00069517}],"asks":[],"checksum":4239763486,"timestamp":"2026-09-16T00:17:13.520606Z"}]}}
{"v":1,"kind":"tick","pair":"ADA/USD","channel":"book","ts_exchange":"2026-09-16T00:17:13.652376Z","ts_recv":"2026-09-16T00:17:13.788219Z","payload":{"channel":"book","type":"update","data":[{"symbol":"ADA/USD","bids":[],"asks":[{"price":0.194784,"qty":0.0},{"price":0.194845,"qty":3008.7},{"price":0.194782,"qty":3079.1243748}],"checksum":310770056,"timestamp":"2026-09-16T00:17:13.652376Z"}]}}
{"v":1,"kind":"tick","pair":"ADA/USD","channel":"book","ts_exchange":"2026-09-16T00:17:13.653090Z","ts_recv":"2026-09-16T00:17:13.790060Z","payload":{"channel":"book","type":"update","data":[{"symbol":"ADA/USD","bids":[],"asks":[{"price":0.194783,"qty":0.0},{"price":0.194845,"qty":3008.7}],"checksum":2112149319,"timestamp":"2026-09-16T00:17:13.653090Z"}]}}
{"v":1,"kind":"tick","pair":"ADA/USD","channel":"book","ts_exchange":"2026-09-16T00:17:13.653183Z","ts_recv":"2026-09-16T00:17:13.790399Z","payload":{"channel":"book","type":"update","data":[{"symbol":"ADA/USD","bids":[],"asks":[{"price":0.194781,"qty":1708.37647242}],"checksum":3907623621,"timestamp":"2026-09-16T00:17:13.653183Z"}]}}
{"v":1,"kind":"tick","pair":"BTC/USD","channel":"book","ts_exchange":"2026-09-16T00:17:13.714623Z","ts_recv":"2026-09-16T00:17:13.861132Z","payload":{"channel":"book","type":"update","data":[{"symbol":"BTC/USD","bids":[{"price":75723.9,"qty":0.0},{"price":75718.1,"qty":0.02051113}],"asks":[],"checksum":191304577,"timestamp":"2026-09-16T00:17:13.714623Z"}]}}
{"v":1,"kind":"tick","pair":"BTC/USD","channel":"book","ts_exchange":"2026-09-16T00:17:13.715767Z","ts_recv":"2026-09-16T00:17:13.867396Z","payload":{"channel":"book","type":"update","data":[{"symbol":"BTC/USD","bids":[{"price":75727.8,"qty":1.3205176}],"asks":[],"checksum":3822820779,"timestamp":"2026-09-16T00:17:13.715767Z"}]}}
{"v":1,"kind":"tick","pair":"BTC/USD","channel":"book","ts_exchange":"2026-09-16T00:17:13.715924Z","ts_recv":"2026-09-16T00:17:13.867583Z","payload":{"channel":"book","type":"update","data":[{"symbol":"BTC/USD","bids":[{"price":75725.2,"qty":3.30140717}],"asks":[],"checksum":1556868041,"timestamp":"2026-09-16T00:17:13.715924Z"}]}}
{"v":1,"kind":"tick","pair":"BTC/USD","channel":"book","ts_exchange":"2026-09-16T00:17:13.717920Z","ts_recv":"2026-09-16T00:17:13.875301Z","payload":{"channel":"book","type":"update","data":[{"symbol":"BTC/USD","bids":[{"price":75722.8,"qty":0.2956982}],"asks":[],"checksum":1244229177,"timestamp":"2026-09-16T00:17:13.717920Z"}]}}
{"v":1,"kind":"tick","pair":"BTC/USD","channel":"book","ts_exchange":"2026-09-16T00:17:13.718283Z","ts_recv":"2026-09-16T00:17:13.875421Z","payload":{"channel":"book","type":"update","data":[{"symbol":"BTC/USD","bids":[{"price":75722.8,"qty":0.0},{"price":75722.7,"qty":0.99061375}],"asks":[],"checksum":1556868041,"timestamp":"2026-09-16T00:17:13.718283Z"}]}}
{"v":1,"kind":"tick","pair":"BTC/USD","channel":"book","ts_exchange":"2026-09-16T00:17:13.718975Z","ts_recv":"2026-09-16T00:17:13.875505Z","payload":{"channel":"book","type":"update","data":[{"symbol":"BTC/USD","bids":[{"price":75731.8,"qty":0.01161095}],"asks":[],"checksum":1380305214,"timestamp":"2026-09-16T00:17:13.718975Z"}]}}
{"v":1,"kind":"tick","pair":"BTC/USD","channel":"book","ts_exchange":"2026-09-16T00:17:13.719455Z","ts_recv":"2026-09-16T00:17:13.875662Z","payload":{"channel":"book","type":"update","data":[{"symbol":"BTC/USD","bids":[{"price":75725.3,"qty":1.30122028}],"asks":[],"checksum":621333209,"timestamp":"2026-09-16T00:17:13.719455Z"}]}}
{"v":1,"kind":"tick","pair":"BTC/USD","channel":"book","ts_exchange":"2026-09-16T00:17:13.767107Z","ts_recv":"2026-09-16T00:17:13.906536Z","payload":{"channel":"book","type":"update","data":[{"symbol":"BTC/USD","bids":[{"price":75731.8,"qty":0.39132706}],"asks":[],"checksum":3730247934,"timestamp":"2026-09-16T00:17:13.767107Z"}]}}
{"v":1,"kind":"tick","pair":"BTC/USD","channel":"book","ts_exchange":"2026-09-16T00:17:13.811870Z","ts_recv":"2026-09-16T00:17:13.946807Z","payload":{"channel":"book","type":"update","data":[{"symbol":"BTC/USD","bids":[{"price":75724.2,"qty":1.04431375}],"asks":[],"checksum":829265539,"timestamp":"2026-09-16T00:17:13.811870Z"}]}}
{"v":1,"kind":"tick","pair":"ADA/USD","channel":"book","ts_exchange":"2026-09-16T00:17:13.822077Z","ts_recv":"2026-09-16T00:17:13.966549Z","payload":{"channel":"book","type":"update","data":[{"symbol":"ADA/USD","bids":[],"asks":[{"price":0.194782,"qty":0.0},{"price":0.194845,"qty":3008.7},{"price":0.19478,"qty":3079.1243748}],"checksum":971327321,"timestamp":"2026-09-16T00:17:13.822077Z"}]}}
{"v":1,"kind":"tick","pair":"ADA/USD","channel":"book","ts_exchange":"2026-09-16T00:17:13.822817Z","ts_recv":"2026-09-16T00:17:13.966821Z","payload":{"channel":"book","type":"update","data":[{"symbol":"ADA/USD","bids":[],"asks":[{"price":0.194781,"qty":0.0},{"price":0.194845,"qty":3008.7}],"checksum":2327718741,"timestamp":"2026-09-16T00:17:13.822817Z"}]}}
{"v":1,"kind":"tick","pair":"BTC/USD","channel":"book","ts_exchange":"2026-09-16T00:17:13.894876Z","ts_recv":"2026-09-16T00:17:14.046528Z","payload":{"channel":"book","type":"update","data":[{"symbol":"BTC/USD","bids":[{"price":75724.3,"qty":0.0},{"price":75720.5,"qty":0.98554825},{"price":75725.4,"qty":0.11117396}],"asks":[],"checksum":4127997702,"timestamp":"2026-09-16T00:17:13.894876Z"}]}}
{"v":1,"kind":"tick","pair":"BTC/USD","channel":"book","ts_exchange":"2026-09-16T00:17:13.945509Z","ts_recv":"2026-09-16T00:17:14.071496Z","payload":{"channel":"book","type":"update","data":[{"symbol":"BTC/USD","bids":[{"price":75724.2,"qty":0.0537}],"asks":[],"checksum":3108722369,"timestamp":"2026-09-16T00:17:13.945509Z"}]}}
{"v":1,"kind":"tick","pair":"BTC/USD","channel":"book","ts_exchange":"2026-09-16T00:17:13.963441Z","ts_recv":"2026-09-16T00:17:14.107154Z","payload":{"channel":"book","type":"update","data":[{"symbol":"BTC/USD","bids":[{"price":75724.1,"qty":0.99061375}],"asks":[],"checksum":3455174975,"timestamp":"2026-09-16T00:17:13.963441Z"}]}}
{"v":1,"kind":"tick","pair":"ADA/USD","channel":"book","ts_exchange":"2026-09-16T00:17:14.005267Z","ts_recv":"2026-09-16T00:17:14.130884Z","payload":{"channel":"book","type":"update","data":[{"symbol":"ADA/USD","bids":[],"asks":[{"price":0.19478,"qty":0.0},{"price":0.194871,"qty":1030.33822061},{"price":0.194786,"qty":3079.1465085}],"checksum":463066402,"timestamp":"2026-09-16T00:17:14.005267Z"}]}}
{"v":1,"kind":"tick","pair":"ADA/USD","channel":"book","ts_exchange":"2026-09-16T00:17:14.005956Z","ts_recv":"2026-09-16T00:17:14.132032Z","payload":{"channel":"book","type":"update","data":[{"symbol":"ADA/USD","bids":[],"asks":[{"price":0.194785,"qty":1708.38307933}],"checksum":1622276744,"timestamp":"2026-09-16T00:17:14.005956Z"}]}}
{"v":1,"kind":"tick","pair":"ADA/USD","channel":"book","ts_exchange":"2026-09-16T00:17:14.023229Z","ts_recv":"2026-09-16T00:17:14.151255Z","payload":{"channel":"book","type":"update","data":[{"symbol":"ADA/USD","bids":[{"price":0.194662,"qty":1040.0}],"asks":[],"checksum":3224139376,"timestamp":"2026-09-16T00:17:14.023229Z"}]}}
{"v":1,"kind":"tick","pair":"ADA/USD","channel":"book","ts_exchange":"2026-09-16T00:17:14.023395Z","ts_recv":"2026-09-16T00:17:14.151419Z","payload":{"channel":"book","type":"update","data":[{"symbol":"ADA/USD","bids":[],"asks":[{"price":0.19479,"qty":800.0}],"checksum":2197268557,"timestamp":"2026-09-16T00:17:14.023395Z"}]}}
{"v":1,"kind":"tick","pair":"ADA/USD","channel":"book","ts_exchange":"2026-09-16T00:17:14.023866Z","ts_recv":"2026-09-16T00:17:14.151508Z","payload":{"channel":"book","type":"update","data":[{"symbol":"ADA/USD","bids":[{"price":0.194661,"qty":0.0},{"price":0.194615,"qty":2569.17503789},{"price":0.194663,"qty":3079.1465085}],"asks":[],"checksum":1219172597,"timestamp":"2026-09-16T00:17:14.023866Z"}]}}
{"v":1,"kind":"tick","pair":"ADA/USD","channel":"book","ts_exchange":"2026-09-16T00:17:14.024067Z","ts_recv":"2026-09-16T00:17:14.151593Z","payload":{"channel":"book","type":"update","data":[{"symbol":"ADA/USD","bids":[{"price":0.194663,"qty":6087.8465085}],"asks":[],"checksum":1361789169,"timestamp":"2026-09-16T00:17:14.024067Z"}]}}
{"v":1,"kind":"tick","pair":"ADA/USD","channel":"book","ts_exchange":"2026-09-16T00:17:14.124640Z","ts_recv":"2026-09-16T00:17:14.251838Z","payload":{"channel":"book","type":"update","data":[{"symbol":"ADA/USD","bids":[{"price":0.19466,"qty":0.0},{"price":0.194615,"qty":2569.17503789}],"asks":[],"checksum":1470501586,"timestamp":"2026-09-16T00:17:14.124640Z"}]}}
{"v":1,"kind":"tick","pair":"ADA/USD","channel":"book","ts_exchange":"2026-09-16T00:17:14.175380Z","ts_recv":"2026-09-16T00:17:14.300835Z","payload":{"channel":"book","type":"update","data":[{"symbol":"ADA/USD","bids":[],"asks":[{"price":0.194786,"qty":0.0},{"price":0.194841,"qty":20349.83229176},{"price":0.194784,"qty":3079.1465085}],"checksum":1902845512,"timestamp":"2026-09-16T00:17:14.175380Z"}]}}
{"v":1,"kind":"tick","pair":"ADA/USD","channel":"book","ts_exchange":"2026-09-16T00:17:14.176275Z","ts_recv":"2026-09-16T00:17:14.301590Z","payload":{"channel":"book","type":"update","data":[{"symbol":"ADA/USD","bids":[],"asks":[{"price":0.194785,"qty":0.0},{"price":0.194841,"qty":20349.83229176}],"checksum":2813383549,"timestamp":"2026-09-16T00:17:14.176275Z"}]}}
{"v":1,"kind":"tick","pair":"ADA/USD","channel":"book","ts_exchange":"2026-09-16T00:17:14.176509Z","ts_recv":"2026-09-16T00:17:14.303391Z","payload":{"channel":"book","type":"update","data":[{"symbol":"ADA/USD","bids":[],"asks":[{"price":0.194783,"qty":1947.18307933}],"checksum":161501089,"timestamp":"2026-09-16T00:17:14.176509Z"}]}}
{"v":1,"kind":"tick","pair":"ADA/USD","channel":"book","ts_exchange":"2026-09-16T00:17:14.238279Z","ts_recv":"2026-09-16T00:17:14.363836Z","payload":{"channel":"book","type":"update","data":[{"symbol":"ADA/USD","bids":[{"price":0.194662,"qty":0.0},{"price":0.194597,"qty":3034.02570007}],"asks":[],"checksum":3556323201,"timestamp":"2026-09-16T00:17:14.238279Z"}]}}
{"v":1,"kind":"tick","pair":"ADA/USD","channel":"book","ts_exchange":"2026-09-16T00:17:14.369829Z","ts_recv":"2026-09-16T00:17:14.498707Z","payload":{"channel":"book","type":"update","data":[{"symbol":"ADA/USD","bids":[{"price":0.194663,"qty":3008.7},{"price":0.194653,"qty":3079.1465085}],"asks":[],"checksum":792387873,"timestamp":"2026-09-16T00:17:14.369829Z"}]}}
{"v":1,"kind":"tick","pair":"ADA/USD","channel":"book","ts_exchange":"2026-09-16T00:17:14.369992Z","ts_recv":"2026-09-16T00:17:14.499595Z","payload":{"channel":"book","type":"update","data":[{"symbol":"ADA/USD","bids":[],"asks":[{"price":0.194784,"qty":0.0},{"price":0.194841,"qty":20349.83229176},{"price":0.194782,"qty":3079.1465085}],"checksum":684229415,"timestamp":"2026-09-16T00:17:14.369992Z"}]}}
{"v":1,"kind":"tick","pair":"ADA/USD","channel":"book","ts_exchange":"2026-09-16T00:17:14.370899Z","ts_recv":"2026-09-16T00:17:14.501194Z","payload":{"channel":"book","type":"update","data":[{"symbol":"ADA/USD","bids":[],"asks":[{"price":0.194783,"qty":0.0},{"price":0.194841,"qty":20349.83229176}],"checksum":3369577793,"timestamp":"2026-09-16T00:17:14.370899Z"}]}}
{"v":1,"kind":"tick","pair":"ADA/USD","channel":"book","ts_exchange":"2026-09-16T00:17:14.370939Z","ts_recv":"2026-09-16T00:17:14.504492Z","payload":{"channel":"book","type":"update","data":[{"symbol":"ADA/USD","bids":[],"asks":[{"price":0.194781,"qty":1947.18307933}],"checksum":699771072,"timestamp":"2026-09-16T00:17:14.370939Z"}]}}
{"v":1,"kind":"tick","pair":"ADA/USD","channel":"book","ts_exchange":"2026-09-16T00:17:14.370967Z","ts_recv":"2026-09-16T00:17:14.505152Z","payload":{"channel":"book","type":"update","data":[{"symbol":"ADA/USD","bids":[{"price":0.194663,"qty":0.0},{"price":0.194597,"qty":3034.02570007}],"asks":[],"checksum":4067845487,"timestamp":"2026-09-16T00:17:14.370967Z"}]}}
{"v":1,"kind":"tick","pair":"ADA/USD","channel":"book","ts_exchange":"2026-09-16T00:17:14.371156Z","ts_recv":"2026-09-16T00:17:14.505821Z","payload":{"channel":"book","type":"update","data":[{"symbol":"ADA/USD","bids":[{"price":0.194654,"qty":3008.7}],"asks":[],"checksum":1241965593,"timestamp":"2026-09-16T00:17:14.371156Z"}]}}
{"v":1,"kind":"tick","pair":"BTC/USD","channel":"book","ts_exchange":"2026-09-16T00:17:14.481542Z","ts_recv":"2026-09-16T00:17:14.620892Z","payload":{"channel":"book","type":"update","data":[{"symbol":"BTC/USD","bids":[{"price":75731.8,"qty":0.01161095}],"asks":[],"checksum":1733374509,"timestamp":"2026-09-16T00:17:14.481542Z"}]}}
{"v":1,"kind":"tick","pair":"ADA/USD","channel":"book","ts_exchange":"2026-09-16T00:17:14.554268Z","ts_recv":"2026-09-16T00:17:14.702029Z","payload":{"channel":"book","type":"update","data":[{"symbol":"ADA/USD","bids":[],"asks":[{"price":0.194781,"qty":0.0},{"price":0.194841,"qty":20349.83229176}],"checksum":2875515288,"timestamp":"2026-09-16T00:17:14.554268Z"}]}}
{"v":1,"kind":"tick","pair":"ADA/USD","channel":"book","ts_exchange":"2026-09-16T00:17:14.555055Z","ts_recv":"2026-09-16T00:17:14.702190Z","payload":{"channel":"book","type":"update","data":[{"symbol":"ADA/USD","bids":[{"price":0.194653,"qty":0.0},{"price":0.194597,"qty":3034.02570007},{"price":0.194655,"qty":3079.1465085}],"asks":[],"checksum":2915675619,"timestamp":"2026-09-16T00:17:14.555055Z"}]}}
{"v":1,"kind":"tick","pair":"ADA/USD","channel":"book","ts_exchange":"2026-09-16T00:17:14.555216Z","ts_recv":"2026-09-16T00:17:14.702285Z","payload":{"channel":"book","type":"update","data":[{"symbol":"ADA/USD","bids":[],"asks":[{"price":0.194782,"qty":0.0},{"price":0.194845,"qty":3008.7},{"price":0.194786,"qty":3079.1465085}],"checksum":3701420747,"timestamp":"2026-09-16T00:17:14.555216Z"}]}}
{"v":1,"kind":"tick","pair":"ADA/USD","channel":"book","ts_exchange":"2026-09-16T00:17:14.555754Z","ts_recv":"2026-09-16T00:17:14.710381Z","payload":{"channel":"book","type":"update","data":[{"symbol":"ADA/USD","bids":[{"price":0.194656,"qty":3008.7}],"asks":[],"checksum":3245052264,"timestamp":"2026-09-16T00:17:14.555754Z"}]}}
{"v":1,"kind":"tick","pair":"ADA/USD","channel":"book","ts_exchange":"2026-09-16T00:17:14.555936Z","ts_recv":"2026-09-16T00:17:14.710546Z","payload":{"channel":"book","type":"update","data":[{"symbol":"ADA/USD","bids":[],"asks":[{"price":0.194785,"qty":1947.18307933}],"checksum":4021926663,"timestamp":"2026-09-16T00:17:14.555936Z"}]}}
{"v":1,"kind":"tick","pair":"ADA/USD","channel":"book","ts_exchange":"2026-09-16T00:17:14.556736Z","ts_recv":"2026-09-16T00:17:14.710639Z","payload":{"channel":"book","type":"update","data":[{"symbol":"ADA/USD","bids":[{"price":0.194677,"qty":3279.605812}],"asks":[],"checksum":1497858794,"timestamp":"2026-09-16T00:17:14.556736Z"}]}}
{"v":1,"kind":"tick","pair":"ADA/USD","channel":"book","ts_exchange":"2026-09-16T00:17:14.594991Z","ts_recv":"2026-09-16T00:17:14.740540Z","payload":{"channel":"book","type":"update","data":[{"symbol":"ADA/USD","bids":[{"price":0.194677,"qty":0.0},{"price":0.194622,"qty":2569.07582444}],"asks":[],"checksum":4021926663,"timestamp":"2026-09-16T00:17:14.594991Z"}]}}
{"v":1,"kind":"tick","pair":"ADA/USD","channel":"book","ts_exchange":"2026-09-16T00:17:14.656171Z","ts_recv":"2026-09-16T00:17:14.792237Z","payload":{"channel":"book","type":"update","data":[{"symbol":"ADA/USD","bids":[{"price":0.194654,"qty":0.0},{"price":0.194615,"qty":2569.17503789}],"asks":[],"checksum":1609772252,"timestamp":"2026-09-16T00:17:14.656171Z"}]}}
{"v":1,"kind":"tick","pair":"ADA/USD","channel":"book","ts_exchange":"2026-09-16T00:17:14.783036Z","ts_recv":"2026-09-16T00:17:14.908891Z","payload":{"channel":"book","type":"update","data":[{"symbol":"ADA/USD","bids":[{"price":0.194655,"qty":0.0},{"price":0.194597,"qty":3034.02570007},{"price":0.194657,"qty":3079.1465085}],"asks":[],"checksum":1285132169,"timestamp":"2026-09-16T00:17:14.783036Z"}]}}
{"v":1,"kind":"tick","pair":"ADA/USD","channel":"book","ts_exchange":"2026-09-16T00:17:14.783215Z","ts_recv":"2026-09-16T00:17:14.909005Z","payload":{"channel":"book","type":"update","data":[{"symbol":"ADA/USD","bids":[],"asks":[{"price":0.194786,"qty":0.0},{"price":0.194841,"qty":20349.83229176},{"price":0.194784,"qty":3079.1465085}],"checksum":311950349,"timestamp":"2026-09-16T00:17:14.783215Z"}]}}
{"v":1,"kind":"tick","pair":"ADA/USD","channel":"book","ts_exchange":"2026-09-16T00:17:14.783819Z","ts_recv":"2026-09-16T00:17:14.913026Z","payload":{"channel":"book","type":"update","data":[{"symbol":"ADA/USD","bids":[{"price":0.194658,"qty":3008.7}],"asks":[],"checksum":3665959170,"timestamp":"2026-09-16T00:17:14.783819Z"}]}}
{"v":1,"kind":"tick","pair":"ADA/USD","channel":"book","ts_exchange":"2026-09-16T00:17:14.783874Z","ts_recv":"2026-09-16T00:17:14.913512Z","payload":{"channel":"book","type":"update","data":[{"symbol":"ADA/USD","bids":[],"asks":[{"price":0.194785,"qty":0.0},{"price":0.194841,"qty":20349.83229176}],"checksum":2465533821,"timestamp":"2026-09-16T00:17:14.783874Z"}]}}
{"v":1,"kind":"tick","pair":"ADA/USD","channel":"book","ts_exchange":"2026-09-16T00:17:14.783959Z","ts_recv":"2026-09-16T00:17:14.913617Z","payload":{"channel":"book","type":"update","data":[{"symbol":"ADA/USD","bids":[],"asks":[{"price":0.194785,"qty":1028.05784654}],"checksum":2577044985,"timestamp":"2026-09-16T00:17:14.783959Z"}]}}
{"v":1,"kind":"tick","pair":"ADA/USD","channel":"book","ts_exchange":"2026-09-16T00:17:14.884338Z","ts_recv":"2026-09-16T00:17:15.011519Z","payload":{"channel":"book","type":"update","data":[{"symbol":"ADA/USD","bids":[{"price":0.194656,"qty":0.0},{"price":0.194615,"qty":2569.17503789}],"asks":[],"checksum":4066380688,"timestamp":"2026-09-16T00:17:14.884338Z"}]}}
{"v":1,"kind":"tick","pair":"BTC/USD","channel":"book","ts_exchange":"2026-09-16T00:17:15.056711Z","ts_recv":"2026-09-16T00:17:15.183301Z","payload":{"channel":"book","type":"update","data":[{"symbol":"BTC/USD","bids":[{"price":75724.1,"qty":0.0},{"price":75723.4,"qty":0.000051}],"asks":[],"checksum":481999984,"timestamp":"2026-09-16T00:17:15.056711Z"}]}}
{"v":1,"kind":"tick","pair":"BTC/USD","channel":"book","ts_exchange":"2026-09-16T00:17:15.063257Z","ts_recv":"2026-09-16T00:17:15.189807Z","payload":{"channel":"book","type":"update","data":[{"symbol":"BTC/USD","bids":[{"price":75724.0,"qty":0.99061375}],"asks":[],"checksum":1881810542,"timestamp":"2026-09-16T00:17:15.063257Z"}]}}
{"v":1,"kind":"tick","pair":"ADA/USD","channel":"book","ts_exchange":"2026-09-16T00:17:15.064762Z","ts_recv":"2026-09-16T00:17:15.193936Z","payload":{"channel":"book","type":"update","data":[{"symbol":"ADA/USD","bids":[{"price":0.194657,"qty":0.0},{"price":0.194597,"qty":3034.02570007},{"price":0.194659,"qty":3079.1465085}],"asks":[],"checksum":3745683895,"timestamp":"2026-09-16T00:17:15.064762Z"}]}}
{"v":1,"kind":"tick","pair":"ADA/USD","channel":"book","ts_exchange":"2026-09-16T00:17:15.065696Z","ts_recv":"2026-09-16T00:17:15.194206Z","payload":{"channel":"book","type":"update","data":[{"symbol":"ADA/USD","bids":[{"price":0.19466,"qty":3008.7}],"asks":[],"checksum":1098692321,"timestamp":"2026-09-16T00:17:15.065696Z"}]}}
{"v":1,"kind":"tick","pair":"ADA/USD","channel":"book","ts_exchange":"2026-09-16T00:17:15.166363Z","ts_recv":"2026-09-16T00:17:15.304219Z","payload":{"channel":"book","type":"update","data":[{"symbol":"ADA/USD","bids":[{"price":0.194658,"qty":0.0},{"price":0.194615,"qty":2569.17503789}],"asks":[],"checksum":1157963349,"timestamp":"2026-09-16T00:17:15.166363Z"}]}}
{"v":1,"kind":"tick","pair":"ADA/USD","channel":"book","ts_exchange":"2026-09-16T00:17:15.303013Z","ts_recv":"2026-09-16T00:17:15.430571Z","payload":{"channel":"book","type":"update","data":[{"symbol":"ADA/USD","bids":[{"price":0.194659,"qty":0.0},{"price":0.194597,"qty":3034.02570007},{"price":0.194661,"qty":3079.1465085}],"asks":[],"checksum":777159507,"timestamp":"2026-09-16T00:17:15.303013Z"}]}}
{"v":1,"kind":"tick","pair":"ADA/USD","channel":"book","ts_exchange":"2026-09-16T00:17:15.303864Z","ts_recv":"2026-09-16T00:17:15.432714Z","payload":{"channel":"book","type":"update","data":[{"symbol":"ADA/USD","bids":[{"price":0.194662,"qty":1210.49049537}],"asks":[],"checksum":3496190200,"timestamp":"2026-09-16T00:17:15.303864Z"}]}}
{"v":1,"kind":"tick","pair":"ADA/USD","channel":"book","ts_exchange":"2026-09-16T00:17:15.304610Z","ts_recv":"2026-09-16T00:17:15.434081Z","payload":{"channel":"book","type":"update","data":[{"symbol":"ADA/USD","bids":[{"price":0.194663,"qty":3008.7}],"asks":[],"checksum":455705688,"timestamp":"2026-09-16T00:17:15.304610Z"}]}}
{"v":1,"kind":"tick","pair":"ADA/USD","channel":"book","ts_exchange":"2026-09-16T00:17:15.405069Z","ts_recv":"2026-09-16T00:17:15.532442Z","payload":{"channel":"book","type":"update","data":[{"symbol":"ADA/USD","bids":[{"price":0.19466,"qty":0.0},{"price":0.194622,"qty":2569.07582444}],"asks":[],"checksum":795172694,"timestamp":"2026-09-16T00:17:15.405069Z"}]}}
{"v":1,"kind":"tick","pair":"ADA/USD","channel":"book","ts_exchange":"2026-09-16T00:17:15.505647Z","ts_recv":"2026-09-16T00:17:15.656533Z","payload":{"channel":"book","type":"update","data":[{"symbol":"ADA/USD","bids":[{"price":0.194661,"qty":0.0},{"price":0.194615,"qty":2569.17503789},{"price":0.194664,"qty":3079.1465085}],"asks":[],"checksum":1271814916,"timestamp":"2026-09-16T00:17:15.505647Z"}]}}
{"v":1,"kind":"tick","pair":"ADA/USD","channel":"book","ts_exchange":"2026-09-16T00:17:15.506632Z","ts_recv":"2026-09-16T00:17:15.656702Z","payload":{"channel":"book","type":"update","data":[{"symbol":"ADA/USD","bids":[{"price":0.194662,"qty":0.0},{"price":0.194615,"qty":2569.17503789}],"asks":[],"checksum":628915015,"timestamp":"2026-09-16T00:17:15.506632Z"}]}}
{"v":1,"kind":"tick","pair":"ADA/USD","channel":"book","ts_exchange":"2026-09-16T00:17:15.506829Z","ts_recv":"2026-09-16T00:17:15.657129Z","payload":{"channel":"book","type":"update","data":[{"symbol":"ADA/USD","bids":[{"price":0.194665,"qty":3008.7}],"asks":[],"checksum":2469685364,"timestamp":"2026-09-16T00:17:15.506829Z"}]}}
{"v":1,"kind":"tick","pair":"ADA/USD","channel":"book","ts_exchange":"2026-09-16T00:17:15.583938Z","ts_recv":"2026-09-16T00:17:15.711593Z","payload":{"channel":"book","type":"update","data":[{"symbol":"ADA/USD","bids":[],"asks":[{"price":0.194785,"qty":0.0},{"price":0.194841,"qty":20349.83229176}],"checksum":2556162800,"timestamp":"2026-09-16T00:17:15.583938Z"}]}}
{"v":1,"kind":"tick","pair":"ADA/USD","channel":"book","ts_exchange":"2026-09-16T00:17:15.584853Z","ts_recv":"2026-09-16T00:17:15.712433Z","payload":{"channel":"book","type":"update","data":[{"symbol":"ADA/USD","bids":[],"asks":[{"price":0.194784,"qty":0.0},{"price":0.194845,"qty":3008.7},{"price":0.194786,"qty":3079.1465085}],"checksum":2700131684,"timestamp":"2026-09-16T00:17:15.584853Z"}]}}
{"v":1,"kind":"tick","pair":"ADA/USD","channel":"book","ts_exchange":"2026-09-16T00:17:15.607303Z","ts_recv":"2026-09-16T00:17:15.749604Z","payload":{"channel":"book","type":"update","data":[{"symbol":"ADA/USD","bids":[{"price":0.194663,"qty":0.0},{"price":0.194615,"qty":2569.17503789}],"asks":[],"checksum":269869612,"timestamp":"2026-09-16T00:17:15.607303Z"}]}}
{"v":1,"kind":"tick","pair":"ADA/USD","channel":"book","ts_exchange":"2026-09-16T00:17:15.731649Z","ts_recv":"2026-09-16T00:17:15.859879Z","payload":{"channel":"book","type":"update","data":[{"symbol":"ADA/USD","bids":[{"price":0.194664,"qty":0.0},{"price":0.194597,"qty":3034.02570007},{"price":0.194666,"qty":3079.1465085}],"asks":[],"checksum":3182155348,"timestamp":"2026-09-16T00:17:15.731649Z"}]}}
{"v":1,"kind":"tick","pair":"ADA/USD","channel":"book","ts_exchange":"2026-09-16T00:17:15.732551Z","ts_recv":"2026-09-16T00:17:15.864604Z","payload":{"channel":"book","type":"update","data":[{"symbol":"ADA/USD","bids":[{"price":0.194667,"qty":3008.7}],"asks":[],"checksum":2844079838,"timestamp":"2026-09-16T00:17:15.732551Z"}]}}
{"v":1,"kind":"tick","pair":"ADA/USD","channel":"book","ts_exchange":"2026-09-16T00:17:15.833005Z","ts_recv":"2026-09-16T00:17:15.973552Z","payload":{"channel":"book","type":"update","data":[{"symbol":"ADA/USD","bids":[{"price":0.194665,"qty":0.0},{"price":0.194615,"qty":2569.17503789}],"asks":[],"checksum":2931913985,"timestamp":"2026-09-16T00:17:15.833005Z"}]}}
{"v":1,"kind":"tick","pair":"ADA/USD","channel":"book","ts_exchange":"2026-09-16T00:17:15.895917Z","ts_recv":"2026-09-16T00:17:16.027971Z","payload":{"channel":"book","type":"update","data":[{"symbol":"ADA/USD","bids":[{"price":0.194666,"qty":0.0},{"price":0.194597,"qty":3034.02570007},{"price":0.194668,"qty":3079.1465085}],"asks":[],"checksum":221122151,"timestamp":"2026-09-16T00:17:15.895917Z"}]}}
{"v":1,"kind":"tick","pair":"ADA/USD","channel":"book","ts_exchange":"2026-09-16T00:17:15.897218Z","ts_recv":"2026-09-16T00:17:16.039664Z","payload":{"channel":"book","type":"update","data":[{"symbol":"ADA/USD","bids":[{"price":0.194669,"qty":3008.7}],"asks":[],"checksum":4244166189,"timestamp":"2026-09-16T00:17:15.897218Z"}]}}
{"v":1,"kind":"tick","pair":"ADA/USD","channel":"book","ts_exchange":"2026-09-16T00:17:15.997756Z","ts_recv":"2026-09-16T00:17:16.122562Z","payload":{"channel":"book","type":"update","data":[{"symbol":"ADA/USD","bids":[{"price":0.194667,"qty":0.0},{"price":0.194615,"qty":2569.17503789}],"asks":[],"checksum":537697344,"timestamp":"2026-09-16T00:17:15.997756Z"}]}}
{"v":1,"kind":"tick","pair":"ADA/USD","channel":"book","ts_exchange":"2026-09-16T00:17:16.102254Z","ts_recv":"2026-09-16T00:17:16.237555Z","payload":{"channel":"book","type":"update","data":[{"symbol":"ADA/USD","bids":[{"price":0.194668,"qty":0.0},{"price":0.194597,"qty":3034.02570007},{"price":0.19467,"qty":3079.1465085}],"asks":[],"checksum":2437641808,"timestamp":"2026-09-16T00:17:16.102254Z"}]}}
{"v":1,"kind":"tick","pair":"ADA/USD","channel":"book","ts_exchange":"2026-09-16T00:17:16.103041Z","ts_recv":"2026-09-16T00:17:16.237740Z","payload":{"channel":"book","type":"update","data":[{"symbol":"ADA/USD","bids":[{"price":0.194671,"qty":3008.7}],"asks":[],"checksum":654996214,"timestamp":"2026-09-16T00:17:16.103041Z"}]}}
{"v":1,"kind":"tick","pair":"ADA/USD","channel":"book","ts_exchange":"2026-09-16T00:17:16.203570Z","ts_recv":"2026-09-16T00:17:16.329050Z","payload":{"channel":"book","type":"update","data":[{"symbol":"ADA/USD","bids":[{"price":0.194669,"qty":0.0},{"price":0.194615,"qty":2569.17503789}],"asks":[],"checksum":2491223622,"timestamp":"2026-09-16T00:17:16.203570Z"}]}}
{"v":1,"kind":"tick","pair":"ADA/USD","channel":"book","ts_exchange":"2026-09-16T00:17:16.277127Z","ts_recv":"2026-09-16T00:17:16.409601Z","payload":{"channel":"book","type":"update","data":[{"symbol":"ADA/USD","bids":[{"price":0.19467,"qty":0.0},{"price":0.194597,"qty":3034.02570007},{"price":0.194672,"qty":3079.1465085}],"asks":[],"checksum":969095742,"timestamp":"2026-09-16T00:17:16.277127Z"}]}}
{"v":1,"kind":"tick","pair":"ADA/USD","channel":"book","ts_exchange":"2026-09-16T00:17:16.277961Z","ts_recv":"2026-09-16T00:17:16.410951Z","payload":{"channel":"book","type":"update","data":[{"symbol":"ADA/USD","bids":[{"price":0.194673,"qty":3008.7}],"asks":[],"checksum":3198057957,"timestamp":"2026-09-16T00:17:16.277961Z"}]}}
{"v":1,"kind":"tick","pair":"BTC/USD","channel":"book","ts_exchange":"2026-09-16T00:17:16.365620Z","ts_recv":"2026-09-16T00:17:16.500808Z","payload":{"channel":"book","type":"update","data":[{"symbol":"BTC/USD","bids":[{"price":75727.8,"qty":0.0},{"price":75723.4,"qty":0.000051}],"asks":[],"checksum":2778793593,"timestamp":"2026-09-16T00:17:16.365620Z"}]}}
{"v":1,"kind":"tick","pair":"BTC/USD","channel":"book","ts_exchange":"2026-09-16T00:17:16.366565Z","ts_recv":"2026-09-16T00:17:16.504548Z","payload":{"channel":"book","type":"update","data":[{"symbol":"BTC/USD","bids":[{"price":75726.6,"qty":1.3205386}],"asks":[],"checksum":2496495508,"timestamp":"2026-09-16T00:17:16.366565Z"}]}}
{"v":1,"kind":"tick","pair":"BTC/USD","channel":"book","ts_exchange":"2026-09-16T00:17:16.369257Z","ts_recv":"2026-09-16T00:17:16.511567Z","payload":{"channel":"book","type":"update","data":[{"symbol":"BTC/USD","bids":[{"price":75731.8,"qty":0.00069517}],"asks":[],"checksum":541312595,"timestamp":"2026-09-16T00:17:16.369257Z"}]}}
{"v":1,"kind":"tick","pair":"BTC/USD","channel":"book","ts_exchange":"2026-09-16T00:17:16.372200Z","ts_recv":"2026-09-16T00:17:16.512315Z","payload":{"channel":"book","type":"update","data":[{"symbol":"BTC/USD","bids":[{"price":75731.8,"qty":0.01161095}],"asks":[],"checksum":2496495508,"timestamp":"2026-09-16T00:17:16.372200Z"}]}}
{"v":1,"kind":"tick","pair":"ADA/USD","channel":"book","ts_exchange":"2026-09-16T00:17:16.378450Z","ts_recv":"2026-09-16T00:17:16.514566Z","payload":{"channel":"book","type":"update","data":[{"symbol":"ADA/USD","bids":[{"price":0.194671,"qty":0.0},{"price":0.194615,"qty":2569.17503789}],"asks":[],"checksum":715757931,"timestamp":"2026-09-16T00:17:16.378450Z"}]}}
{"v":1,"kind":"tick","pair":"ADA/USD","channel":"book","ts_exchange":"2026-09-16T00:17:16.474059Z","ts_recv":"2026-09-16T00:17:16.613647Z","payload":{"channel":"book","type":"update","data":[{"symbol":"ADA/USD","bids":[{"price":0.194672,"qty":0.0},{"price":0.194597,"qty":3034.02570007},{"price":0.194674,"qty":3079.1465085}],"asks":[],"checksum":872966694,"timestamp":"2026-09-16T00:17:16.474059Z"}]}}
{"v":1,"kind":"tick","pair":"ADA/USD","channel":"book","ts_exchange":"2026-09-16T00:17:16.475063Z","ts_recv":"2026-09-16T00:17:16.614710Z","payload":{"channel":"book","type":"update","data":[{"symbol":"ADA/USD","bids":[{"price":0.194675,"qty":3008.7}],"asks":[],"checksum":2099432289,"timestamp":"2026-09-16T00:17:16.475063Z"}]}}
{"v":1,"kind":"tick","pair":"ADA/USD","channel":"book","ts_exchange":"2026-09-16T00:17:16.575570Z","ts_recv":"2026-09-16T00:17:16.713023Z","payload":{"channel":"book","type":"update","data":[{"symbol":"ADA/USD","bids":[{"price":0.194673,"qty":0.0},{"price":0.194615,"qty":2569.17503789}],"asks":[],"checksum":849684061,"timestamp":"2026-09-16T00:17:16.575570Z"}]}}
{"v":1,"kind":"tick","pair":"ADA/USD","channel":"book","ts_exchange":"2026-09-16T00:17:16.576271Z","ts_recv":"2026-09-16T00:17:16.713247Z","payload":{"channel":"book","type":"update","data":[{"symbol":"ADA/USD","bids":[],"asks":[{"price":0.194785,"qty":1947.18307933}],"checksum":477563954,"timestamp":"2026-09-16T00:17:16.576271Z"}]}}
{"v":1,"kind":"tick","pair":"ADA/USD","channel":"book","ts_exchange":"2026-09-16T00:17:16.577036Z","ts_recv":"2026-09-16T00:17:16.713447Z","payload":{"channel":"book","type":"update","data":[{"symbol":"ADA/USD","bids":[],"asks":[{"price":0.194786,"qty":0.0},{"price":0.194841,"qty":20349.83229176},{"price":0.194784,"qty":3079.1465085}],"checksum":1115258806,"timestamp":"2026-09-16T00:17:16.577036Z"}]}}
{"v":1,"kind":"tick","pair":"ADA/USD","channel":"book","ts_exchange":"2026-09-16T00:17:16.577622Z","ts_recv":"2026-09-16T00:17:16.721507Z","payload":{"channel":"book","type":"update","data":[{"symbol":"ADA/USD","bids":[],"asks":[{"price":0.194785,"qty":0.0},{"price":0.194841,"qty":20349.83229176}],"checksum":168716745,"timestamp":"2026-09-16T00:17:16.577622Z"}]}}
{"v":1,"kind":"tick","pair":"ADA/USD","channel":"book","ts_exchange":"2026-09-16T00:17:16.577709Z","ts_recv":"2026-09-16T00:17:16.721984Z","payload":{"channel":"book","type":"update","data":[{"symbol":"ADA/USD","bids":[],"asks":[{"price":0.194783,"qty":1947.18307933}],"checksum":2753492245,"timestamp":"2026-09-16T00:17:16.577709Z"}]}}
{"v":1,"kind":"tick","pair":"ADA/USD","channel":"book","ts_exchange":"2026-09-16T00:17:16.663272Z","ts_recv":"2026-09-16T00:17:16.793817Z","payload":{"channel":"book","type":"update","data":[{"symbol":"ADA/USD","bids":[{"price":0.194674,"qty":0.0},{"price":0.194597,"qty":3034.02570007},{"price":0.194676,"qty":3079.1465085}],"asks":[],"checksum":161530221,"timestamp":"2026-09-16T00:17:16.663272Z"}]}}
{"v":1,"kind":"tick","pair":"ADA/USD","channel":"book","ts_exchange":"2026-09-16T00:17:16.664218Z","ts_recv":"2026-09-16T00:17:16.794993Z","payload":{"channel":"book","type":"update","data":[{"symbol":"ADA/USD","bids":[{"price":0.194677,"qty":3008.7}],"asks":[],"checksum":3807155091,"timestamp":"2026-09-16T00:17:16.664218Z"}]}}
{"v":1,"kind":"tick","pair":"ADA/USD","channel":"book","ts_exchange":"2026-09-16T00:17:16.751955Z","ts_recv":"2026-09-16T00:17:16.884265Z","payload":{"channel":"book","type":"update","data":[{"symbol":"ADA/USD","bids":[{"price":0.194678,"qty":1040.0}],"asks":[],"checksum":3758934398,"timestamp":"2026-09-16T00:17:16.751955Z"}]}}
{"v":1,"kind":"tick","pair":"ADA/USD","channel":"book","ts_exchange":"2026-09-16T00:17:16.752782Z","ts_recv":"2026-09-16T00:17:16.884744Z","payload":{"channel":"book","type":"update","data":[{"symbol":"ADA/USD","bids":[],"asks":[{"price":0.194784,"qty":0.0},{"price":0.194841,"qty":20349.83229176},{"price":0.194782,"qty":3079.1465085}],"checksum":3892226936,"timestamp":"2026-09-16T00:17:16.752782Z"}]}}
{"v":1,"kind":"tick","pair":"ADA/USD","channel":"book","ts_exchange":"2026-09-16T00:17:16.753399Z","ts_recv":"2026-09-16T00:17:16.885139Z","payload":{"channel":"book","type":"update","data":[{"symbol":"ADA/USD","bids":[],"asks":[{"price":0.194783,"qty":0.0},{"price":0.194841,"qty":20349.83229176}],"checksum":132220190,"timestamp":"2026-09-16T00:17:16.753399Z"}]}}
{"v":1,"kind":"tick","pair":"ADA/USD","channel":"book","ts_exchange":"2026-09-16T00:17:16.753466Z","ts_recv":"2026-09-16T00:17:16.893417Z","payload":{"channel":"book","type":"update","data":[{"symbol":"ADA/USD","bids":[],"asks":[{"price":0.194781,"qty":1947.18307933}],"checksum":3867377823,"timestamp":"2026-09-16T00:17:16.753466Z"}]}}
{"v":1,"kind":"tick","pair":"ADA/USD","channel":"book","ts_exchange":"2026-09-16T00:17:16.764707Z","ts_recv":"2026-09-16T00:17:16.904150Z","payload":{"channel":"book","type":"update","data":[{"symbol":"ADA/USD","bids":[{"price":0.194675,"qty":0.0},{"price":0.194622,"qty":2569.07582444}],"asks":[],"checksum":3362326359,"timestamp":"2026-09-16T00:17:16.764707Z"}]}}
{"v":1,"kind":"tick","pair":"ADA/USD","channel":"book","ts_exchange":"2026-09-16T00:17:16.765443Z","ts_recv":"2026-09-16T00:17:16.904666Z","payload":{"channel":"book","type":"update","data":[{"symbol":"ADA/USD","bids":[{"price":0.194679,"qty":3008.7}],"asks":[],"checksum":3924066920,"timestamp":"2026-09-16T00:17:16.765443Z"}]}}
{"v":1,"kind":"tick","pair":"ADA/USD","channel":"book","ts_exchange":"2026-09-16T00:17:16.852208Z","ts_recv":"2026-09-16T00:17:16.997064Z","payload":{"channel":"book","type":"update","data":[{"symbol":"ADA/USD","bids":[],"asks":[{"price":0.194781,"qty":0.0},{"price":0.194841,"qty":20349.83229176}],"checksum":143034345,"timestamp":"2026-09-16T00:17:16.852208Z"}]}}
{"v":1,"kind":"tick","pair":"ADA/USD","channel":"book","ts_exchange":"2026-09-16T00:17:16.853019Z","ts_recv":"2026-09-16T00:17:16.998549Z","payload":{"channel":"book","type":"update","data":[{"symbol":"ADA/USD","bids":[{"price":0.194676,"qty":0.0},{"price":0.194622,"qty":2569.07582444},{"price":0.19468,"qty":3079.1465085}],"asks":[],"checksum":3365086302,"timestamp":"2026-09-16T00:17:16.853019Z"}]}}
{"v":1,"kind":"tick","pair":"ADA/USD","channel":"book","ts_exchange":"2026-09-16T00:17:16.865947Z","ts_recv":"2026-09-16T00:17:16.999643Z","payload":{"channel":"book","type":"update","data":[{"symbol":"ADA/USD","bids":[{"price":0.194677,"qty":0.0},{"price":0.194622,"qty":2569.07582444}],"asks":[],"checksum":397399339,"timestamp":"2026-09-16T00:17:16.865947Z"}]}}
{"v":1,"kind":"tick","pair":"ADA/USD","channel":"book","ts_exchange":"2026-09-16T00:17:16.866736Z","ts_recv":"2026-09-16T00:17:17.004874Z","payload":{"channel":"book","type":"update","data":[{"symbol":"ADA/USD","bids":[{"price":0.194681,"qty":3008.7}],"asks":[],"checksum":3187454440,"timestamp":"2026-09-16T00:17:16.866736Z"}]}}
{"v":1,"kind":"tick","pair":"ADA/USD","channel":"book","ts_exchange":"2026-09-16T00:17:16.916370Z","ts_recv":"2026-09-16T00:17:17.055260Z","payload":{"channel":"book","type":"update","data":[{"symbol":"ADA/USD","bids":[],"asks":[{"price":0.194782,"qty":0.0},{"price":0.194845,"qty":3008.7},{"price":0.194786,"qty":3079.1465085}],"checksum":3433705152,"timestamp":"2026-09-16T00:17:16.916370Z"}]}}
{"v":1,"kind":"tick","pair":"ADA/USD","channel":"book","ts_exchange":"2026-09-16T00:17:16.917191Z","ts_recv":"2026-09-16T00:17:17.055803Z","payload":{"channel":"book","type":"update","data":[{"symbol":"ADA/USD","bids":[],"asks":[{"price":0.194785,"qty":1947.18307933}],"checksum":3799516335,"timestamp":"2026-09-16T00:17:16.917191Z"}]}}
{"v":1,"kind":"tick","pair":"ADA/USD","channel":"book","ts_exchange":"2026-09-16T00:17:16.968692Z","ts_recv":"2026-09-16T00:17:17.104165Z","payload":{"channel":"book","type":"update","data":[{"symbol":"ADA/USD","bids":[{"price":0.194679,"qty":0.0},{"price":0.194622,"qty":2569.07582444}],"asks":[],"checksum":2638849355,"timestamp":"2026-09-16T00:17:16.968692Z"}]}}
{"v":1,"kind":"tick","pair":"ADA/USD","channel":"book","ts_exchange":"2026-09-16T00:17:17.130514Z","ts_recv":"2026-09-16T00:17:17.264992Z","payload":{"channel":"book","type":"update","data":[{"symbol":"ADA/USD","bids":[],"asks":[{"price":0.194786,"qty":0.0},{"price":0.194841,"qty":20349.83229176},{"price":0.194784,"qty":3079.1465085}],"checksum":3276265167,"timestamp":"2026-09-16T00:17:17.130514Z"}]}}
{"v":1,"kind":"tick","pair":"ADA/USD","channel":"book","ts_exchange":"2026-09-16T00:17:17.131183Z","ts_recv":"2026-09-16T00:17:17.265397Z","payload":{"channel":"book","type":"update","data":[{"symbol":"ADA/USD","bids":[],"asks":[{"price":0.194785,"qty":0.0},{"price":0.194841,"qty":20349.83229176}],"checksum":2335228080,"timestamp":"2026-09-16T00:17:17.131183Z"}]}}
{"v":1,"kind":"tick","pair":"ADA/USD","channel":"book","ts_exchange":"2026-09-16T00:17:17.131428Z","ts_recv":"2026-09-16T00:17:17.265753Z","payload":{"channel":"book","type":"update","data":[{"symbol":"ADA/USD","bids":[],"asks":[{"price":0.194783,"qty":1947.18307933}],"checksum":622877804,"timestamp":"2026-09-16T00:17:17.131428Z"}]}}
{"v":1,"kind":"tick","pair":"ADA/USD","channel":"book","ts_exchange":"2026-09-16T00:17:17.223552Z","ts_recv":"2026-09-16T00:17:17.356429Z","payload":{"channel":"book","type":"update","data":[{"symbol":"ADA/USD","bids":[{"price":0.19468,"qty":0.0},{"price":0.194615,"qty":2569.17503789},{"price":0.194682,"qty":3079.1465085}],"asks":[],"checksum":2292082708,"timestamp":"2026-09-16T00:17:17.223552Z"}]}}
{"v":1,"kind":"tick","pair":"ADA/USD","channel":"book","ts_exchange":"2026-09-16T00:17:17.329402Z","ts_recv":"2026-09-16T00:17:17.506950Z","payload":{"channel":"book","type":"update","data":[{"symbol":"ADA/USD","bids":[],"asks":[{"price":0.194784,"qty":0.0},{"price":0.194841,"qty":20349.83229176},{"price":0.194782,"qty":3079.1465085}],"checksum":2406222354,"timestamp":"2026-09-16T00:17:17.329402Z"}]}}
{"v":1,"kind":"tick","pair":"ADA/USD","channel":"book","ts_exchange":"2026-09-16T00:17:17.330395Z","ts_recv":"2026-09-16T00:17:17.509313Z","payload":{"channel":"book","type":"update","data":[{"symbol":"ADA/USD","bids":[],"asks":[{"price":0.194783,"qty":0.0},{"price":0.194841,"qty":20349.83229176}],"checksum":1869816948,"timestamp":"2026-09-16T00:17:17.330395Z"}]}}
{"v":1,"kind":"tick","pair":"ADA/USD","channel":"book","ts_exchange":"2026-09-16T00:17:17.330463Z","ts_recv":"2026-09-16T00:17:17.510602Z","payload":{"channel":"book","type":"update","data":[{"symbol":"ADA/USD","bids":[],"asks":[{"price":0.194783,"qty":1028.05784654}],"checksum":3430188777,"timestamp":"2026-09-16T00:17:17.330463Z"}]}}
{"v":1,"kind":"tick","pair":"BTC/USD","channel":"book","ts_exchange":"2026-09-16T00:17:17.535678Z","ts_recv":"2026-09-16T00:17:17.664293Z","payload":{"channel":"book","type":"update","data":[{"symbol":"BTC/USD","bids":[{"price":75726.6,"qty":0.0},{"price":75723.4,"qty":0.000051}],"asks":[],"checksum":2778793593,"timestamp":"2026-09-16T00:17:17.535678Z"}]}}
{"v":1,"kind":"tick","pair":"BTC/USD","channel":"book","ts_exchange":"2026-09-16T00:17:17.536589Z","ts_recv":"2026-09-16T00:17:17.666376Z","payload":{"channel":"book","type":"update","data":[{"symbol":"BTC/USD","bids":[{"price":75727.4,"qty":1.3205248}],"asks":[],"checksum":2813009463,"timestamp":"2026-09-16T00:17:17.536589Z"}]}}
{"v":1,"kind":"tick","pair":"BTC/USD","channel":"book","ts_exchange":"2026-09-16T00:17:18.000003Z","ts_recv":"2026-09-16T00:17:18.133246Z","payload":{"channel":"book","type":"update","data":[{"symbol":"BTC/USD","bids":[],"asks":[{"price":75734.0,"qty":0.0},{"price":75734.4,"qty":3.30101414}],"checksum":875813699,"timestamp":"2026-09-16T00:17:18.000003Z"}]}}
{"v":1,"kind":"tick","pair":"BTC/USD","channel":"book","ts_exchange":"2026-09-16T00:17:18.234955Z","ts_recv":"2026-09-16T00:17:18.371242Z","payload":{"channel":"book","type":"update","data":[{"symbol":"BTC/USD","bids":[],"asks":[{"price":75733.2,"qty":3.30106321}],"checksum":3650024792,"timestamp":"2026-09-16T00:17:18.234955Z"}]}}
{"v":1,"kind":"tick","pair":"BTC/USD","channel":"book","ts_exchange":"2026-09-16T00:17:18.238245Z","ts_recv":"2026-09-16T00:17:18.371785Z","payload":{"channel":"book","type":"update","data":[{"symbol":"BTC/USD","bids":[],"asks":[{"price":75731.9,"qty":0.09872832}],"checksum":3507365258,"timestamp":"2026-09-16T00:17:18.238245Z"}]}}
{"v":1,"kind":"tick","pair":"BTC/USD","channel":"book","ts_exchange":"2026-09-16T00:17:18.238547Z","ts_recv":"2026-09-16T00:17:18.371962Z","payload":{"channel":"book","type":"update","data":[{"symbol":"BTC/USD","bids":[{"price":75731.8,"qty":0.00069517}],"asks":[],"checksum":3048227833,"timestamp":"2026-09-16T00:17:18.238547Z"}]}}
{"v":1,"kind":"tick","pair":"BTC/USD","channel":"book","ts_exchange":"2026-09-16T00:17:18.309342Z","ts_recv":"2026-09-16T00:17:18.441278Z","payload":{"channel":"book","type":"update","data":[{"symbol":"BTC/USD","bids":[{"price":75725.3,"qty":0.0},{"price":75723.4,"qty":0.000051}],"asks":[],"checksum":1592586359,"timestamp":"2026-09-16T00:17:18.309342Z"}]}}
{"v":1,"kind":"tick","pair":"BTC/USD","channel":"book","ts_exchange":"2026-09-16T00:17:18.310665Z","ts_recv":"2026-09-16T00:17:18.441608Z","payload":{"channel":"book","type":"update","data":[{"symbol":"BTC/USD","bids":[{"price":75725.4,"qty":0.0},{"price":75720.5,"qty":1.09672221},{"price":75725.3,"qty":0.11117396}],"asks":[],"checksum":4110357899,"timestamp":"2026-09-16T00:17:18.310665Z"}]}}
{"v":1,"kind":"tick","pair":"BTC/USD","channel":"book","ts_exchange":"2026-09-16T00:17:18.310713Z","ts_recv":"2026-09-16T00:17:18.441942Z","payload":{"channel":"book","type":"update","data":[{"symbol":"BTC/USD","bids":[{"price":75724.2,"qty":0.0},{"price":75720.5,"qty":1.09672221}],"asks":[],"checksum":2438753494,"timestamp":"2026-09-16T00:17:18.310713Z"}]}}
{"v":1,"kind":"tick","pair":"BTC/USD","channel":"book","ts_exchange":"2026-09-16T00:17:18.312288Z","ts_recv":"2026-09-16T00:17:18.442119Z","payload":{"channel":"book","type":"update","data":[{"symbol":"BTC/USD","bids":[{"price":75727.4,"qty":0.0},{"price":75720.4,"qty":3.30161818}],"asks":[],"checksum":1476853892,"timestamp":"2026-09-16T00:17:18.312288Z"}]}}
{"v":1,"kind":"tick","pair":"BTC/USD","channel":"book","ts_exchange":"2026-09-16T00:17:18.312639Z","ts_recv":"2026-09-16T00:17:18.451046Z","payload":{"channel":"book","type":"update","data":[{"symbol":"BTC/USD","bids":[{"price":75725.2,"qty":0.0},{"price":75719.6,"qty":0.000051}],"asks":[],"checksum":2757952381,"timestamp":"2026-09-16T00:17:18.312639Z"}]}}
{"v":1,"kind":"tick","pair":"BTC/USD","channel":"book","ts_exchange":"2026-09-16T00:17:18.313592Z","ts_recv":"2026-09-16T00:17:18.451287Z","payload":{"channel":"book","type":"update","data":[{"symbol":"BTC/USD","bids":[{"price":75725.8,"qty":1.32055371}],"asks":[],"checksum":2446074417,"timestamp":"2026-09-16T00:17:18.313592Z"}]}}
{"v":1,"kind":"tick","pair":"BTC/USD","channel":"book","ts_exchange":"2026-09-16T00:17:18.313807Z","ts_recv":"2026-09-16T00:17:18.451461Z","payload":{"channel":"book","type":"update","data":[{"symbol":"BTC/USD","bids":[{"price":75723.2,"qty":3.30149548}],"asks":[],"checksum":3962814016,"timestamp":"2026-09-16T00:17:18.313807Z"}]}}
{"v":1,"kind":"tick","pair":"BTC/USD","channel":"book","ts_exchange":"2026-09-16T00:17:18.316143Z","ts_recv":"2026-09-16T00:17:18.451630Z","payload":{"channel":"book","type":"update","data":[{"symbol":"BTC/USD","bids":[{"price":75720.6,"qty":0.00105736}],"asks":[],"checksum":1000806565,"timestamp":"2026-09-16T00:17:18.316143Z"}]}}
{"v":1,"kind":"tick","pair":"BTC/USD","channel":"book","ts_exchange":"2026-09-16T00:17:18.320209Z","ts_recv":"2026-09-16T00:17:18.451793Z","payload":{"channel":"book","type":"update","data":[{"symbol":"BTC/USD","bids":[{"price":75725.8,"qty":0.0},{"price":75720.5,"qty":1.09672221}],"asks":[],"checksum":2978789654,"timestamp":"2026-09-16T00:17:18.320209Z"}]}}
{"v":1,"kind":"tick","pair":"BTC/USD","channel":"book","ts_exchange":"2026-09-16T00:17:18.321230Z","ts_recv":"2026-09-16T00:17:18.451955Z","payload":{"channel":"book","type":"update","data":[{"symbol":"BTC/USD","bids":[{"price":75720.5,"qty":0.11117396}],"asks":[],"checksum":2506448896,"timestamp":"2026-09-16T00:17:18.321230Z"}]}}
{"v":1,"kind":"tick","pair":"BTC/USD","channel":"book","ts_exchange":"2026-09-16T00:17:18.321932Z","ts_recv":"2026-09-16T00:17:18.452115Z","payload":{"channel":"book","type":"update","data":[{"symbol":"BTC/USD","bids":[{"price":75720.6,"qty":0.03425801}],"asks":[],"checksum":1276797445,"timestamp":"2026-09-16T00:17:18.321932Z"}]}}
{"v":1,"kind":"tick","pair":"BTC/USD","channel":"book","ts_exchange":"2026-09-16T00:17:18.335755Z","ts_recv":"2026-09-16T00:17:18.472663Z","payload":{"channel":"book","type":"update","data":[{"symbol":"BTC/USD","bids":[{"price":75724.0,"qty":0.0},{"price":75719.6,"qty":0.000051}],"asks":[],"checksum":3458640355,"timestamp":"2026-09-16T00:17:18.335755Z"}]}}
{"v":1,"kind":"tick","pair":"BTC/USD","channel":"book","ts_exchange":"2026-09-16T00:17:18.349237Z","ts_recv":"2026-09-16T00:17:18.482342Z","payload":{"channel":"book","type":"update","data":[{"symbol":"BTC/USD","bids":[{"price":75723.2,"qty":0.0},{"price":75718.1,"qty":0.02051113}],"asks":[],"checksum":1686819284,"timestamp":"2026-09-16T00:17:18.349237Z"}]}}
{"v":1,"kind":"tick","pair":"BTC/USD","channel":"book","ts_exchange":"2026-09-16T00:17:18.351959Z","ts_recv":"2026-09-16T00:17:18.491832Z","payload":{"channel":"book","type":"update","data":[{"symbol":"BTC/USD","bids":[{"price":75720.6,"qty":0.03320065}],"asks":[],"checksum":3383724752,"timestamp":"2026-09-16T00:17:18.351959Z"}]}}
{"v":1,"kind":"tick","pair":"BTC/USD","channel":"book","ts_exchange":"2026-09-16T00:17:18.363223Z","ts_recv":"2026-09-16T00:17:18.492693Z","payload":{"channel":"book","type":"update","data":[{"symbol":"BTC/USD","bids":[{"price":75723.3,"qty":0.99061375}],"asks":[],"checksum":942863947,"timestamp":"2026-09-16T00:17:18.363223Z"}]}}
{"v":1,"kind":"tick","pair":"BTC/USD","channel":"book","ts_exchange":"2026-09-16T00:17:18.369807Z","ts_recv":"2026-09-16T00:17:18.499729Z","payload":{"channel":"book","type":"update","data":[{"symbol":"BTC/USD","bids":[{"price":75725.3,"qty":0.0},{"price":75718.1,"qty":0.02051113}],"asks":[],"checksum":722477988,"timestamp":"2026-09-16T00:17:18.369807Z"}]}}
{"v":1,"kind":"tick","pair":"BTC/USD","channel":"book","ts_exchange":"2026-09-16T00:17:18.372675Z","ts_recv":"2026-09-16T00:17:18.511342Z","payload":{"channel":"book","type":"update","data":[{"symbol":"BTC/USD","bids":[],"asks":[{"price":75732.4,"qty":1.71224088}],"checksum":76727381,"timestamp":"2026-09-16T00:17:18.372675Z"}]}}
{"v":1,"kind":"tick","pair":"BTC/USD","channel":"book","ts_exchange":"2026-09-16T00:17:18.394664Z","ts_recv":"2026-09-16T00:17:18.532200Z","payload":{"channel":"book","type":"update","data":[{"symbol":"BTC/USD","bids":[],"asks":[{"price":75731.9,"qty":0.13623516}],"checksum":3983821787,"timestamp":"2026-09-16T00:17:18.394664Z"}]}}
{"v":1,"kind":"tick","pair":"BTC/USD","channel":"book","ts_exchange":"2026-09-16T00:17:18.395997Z","ts_recv":"2026-09-16T00:17:18.532675Z","payload":{"channel":"book","type":"update","data":[{"symbol":"BTC/USD","bids":[],"asks":[{"price":75734.3,"qty":0.95245258},{"price":75733.1,"qty":0.11117396}],"checksum":3564027494,"timestamp":"2026-09-16T00:17:18.395997Z"}]}}
{"v":1,"kind":"tick","pair":"BTC/USD","channel":"book","ts_exchange":"2026-09-16T00:17:18.470201Z","ts_recv":"2026-09-16T00:17:18.604317Z","payload":{"channel":"book","type":"update","data":[{"symbol":"BTC/USD","bids":[{"price":75723.3,"qty":0.0},{"price":75717.7,"qty":0.00105736}],"asks":[],"checksum":1035528480,"timestamp":"2026-09-16T00:17:18.470201Z"}]}}
{"v":1,"kind":"tick","pair":"BTC/USD","channel":"book","ts_exchange":"2026-09-16T00:17:18.471328Z","ts_recv":"2026-09-16T00:17:18.605280Z","payload":{"channel":"book","type":"update","data":[{"symbol":"BTC/USD","bids":[{"price":75720.5,"qty":0.0},{"price":75717.6,"qty":1.01545327},{"price":75720.7,"qty":0.01320355}],"asks":[],"checksum":4087102586,"timestamp":"2026-09-16T00:17:18.471328Z"}]}}
{"v":1,"kind":"tick","pair":"BTC/USD","channel":"book","ts_exchange":"2026-09-16T00:17:18.472039Z","ts_recv":"2026-09-16T00:17:18.606217Z","payload":{"channel":"book","type":"update","data":[{"symbol":"BTC/USD","bids":[{"price":75720.6,"qty":0.0},{"price":75717.6,"qty":1.01545327}],"asks":[],"checksum":2812032602,"timestamp":"2026-09-16T00:17:18.472039Z"}]}}
{"v":1,"kind":"tick","pair":"BTC/USD","channel":"book","ts_exchange":"2026-09-16T00:17:18.497153Z","ts_recv":"2026-09-16T00:17:18.647760Z","payload":{"channel":"book","type":"update","data":[{"symbol":"BTC/USD","bids":[],"asks":[{"price":75731.9,"qty":0.1354559}],"checksum":2364711459,"timestamp":"2026-09-16T00:17:18.497153Z"}]}}
{"v":1,"kind":"tick","pair":"BTC/USD","channel":"book","ts_exchange":"2026-09-16T00:17:18.513074Z","ts_recv":"2026-09-16T00:17:18.653347Z","payload":{"channel":"book","type":"update","data":[{"symbol":"BTC/USD","bids":[{"price":75721.8,"qty":0.99061375}],"asks":[],"checksum":4141532823,"timestamp":"2026-09-16T00:17:18.513074Z"}]}}
{"v":1,"kind":"tick","pair":"ADA/USD","channel":"book","ts_exchange":"2026-09-16T00:17:18.575936Z","ts_recv":"2026-09-16T00:17:18.772372Z","payload":{"channel":"book","type":"update","data":[{"symbol":"ADA/USD","bids":[],"asks":[{"price":0.194783,"qty":0.0},{"price":0.194841,"qty":20349.83229176}],"checksum":1869816948,"timestamp":"2026-09-16T00:17:18.575936Z"}]}}
{"v":1,"kind":"tick","pair":"ADA/USD","channel":"book","ts_exchange":"2026-09-16T00:17:18.576078Z","ts_recv":"2026-09-16T00:17:18.778425Z","payload":{"channel":"book","type":"update","data":[{"symbol":"ADA/USD","bids":[],"asks":[{"price":0.194781,"qty":1947.18307933}],"checksum":2383487477,"timestamp":"2026-09-16T00:17:18.576078Z"}]}}
{"v":1,"kind":"tick","pair":"ADA/USD","channel":"book","ts_exchange":"2026-09-16T00:17:18.576788Z","ts_recv":"2026-09-16T00:17:18.782416Z","payload":{"channel":"book","type":"update","data":[{"symbol":"ADA/USD","bids":[],"asks":[{"price":0.194782,"qty":0.0},{"price":0.194841,"qty":20349.83229176},{"price":0.194786,"qty":3079.1465085}],"checksum":3622645879,"timestamp":"2026-09-16T00:17:18.576788Z"}]}}
{"v":1,"kind":"tick","pair":"BTC/USD","channel":"book","ts_exchange":"2026-09-16T00:17:18.640202Z","ts_recv":"2026-09-16T00:17:18.817287Z","payload":{"channel":"book","type":"update","data":[{"symbol":"BTC/USD","bids":[{"price":75720.7,"qty":0.0},{"price":75717.6,"qty":1.01545327},{"price":75721.9,"qty":0.11117396}],"asks":[],"checksum":2841154716,"timestamp":"2026-09-16T00:17:18.640202Z"}]}}
{"v":1,"kind":"tick","pair":"ADA/USD","channel":"book","ts_exchange":"2026-09-16T00:17:18.643899Z","ts_recv":"2026-09-16T00:17:18.821012Z","payload":{"channel":"book","type":"update","data":[{"symbol":"ADA/USD","bids":[],"asks":[{"price":0.194781,"qty":0.0},{"price":0.194841,"qty":20349.83229176}],"checksum":505789276,"timestamp":"2026-09-16T00:17:18.643899Z"}]}}
{"v":1,"kind":"tick","pair":"ADA/USD","channel":"book","ts_exchange":"2026-09-16T00:17:18.644714Z","ts_recv":"2026-09-16T00:17:18.822659Z","payload":{"channel":"book","type":"update","data":[{"symbol":"ADA/USD","bids":[],"asks":[{"price":0.194785,"qty":1947.18307933}],"checksum":821530931,"timestamp":"2026-09-16T00:17:18.644714Z"}]}}
{"v":1,"kind":"tick","pair":"ADA/USD","channel":"book","ts_exchange":"2026-09-16T00:17:18.750314Z","ts_recv":"2026-09-16T00:17:18.884631Z","payload":{"channel":"book","type":"update","data":[{"symbol":"ADA/USD","bids":[],"asks":[{"price":0.194786,"qty":0.0},{"price":0.194841,"qty":20349.83229176},{"price":0.194784,"qty":3079.1465085}],"checksum":1861870263,"timestamp":"2026-09-16T00:17:18.750314Z"}]}}
{"v":1,"kind":"tick","pair":"ADA/USD","channel":"book","ts_exchange":"2026-09-16T00:17:18.751220Z","ts_recv":"2026-09-16T00:17:18.885794Z","payload":{"channel":"book","type":"update","data":[{"symbol":"ADA/USD","bids":[],"asks":[{"price":0.194783,"qty":1947.18307933}],"checksum":701788283,"timestamp":"2026-09-16T00:17:18.751220Z"}]}}
{"v":1,"kind":"tick","pair":"ADA/USD","channel":"book","ts_exchange":"2026-09-16T00:17:18.751243Z","ts_recv":"2026-09-16T00:17:18.886419Z","payload":{"channel":"book","type":"update","data":[{"symbol":"ADA/USD","bids":[],"asks":[{"price":0.194785,"qty":0.0},{"price":0.19484,"qty":7891.99819803}],"checksum":2292082708,"timestamp":"2026-09-16T00:17:18.751243Z"}]}}
{"v":1,"kind":"tick","pair":"BTC/USD","channel":"book","ts_exchange":"2026-09-16T00:17:18.845188Z","ts_recv":"2026-09-16T00:17:19.001808Z","payload":{"channel":"book","type":"update","data":[{"symbol":"BTC/USD","bids":[{"price":75725.9,"qty":1.32055055}],"asks":[],"checksum":115118455,"timestamp":"2026-09-16T00:17:18.845188Z"}]}}
{"v":1,"kind":"tick","pair":"BTC/USD","channel":"book","ts_exchange":"2026-09-16T00:17:18.845327Z","ts_recv":"2026-09-16T00:17:19.004294Z","payload":{"channel":"book","type":"update","data":[{"symbol":"BTC/USD","bids":[{"price":75722.5,"qty":3.30152593}],"asks":[],"checksum":2502640591,"timestamp":"2026-09-16T00:17:18.845327Z"}]}}
{"v":1,"kind":"tick","pair":"ADA/USD","channel":"book","ts_exchange":"2026-09-16T00:17:18.913330Z","ts_recv":"2026-09-16T00:17:19.048335Z","payload":{"channel":"book","type":"update","data":[{"symbol":"ADA/USD","bids":[],"asks":[{"price":0.194784,"qty":0.0},{"price":0.194841,"qty":20349.83229176},{"price":0.194782,"qty":3079.1465085}],"checksum":2406222354,"timestamp":"2026-09-16T00:17:18.913330Z"}]}}
{"v":1,"kind":"tick","pair":"ADA/USD","channel":"book","ts_exchange":"2026-09-16T00:17:18.913999Z","ts_recv":"2026-09-16T00:17:19.049388Z","payload":{"channel":"book","type":"update","data":[{"symbol":"ADA/USD","bids":[],"asks":[{"price":0.194783,"qty":0.0},{"price":0.194841,"qty":20349.83229176}],"checksum":1869816948,"timestamp":"2026-09-16T00:17:18.913999Z"}]}}
{"v":1,"kind":"tick","pair":"ADA/USD","channel":"book","ts_exchange":"2026-09-16T00:17:18.914013Z","ts_recv":"2026-09-16T00:17:19.050516Z","payload":{"channel":"book","type":"update","data":[{"symbol":"ADA/USD","bids":[],"asks":[{"price":0.194783,"qty":1028.05784654}],"checksum":3430188777,"timestamp":"2026-09-16T00:17:18.914013Z"}]}}
{"v":1,"kind":"tick","pair":"BTC/USD","channel":"book","ts_exchange":"2026-09-16T00:17:18.931030Z","ts_recv":"2026-09-16T00:17:19.122180Z","payload":{"channel":"book","type":"update","data":[{"symbol":"BTC/USD","bids":[{"price":75722.5,"qty":0.0},{"price":75718.1,"qty":0.02051113}],"asks":[],"checksum":115118455,"timestamp":"2026-09-16T00:17:18.931030Z"}]}}
{"v":1,"kind":"tick","pair":"BTC/USD","channel":"book","ts_exchange":"2026-09-16T00:17:18.936058Z","ts_recv":"2026-09-16T00:17:19.133835Z","payload":{"channel":"book","type":"update","data":[{"symbol":"BTC/USD","bids":[{"price":75725.9,"qty":0.0},{"price":75717.7,"qty":0.00105736}],"asks":[],"checksum":2841154716,"timestamp":"2026-09-16T00:17:18.936058Z"}]}}
{"v":1,"kind":"tick","pair":"ADA/USD","channel":"book","ts_exchange":"2026-09-16T00:17:18.949317Z","ts_recv":"2026-09-16T00:17:19.135794Z","payload":{"channel":"book","type":"update","data":[{"symbol":"ADA/USD","bids":[],"asks":[{"price":0.194783,"qty":0.0},{"price":0.194841,"qty":20349.83229176}],"checksum":1869816948,"timestamp":"2026-09-16T00:17:18.949317Z"}]}}
{"v":1,"kind":"tick","pair":"BTC/USD","channel":"book","ts_exchange":"2026-09-16T00:17:19.161523Z","ts_recv":"2026-09-16T00:17:19.367036Z","payload":{"channel":"book","type":"update","data":[{"symbol":"BTC/USD","bids":[{"price":75724.2,"qty":0.0537}],"asks":[],"checksum":1143774352,"timestamp":"2026-09-16T00:17:19.161523Z"}]}}
{"v":1,"kind":"tick","pair":"BTC/USD","channel":"book","ts_exchange":"2026-09-16T00:17:19.194349Z","ts_recv":"2026-09-16T00:17:19.387776Z","payload":{"channel":"book","type":"update","data":[{"symbol":"BTC/USD","bids":[{"price":75721.9,"qty":0.0},{"price":75717.7,"qty":0.00105736},{"price":75724.3,"qty":0.013425}],"asks":[],"checksum":3321542350,"timestamp":"2026-09-16T00:17:19.194349Z"}]}}
{"v":1,"kind":"tick","pair":"BTC/USD","channel":"book","ts_exchange":"2026-09-16T00:17:19.228773Z","ts_recv":"2026-09-16T00:17:19.416802Z","payload":{"channel":"book","type":"update","data":[{"symbol":"BTC/USD","bids":[{"price":75726.6,"qty":1.32053958}],"asks":[],"checksum":2918014611,"timestamp":"2026-09-16T00:17:19.228773Z"}]}}
{"v":1,"kind":"tick","pair":"BTC/USD","channel":"book","ts_exchange":"2026-09-16T00:17:19.228813Z","ts_recv":"2026-09-16T00:17:19.417172Z","payload":{"channel":"book","type":"update","data":[{"symbol":"BTC/USD","bids":[{"price":75723.9,"qty":3.3014646}],"asks":[],"checksum":2932018936,"timestamp":"2026-09-16T00:17:19.228813Z"}]}}
{"v":1,"kind":"tick","pair":"ADA/USD","channel":"book","ts_exchange":"2026-09-16T00:17:19.232618Z","ts_recv":"2026-09-16T00:17:19.418800Z","payload":{"channel":"book","type":"update","data":[{"symbol":"ADA/USD","bids":[],"asks":[{"price":0.194782,"qty":0.0},{"price":0.194845,"qty":3008.7},{"price":0.194786,"qty":3079.1465085}],"checksum":505789276,"timestamp":"2026-09-16T00:17:19.232618Z"}]}}
{"v":1,"kind":"tick","pair":"ADA/USD","channel":"book","ts_exchange":"2026-09-16T00:17:19.234919Z","ts_recv":"2026-09-16T00:17:19.419768Z","payload":{"channel":"book","type":"update","data":[{"symbol":"ADA/USD","bids":[],"asks":[{"price":0.194785,"qty":1947.18307933}],"checksum":821530931,"timestamp":"2026-09-16T00:17:19.234919Z"}]}}
{"v":1,"kind":"tick","pair":"BTC/USD","channel":"book","ts_exchange":"2026-09-16T00:17:19.251750Z","ts_recv":"2026-09-16T00:17:19.466214Z","payload":{"channel":"book","type":"update","data":[{"symbol":"BTC/USD","bids":[{"price":75726.6,"qty":0.0},{"price":75719.6,"qty":0.000051}],"asks":[],"checksum":1912113772,"timestamp":"2026-09-16T00:17:19.251750Z"}]}}
{"v":1,"kind":"tick","pair":"BTC/USD","channel":"book","ts_exchange":"2026-09-16T00:17:19.310423Z","ts_recv":"2026-09-16T00:17:19.510828Z","payload":{"channel":"book","type":"update","data":[{"symbol":"BTC/USD","bids":[],"asks":[{"price":75731.9,"qty":0.09794906}],"checksum":1147205038,"timestamp":"2026-09-16T00:17:19.310423Z"}]}}
{"v":1,"kind":"tick","pair":"BTC/USD","channel":"book","ts_exchange":"2026-09-16T00:17:19.331008Z","ts_recv":"2026-09-16T00:17:19.527648Z","payload":{"channel":"book","type":"update","data":[{"symbol":"BTC/USD","bids":[{"price":75723.9,"qty":0.0},{"price":75718.1,"qty":0.02051113}],"asks":[],"checksum":271389489,"timestamp":"2026-09-16T00:17:19.331008Z"}]}}
{"v":1,"kind":"tick","pair":"BTC/USD","channel":"book","ts_exchange":"2026-09-16T00:17:19.331907Z","ts_recv":"2026-09-16T00:17:19.528020Z","payload":{"channel":"book","type":"update","data":[{"symbol":"BTC/USD","bids":[{"price":75728.1,"qty":1.32051337}],"asks":[],"checksum":3867970926,"timestamp":"2026-09-16T00:17:19.331907Z"}]}}
{"v":1,"kind":"tick","pair":"BTC/USD","channel":"book","ts_exchange":"2026-09-16T00:17:19.332037Z","ts_recv":"2026-09-16T00:17:19.528366Z","payload":{"channel":"book","type":"update","data":[{"symbol":"BTC/USD","bids":[{"price":75720.8,"qty":3.30160174}],"asks":[],"checksum":3174168940,"timestamp":"2026-09-16T00:17:19.332037Z"}]}}
{"v":1,"kind":"tick","pair":"BTC/USD","channel":"book","ts_exchange":"2026-09-16T00:17:19.333064Z","ts_recv":"2026-09-16T00:17:19.528716Z","payload":{"channel":"book","type":"update","data":[{"symbol":"BTC/USD","bids":[{"price":75724.3,"qty":0.02946967}],"asks":[],"checksum":995189229,"timestamp":"2026-09-16T00:17:19.333064Z"}]}}
{"v":1,"kind":"tick","pair":"ADA/USD","channel":"book","ts_exchange":"2026-09-16T00:17:19.418050Z","ts_recv":"2026-09-16T00:17:19.567706Z","payload":{"channel":"book","type":"update","data":[{"symbol":"ADA/USD","bids":[],"asks":[{"price":0.194786,"qty":0.0},{"price":0.194841,"qty":20349.83229176},{"price":0.194784,"qty":3079.1465085}],"checksum":1861870263,"timestamp":"2026-09-16T00:17:19.418050Z"}]}}
{"v":1,"kind":"tick","pair":"ADA/USD","channel":"book","ts_exchange":"2026-09-16T00:17:19.418961Z","ts_recv":"2026-09-16T00:17:19.567758Z","payload":{"channel":"book","type":"update","data":[{"symbol":"ADA/USD","bids":[],"asks":[{"price":0.194785,"qty":0.0},{"price":0.194841,"qty":20349.83229176}],"checksum":646902984,"timestamp":"2026-09-16T00:17:19.418961Z"}]}}
{"v":1,"kind":"tick","pair":"ADA/USD","channel":"book","ts_exchange":"2026-09-16T00:17:19.419004Z","ts_recv":"2026-09-16T00:17:19.567813Z","payload":{"channel":"book","type":"update","data":[{"symbol":"ADA/USD","bids":[],"asks":[{"price":0.194783,"qty":1947.18307933}],"checksum":2292082708,"timestamp":"2026-09-16T00:17:19.419004Z"}]}}
{"v":1,"kind":"tick","pair":"BTC/USD","channel":"book","ts_exchange":"2026-09-16T00:17:19.470376Z","ts_recv":"2026-09-16T00:17:19.596228Z","payload":{"channel":"book","type":"update","data":[{"symbol":"BTC/USD","bids":[{"price":75721.8,"qty":0.0},{"price":75719.6,"qty":0.000051}],"asks":[],"checksum":1599658122,"timestamp":"2026-09-16T00:17:19.470376Z"}]}}
{"v":1,"kind":"tick","pair":"BTC/USD","channel":"book","ts_exchange":"2026-09-16T00:17:19.513222Z","ts_recv":"2026-09-16T00:17:19.647487Z","payload":{"channel":"book","type":"update","data":[{"symbol":"BTC/USD","bids":[{"price":75723.8,"qty":0.99061375}],"asks":[],"checksum":4232483179,"timestamp":"2026-09-16T00:17:19.513222Z"}]}}
{"v":1,"kind":"tick","pair":"ADA/USD","channel":"book","ts_exchange":"2026-09-16T00:17:19.581062Z","ts_recv":"2026-09-16T00:17:19.707656Z","payload":{"channel":"book","type":"update","data":[{"symbol":"ADA/USD","bids":[],"asks":[{"price":0.194784,"qty":0.0},{"price":0.194841,"qty":20349.83229176},{"price":0.194782,"qty":3079.1465085}],"checksum":2406222354,"timestamp":"2026-09-16T00:17:19.581062Z"}]}}
{"v":1,"kind":"tick","pair":"ADA/USD","channel":"book","ts_exchange":"2026-09-16T00:17:19.582018Z","ts_recv":"2026-09-16T00:17:19.708442Z","payload":{"channel":"book","type":"update","data":[{"symbol":"ADA/USD","bids":[],"asks":[{"price":0.194783,"qty":0.0},{"price":0.194841,"qty":20349.83229176}],"checksum":1869816948,"timestamp":"2026-09-16T00:17:19.582018Z"}]}}
{"v":1,"kind":"tick","pair":"ADA/USD","channel":"book","ts_exchange":"2026-09-16T00:17:19.582064Z","ts_recv":"2026-09-16T00:17:19.708906Z","payload":{"channel":"book","type":"update","data":[{"symbol":"ADA/USD","bids":[],"asks":[{"price":0.194783,"qty":1028.05784654}],"checksum":3430188777,"timestamp":"2026-09-16T00:17:19.582064Z"}]}}
{"v":1,"kind":"tick","pair":"ADA/USD","channel":"book","ts_exchange":"2026-09-16T00:17:20.028987Z","ts_recv":"2026-09-16T00:17:20.163952Z","payload":{"channel":"book","type":"update","data":[{"symbol":"ADA/USD","bids":[],"asks":[{"price":0.194783,"qty":0.0},{"price":0.194841,"qty":20349.83229176}],"checksum":1869816948,"timestamp":"2026-09-16T00:17:20.028987Z"}]}}
{"v":1,"kind":"tick","pair":"ADA/USD","channel":"book","ts_exchange":"2026-09-16T00:17:20.030102Z","ts_recv":"2026-09-16T00:17:20.164656Z","payload":{"channel":"book","type":"update","data":[{"symbol":"ADA/USD","bids":[],"asks":[{"price":0.194782,"qty":0.0},{"price":0.194845,"qty":3008.7},{"price":0.194786,"qty":3079.1465085}],"checksum":505789276,"timestamp":"2026-09-16T00:17:20.030102Z"}]}}
{"v":1,"kind":"tick","pair":"ADA/USD","channel":"book","ts_exchange":"2026-09-16T00:17:20.030898Z","ts_recv":"2026-09-16T00:17:20.165200Z","payload":{"channel":"book","type":"update","data":[{"symbol":"ADA/USD","bids":[],"asks":[{"price":0.194785,"qty":1947.18307933}],"checksum":821530931,"timestamp":"2026-09-16T00:17:20.030898Z"}]}}
{"v":1,"kind":"tick","pair":"BTC/USD","channel":"book","ts_exchange":"2026-09-16T00:17:20.229703Z","ts_recv":"2026-09-16T00:17:20.364808Z","payload":{"channel":"book","type":"update","data":[{"symbol":"BTC/USD","bids":[{"price":75725.5,"qty":3.30139425}],"asks":[],"checksum":3360637206,"timestamp":"2026-09-16T00:17:20.229703Z"}]}}
{"v":1,"kind":"tick","pair":"BTC/USD","channel":"book","ts_exchange":"2026-09-16T00:17:20.230447Z","ts_recv":"2026-09-16T00:17:20.365358Z","payload":{"channel":"book","type":"update","data":[{"symbol":"BTC/USD","bids":[{"price":75724.3,"qty":0.01604467},{"price":75725.6,"qty":0.11117396}],"asks":[],"checksum":3828748278,"timestamp":"2026-09-16T00:17:20.230447Z"}]}}
{"v":1,"kind":"tick","pair":"BTC/USD","channel":"book","ts_exchange":"2026-09-16T00:17:20.230520Z","ts_recv":"2026-09-16T00:17:20.365857Z","payload":{"channel":"book","type":"update","data":[{"symbol":"BTC/USD","bids":[{"price":75724.3,"qty":0.0},{"price":75723.4,"qty":0.000051}],"asks":[],"checksum":3926860938,"timestamp":"2026-09-16T00:17:20.230520Z"}]}}
{"v":1,"kind":"tick","pair":"BTC/USD","channel":"book","ts_exchange":"2026-09-16T00:17:20.231207Z","ts_recv":"2026-09-16T00:17:20.366931Z","payload":{"channel":"book","type":"update","data":[{"symbol":"BTC/USD","bids":[{"price":75725.6,"qty":1.40838302}],"asks":[],"checksum":1739280428,"timestamp":"2026-09-16T00:17:20.231207Z"}]}}
{"v":1,"kind":"tick","pair":"BTC/USD","channel":"book","ts_exchange":"2026-09-16T00:17:20.233940Z","ts_recv":"2026-09-16T00:17:20.368607Z","payload":{"channel":"book","type":"update","data":[{"symbol":"BTC/USD","bids":[],"asks":[{"price":75732.6,"qty":0.0},{"price":75734.3,"qty":0.95245258}],"checksum":2827034671,"timestamp":"2026-09-16T00:17:20.233940Z"}]}}
{"v":1,"kind":"tick","pair":"BTC/USD","channel":"book","ts_exchange":"2026-09-16T00:17:20.234954Z","ts_recv":"2026-09-16T00:17:20.369558Z","payload":{"channel":"book","type":"update","data":[{"symbol":"BTC/USD","bids":[],"asks":[{"price":75731.9,"qty":1.41839658}],"checksum":2419737160,"timestamp":"2026-09-16T00:17:20.234954Z"}]}}
{"v":1,"kind":"tick","pair":"BTC/USD","channel":"book","ts_exchange":"2026-09-16T00:17:20.235057Z","ts_recv":"2026-09-16T00:17:20.371945Z","payload":{"channel":"book","type":"update","data":[{"symbol":"BTC/USD","bids":[],"asks":[{"price":75733.1,"qty":0.0},{"price":75734.4,"qty":3.30101414},{"price":75734.2,"qty":0.11117396}],"checksum":1501740281,"timestamp":"2026-09-16T00:17:20.235057Z"}]}}
{"v":1,"kind":"tick","pair":"BTC/USD","channel":"book","ts_exchange":"2026-09-16T00:17:20.269172Z","ts_recv":"2026-09-16T00:17:20.402470Z","payload":{"channel":"book","type":"update","data":[{"symbol":"BTC/USD","bids":[{"price":75728.1,"qty":0.0},{"price":75720.8,"qty":3.30160174}],"asks":[],"checksum":1089473845,"timestamp":"2026-09-16T00:17:20.269172Z"}]}}
{"v":1,"kind":"tick","pair":"BTC/USD","channel":"book","ts_exchange":"2026-09-16T00:17:20.270080Z","ts_recv":"2026-09-16T00:17:20.403506Z","payload":{"channel":"book","type":"update","data":[{"symbol":"BTC/USD","bids":[{"price":75727.2,"qty":1.32057944}],"asks":[],"checksum":2310946541,"timestamp":"2026-09-16T00:17:20.270080Z"}]}}
{"v":1,"kind":"tick","pair":"ADA/USD","channel":"book","ts_exchange":"2026-09-16T00:17:20.306730Z","ts_recv":"2026-09-16T00:17:20.446030Z","payload":{"channel":"book","type":"update","data":[{"symbol":"ADA/USD","bids":[],"asks":[{"price":0.194786,"qty":0.0},{"price":0.194841,"qty":20349.83229176},{"price":0.194784,"qty":3079.1465085}],"checksum":1861870263,"timestamp":"2026-09-16T00:17:20.306730Z"}]}}
{"v":1,"kind":"tick","pair":"ADA/USD","channel":"book","ts_exchange":"2026-09-16T00:17:20.307465Z","ts_recv":"2026-09-16T00:17:20.447269Z","payload":{"channel":"book","type":"update","data":[{"symbol":"ADA/USD","bids":[],"asks":[{"price":0.194785,"qty":0.0},{"price":0.194841,"qty":20349.83229176}],"checksum":646902984,"timestamp":"2026-09-16T00:17:20.307465Z"}]}}
{"v":1,"kind":"tick","pair":"ADA/USD","channel":"book","ts_exchange":"2026-09-16T00:17:20.308935Z","ts_recv":"2026-09-16T00:17:20.448388Z","payload":{"channel":"book","type":"update","data":[{"symbol":"ADA/USD","bids":[],"asks":[{"price":0.194783,"qty":1947.18307933}],"checksum":2292082708,"timestamp":"2026-09-16T00:17:20.308935Z"}]}}
{"v":1,"kind":"tick","pair":"ADA/USD","channel":"book","ts_exchange":"2026-09-16T00:17:20.531245Z","ts_recv":"2026-09-16T00:17:20.667982Z","payload":{"channel":"book","type":"update","data":[{"symbol":"ADA/USD","bids":[],"asks":[{"price":0.194784,"qty":0.0},{"price":0.194841,"qty":20349.83229176},{"price":0.194782,"qty":3079.1465085}],"checksum":2406222354,"timestamp":"2026-09-16T00:17:20.531245Z"}]}}
{"v":1,"kind":"tick","pair":"ADA/USD","channel":"book","ts_exchange":"2026-09-16T00:17:20.531960Z","ts_recv":"2026-09-16T00:17:20.675313Z","payload":{"channel":"book","type":"update","data":[{"symbol":"ADA/USD","bids":[],"asks":[{"price":0.194783,"qty":0.0},{"price":0.194841,"qty":20349.83229176}],"checksum":1869816948,"timestamp":"2026-09-16T00:17:20.531960Z"}]}}
{"v":1,"kind":"tick","pair":"ADA/USD","channel":"book","ts_exchange":"2026-09-16T00:17:20.532046Z","ts_recv":"2026-09-16T00:17:20.678184Z","payload":{"channel":"book","type":"update","data":[{"symbol":"ADA/USD","bids":[],"asks":[{"price":0.194783,"qty":1028.05784654}],"checksum":3430188777,"timestamp":"2026-09-16T00:17:20.532046Z"}]}}
{"v":1,"kind":"tick","pair":"BTC/USD","channel":"book","ts_exchange":"2026-09-16T00:17:21.397145Z","ts_recv":"2026-09-16T00:17:21.531822Z","payload":{"channel":"book","type":"update","data":[{"symbol":"BTC/USD","bids":[{"price":75723.8,"qty":0.0},{"price":75719.6,"qty":0.000051}],"asks":[],"checksum":4146967222,"timestamp":"2026-09-16T00:17:21.397145Z"}]}}
{"v":1,"kind":"tick","pair":"BTC/USD","channel":"book","ts_exchange":"2026-09-16T00:17:21.413443Z","ts_recv":"2026-09-16T00:17:21.550428Z","payload":{"channel":"book","type":"update","data":[{"symbol":"BTC/USD","bids":[{"price":75722.8,"qty":0.99061375}],"asks":[],"checksum":2068084792,"timestamp":"2026-09-16T00:17:21.413443Z"}]}}
{"v":1,"kind":"tick","pair":"BTC/USD","channel":"book","ts_exchange":"2026-09-16T00:17:21.658136Z","ts_recv":"2026-09-16T00:17:21.791462Z","payload":{"channel":"book","type":"update","data":[{"symbol":"BTC/USD","bids":[{"price":75731.8,"qty":0.38337943}],"asks":[],"checksum":653919855,"timestamp":"2026-09-16T00:17:21.658136Z"}]}}
{"v":1,"kind":"tick","pair":"BTC/USD","channel":"book","ts_exchange":"2026-09-16T00:17:22.162241Z","ts_recv":"2026-09-16T00:17:22.289059Z","payload":{"channel":"book","type":"update","data":[{"symbol":"BTC/USD","bids":[{"price":75731.8,"qty":0.00069517}],"asks":[],"checksum":2068084792,"timestamp":"2026-09-16T00:17:22.162241Z"}]}}
{"v":1,"kind":"tick","pair":"ADA/USD","channel":"book","ts_exchange":"2026-09-16T00:17:22.306718Z","ts_recv":"2026-09-16T00:17:22.437320Z","payload":{"channel":"book","type":"update","data":[{"symbol":"ADA/USD","bids":[],"asks":[{"price":0.194782,"qty":3068.18656354}],"checksum":983816179,"timestamp":"2026-09-16T00:17:22.306718Z"}]}}
{"v":1,"kind":"tick","pair":"ADA/USD","channel":"book","ts_exchange":"2026-09-16T00:17:22.325371Z","ts_recv":"2026-09-16T00:17:22.450779Z","payload":{"channel":"book","type":"update","data":[{"symbol":"ADA/USD","bids":[{"price":0.194678,"qty":0.0},{"price":0.194615,"qty":2569.17503789}],"asks":[],"checksum":1050684943,"timestamp":"2026-09-16T00:17:22.325371Z"}]}}
{"v":1,"kind":"tick","pair":"BTC/USD","channel":"book","ts_exchange":"2026-09-16T00:17:22.810508Z","ts_recv":"2026-09-16T00:17:22.936798Z","payload":{"channel":"book","type":"update","data":[{"symbol":"BTC/USD","bids":[{"price":75727.2,"qty":0.000051}],"asks":[],"checksum":2987019232,"timestamp":"2026-09-16T00:17:22.810508Z"}]}}
{"v":1,"kind":"tick","pair":"BTC/USD","channel":"book","ts_exchange":"2026-09-16T00:17:22.811210Z","ts_recv":"2026-09-16T00:17:22.945950Z","payload":{"channel":"book","type":"update","data":[{"symbol":"BTC/USD","bids":[{"price":75728.0,"qty":1.32051455}],"asks":[],"checksum":3849080519,"timestamp":"2026-09-16T00:17:22.811210Z"}]}}
{"v":1,"kind":"tick","pair":"BTC/USD","channel":"book","ts_exchange":"2026-09-16T00:17:22.813526Z","ts_recv":"2026-09-16T00:17:22.957218Z","payload":{"channel":"book","type":"update","data":[{"symbol":"BTC/USD","bids":[],"asks":[{"price":75731.9,"qty":1.396914}],"checksum":557770655,"timestamp":"2026-09-16T00:17:22.813526Z"}]}}
{"v":1,"kind":"tick","pair":"ADA/USD","channel":"book","ts_exchange":"2026-09-16T00:17:22.851108Z","ts_recv":"2026-09-16T00:17:22.980162Z","payload":{"channel":"book","type":"update","data":[{"symbol":"ADA/USD","bids":[],"asks":[{"price":0.194783,"qty":0.0},{"price":0.194841,"qty":20349.83229176}],"checksum":2531586979,"timestamp":"2026-09-16T00:17:22.851108Z"}]}}
{"v":1,"kind":"tick","pair":"ADA/USD","channel":"book","ts_exchange":"2026-09-16T00:17:22.851774Z","ts_recv":"2026-09-16T00:17:22.982145Z","payload":{"channel":"book","type":"update","data":[{"symbol":"ADA/USD","bids":[],"asks":[{"price":0.194782,"qty":0.0},{"price":0.194845,"qty":3008.7},{"price":0.194786,"qty":3079.14650844}],"checksum":2713832672,"timestamp":"2026-09-16T00:17:22.851774Z"}]}}
{"v":1,"kind":"tick","pair":"ADA/USD","channel":"book","ts_exchange":"2026-09-16T00:17:22.852541Z","ts_recv":"2026-09-16T00:17:22.983952Z","payload":{"channel":"book","type":"update","data":[{"symbol":"ADA/USD","bids":[],"asks":[{"price":0.194785,"qty":1947.18307931}],"checksum":1201060428,"timestamp":"2026-09-16T00:17:22.852541Z"}]}}
{"v":1,"kind":"tick","pair":"ADA/USD","channel":"book","ts_exchange":"2026-09-16T00:17:22.900663Z","ts_recv":"2026-09-16T00:17:23.026438Z","payload":{"channel":"book","type":"update","data":[{"symbol":"ADA/USD","bids":[],"asks":[{"price":0.194785,"qty":0.0},{"price":0.194841,"qty":20349.83229176}],"checksum":2713832672,"timestamp":"2026-09-16T00:17:22.900663Z"}]}}
{"v":1,"kind":"tick","pair":"ADA/USD","channel":"book","ts_exchange":"2026-09-16T00:17:23.061055Z","ts_recv":"2026-09-16T00:17:23.214678Z","payload":{"channel":"book","type":"update","data":[{"symbol":"ADA/USD","bids":[],"asks":[{"price":0.194785,"qty":1947.18307931}],"checksum":1201060428,"timestamp":"2026-09-16T00:17:23.061055Z"}]}}
{"v":1,"kind":"tick","pair":"ADA/USD","channel":"book","ts_exchange":"2026-09-16T00:17:23.062034Z","ts_recv":"2026-09-16T00:17:23.215026Z","payload":{"channel":"book","type":"update","data":[{"symbol":"ADA/USD","bids":[],"asks":[{"price":0.194786,"qty":0.0},{"price":0.194841,"qty":20349.83229176},{"price":0.194784,"qty":3079.14650844}],"checksum":2155704710,"timestamp":"2026-09-16T00:17:23.062034Z"}]}}
{"v":1,"kind":"tick","pair":"ADA/USD","channel":"book","ts_exchange":"2026-09-16T00:17:23.063837Z","ts_recv":"2026-09-16T00:17:23.215199Z","payload":{"channel":"book","type":"update","data":[{"symbol":"ADA/USD","bids":[],"asks":[{"price":0.194785,"qty":0.0},{"price":0.194841,"qty":20349.83229176}],"checksum":2573894516,"timestamp":"2026-09-16T00:17:23.063837Z"}]}}
{"v":1,"kind":"tick","pair":"ADA/USD","channel":"book","ts_exchange":"2026-09-16T00:17:23.064056Z","ts_recv":"2026-09-16T00:17:23.215528Z","payload":{"channel":"book","type":"update","data":[{"symbol":"ADA/USD","bids":[],"asks":[{"price":0.194785,"qty":1028.05784654}],"checksum":3307983877,"timestamp":"2026-09-16T00:17:23.064056Z"}]}}
{"v":1,"kind":"tick","pair":"ADA/USD","channel":"book","ts_exchange":"2026-09-16T00:17:23.326524Z","ts_recv":"2026-09-16T00:17:23.462360Z","payload":{"channel":"book","type":"update","data":[{"symbol":"ADA/USD","bids":[{"price":0.194683,"qty":1040.0}],"asks":[],"checksum":130511041,"timestamp":"2026-09-16T00:17:23.326524Z"}]}}
{"v":1,"kind":"tick","pair":"ADA/USD","channel":"book","ts_exchange":"2026-09-16T00:17:23.327213Z","ts_recv":"2026-09-16T00:17:23.462465Z","payload":{"channel":"book","type":"update","data":[{"symbol":"ADA/USD","bids":[{"price":0.194682,"qty":0.0},{"price":0.194615,"qty":2569.17503789},{"price":0.194684,"qty":3079.1465085}],"asks":[],"checksum":2120350267,"timestamp":"2026-09-16T00:17:23.327213Z"}]}}
{"v":1,"kind":"tick","pair":"BTC/USD","channel":"book","ts_exchange":"2026-09-16T00:17:23.336210Z","ts_recv":"2026-09-16T00:17:23.489285Z","payload":{"channel":"book","type":"update","data":[{"symbol":"BTC/USD","bids":[{"price":75731.8,"qty":0.00061717}],"asks":[],"checksum":3523330840,"timestamp":"2026-09-16T00:17:23.336210Z"}]}}
{"v":1,"kind":"tick","pair":"BTC/USD","channel":"book","ts_exchange":"2026-09-16T00:17:23.424155Z","ts_recv":"2026-09-16T00:17:23.552388Z","payload":{"channel":"book","type":"update","data":[{"symbol":"BTC/USD","bids":[{"price":75728.0,"qty":0.0},{"price":75720.8,"qty":3.30160174}],"asks":[],"checksum":2238170687,"timestamp":"2026-09-16T00:17:23.424155Z"}]}}
{"v":1,"kind":"tick","pair":"BTC/USD","channel":"book","ts_exchange":"2026-09-16T00:17:23.424239Z","ts_recv":"2026-09-16T00:17:23.552496Z","payload":{"channel":"book","type":"update","data":[{"symbol":"BTC/USD","bids":[{"price":75725.5,"qty":0.0},{"price":75719.6,"qty":0.000051}],"asks":[],"checksum":4242637899,"timestamp":"2026-09-16T00:17:23.424239Z"}]}}
{"v":1,"kind":"tick","pair":"BTC/USD","channel":"book","ts_exchange":"2026-09-16T00:17:23.425108Z","ts_recv":"2026-09-16T00:17:23.563715Z","payload":{"channel":"book","type":"update","data":[{"symbol":"BTC/USD","bids":[{"price":75725.6,"qty":0.11117396}],"asks":[],"checksum":2530751565,"timestamp":"2026-09-16T00:17:23.425108Z"}]}}
{"v":1,"kind":"tick","pair":"BTC/USD","channel":"book","ts_exchange":"2026-09-16T00:17:23.425156Z","ts_recv":"2026-09-16T00:17:23.564136Z","payload":{"channel":"book","type":"update","data":[{"symbol":"BTC/USD","bids":[{"price":75725.6,"qty":0.0},{"price":75719.4,"qty":0.02109115},{"price":75724.3,"qty":0.11117396}],"asks":[],"checksum":1022348819,"timestamp":"2026-09-16T00:17:23.425156Z"}]}}
{"v":1,"kind":"tick","pair":"BTC/USD","channel":"book","ts_exchange":"2026-09-16T00:17:23.425292Z","ts_recv":"2026-09-16T00:17:23.564532Z","payload":{"channel":"book","type":"update","data":[{"symbol":"BTC/USD","bids":[{"price":75726.8,"qty":1.32053631}],"asks":[],"checksum":1613086531,"timestamp":"2026-09-16T00:17:23.425292Z"}]}}
{"v":1,"kind":"tick","pair":"BTC/USD","channel":"book","ts_exchange":"2026-09-16T00:17:23.425528Z","ts_recv":"2026-09-16T00:17:23.564941Z","payload":{"channel":"book","type":"update","data":[{"symbol":"BTC/USD","bids":[{"price":75724.2,"qty":3.35515026}],"asks":[],"checksum":3572430138,"timestamp":"2026-09-16T00:17:23.425528Z"}]}}
{"v":1,"kind":"tick","pair":"BTC/USD","channel":"book","ts_exchange":"2026-09-16T00:17:23.426217Z","ts_recv":"2026-09-16T00:17:23.566054Z","payload":{"channel":"book","type":"update","data":[{"symbol":"BTC/USD","bids":[{"price":75722.9,"qty":0.2956982}],"asks":[],"checksum":633917328,"timestamp":"2026-09-16T00:17:23.426217Z"}]}}
{"v":1,"kind":"tick","pair":"BTC/USD","channel":"book","ts_exchange":"2026-09-16T00:17:23.426546Z","ts_recv":"2026-09-16T00:17:23.566422Z","payload":{"channel":"book","type":"update","data":[{"symbol":"BTC/USD","bids":[{"price":75722.9,"qty":0.0},{"price":75720.8,"qty":3.30160174}],"asks":[],"checksum":3572430138,"timestamp":"2026-09-16T00:17:23.426546Z"}]}}
{"v":1,"kind":"tick","pair":"BTC/USD","channel":"book","ts_exchange":"2026-09-16T00:17:23.427360Z","ts_recv":"2026-09-16T00:17:23.571965Z","payload":{"channel":"book","type":"update","data":[{"symbol":"BTC/USD","bids":[{"price":75724.3,"qty":1.40839974}],"asks":[],"checksum":3182997997,"timestamp":"2026-09-16T00:17:23.427360Z"}]}}
{"v":1,"kind":"tick","pair":"BTC/USD","channel":"book","ts_exchange":"2026-09-16T00:17:23.427592Z","ts_recv":"2026-09-16T00:17:23.572342Z","payload":{"channel":"book","type":"update","data":[{"symbol":"BTC/USD","bids":[],"asks":[{"price":75731.9,"qty":1.41839658}],"checksum":1624291759,"timestamp":"2026-09-16T00:17:23.427592Z"}]}}
{"v":1,"kind":"tick","pair":"BTC/USD","channel":"book","ts_exchange":"2026-09-16T00:17:23.490849Z","ts_recv":"2026-09-16T00:17:23.623869Z","payload":{"channel":"book","type":"update","data":[{"symbol":"BTC/USD","bids":[{"price":75726.8,"qty":0.0},{"price":75719.6,"qty":0.000051}],"asks":[],"checksum":362835085,"timestamp":"2026-09-16T00:17:23.490849Z"}]}}
{"v":1,"kind":"tick","pair":"BTC/USD","channel":"book","ts_exchange":"2026-09-16T00:17:23.733049Z","ts_recv":"2026-09-16T00:17:23.882119Z","payload":{"channel":"book","type":"update","data":[{"symbol":"BTC/USD","bids":[{"price":75726.6,"qty":1.32053931}],"asks":[],"checksum":3174106442,"timestamp":"2026-09-16T00:17:23.733049Z"}]}}
{"v":1,"kind":"tick","pair":"BTC/USD","channel":"book","ts_exchange":"2026-09-16T00:17:23.735615Z","ts_recv":"2026-09-16T00:17:23.924698Z","payload":{"channel":"book","type":"update","data":[{"symbol":"BTC/USD","bids":[{"price":75722.8,"qty":0.0},{"price":75719.6,"qty":0.000051}],"asks":[],"checksum":3398124026,"timestamp":"2026-09-16T00:17:23.735615Z"}]}}
{"v":1,"kind":"tick","pair":"BTC/USD","channel":"book","ts_exchange":"2026-09-16T00:17:23.735698Z","ts_recv":"2026-09-16T00:17:23.926425Z","payload":{"channel":"book","type":"update","data":[{"symbol":"BTC/USD","bids":[],"asks":[{"price":75731.9,"qty":1.396914}],"checksum":712400279,"timestamp":"2026-09-16T00:17:23.735698Z"}]}}
{"v":1,"kind":"tick","pair":"BTC/USD","channel":"book","ts_exchange":"2026-09-16T00:17:23.735737Z","ts_recv":"2026-09-16T00:17:23.926594Z","payload":{"channel":"book","type":"update","data":[{"symbol":"BTC/USD","bids":[{"price":75728.4,"qty":0.0},{"price":75719.4,"qty":0.02109115}],"asks":[],"checksum":1469981025,"timestamp":"2026-09-16T00:17:23.735737Z"}]}}
{"v":1,"kind":"tick","pair":"ADA/USD","channel":"book","ts_exchange":"2026-09-16T00:17:23.735919Z","ts_recv":"2026-09-16T00:17:23.927687Z","payload":{"channel":"book","type":"update","data":[{"symbol":"ADA/USD","bids":[{"price":0.19465,"qty":0.0},{"price":0.194615,"qty":2569.17503789}],"asks":[],"checksum":838418315,"timestamp":"2026-09-16T00:17:23.735919Z"}]}}
{"v":1,"kind":"tick","pair":"BTC/USD","channel":"book","ts_exchange":"2026-09-16T00:17:23.737316Z","ts_recv":"2026-09-16T00:17:23.928052Z","payload":{"channel":"book","type":"update","data":[{"symbol":"BTC/USD","bids":[{"price":75726.6,"qty":0.0},{"price":75717.0,"qty":0.00006024}],"asks":[],"checksum":2599486913,"timestamp":"2026-09-16T00:17:23.737316Z"}]}}
{"v":1,"kind":"tick","pair":"ADA/USD","channel":"book","ts_exchange":"2026-09-16T00:17:23.738833Z","ts_recv":"2026-09-16T00:17:23.929575Z","payload":{"channel":"book","type":"update","data":[{"symbol":"ADA/USD","bids":[],"asks":[{"price":0.194783,"qty":1947.18307931}],"checksum":1615353844,"timestamp":"2026-09-16T00:17:23.738833Z"}]}}
{"v":1,"kind":"tick","pair":"ADA/USD","channel":"book","ts_exchange":"2026-09-16T00:17:23.738911Z","ts_recv":"2026-09-16T00:17:23.929733Z","payload":{"channel":"book","type":"update","data":[{"symbol":"ADA/USD","bids":[{"price":0.194652,"qty":100.0}],"asks":[],"checksum":414410874,"timestamp":"2026-09-16T00:17:23.738911Z"}]}}
{"v":1,"kind":"tick","pair":"ADA/USD","channel":"book","ts_exchange":"2026-09-16T00:17:23.739103Z","ts_recv":"2026-09-16T00:17:23.930059Z","payload":{"channel":"book","type":"update","data":[{"symbol":"ADA/USD","bids":[],"asks":[{"price":0.194785,"qty":0.0},{"price":0.19484,"qty":7891.99819803}],"checksum":371035434,"timestamp":"2026-09-16T00:17:23.739103Z"}]}}
{"v":1,"kind":"tick","pair":"ADA/USD","channel":"book","ts_exchange":"2026-09-16T00:17:23.739214Z","ts_recv":"2026-09-16T00:17:23.930225Z","payload":{"channel":"book","type":"update","data":[{"symbol":"ADA/USD","bids":[{"price":0.194648,"qty":1201.63699232}],"asks":[],"checksum":332862748,"timestamp":"2026-09-16T00:17:23.739214Z"}]}}
{"v":1,"kind":"tick","pair":"BTC/USD","channel":"book","ts_exchange":"2026-09-16T00:17:23.740137Z","ts_recv":"2026-09-16T00:17:23.931326Z","payload":{"channel":"book","type":"update","data":[{"symbol":"BTC/USD","bids":[],"asks":[{"price":75731.9,"qty":1.41839658}],"checksum":1600577428,"timestamp":"2026-09-16T00:17:23.740137Z"}]}}
{"v":1,"kind":"tick","pair":"ADA/USD","channel":"book","ts_exchange":"2026-09-16T00:17:23.740755Z","ts_recv":"2026-09-16T00:17:23.932981Z","payload":{"channel":"book","type":"update","data":[{"symbol":"ADA/USD","bids":[],"asks":[{"price":0.194784,"qty":0.0},{"price":0.194841,"qty":20349.83229176},{"price":0.194782,"qty":3079.14650844}],"checksum":1620639259,"timestamp":"2026-09-16T00:17:23.740755Z"}]}}
{"v":1,"kind":"tick","pair":"BTC/USD","channel":"book","ts_exchange":"2026-09-16T00:17:23.742765Z","ts_recv":"2026-09-16T00:17:23.933703Z","payload":{"channel":"book","type":"update","data":[{"symbol":"BTC/USD","bids":[{"price":75720.8,"qty":0.0},{"price":75716.7,"qty":0.1}],"asks":[],"checksum":793861999,"timestamp":"2026-09-16T00:17:23.742765Z"}]}}
{"v":1,"kind":"tick","pair":"BTC/USD","channel":"book","ts_exchange":"2026-09-16T00:17:23.743035Z","ts_recv":"2026-09-16T00:17:23.934249Z","payload":{"channel":"book","type":"update","data":[{"symbol":"BTC/USD","bids":[{"price":75724.2,"qty":0.0537}],"asks":[],"checksum":3296639912,"timestamp":"2026-09-16T00:17:23.743035Z"}]}}
{"v":1,"kind":"tick","pair":"ADA/USD","channel":"book","ts_exchange":"2026-09-16T00:17:23.743757Z","ts_recv":"2026-09-16T00:17:23.934723Z","payload":{"channel":"book","type":"update","data":[{"symbol":"ADA/USD","bids":[],"asks":[{"price":0.194783,"qty":0.0},{"price":0.194841,"qty":20349.83229176}],"checksum":347812128,"timestamp":"2026-09-16T00:17:23.743757Z"}]}}
{"v":1,"kind":"tick","pair":"ADA/USD","channel":"book","ts_exchange":"2026-09-16T00:17:23.743930Z","ts_recv":"2026-09-16T00:17:23.935042Z","payload":{"channel":"book","type":"update","data":[{"symbol":"ADA/USD","bids":[],"asks":[{"price":0.194781,"qty":1947.18307931}],"checksum":707521369,"timestamp":"2026-09-16T00:17:23.743930Z"}]}}
{"v":1,"kind":"tick","pair":"BTC/USD","channel":"book","ts_exchange":"2026-09-16T00:17:23.746405Z","ts_recv":"2026-09-16T00:17:23.936133Z","payload":{"channel":"book","type":"update","data":[{"symbol":"BTC/USD","bids":[{"price":75724.3,"qty":0.11117396}],"asks":[],"checksum":843700010,"timestamp":"2026-09-16T00:17:23.746405Z"}]}}
{"v":1,"kind":"tick","pair":"BTC/USD","channel":"book","ts_exchange":"2026-09-16T00:17:23.746617Z","ts_recv":"2026-09-16T00:17:23.936442Z","payload":{"channel":"book","type":"update","data":[{"symbol":"BTC/USD","bids":[{"price":75722.8,"qty":3.30151438}],"asks":[],"checksum":2287272246,"timestamp":"2026-09-16T00:17:23.746617Z"}]}}
{"v":1,"kind":"tick","pair":"BTC/USD","channel":"book","ts_exchange":"2026-09-16T00:17:23.746753Z","ts_recv":"2026-09-16T00:17:23.936593Z","payload":{"channel":"book","type":"update","data":[{"symbol":"BTC/USD","bids":[{"price":75718.1,"qty":3.30171989}],"asks":[],"checksum":2383703862,"timestamp":"2026-09-16T00:17:23.746753Z"}]}}
{"v":1,"kind":"tick","pair":"BTC/USD","channel":"book","ts_exchange":"2026-09-16T00:17:23.747626Z","ts_recv":"2026-09-16T00:17:23.936748Z","payload":{"channel":"book","type":"update","data":[{"symbol":"BTC/USD","bids":[{"price":75724.4,"qty":0.0492301}],"asks":[],"checksum":1019736501,"timestamp":"2026-09-16T00:17:23.747626Z"}]}}
{"v":1,"kind":"tick","pair":"BTC/USD","channel":"book","ts_exchange":"2026-09-16T00:17:23.767622Z","ts_recv":"2026-09-16T00:17:23.940896Z","payload":{"channel":"book","type":"update","data":[{"symbol":"BTC/USD","bids":[],"asks":[{"price":75731.9,"qty":1.45267597}],"checksum":3428210859,"timestamp":"2026-09-16T00:17:23.767622Z"}]}}
{"v":1,"kind":"tick","pair":"ADA/USD","channel":"book","ts_exchange":"2026-09-16T00:17:23.790226Z","ts_recv":"2026-09-16T00:17:23.972969Z","payload":{"channel":"book","type":"update","data":[{"symbol":"ADA/USD","bids":[],"asks":[{"price":0.194781,"qty":0.0},{"price":0.194841,"qty":20349.83229176}],"checksum":347812128,"timestamp":"2026-09-16T00:17:23.790226Z"}]}}
{"v":1,"kind":"tick","pair":"ADA/USD","channel":"book","ts_exchange":"2026-09-16T00:17:23.791974Z","ts_recv":"2026-09-16T00:17:23.980655Z","payload":{"channel":"book","type":"update","data":[{"symbol":"ADA/USD","bids":[{"price":0.194648,"qty":4653.35632434}],"asks":[],"checksum":1855164748,"timestamp":"2026-09-16T00:17:23.791974Z"}]}}
{"v":1,"kind":"tick","pair":"BTC/USD","channel":"book","ts_exchange":"2026-09-16T00:17:23.853652Z","ts_recv":"2026-09-16T00:17:24.052254Z","payload":{"channel":"book","type":"update","data":[{"symbol":"BTC/USD","bids":[{"price":75722.6,"qty":0.9904235}],"asks":[],"checksum":2466366981,"timestamp":"2026-09-16T00:17:23.853652Z"}]}}
{"v":1,"kind":"tick","pair":"ADA/USD","channel":"book","ts_exchange":"2026-09-16T00:17:23.884270Z","ts_recv":"2026-09-16T00:17:24.087453Z","payload":{"channel":"book","type":"update","data":[{"symbol":"ADA/USD","bids":[],"asks":[{"price":0.194782,"qty":0.0},{"price":0.194845,"qty":3008.7},{"price":0.194786,"qty":3079.14650844}],"checksum":2307469320,"timestamp":"2026-09-16T00:17:23.884270Z"}]}}
{"v":1,"kind":"tick","pair":"BTC/USD","channel":"book","ts_exchange":"2026-09-16T00:17:23.894116Z","ts_recv":"2026-09-16T00:17:24.106462Z","payload":{"channel":"book","type":"update","data":[{"symbol":"BTC/USD","bids":[{"price":75722.8,"qty":0.0},{"price":75719.4,"qty":0.02109115}],"asks":[],"checksum":1505605232,"timestamp":"2026-09-16T00:17:23.894116Z"}]}}
{"v":1,"kind":"tick","pair":"BTC/USD","channel":"book","ts_exchange":"2026-09-16T00:17:23.895392Z","ts_recv":"2026-09-16T00:17:24.111753Z","payload":{"channel":"book","type":"update","data":[{"symbol":"BTC/USD","bids":[{"price":75727.0,"qty":1.32053278}],"asks":[],"checksum":4129755982,"timestamp":"2026-09-16T00:17:23.895392Z"}]}}
{"v":1,"kind":"tick","pair":"BTC/USD","channel":"book","ts_exchange":"2026-09-16T00:17:23.897927Z","ts_recv":"2026-09-16T00:17:24.112541Z","payload":{"channel":"book","type":"update","data":[{"symbol":"BTC/USD","bids":[],"asks":[{"price":75731.9,"qty":1.43119339}],"checksum":1634830133,"timestamp":"2026-09-16T00:17:23.897927Z"}]}}
{"v":1,"kind":"tick","pair":"BTC/USD","channel":"book","ts_exchange":"2026-09-16T00:17:24.055257Z","ts_recv":"2026-09-16T00:17:24.217594Z","payload":{"channel":"book","type":"update","data":[{"symbol":"BTC/USD","bids":[{"price":75724.3,"qty":0.0},{"price":75719.4,"qty":0.02109115},{"price":75724.5,"qty":0.01320355}],"asks":[],"checksum":3229981024,"timestamp":"2026-09-16T00:17:24.055257Z"}]}}
{"v":1,"kind":"tick","pair":"BTC/USD","channel":"book","ts_exchange":"2026-09-16T00:17:24.059043Z","ts_recv":"2026-09-16T00:17:24.219535Z","payload":{"channel":"book","type":"update","data":[{"symbol":"BTC/USD","bids":[{"price":75727.0,"qty":0.0},{"price":75719.4,"qty":0.02109115}],"asks":[],"checksum":812096734,"timestamp":"2026-09-16T00:17:24.059043Z"}]}}
{"v":1,"kind":"tick","pair":"BTC/USD","channel":"book","ts_exchange":"2026-09-16T00:17:24.059907Z","ts_recv":"2026-09-16T00:17:24.219726Z","payload":{"channel":"book","type":"update","data":[{"symbol":"BTC/USD","bids":[{"price":75727.8,"qty":1.32051818}],"asks":[],"checksum":1143137631,"timestamp":"2026-09-16T00:17:24.059907Z"}]}}
{"v":1,"kind":"tick","pair":"BTC/USD","channel":"book","ts_exchange":"2026-09-16T00:17:24.060098Z","ts_recv":"2026-09-16T00:17:24.220194Z","payload":{"channel":"book","type":"update","data":[{"symbol":"BTC/USD","bids":[{"price":75724.4,"qty":3.35067154}],"asks":[],"checksum":1815389194,"timestamp":"2026-09-16T00:17:24.060098Z"}]}}
{"v":1,"kind":"tick","pair":"BTC/USD","channel":"book","ts_exchange":"2026-09-16T00:17:24.061418Z","ts_recv":"2026-09-16T00:17:24.220635Z","payload":{"channel":"book","type":"update","data":[{"symbol":"BTC/USD","bids":[{"price":75724.4,"qty":3.30144144}],"asks":[],"checksum":3425492696,"timestamp":"2026-09-16T00:17:24.061418Z"}]}}
{"v":1,"kind":"tick","pair":"BTC/USD","channel":"book","ts_exchange":"2026-09-16T00:17:24.061638Z","ts_recv":"2026-09-16T00:17:24.220840Z","payload":{"channel":"book","type":"update","data":[{"symbol":"BTC/USD","bids":[],"asks":[{"price":75731.9,"qty":1.45267597}],"checksum":191635704,"timestamp":"2026-09-16T00:17:24.061638Z"}]}}
{"v":1,"kind":"tick","pair":"BTC/USD","channel":"book","ts_exchange":"2026-09-16T00:17:24.062510Z","ts_recv":"2026-09-16T00:17:24.221241Z","payload":{"channel":"book","type":"update","data":[{"symbol":"BTC/USD","bids":[{"price":75727.9,"qty":0.3941899}],"asks":[],"checksum":504302215,"timestamp":"2026-09-16T00:17:24.062510Z"}]}}
{"v":1,"kind":"tick","pair":"BTC/USD","channel":"book","ts_exchange":"2026-09-16T00:17:24.064265Z","ts_recv":"2026-09-16T00:17:24.226651Z","payload":{"channel":"book","type":"update","data":[{"symbol":"BTC/USD","bids":[],"asks":[{"price":75731.9,"qty":1.43119339}],"checksum":4095665013,"timestamp":"2026-09-16T00:17:24.064265Z"}]}}
{"v":1,"kind":"tick","pair":"BTC/USD","channel":"book","ts_exchange":"2026-09-16T00:17:24.109359Z","ts_recv":"2026-09-16T00:17:24.257265Z","payload":{"channel":"book","type":"update","data":[{"symbol":"BTC/USD","bids":[{"price":75727.9,"qty":0.0},{"price":75719.6,"qty":0.000051}],"asks":[],"checksum":3425492696,"timestamp":"2026-09-16T00:17:24.109359Z"}]}}
{"v":1,"kind":"tick","pair":"BTC/USD","channel":"book","ts_exchange":"2026-09-16T00:17:24.117783Z","ts_recv":"2026-09-16T00:17:24.266366Z","payload":{"channel":"book","type":"update","data":[{"symbol":"BTC/USD","bids":[{"price":75724.5,"qty":1.31036991}],"asks":[],"checksum":3608992931,"timestamp":"2026-09-16T00:17:24.117783Z"}]}}
{"v":1,"kind":"tick","pair":"ADA/USD","channel":"book","ts_exchange":"2026-09-16T00:17:24.186498Z","ts_recv":"2026-09-16T00:17:24.355699Z","payload":{"channel":"book","type":"update","data":[{"symbol":"ADA/USD","bids":[],"asks":[{"price":0.194785,"qty":1947.18307931}],"checksum":3181616455,"timestamp":"2026-09-16T00:17:24.186498Z"}]}}
{"v":1,"kind":"tick","pair":"ADA/USD","channel":"book","ts_exchange":"2026-09-16T00:17:24.187624Z","ts_recv":"2026-09-16T00:17:24.359601Z","payload":{"channel":"book","type":"update","data":[{"symbol":"ADA/USD","bids":[],"asks":[{"price":0.194786,"qty":0.0},{"price":0.194841,"qty":20349.83229176},{"price":0.194784,"qty":3079.14650844}],"checksum":2176901948,"timestamp":"2026-09-16T00:17:24.187624Z"}]}}
